File: Tests de traction/Fichiers source/04_07_2016/Sample_8_1kN.txt
Time (s)	Load (N)	Machine Extension (mm)	Stress (MPa)	Extension from Preload (mm)	Strain	Percentage Strain	Gauge Length (mm)
0
0,658	0,70963	0,068612	2,2891	-0,072167	-0,0059153	-0,59153	12,128
1,316	7,5097	0,13754	24,225	-0,0032353	-0,00026519	-0,026519	12,197
1,974	8,1033	0,14451	26,14	0,0037351	0,00030616	0,030616	12,204
2,632	9,9159	0,16079	31,987	0,020008	0,00164	0,164	12,22
3,29	11,576	0,17785	37,342	0,03707	0,0030385	0,30385	12,237
3,948	11,232	0,17962	36,231	0,038839	0,0031836	0,31836	12,239
4,606	12,406	0,19272	40,02	0,051945	0,0042577	0,42577	12,252
5,264	13,431	0,20451	43,326	0,063732	0,0052239	0,52239	12,264
5,922	14,386	0,21728	46,407	0,076499	0,0062704	0,62704	12,276
6,58	14,996	0,22776	48,373	0,086978	0,0071293	0,71293	12,287
7,238	15,885	0,23742	51,241	0,096639	0,0079212	0,79212	12,297
7,896	16,433	0,24881	53,009	0,10803	0,0088553	0,88553	12,308
8,554	17,201	0,26025	55,489	0,11947	0,0097926	0,97926	12,319
9,212	17,697	0,27057	57,087	0,12979	0,010639	1,0639	12,33
9,87	18,515	0,28205	59,726	0,14127	0,01158	1,158	12,341
10,53	18,973	0,29022	61,204	0,14944	0,012249	1,2249	12,349
11,19	19,582	0,30252	63,168	0,16174	0,013257	1,3257	12,362
11,84	20,385	0,3173	65,759	0,17652	0,014469	1,4469	12,377
12,5	20,627	0,32553	66,538	0,18475	0,015144	1,5144	12,385
13,16	21,172	0,33486	68,297	0,19408	0,015908	1,5908	12,394
13,82	21,702	0,34752	70,006	0,20674	0,016946	1,6946	12,407
14,48	22,18	0,35895	71,549	0,21817	0,017883	1,7883	12,418
15,13	22,408	0,37003	72,285	0,22925	0,018791	1,8791	12,429
15,79	23,035	0,38027	74,306	0,23949	0,01963	1,963	12,439
16,45	23,288	0,39146	75,122	0,25069	0,020548	2,0548	12,451
17,11	23,589	0,40216	76,095	0,26138	0,021424	2,1424	12,461
17,77	24,049	0,41763	77,577	0,27685	0,022693	2,2693	12,477
18,42	23,432	0,4176	75,587	0,27683	0,022691	2,2691	12,477
19,08	24,224	0,43312	78,143	0,29234	0,023962	2,3962	12,492
19,74	24,608	0,44514	79,382	0,30436	0,024948	2,4948	12,504
20,4	25,38	0,46428	81,872	0,3235	0,026517	2,6517	12,524
21,06	24,481	0,46429	78,97	0,32351	0,026517	2,6517	12,524
21,71	25,07	0,47846	80,872	0,33768	0,027679	2,7679	12,538
22,37	25,358	0,49028	81,8	0,3495	0,028647	2,8647	12,549
23,03	25,775	0,5038	83,144	0,36302	0,029756	2,9756	12,563
23,69	25,481	0,51314	82,198	0,37236	0,030522	3,0522	12,572
24,35	25,633	0,52347	82,686	0,38269	0,031368	3,1368	12,583
25	25,519	0,53278	82,321	0,392	0,032131	3,2131	12,592
25,66	25,705	0,54453	82,919	0,40375	0,033094	3,3094	12,604
26,32	26,211	0,56273	84,552	0,42195	0,034586	3,4586	12,622
26,98	25,224	0,56278	81,369	0,42201	0,034591	3,4591	12,622
27,64	25,765	0,57575	83,114	0,43498	0,035654	3,5654	12,635
28,29	25,813	0,58733	83,268	0,44655	0,036602	3,6602	12,647
28,95	26,692	0,60834	86,103	0,46756	0,038324	3,8324	12,668
29,61	25,559	0,60962	82,447	0,46885	0,03843	3,843	12,669
30,27	26,026	0,62063	83,956	0,47985	0,039332	3,9332	12,68
30,93	26,051	0,63253	84,037	0,49175	0,040308	4,0308	12,692
31,58	26,089	0,64396	84,156	0,50318	0,041245	4,1245	12,703
32,24	26,118	0,65497	84,252	0,51419	0,042147	4,2147	12,714
32,9	26,239	0,66663	84,643	0,52586	0,043103	4,3103	12,726
33,56	26,18	0,67503	84,452	0,53425	0,043791	4,3791	12,734
34,22	26,251	0,68715	84,682	0,54637	0,044784	4,4784	12,746
34,87	26,661	0,70489	86,004	0,56411	0,046238	4,6238	12,764
35,53	25,665	0,70455	82,791	0,56377	0,046211	4,6211	12,764
36,19	26,272	0,71817	84,748	0,57739	0,047327	4,7327	12,777
36,85	26,382	0,73095	85,102	0,59017	0,048375	4,8375	12,79
37,51	27,086	0,75011	87,375	0,60933	0,049945	4,9945	12,809
38,16	26,007	0,75023	83,893	0,60946	0,049955	4,9955	12,809
38,82	26,428	0,76314	85,25	0,62237	0,051014	5,1014	12,822
39,48	26,614	0,77532	85,851	0,63454	0,052011	5,2011	12,835
40,14	26,85	0,78661	86,612	0,64583	0,052937	5,2937	12,846
40,8	26,419	0,79655	85,221	0,65577	0,053751	5,3751	12,856
41,45	26,632	0,8074	85,911	0,66662	0,054641	5,4641	12,867
42,11	26,712	0,81848	86,169	0,6777	0,055549	5,5549	12,878
42,77	26,627	0,82937	85,895	0,68859	0,056442	5,6442	12,889
43,43	26,785	0,84462	86,402	0,70384	0,057692	5,7692	12,904
44,09	26,563	0,85087	85,686	0,71009	0,058204	5,8204	12,91
44,74	26,391	0,86078	85,132	0,72	0,059016	5,9016	12,92
45,4	26,563	0,87252	85,688	0,73174	0,059979	5,9979	12,932
46,06	27,252	0,89391	87,91	0,75313	0,061732	6,1732	12,953
46,72	26,038	0,89396	83,994	0,75318	0,061736	6,1736	12,953
47,38	26,484	0,90597	85,432	0,76519	0,06272	6,272	12,965
48,03	26,524	0,91807	85,562	0,77729	0,063712	6,3712	12,977
48,69	26,565	0,92922	85,694	0,78845	0,064627	6,4627	12,988
49,35	26,199	0,9387	84,512	0,79792	0,065403	6,5403	12,998
50,01	26,181	0,95186	84,456	0,81108	0,066482	6,6482	13,011
50,67	25,703	0,95977	82,912	0,81899	0,06713	6,713	13,019
51,32	25,689	0,97164	82,869	0,83086	0,068103	6,8103	13,031
51,98	26,045	0,98855	84,018	0,84777	0,06949	6,949	13,048
52,64	25,033	0,98865	80,751	0,84787	0,069498	6,9498	13,048
53,3	25,672	1,0041	82,812	0,86333	0,070765	7,0765	13,063
53,96	26,033	1,0161	83,976	0,87535	0,07175	7,175	13,075
54,61	26,724	1,0348	86,207	0,89406	0,073284	7,3284	13,094
55,27	25,511	1,0354	82,295	0,89462	0,073329	7,3329	13,095
55,93	26,121	1,0483	84,261	0,90754	0,074389	7,4389	13,108
56,59	26,111	1,0603	84,23	0,91957	0,075374	7,5374	13,12
57,25	26,255	1,0716	84,693	0,93085	0,076299	7,6299	13,131
57,9	26,36	1,0842	85,033	0,94345	0,077332	7,7332	13,143
58,56	26,449	1,0952	85,319	0,95441	0,078231	7,8231	13,154
59,22	26,078	1,1019	84,123	0,96116	0,078784	7,8784	13,161
59,88	26,258	1,1138	84,705	0,97298	0,079753	7,9753	13,173
60,54	26,785	1,132	86,403	0,99126	0,081251	8,1251	13,191
61,19	25,947	1,1345	83,701	0,99376	0,081456	8,1456	13,194
61,85	26,216	1,1475	84,567	1,0067	0,082515	8,2515	13,207
62,51	26,397	1,1581	85,153	1,0173	0,083384	8,3384	13,217
63,17	26,812	1,1736	86,49	1,0328	0,084657	8,4657	13,233
63,83	26,032	1,1791	83,976	1,0383	0,08511	8,511	13,238
64,48	26,373	1,191	85,075	1,0502	0,08608	8,608	13,25
65,14	26,392	1,2024	85,136	1,0616	0,087019	8,7019	13,262
65,8	26,612	1,2145	85,846	1,0737	0,088007	8,8007	13,274
66,46	26,454	1,2256	85,336	1,0848	0,08892	8,892	13,285
67,12	26,563	1,2373	85,688	1,0965	0,089877	8,9877	13,297
67,77	26,2	1,2445	84,515	1,1037	0,090466	9,0466	13,304
68,43	26,355	1,2565	85,017	1,1157	0,091452	9,1452	13,316
69,09	26,666	1,2715	86,019	1,1308	0,092685	9,2685	13,331
69,75	26,407	1,279	85,183	1,1383	0,093299	9,3299	13,338
70,41	26,256	1,2892	84,698	1,1484	0,09413	9,413	13,348
71,06	26,49	1,3012	85,45	1,1605	0,09512	9,512	13,36
71,72	26,803	1,3158	86,463	1,1751	0,096316	9,6316	13,375
72,38	26,668	1,3247	86,025	1,1839	0,097043	9,7043	13,384
73,04	26,372	1,3326	85,07	1,1918	0,097692	9,7692	13,392
73,7	26,566	1,3451	85,696	1,2043	0,098714	9,8714	13,404
74,35	26,611	1,357	85,844	1,2162	0,099693	9,9693	13,416
75,01	26,584	1,3684	85,755	1,2276	0,10062	10,062	13,428
75,67	26,518	1,3785	85,541	1,2377	0,10145	10,145	13,438
76,33	26,461	1,388	85,358	1,2472	0,10223	10,223	13,447
76,99	26,438	1,3989	85,285	1,2581	0,10313	10,313	13,458
77,64	26,893	1,4164	86,75	1,2756	0,10456	10,456	13,476
78,3	25,996	1,4166	83,859	1,2758	0,10457	10,457	13,476
78,96	26,431	1,4313	85,262	1,2906	0,10578	10,578	13,491
79,62	26,386	1,4434	85,117	1,3027	0,10678	10,678	13,503
80,28	26,835	1,4603	86,564	1,3196	0,10816	10,816	13,52
80,93	25,931	1,4633	83,648	1,3225	0,1084	10,84	13,523
81,59	26,137	1,4755	84,313	1,3347	0,10941	10,941	13,535
82,25	26,268	1,4878	84,736	1,347	0,11041	11,041	13,547
82,91	26,009	1,4992	83,9	1,3584	0,11135	11,135	13,558
83,57	25,529	1,5135	82,353	1,3727	0,11252	11,252	13,573
84,22	24,855	1,5171	80,178	1,3763	0,11281	11,281	13,576
84,88	25,084	1,5297	80,917	1,3889	0,11385	11,385	13,589
85,54	25,133	1,5419	81,073	1,4011	0,11484	11,484	13,601
86,2	25,544	1,5587	82,399	1,4179	0,11622	11,622	13,618
86,86	24,65	1,5592	79,516	1,4185	0,11627	11,627	13,618
87,51	25,095	1,5748	80,951	1,434	0,11754	11,754	13,634
88,17	25,274	1,5861	81,528	1,4453	0,11847	11,847	13,645
88,83	25,404	1,5984	81,95	1,4576	0,11948	11,948	13,658
89,49	25,223	1,6093	81,364	1,4685	0,12037	12,037	13,669
90,15	25,45	1,6199	82,096	1,4791	0,12124	12,124	13,679
90,8	25,324	1,6302	81,691	1,4894	0,12209	12,209	13,689
91,46	25,372	1,6419	81,845	1,5011	0,12304	12,304	13,701
92,12	25,708	1,6556	82,93	1,5148	0,12417	12,417	13,715
92,78	25,677	1,6654	82,829	1,5246	0,12497	12,497	13,725
93,44	25,326	1,6724	81,697	1,5316	0,12554	12,554	13,732
94,09	25,389	1,6847	81,899	1,544	0,12655	12,655	13,744
94,75	26,171	1,704	84,424	1,5632	0,12813	12,813	13,763
95,41	25,078	1,7042	80,895	1,5634	0,12815	12,815	13,763
96,07	25,512	1,7183	82,298	1,5775	0,1293	12,93	13,777
96,73	25,522	1,7288	82,33	1,5881	0,13017	13,017	13,788
97,38	25,7	1,7416	82,902	1,6008	0,13121	13,121	13,801
98,04	25,357	1,7498	81,798	1,6091	0,13189	13,189	13,809
98,7	25,516	1,7621	82,31	1,6214	0,1329	13,29	13,821
99,36	25,561	1,7717	82,454	1,6309	0,13368	13,368	13,831
100	25,683	1,7846	82,848	1,6439	0,13474	13,474	13,844
100,7	25,837	1,798	83,344	1,6572	0,13584	13,584	13,857
101,3	25,81	1,8085	83,26	1,6677	0,1367	13,67	13,868
102	25,408	1,8143	81,961	1,6735	0,13718	13,718	13,874
102,6	25,381	1,8269	81,875	1,6861	0,13821	13,821	13,886
103,3	25,81	1,8474	83,258	1,7066	0,13988	13,988	13,907
104	24,85	1,8475	80,162	1,7067	0,1399	13,99	13,907
104,6	25,187	1,86	81,248	1,7192	0,14092	14,092	13,919
105,3	25,297	1,8716	81,603	1,7308	0,14187	14,187	13,931
105,9	25,63	1,8851	82,677	1,7443	0,14298	14,298	13,944
106,6	25,43	1,8944	82,033	1,7536	0,14374	14,374	13,954
107,3	25,32	1,9035	81,677	1,7627	0,14449	14,449	13,963
107,9	25,438	1,9156	82,058	1,7748	0,14548	14,548	13,975
108,6	25,431	1,9271	82,036	1,7863	0,14642	14,642	13,986
109,2	25,448	1,9388	82,091	1,798	0,14738	14,738	13,998
109,9	25,493	1,9503	82,234	1,8096	0,14832	14,832	14,01
110,5	25,111	1,957	81,003	1,8162	0,14887	14,887	14,016
111,2	25,365	1,9697	81,821	1,8289	0,14991	14,991	14,029
111,9	25,688	1,9858	82,864	1,8451	0,15123	15,123	14,045
112,5	25,434	1,9923	82,045	1,8515	0,15176	15,176	14,052
113,2	25,229	2,0019	81,383	1,8611	0,15255	15,255	14,061
113,8	25,378	2,0135	81,863	1,8727	0,1535	15,35	14,073
114,5	25,602	2,028	82,587	1,8872	0,15469	15,469	14,087
115,1	25,14	2,0351	81,098	1,8943	0,15527	15,527	14,094
115,8	25,426	2,047	82,021	1,9062	0,15625	15,625	14,106
116,5	25,369	2,058	81,837	1,9173	0,15715	15,715	14,117
117,1	25,381	2,0699	81,873	1,9291	0,15812	15,812	14,129
117,8	25,549	2,0819	82,416	1,9412	0,15911	15,911	14,141
118,4	25,479	2,0925	82,189	1,9517	0,15997	15,997	14,152
119,1	25,146	2,1005	81,116	1,9597	0,16063	16,063	14,16
119,8	25,374	2,1119	81,853	1,9711	0,16156	16,156	14,171
120,4	26,209	2,1335	84,546	1,9927	0,16334	16,334	14,193
121,1	25,137	2,1326	81,089	1,9919	0,16327	16,327	14,192
121,7	25,45	2,1451	82,095	2,0043	0,16429	16,429	14,204
122,4	25,398	2,1563	81,928	2,0155	0,16521	16,521	14,216
123	25,601	2,1697	82,583	2,0289	0,1663	16,63	14,229
123,7	25,329	2,1769	81,706	2,0361	0,16689	16,689	14,236
124,4	25,427	2,1898	82,023	2,049	0,16795	16,795	14,249
125	25,3	2,2006	81,613	2,0598	0,16884	16,884	14,26
125,7	25,391	2,2111	81,907	2,0703	0,1697	16,97	14,27
126,3	25,445	2,2231	82,082	2,0823	0,17068	17,068	14,282
127	25,313	2,2327	81,656	2,0919	0,17147	17,147	14,292
127,7	25,381	2,2428	81,876	2,102	0,1723	17,23	14,302
128,3	25,42	2,2547	81,999	2,1139	0,17327	17,327	14,314
129	25,976	2,2727	83,792	2,1319	0,17474	17,474	14,332
129,6	25,146	2,2744	81,115	2,1336	0,17489	17,489	14,334
130,3	25,41	2,2883	81,966	2,1475	0,17602	17,602	14,347
130,9	25,495	2,2991	82,241	2,1584	0,17691	17,691	14,358
131,6	25,494	2,3111	82,237	2,1703	0,17789	17,789	14,37
132,3	25,496	2,322	82,247	2,1813	0,17879	17,879	14,381
132,9	25,549	2,3331	82,415	2,1923	0,1797	17,97	14,392
133,6	25,32	2,3416	81,678	2,2009	0,1804	18,04	14,401
134,2	25,54	2,3547	82,386	2,214	0,18147	18,147	14,414
134,9	25,836	2,3695	83,342	2,2287	0,18268	18,268	14,429
135,5	25,696	2,3773	82,891	2,2365	0,18332	18,332	14,437
136,2	25,414	2,3851	81,979	2,2443	0,18396	18,396	14,444
136,9	25,537	2,3976	82,378	2,2568	0,18498	18,498	14,457
137,5	26,254	2,417	84,689	2,2762	0,18657	18,657	14,476
138,2	25,265	2,4173	81,5	2,2765	0,1866	18,66	14,477
138,8	25,536	2,4301	82,375	2,2893	0,18765	18,765	14,489
139,5	25,695	2,4422	82,887	2,3014	0,18864	18,864	14,501
140,2	25,83	2,4556	83,322	2,3148	0,18974	18,974	14,515
140,8	25,511	2,4633	82,294	2,3225	0,19037	19,037	14,523
141,5	25,676	2,4741	82,825	2,3333	0,19125	19,125	14,533
142,1	25,707	2,4862	82,926	2,3455	0,19225	19,225	14,545
142,8	25,662	2,4968	82,78	2,356	0,19311	19,311	14,556
143,4	25,91	2,5114	83,579	2,3706	0,19431	19,431	14,571
144,1	25,734	2,5201	83,014	2,3793	0,19503	19,503	14,579
144,8	25,461	2,5275	82,131	2,3867	0,19563	19,563	14,587
145,4	25,597	2,5404	82,571	2,3997	0,19669	19,669	14,6
146,1	26,361	2,5613	85,037	2,4205	0,1984	19,84	14,62
146,7	25,409	2,5613	81,964	2,4205	0,1984	19,84	14,62
147,4	25,646	2,5727	82,729	2,4319	0,19934	19,934	14,632
148	25,666	2,5841	82,794	2,4433	0,20027	20,027	14,643
148,7	25,651	2,5963	82,744	2,4555	0,20127	20,127	14,656
149,4	25,698	2,608	82,895	2,4673	0,20224	20,224	14,667
150	25,726	2,6189	82,987	2,4782	0,20313	20,313	14,678
150,7	25,545	2,628	82,404	2,4872	0,20387	20,387	14,687
151,3	25,587	2,6386	82,54	2,4979	0,20474	20,474	14,698
152	25,492	2,6501	82,232	2,5093	0,20568	20,568	14,709
152,7	25,598	2,6615	82,573	2,5207	0,20661	20,661	14,721
153,3	25,383	2,6705	81,88	2,5298	0,20736	20,736	14,73
154	25,468	2,6827	82,156	2,5419	0,20835	20,835	14,742
154,6	26,384	2,7035	85,109	2,5627	0,21006	21,006	14,763
155,3	25,267	2,7048	81,506	2,5641	0,21017	21,017	14,764
155,9	25,464	2,7157	82,14	2,5749	0,21106	21,106	14,775
156,6	25,382	2,7273	81,877	2,5865	0,21201	21,201	14,787
157,3	25,485	2,7391	82,21	2,5983	0,21298	21,298	14,798
157,9	25,402	2,7485	81,94	2,6077	0,21375	21,375	14,808
158,6	25,549	2,761	82,416	2,6202	0,21477	21,477	14,82
159,2	25,301	2,7689	81,618	2,6281	0,21542	21,542	14,828
159,9	25,48	2,7812	82,193	2,6404	0,21643	21,643	14,84
160,6	26,041	2,7997	84,005	2,6589	0,21795	21,795	14,859
161,2	25,271	2,8	81,521	2,6593	0,21797	21,797	14,859
161,9	25,359	2,8129	81,802	2,6721	0,21903	21,903	14,872
162,5	25,52	2,8251	82,321	2,6843	0,22002	22,002	14,884
163,2	25,715	2,8381	82,95	2,6974	0,2211	22,11	14,897
163,8	25,556	2,8482	82,44	2,7074	0,22192	22,192	14,907
164,5	25,655	2,8587	82,759	2,7179	0,22278	22,278	14,918
165,2	25,551	2,8699	82,421	2,7292	0,2237	22,37	14,929
165,8	25,6	2,8812	82,581	2,7405	0,22463	22,463	14,94
166,5	25,739	2,8936	83,031	2,7528	0,22564	22,564	14,953
167,1	25,751	2,9045	83,067	2,7637	0,22653	22,653	14,964
167,8	25,439	2,9116	82,063	2,7708	0,22711	22,711	14,971
168,4	25,545	2,9244	82,402	2,7837	0,22817	22,817	14,984
169,1	25,717	2,9368	82,958	2,796	0,22918	22,918	14,996
169,8	25,706	2,9475	82,921	2,8067	0,23006	23,006	15,007
170,4	25,604	2,9558	82,593	2,815	0,23074	23,074	15,015
171,1	25,717	2,9686	82,959	2,8278	0,23179	23,179	15,028
171,7	25,802	2,9801	83,233	2,8393	0,23273	23,273	15,039
172,4	25,593	2,9915	82,558	2,8507	0,23366	23,366	15,051
173,1	25,751	3,002	83,068	2,8612	0,23452	23,452	15,061
173,7	25,686	3,0125	82,858	2,8717	0,23539	23,539	15,072
174,4	25,662	3,0235	82,78	2,8827	0,23629	23,629	15,083
175	25,552	3,0347	82,425	2,8939	0,23721	23,721	15,094
175,7	25,561	3,0454	82,455	2,9046	0,23808	23,808	15,105
176,3	25,611	3,0555	82,618	2,9147	0,23891	23,891	15,115
177	25,692	3,0671	82,879	2,9263	0,23986	23,986	15,126
177,7	26,082	3,0829	84,137	2,9421	0,24116	24,116	15,142
178,3	25,408	3,0867	81,961	2,9459	0,24147	24,147	15,146
179	25,558	3,098	82,446	2,9572	0,24239	24,239	15,157
179,6	25,584	3,1102	82,528	2,9694	0,24339	24,339	15,169
180,3	26,103	3,1279	84,202	2,9871	0,24485	24,485	15,187
180,9	25,477	3,1326	82,183	2,9918	0,24523	24,523	15,192
181,6	25,689	3,1439	82,868	3,0031	0,24616	24,616	15,203
182,3	25,635	3,155	82,694	3,0142	0,24707	24,707	15,214
182,9	25,674	3,1662	82,819	3,0254	0,24799	24,799	15,225
183,6	25,866	3,1795	83,438	3,0387	0,24908	24,908	15,239
184,2	25,805	3,1906	83,242	3,0498	0,24998	24,998	15,25
184,9	25,604	3,1974	82,594	3,0566	0,25054	25,054	15,257
185,6	25,658	3,2104	82,767	3,0696	0,2516	25,16	15,27
186,2	25,75	3,2218	83,066	3,081	0,25254	25,254	15,281
186,9	25,596	3,2315	82,567	3,0907	0,25334	25,334	15,291
187,5	25,514	3,2408	82,303	3,1	0,2541	25,41	15,3
188,2	25,566	3,2533	82,472	3,1126	0,25513	25,513	15,313
188,8	25,945	3,2691	83,693	3,1283	0,25642	25,642	15,328
189,5	25,525	3,2753	82,339	3,1345	0,25693	25,693	15,335
190,2	25,646	3,2862	82,728	3,1454	0,25782	25,782	15,345
190,8	25,643	3,2976	82,719	3,1568	0,25875	25,875	15,357
191,5	25,552	3,3086	82,426	3,1679	0,25966	25,966	15,368
192,1	25,806	3,324	83,245	3,1833	0,26092	26,092	15,383
192,8	25,04	3,324	80,774	3,1832	0,26092	26,092	15,383
193,5	25,489	3,3397	82,223	3,199	0,26221	26,221	15,399
194,1	25,431	3,3513	82,036	3,2105	0,26316	26,316	15,411
194,8	25,99	3,3691	83,84	3,2284	0,26462	26,462	15,428
195,4	25,109	3,3691	80,998	3,2284	0,26462	26,462	15,428
196,1	25,464	3,3838	82,142	3,243	0,26582	26,582	15,443
196,7	25,505	3,3956	82,273	3,2548	0,26679	26,679	15,455
197,4	25,58	3,4075	82,516	3,2667	0,26776	26,776	15,467
198,1	25,699	3,4207	82,899	3,2799	0,26884	26,884	15,48
198,7	25,483	3,4278	82,204	3,2871	0,26943	26,943	15,487
199,4	25,558	3,4401	82,444	3,2994	0,27044	27,044	15,499
200	25,546	3,4512	82,407	3,3104	0,27134	27,134	15,51
200,7	25,879	3,4657	83,48	3,325	0,27254	27,254	15,525
201,3	25,593	3,4737	82,558	3,3329	0,27319	27,319	15,533
202	25,438	3,482	82,06	3,3413	0,27387	27,387	15,541
202,7	25,49	3,4946	82,225	3,3539	0,27491	27,491	15,554
203,3	25,577	3,5064	82,508	3,3656	0,27587	27,587	15,566
204	25,424	3,5139	82,013	3,3732	0,27649	27,649	15,573
204,6	25,4	3,526	81,936	3,3852	0,27748	27,748	15,585
205,3	25,557	3,5387	82,442	3,3979	0,27852	27,852	15,598
206	25,617	3,5503	82,636	3,4095	0,27947	27,947	15,609
206,6	25,542	3,5615	82,394	3,4207	0,28039	28,039	15,621
207,3	25,504	3,5713	82,272	3,4305	0,28119	28,119	15,631
207,9	25,486	3,5827	82,212	3,4419	0,28212	28,212	15,642
208,6	25,607	3,5942	82,605	3,4534	0,28306	28,306	15,653
209,2	25,678	3,6065	82,833	3,4658	0,28408	28,408	15,666
209,9	25,619	3,6165	82,643	3,4757	0,2849	28,49	15,676
210,6	25,356	3,625	81,793	3,4842	0,28559	28,559	15,684
211,2	25,467	3,6372	82,152	3,4964	0,28659	28,659	15,696
211,9	25,965	3,654	83,758	3,5133	0,28797	28,797	15,713
212,5	25,356	3,6571	81,794	3,5163	0,28822	28,822	15,716
213,2	25,429	3,6685	82,03	3,5277	0,28916	28,916	15,728
213,8	25,479	3,6802	82,189	3,5394	0,29012	29,012	15,739
214,5	25,692	3,6934	82,879	3,5526	0,2912	29,12	15,753
215,2	25,377	3,7022	81,861	3,5614	0,29192	29,192	15,761
215,8	25,444	3,7135	82,076	3,5727	0,29285	29,285	15,773
216,5	25,544	3,725	82,4	3,5843	0,29379	29,379	15,784
217,1	25,53	3,7366	82,354	3,5958	0,29474	29,474	15,796
217,8	25,735	3,7505	83,016	3,6097	0,29588	29,588	15,81
218,5	25,531	3,7598	82,358	3,619	0,29664	29,664	15,819
219,1	25,385	3,7673	81,886	3,6266	0,29726	29,726	15,827
219,8	25,38	3,7787	81,87	3,6379	0,29819	29,819	15,838
220,4	25,727	3,7947	82,989	3,654	0,2995	29,95	15,854
221,1	25,257	3,8006	81,473	3,6599	0,29999	29,999	15,86
221,7	25,357	3,8111	81,798	3,6703	0,30084	30,084	15,87
222,4	25,438	3,8235	82,059	3,6827	0,30186	30,186	15,883
223,1	25,474	3,8354	82,175	3,6946	0,30284	30,284	15,895
223,7	25,476	3,847	82,182	3,7062	0,30379	30,379	15,906
224,4	25,336	3,8571	81,729	3,7163	0,30462	30,462	15,916
225	25,338	3,8675	81,735	3,7267	0,30547	30,547	15,927
225,7	25,404	3,8789	81,949	3,7381	0,3064	30,64	15,938
226,3	25,654	3,8934	82,754	3,7527	0,3076	30,76	15,953
227	25,02	3,8966	80,71	3,7559	0,30786	30,786	15,956
227,7	25,305	3,9103	81,63	3,7696	0,30898	30,898	15,97
228,3	25,313	3,9211	81,654	3,7803	0,30986	30,986	15,98
229	25,855	3,9397	83,404	3,7989	0,31138	31,138	15,999
229,6	25,198	3,9415	81,283	3,8007	0,31153	31,153	16,001
230,3	25,274	3,954	81,529	3,8132	0,31256	31,256	16,013
231	25,382	3,9658	81,878	3,825	0,31353	31,353	16,025
231,6	25,486	3,9777	82,214	3,8369	0,3145	31,45	16,037
232,3	25,592	3,9906	82,554	3,8499	0,31556	31,556	16,05
232,9	25,423	4,0001	82,009	3,8593	0,31634	31,634	16,059
233,6	25,377	4,0092	81,861	3,8684	0,31708	31,708	16,068
234,2	25,431	4,0213	82,036	3,8805	0,31807	31,807	16,08
234,9	25,785	4,0381	83,179	3,8973	0,31945	31,945	16,097
235,6	25,077	4,0387	80,895	3,8979	0,3195	31,95	16,098
236,2	25,317	4,0526	81,667	3,9119	0,32064	32,064	16,112
236,9	25,331	4,0645	81,713	3,9238	0,32162	32,162	16,124
237,5	25,866	4,0813	83,438	3,9405	0,323	32,3	16,141
238,2	25,17	4,0843	81,194	3,9435	0,32324	32,324	16,144
238,9	25,294	4,0973	81,592	3,9565	0,3243	32,43	16,157
239,5	25,488	4,109	82,219	3,9683	0,32527	32,527	16,168
240,2	25,428	4,1203	82,026	3,9795	0,32619	32,619	16,179
240,8	25,465	4,1327	82,146	3,9919	0,32721	32,721	16,192
241,5	25,464	4,1431	82,143	4,0024	0,32806	32,806	16,202
242,1	25,332	4,153	81,717	4,0122	0,32887	32,887	16,212
242,8	25,396	4,1642	81,923	4,0234	0,32979	32,979	16,223
243,5	25,535	4,1762	82,371	4,0354	0,33077	33,077	16,235
244,1	25,521	4,1867	82,326	4,0459	0,33163	33,163	16,246
244,8	25,287	4,1944	81,569	4,0536	0,33226	33,226	16,254
245,4	25,379	4,207	81,868	4,0662	0,3333	33,33	16,266
246,1	25,587	4,2209	82,539	4,0801	0,33443	33,443	16,28
246,7	25,451	4,2303	82,099	4,0896	0,33521	33,521	16,29
247,4	25,247	4,2392	81,442	4,0985	0,33594	33,594	16,298
248,1	25,401	4,2514	81,94	4,1106	0,33693	33,693	16,311
248,7	25,454	4,2629	82,11	4,1221	0,33788	33,788	16,322
249,4	25,369	4,273	81,834	4,1322	0,3387	33,87	16,332
250	25,422	4,2847	82,006	4,1439	0,33967	33,967	16,344
250,7	25,364	4,2956	81,82	4,1548	0,34056	34,056	16,355
251,4	25,303	4,3051	81,624	4,1644	0,34134	34,134	16,364
252	25,336	4,3175	81,727	4,1768	0,34236	34,236	16,377
252,7	25,52	4,3315	82,323	4,1907	0,3435	34,35	16,391
253,3	25,223	4,3374	81,365	4,1966	0,34398	34,398	16,397
254	25,332	4,3502	81,718	4,2094	0,34503	34,503	16,409
254,6	25,759	4,3666	83,093	4,2259	0,34638	34,638	16,426
255,3	25,095	4,3696	80,952	4,2289	0,34663	34,663	16,429
256	25,151	4,3815	81,133	4,2407	0,3476	34,76	16,441
256,6	25,381	4,3945	81,874	4,2537	0,34867	34,867	16,454
257,3	25,431	4,4059	82,036	4,2651	0,3496	34,96	16,465
257,9	25,585	4,4192	82,534	4,2784	0,35069	35,069	16,478
258,6	25,292	4,4273	81,587	4,2865	0,35135	35,135	16,486
259,2	25,257	4,4373	81,474	4,2965	0,35217	35,217	16,497
259,9	25,37	4,4492	81,838	4,3084	0,35315	35,315	16,508
260,6	25,587	4,4634	82,54	4,3226	0,35431	35,431	16,523
261,2	25,263	4,4703	81,493	4,3296	0,35488	35,488	16,53
261,9	25,167	4,4806	81,185	4,3398	0,35573	35,573	16,54
262,5	25,306	4,4931	81,633	4,3523	0,35675	35,675	16,552
263,2	25,433	4,5065	82,043	4,3657	0,35784	35,784	16,566
263,9	25,092	4,5123	80,943	4,3715	0,35832	35,832	16,572
264,5	25,174	4,5242	81,205	4,3834	0,35929	35,929	16,583
265,2	25,269	4,5362	81,513	4,3954	0,36028	36,028	16,595
265,8	25,328	4,5476	81,704	4,4069	0,36122	36,122	16,607
266,5	25,366	4,56	81,827	4,4192	0,36223	36,223	16,619
267,1	25,52	4,5723	82,321	4,4315	0,36324	36,324	16,631
267,8	25,216	4,5789	81,341	4,4381	0,36378	36,378	16,638
268,5	25,319	4,5916	81,673	4,4508	0,36482	36,482	16,651
269,1	25,843	4,6098	83,365	4,469	0,36631	36,631	16,669
269,8	25,013	4,6099	80,686	4,4691	0,36632	36,632	16,669
270,4	25,216	4,6233	81,343	4,4825	0,36742	36,742	16,682
271,1	25,24	4,6352	81,418	4,4944	0,36839	36,839	16,694
271,8	25,464	4,6491	82,141	4,5083	0,36953	36,953	16,708
272,4	25,267	4,6578	81,508	4,517	0,37025	37,025	16,717
273,1	25,256	4,6675	81,47	4,5268	0,37105	37,105	16,727
273,7	25,314	4,6796	81,66	4,5388	0,37204	37,204	16,739
274,4	25,317	4,69	81,667	4,5493	0,37289	37,289	16,749
275	25,666	4,7064	82,794	4,5656	0,37423	37,423	16,766
275,7	24,899	4,706	80,32	4,5653	0,3742	37,42	16,765
276,4	25,222	4,7216	81,363	4,5808	0,37547	37,547	16,781
277	25,298	4,7333	81,607	4,5925	0,37643	37,643	16,792
277,7	25,701	4,7504	82,908	4,6096	0,37784	37,784	16,81
278,3	25,295	4,7562	81,598	4,6154	0,37831	37,831	16,815
279	25,148	4,7645	81,121	4,6238	0,379	37,9	16,824
279,6	25,243	4,7769	81,428	4,6361	0,38001	38,001	16,836
280,3	25,66	4,7937	82,775	4,653	0,38139	38,139	16,853
281	25,112	4,7976	81,006	4,6568	0,38171	38,171	16,857
281,6	25,229	4,81	81,383	4,6692	0,38272	38,272	16,869
282,3	25,311	4,8218	81,647	4,681	0,38369	38,369	16,881
282,9	25,408	4,8327	81,961	4,6919	0,38458	38,458	16,892
283,6	25,519	4,8465	82,319	4,7057	0,38572	38,572	16,906
284,3	25,132	4,8531	81,072	4,7123	0,38626	38,626	16,912
284,9	25,29	4,8651	81,579	4,7244	0,38724	38,724	16,924
285,6	25,296	4,8767	81,6	4,7359	0,38819	38,819	16,936
286,2	25,809	4,895	83,256	4,7542	0,38969	38,969	16,954
286,9	25,02	4,8952	80,711	4,7544	0,38971	38,971	16,954
287,5	25,34	4,9077	81,743	4,7669	0,39073	39,073	16,967
288,2	25,327	4,9201	81,699	4,7793	0,39174	39,174	16,979
288,9	25,863	4,9388	83,43	4,7981	0,39328	39,328	16,998
289,5	25,108	4,9389	80,992	4,7981	0,39329	39,329	16,998
290,2	25,236	4,9528	81,408	4,812	0,39442	39,442	17,012
290,8	25,293	4,9644	81,591	4,8236	0,39538	39,538	17,024
291,5	25,31	4,9755	81,645	4,8348	0,39629	39,629	17,035
292,1	25,528	4,9898	82,347	4,8491	0,39746	39,746	17,049
292,8	24,817	4,9904	80,054	4,8496	0,39751	39,751	17,05
293,5	25,244	5,0069	81,433	4,8661	0,39886	39,886	17,066
294,1	25,183	5,0182	81,236	4,8774	0,39979	39,979	17,077
294,8	25,328	5,0317	81,702	4,8909	0,40089	40,089	17,091
295,4	25,256	5,0405	81,47	4,8997	0,40162	40,162	17,1
296,1	25,224	5,0506	81,367	4,9098	0,40245	40,245	17,11
296,8	25,219	5,0628	81,351	4,922	0,40344	40,344	17,122
297,4	25,367	5,0765	81,828	4,9357	0,40457	40,457	17,136
298,1	25,303	5,0862	81,624	4,9455	0,40537	40,537	17,145
298,7	25,19	5,0957	81,257	4,955	0,40615	40,615	17,155
299,4	25,146	5,1063	81,117	4,9655	0,40701	40,701	17,166
300	25,321	5,1184	81,679	4,9776	0,408	40,8	17,178
300,7	25,385	5,1311	81,886	4,9903	0,40904	40,904	17,19
301,4	25,245	5,1401	81,436	4,9993	0,40978	40,978	17,199
302	25,102	5,1488	80,973	5,008	0,41049	41,049	17,208
302,7	25,2	5,1605	81,29	5,0198	0,41146	41,146	17,22
303,3	25,761	5,1797	83,1	5,0389	0,41303	41,303	17,239
304	25,005	5,18	80,661	5,0392	0,41305	41,305	17,239
304,7	25,213	5,1931	81,333	5,0523	0,41412	41,412	17,252
305,3	25,291	5,2057	81,583	5,0649	0,41515	41,515	17,265
306	25,39	5,2172	81,902	5,0765	0,4161	41,61	17,276
306,6	25,229	5,2269	81,384	5,0861	0,41689	41,689	17,286
307,3	25,399	5,2382	81,933	5,0975	0,41783	41,783	17,297
307,9	25,246	5,2494	81,438	5,1086	0,41874	41,874	17,309
308,6	25,328	5,2608	81,703	5,12	0,41967	41,967	17,32
309,3	25,316	5,2711	81,664	5,1303	0,42052	42,052	17,33
309,9	25,352	5,2845	81,781	5,1438	0,42162	42,162	17,344
310,6	25,211	5,2916	81,327	5,1508	0,4222	42,22	17,351
311,2	25,264	5,3034	81,497	5,1626	0,42316	42,316	17,363
311,9	25,472	5,3186	82,169	5,1778	0,42441	42,441	17,378
312,5	25,325	5,3271	81,694	5,1863	0,42511	42,511	17,386
313,2	25,145	5,3358	81,113	5,195	0,42582	42,582	17,395
313,9	25,319	5,3479	81,673	5,2071	0,42681	42,681	17,407
314,5	25,43	5,3624	82,032	5,2216	0,428	42,8	17,422
315,2	25,168	5,3705	81,188	5,2297	0,42866	42,866	17,43
315,8	25,201	5,3791	81,293	5,2383	0,42937	42,937	17,438
316,5	25,272	5,3922	81,521	5,2515	0,43045	43,045	17,451
317,2	25,241	5,4029	81,422	5,2622	0,43132	43,132	17,462
317,8	25,318	5,4145	81,67	5,2737	0,43227	43,227	17,474
318,5	25,385	5,4266	81,888	5,2859	0,43327	43,327	17,486
319,1	25,143	5,4339	81,107	5,2931	0,43386	43,386	17,493
319,8	25,263	5,4457	81,492	5,3049	0,43483	43,483	17,505
320,4	25,925	5,4667	83,63	5,3259	0,43655	43,655	17,526
321,1	25,158	5,4668	81,156	5,326	0,43656	43,656	17,526
321,8	25,356	5,4789	81,794	5,3381	0,43755	43,755	17,538
322,4	25,254	5,4907	81,465	5,3499	0,43852	43,852	17,55
323,1	25,285	5,502	81,566	5,3612	0,43944	43,944	17,561
323,7	25,361	5,5128	81,811	5,372	0,44033	44,033	17,572
324,4	25,443	5,5243	82,073	5,3835	0,44127	44,127	17,584
325	25,185	5,5339	81,241	5,3932	0,44206	44,206	17,593
325,7	25,214	5,5446	81,336	5,4039	0,44294	44,294	17,604
326,4	25,359	5,5582	81,803	5,4174	0,44405	44,405	17,617
327	25,356	5,5698	81,794	5,429	0,445	44,5	17,629
327,7	25,136	5,5769	81,083	5,4362	0,44559	44,559	17,636
328,3	25,286	5,5891	81,566	5,4483	0,44658	44,658	17,648
329	25,585	5,6061	82,534	5,4653	0,44797	44,797	17,665
329,7	25,162	5,6113	81,169	5,4706	0,44841	44,841	17,671
330,3	25,214	5,6203	81,335	5,4795	0,44914	44,914	17,68
331	25,199	5,6327	81,286	5,4919	0,45016	45,016	17,692
331,6	25,242	5,6445	81,425	5,5037	0,45113	45,113	17,704
332,3	25,234	5,6547	81,4	5,5139	0,45196	45,196	17,714
332,9	25,223	5,6661	81,366	5,5253	0,4529	45,29	17,725
333,6	25,244	5,6763	81,431	5,5355	0,45373	45,373	17,736
334,3	25,204	5,6874	81,304	5,5466	0,45464	45,464	17,747
334,9	25,698	5,7052	82,896	5,5644	0,4561	45,61	17,764
335,6	24,976	5,7054	80,569	5,5646	0,45611	45,611	17,765
336,2	25,295	5,7192	81,598	5,5784	0,45725	45,725	17,778
336,9	25,349	5,7307	81,771	5,59	0,45819	45,819	17,79
337,6	25,869	5,7507	83,448	5,6099	0,45983	45,983	17,81
338,2	25,159	5,751	81,157	5,6102	0,45985	45,985	17,81
338,9	25,205	5,7634	81,305	5,6226	0,46087	46,087	17,823
339,5	25,339	5,776	81,738	5,6352	0,4619	46,19	17,835
340,2	25,397	5,7872	81,924	5,6465	0,46283	46,283	17,846
340,8	25,404	5,7987	81,948	5,6579	0,46377	46,377	17,858
341,5	25,321	5,8096	81,682	5,6688	0,46466	46,466	17,869
342,2	25,288	5,8183	81,575	5,6775	0,46537	46,537	17,878
342,8	25,257	5,8296	81,475	5,6888	0,46629	46,629	17,889
343,5	25,568	5,8461	82,479	5,7053	0,46765	46,765	17,905
344,1	25,033	5,8493	80,753	5,7085	0,46791	46,791	17,908
344,8	25,197	5,8618	81,281	5,721	0,46893	46,893	17,921
345,4	25,28	5,8745	81,549	5,7337	0,46998	46,998	17,934
346,1	25,56	5,8898	82,452	5,749	0,47123	47,123	17,949
346,8	25,38	5,8966	81,871	5,7559	0,47179	47,179	17,956
347,4	25,175	5,9064	81,208	5,7656	0,47259	47,259	17,966
348,1	25,39	5,918	81,904	5,7773	0,47355	47,355	17,977
348,7	25,595	5,9322	82,566	5,7914	0,47471	47,471	17,991
349,4	25,3	5,94	81,614	5,7993	0,47535	47,535	17,999
350,1	25,416	5,9508	81,989	5,8101	0,47623	47,623	18,01
350,7	25,417	5,9624	81,989	5,8216	0,47718	47,718	18,022
351,4	25,416	5,9729	81,987	5,8321	0,47804	47,804	18,032
352	25,476	5,9853	82,181	5,8445	0,47906	47,906	18,045
352,7	25,346	5,9961	81,761	5,8553	0,47994	47,994	18,055
353,3	25,255	6,0045	81,469	5,8637	0,48063	48,063	18,064
354	25,289	6,0164	81,577	5,8756	0,48161	48,161	18,076
354,7	25,754	6,0348	83,078	5,894	0,48311	48,311	18,094
355,3	25,038	6,0349	80,767	5,8941	0,48312	48,312	18,094
356	25,322	6,0481	81,685	5,9074	0,48421	48,421	18,107
356,6	25,314	6,0616	81,657	5,9208	0,48531	48,531	18,121
357,3	25,356	6,0722	81,793	5,9314	0,48618	48,618	18,131
357,9	25,219	6,0808	81,352	5,94	0,48689	48,689	18,14
358,6	25,282	6,094	81,555	5,9532	0,48797	48,797	18,153
359,3	25,161	6,1034	81,166	5,9626	0,48874	48,874	18,163
359,9	25,302	6,1156	81,618	5,9749	0,48974	48,974	18,175
360,6	25,67	6,1337	82,806	5,993	0,49123	49,123	18,193
361,2	24,929	6,1342	80,415	5,9934	0,49126	49,126	18,193
361,9	25,15	6,1473	81,128	6,0065	0,49234	49,234	18,207
362,6	25,22	6,1589	81,355	6,0181	0,49329	49,329	18,218
363,2	25,365	6,1716	81,823	6,0308	0,49433	49,433	18,231
363,9	25,28	6,1814	81,547	6,0407	0,49514	49,514	18,241
364,5	25,315	6,192	81,661	6,0512	0,496	49,6	18,251
365,2	25,292	6,2037	81,588	6,0629	0,49696	49,696	18,263
365,8	25,388	6,2151	81,897	6,0744	0,4979	49,79	18,274
366,5	25,377	6,2256	81,861	6,0848	0,49876	49,876	18,285
367,2	25,389	6,2364	81,898	6,0956	0,49964	49,964	18,296
367,8	25,32	6,246	81,679	6,1052	0,50042	50,042	18,305
368,5	25,465	6,2589	82,144	6,1181	0,50149	50,149	18,318
369,1	25,925	6,278	83,629	6,1372	0,50305	50,305	18,337
369,8	25,215	6,2781	81,34	6,1373	0,50306	50,306	18,337
370,5	25,277	6,2904	81,54	6,1496	0,50407	50,407	18,35
371,1	25,304	6,3016	81,626	6,1609	0,50499	50,499	18,361
371,8	25,95	6,3222	83,71	6,1815	0,50668	50,668	18,381
372,4	25,246	6,3225	81,44	6,1817	0,5067	50,67	18,382
373,1	25,422	6,3352	82,005	6,1944	0,50774	50,774	18,394
373,7	25,324	6,3458	81,691	6,2051	0,50861	50,861	18,405
374,4	25,398	6,3576	81,928	6,2168	0,50958	50,958	18,417
375,1	25,656	6,372	82,761	6,2312	0,51075	51,075	18,431
375,7	25,419	6,3789	81,998	6,2381	0,51132	51,132	18,438
376,4	25,353	6,3876	81,785	6,2469	0,51204	51,204	18,447
377	25,409	6,4004	81,966	6,2596	0,51308	51,308	18,46
377,7	25,737	6,4171	83,023	6,2763	0,51445	51,445	18,476
378,3	25,527	6,4229	82,344	6,2822	0,51493	51,493	18,482
379	25,367	6,4319	81,828	6,2912	0,51567	51,567	18,491
379,7	25,549	6,4442	82,416	6,3034	0,51667	51,667	18,503
380,3	25,609	6,4577	82,61	6,3169	0,51778	51,778	18,517
381	25,397	6,4645	81,926	6,3237	0,51834	51,834	18,524
381,6	25,555	6,4763	82,434	6,3355	0,5193	51,93	18,535
382,3	25,631	6,4884	82,681	6,3476	0,5203	52,03	18,548
383	25,644	6,5001	82,723	6,3593	0,52125	52,125	18,559
383,6	25,664	6,5116	82,786	6,3708	0,5222	52,22	18,571
384,3	25,769	6,523	83,127	6,3822	0,52313	52,313	18,582
384,9	25,516	6,5322	82,31	6,3914	0,52389	52,389	18,591
385,6	25,537	6,5432	82,376	6,4024	0,52479	52,479	18,602
386,2	25,996	6,5616	83,857	6,4208	0,5263	52,63	18,621
386,9	25,273	6,5611	81,526	6,4204	0,52626	52,626	18,62
387,6	25,553	6,5743	82,428	6,4335	0,52734	52,734	18,634
388,2	25,514	6,587	82,304	6,4463	0,52838	52,838	18,646
388,9	26,253	6,6094	84,689	6,4686	0,53021	53,021	18,669
389,5	25,479	6,609	82,19	6,4682	0,53018	53,018	18,668
390,2	25,6	6,62	82,58	6,4792	0,53108	53,108	18,679
390,8	25,507	6,6304	82,28	6,4896	0,53193	53,193	18,69
391,5	25,571	6,6428	82,487	6,502	0,53295	53,295	18,702
392,2	25,547	6,6527	82,409	6,5119	0,53376	53,376	18,712
392,8	25,57	6,6648	82,485	6,524	0,53476	53,476	18,724
393,5	25,517	6,6733	82,312	6,5326	0,53546	53,546	18,733
394,1	25,664	6,6863	82,788	6,5455	0,53651	53,651	18,745
394,8	25,931	6,7025	83,65	6,5617	0,53784	53,784	18,762
395,5	25,53	6,7077	82,354	6,5669	0,53827	53,827	18,767
396,1	25,562	6,7175	82,459	6,5767	0,53907	53,907	18,777
396,8	25,561	6,7292	82,456	6,5884	0,54003	54,003	18,788
397,4	25,719	6,7418	82,966	6,601	0,54107	54,107	18,801
398,1	25,514	6,7494	82,304	6,6087	0,54169	54,169	18,809
398,7	25,607	6,7622	82,602	6,6215	0,54274	54,274	18,821
399,4	25,609	6,774	82,61	6,6333	0,54371	54,371	18,833
400,1	25,666	6,7849	82,792	6,6442	0,5446	54,46	18,844
400,7	25,861	6,7989	83,424	6,6581	0,54575	54,575	18,858
401,4	25,662	6,8085	82,779	6,6677	0,54653	54,653	18,868
402	25,607	6,8159	82,604	6,6751	0,54714	54,714	18,875
402,7	25,696	6,829	82,892	6,6882	0,54822	54,822	18,888
403,4	26,021	6,8463	83,937	6,7055	0,54963	54,963	18,906
404	25,419	6,8479	81,996	6,7071	0,54976	54,976	18,907
404,7	25,572	6,8601	82,49	6,7193	0,55076	55,076	18,919
405,3	25,58	6,8721	82,515	6,7313	0,55175	55,175	18,931
406	25,898	6,8883	83,541	6,7475	0,55307	55,307	18,948
406,6	25,587	6,8936	82,539	6,7528	0,55351	55,351	18,953
407,3	25,762	6,906	83,104	6,7652	0,55453	55,453	18,965
408	25,641	6,9166	82,714	6,7758	0,55539	55,539	18,976
408,6	25,7	6,9275	82,904	6,7868	0,55629	55,629	18,987
409,3	25,875	6,9409	83,466	6,8001	0,55738	55,738	19
409,9	25,89	6,952	83,515	6,8113	0,5583	55,83	19,011
410,6	25,639	6,9582	82,705	6,8174	0,5588	55,88	19,017
411,2	25,705	6,9703	82,919	6,8296	0,5598	55,98	19,03
411,9	26,31	6,9911	84,871	6,8503	0,5615	56,15	19,05
412,6	25,527	6,9888	82,346	6,848	0,56131	56,131	19,048
413,2	25,748	7,0031	83,058	6,8623	0,56249	56,249	19,062
413,9	25,794	7,0154	83,207	6,8746	0,56349	56,349	19,075
414,5	25,826	7,0267	83,309	6,886	0,56442	56,442	19,086
415,2	25,715	7,036	82,951	6,8952	0,56518	56,518	19,095
415,9	25,756	7,047	83,085	6,9062	0,56608	56,608	19,106
416,5	25,762	7,0592	83,103	6,9184	0,56708	56,708	19,118
417,2	25,807	7,0706	83,249	6,9298	0,56802	56,802	19,13
417,8	25,75	7,0823	83,064	6,9415	0,56897	56,897	19,141
418,5	25,855	7,0937	83,404	6,9529	0,56991	56,991	19,153
419,1	25,611	7,1004	82,615	6,9596	0,57046	57,046	19,16
419,8	25,733	7,1132	83,011	6,9724	0,57151	57,151	19,172
420,5	26,063	7,1303	84,074	6,9896	0,57291	57,291	19,19
421,1	25,428	7,1309	82,025	6,9901	0,57296	57,296	19,19
421,8	25,675	7,145	82,822	7,0042	0,57412	57,412	19,204
422,4	25,719	7,1572	82,966	7,0165	0,57512	57,512	19,216
423,1	25,913	7,1699	83,591	7,0291	0,57616	57,616	19,229
423,7	25,835	7,1805	83,338	7,0397	0,57702	57,702	19,24
424,4	25,896	7,1912	83,537	7,0504	0,5779	57,79	19,25
425,1	25,813	7,2014	83,268	7,0606	0,57874	57,874	19,261
425,7	25,842	7,2128	83,36	7,072	0,57967	57,967	19,272
426,4	26,064	7,2269	84,076	7,0862	0,58083	58,083	19,286
427	25,776	7,2326	83,147	7,0919	0,5813	58,13	19,292
427,7	25,798	7,2432	83,22	7,1024	0,58216	58,216	19,302
428,4	25,863	7,2562	83,428	7,1155	0,58323	58,323	19,315
429	26,148	7,2736	84,348	7,1328	0,58465	58,465	19,333
429,7	25,772	7,2767	83,135	7,1359	0,58491	58,491	19,336
430,3	25,845	7,2877	83,37	7,1469	0,58581	58,581	19,347
431	25,779	7,2995	83,159	7,1587	0,58678	58,678	19,359
431,6	25,812	7,3117	83,265	7,1709	0,58778	58,778	19,371
432,3	25,809	7,3218	83,253	7,181	0,5886	58,86	19,381
433	25,853	7,3329	83,397	7,1921	0,58951	58,951	19,392
433,6	25,746	7,3439	83,051	7,2031	0,59042	59,042	19,403
434,3	25,834	7,355	83,336	7,2143	0,59133	59,133	19,414
434,9	25,968	7,3685	83,767	7,2277	0,59243	59,243	19,428
435,6	25,967	7,3808	83,763	7,24	0,59345	59,345	19,44
436,2	25,726	7,3863	82,986	7,2455	0,59389	59,389	19,445
436,9	25,809	7,3985	83,254	7,2578	0,5949	59,49	19,458
437,6	25,976	7,4114	83,793	7,2706	0,59595	59,595	19,471
438,2	25,757	7,4192	83,086	7,2784	0,59659	59,659	19,478
438,9	25,853	7,4301	83,395	7,2894	0,59749	59,749	19,489
439,5	25,907	7,442	83,57	7,3012	0,59846	59,846	19,501
440,2	26,012	7,4548	83,908	7,314	0,59951	59,951	19,514
440,9	26,013	7,4654	83,913	7,3247	0,60038	60,038	19,525
441,5	26,136	7,4766	84,309	7,3359	0,6013	60,13	19,536
442,2	25,939	7,4855	83,676	7,3448	0,60203	60,203	19,545
442,8	25,988	7,4976	83,833	7,3568	0,60302	60,302	19,557
443,5	26,233	7,5124	84,623	7,3716	0,60423	60,423	19,572
444,1	26,022	7,5216	83,94	7,3808	0,60498	60,498	19,581
444,8	25,889	7,5283	83,514	7,3875	0,60554	60,554	19,588
445,5	25,998	7,5413	83,863	7,4005	0,6066	60,66	19,6
446,1	26,599	7,5631	85,804	7,4223	0,60839	60,839	19,622
446,8	25,921	7,5626	83,616	7,4218	0,60835	60,835	19,622
447,4	26,009	7,5735	83,899	7,4327	0,60924	60,924	19,633
448,1	25,999	7,5854	83,868	7,4446	0,61021	61,021	19,645
448,8	26,132	7,6006	84,296	7,4599	0,61146	61,146	19,66
449,4	25,973	7,6074	83,785	7,4666	0,61202	61,202	19,667
450,1	26	7,6182	83,872	7,4774	0,6129	61,29	19,677
450,7	25,923	7,6288	83,624	7,488	0,61377	61,377	19,688
451,4	25,937	7,6401	83,667	7,4993	0,61469	61,469	19,699
452	26,163	7,6543	84,396	7,5135	0,61586	61,586	19,714
452,7	26,054	7,6644	84,046	7,5236	0,61669	61,669	19,724
453,4	25,898	7,6704	83,541	7,5296	0,61718	61,718	19,73
454	25,969	7,683	83,772	7,5422	0,61821	61,821	19,742
454,7	26,566	7,7043	85,697	7,5635	0,61996	61,996	19,764
455,3	25,903	7,7044	83,558	7,5636	0,61997	61,997	19,764
456	26,046	7,7159	84,02	7,5752	0,62091	62,091	19,775
456,6	26,023	7,7271	83,947	7,5863	0,62183	62,183	19,786
457,3	26,109	7,7401	84,222	7,5993	0,6229	62,29	19,799
458	26,025	7,7497	83,952	7,6089	0,62368	62,368	19,809
458,6	26,141	7,761	84,327	7,6202	0,62461	62,461	19,82
459,3	26,106	7,7713	84,214	7,6305	0,62545	62,545	19,831
459,9	25,999	7,7828	83,869	7,642	0,62639	62,639	19,842
460,6	26,186	7,7965	84,471	7,6557	0,62752	62,752	19,856
461,3	26,088	7,8053	84,154	7,6646	0,62824	62,824	19,865
461,9	25,889	7,8135	83,514	7,6728	0,62891	62,891	19,873
462,6	25,989	7,8257	83,835	7,6849	0,62991	62,991	19,885
463,2	26,408	7,8448	85,189	7,7041	0,63148	63,148	19,904
463,9	26	7,8464	83,871	7,7056	0,6316	63,16	19,906
464,5	26,049	7,8579	84,03	7,7171	0,63255	63,255	19,917
465,2	26,08	7,8703	84,13	7,7296	0,63357	63,357	19,93
465,9	26,142	7,8832	84,33	7,7424	0,63462	63,462	19,942
466,5	26,096	7,8932	84,182	7,7524	0,63545	63,545	19,952
467,2	26,131	7,9042	84,294	7,7634	0,63634	63,634	19,963
467,8	26,014	7,913	83,918	7,7722	0,63706	63,706	19,972
468,5	26,054	7,9243	84,044	7,7835	0,63799	63,799	19,984
469,1	26,031	7,9351	83,971	7,7943	0,63888	63,888	19,994
469,8	26,121	7,9474	84,262	7,8067	0,63989	63,989	20,007
470,5	26,011	7,9567	83,908	7,8159	0,64065	64,065	20,016
471,1	26,117	7,9685	84,249	7,8277	0,64162	64,162	20,028
471,8	26,2	7,9811	84,517	7,8403	0,64265	64,265	20,04
472,4	26,053	7,9898	84,041	7,8491	0,64337	64,337	20,049
473,1	26,108	8,0019	84,219	7,8611	0,64435	64,435	20,061
473,8	26,117	8,0132	84,249	7,8725	0,64528	64,528	20,072
474,4	26,149	8,0244	84,352	7,8837	0,6462	64,62	20,084
475,1	26,384	8,0388	85,11	7,898	0,64738	64,738	20,098
475,7	25,858	8,0408	83,413	7,9	0,64754	64,754	20,1
476,4	26,103	8,0544	84,202	7,9136	0,64866	64,866	20,114
477	26,028	8,0675	83,963	7,9267	0,64973	64,973	20,127
477,7	26,423	8,0852	85,235	7,9444	0,65118	65,118	20,144
478,4	26,001	8,0857	83,874	7,945	0,65123	65,123	20,145
479	26,037	8,0981	83,992	7,9574	0,65224	65,224	20,157
479,7	26,088	8,1111	84,156	7,9703	0,65331	65,331	20,17
480,3	26,288	8,1252	84,8	7,9844	0,65446	65,446	20,184
481	26,122	8,1329	84,266	7,9921	0,65509	65,509	20,192
481,7	26,104	8,1444	84,208	8,0037	0,65604	65,604	20,204
482,3	26,161	8,1557	84,39	8,0149	0,65696	65,696	20,215
483	26,19	8,1671	84,484	8,0263	0,65789	65,789	20,226
483,6	26,127	8,1763	84,281	8,0355	0,65865	65,865	20,235
484,3	26,137	8,1876	84,314	8,0468	0,65958	65,958	20,247
484,9	26,139	8,1991	84,319	8,0583	0,66052	66,052	20,258
485,6	26,196	8,2104	84,505	8,0697	0,66145	66,145	20,27
486,3	26,61	8,2276	85,837	8,0868	0,66286	66,286	20,287
486,9	25,967	8,2279	83,764	8,0872	0,66288	66,288	20,287
487,6	26,094	8,2409	84,174	8,1001	0,66395	66,395	20,3
488,2	26,298	8,2549	84,832	8,1141	0,66509	66,509	20,314
488,9	26,395	8,2682	85,145	8,1274	0,66618	66,618	20,327
489,5	26,162	8,2745	84,393	8,1337	0,66669	66,669	20,334
490,2	26,214	8,2866	84,563	8,1458	0,66769	66,769	20,346
490,9	26,17	8,298	84,418	8,1572	0,66862	66,862	20,357
491,5	26,265	8,3096	84,725	8,1689	0,66958	66,958	20,369
492,2	26,197	8,3199	84,506	8,1791	0,67042	67,042	20,379
492,8	26,252	8,3324	84,682	8,1916	0,67144	67,144	20,392
493,5	26,245	8,3414	84,661	8,2006	0,67218	67,218	20,401
494,2	26,161	8,3531	84,391	8,2123	0,67314	67,314	20,412
494,8	26,285	8,3654	84,791	8,2247	0,67415	67,415	20,425
495,5	26,161	8,3751	84,391	8,2344	0,67495	67,495	20,434
496,1	26,108	8,3842	84,218	8,2434	0,67569	67,569	20,443
496,8	26,154	8,396	84,367	8,2552	0,67666	67,666	20,455
497,4	26,615	8,415	85,854	8,2743	0,67822	67,822	20,474
498,1	26,067	8,4188	84,086	8,278	0,67853	67,853	20,478
498,8	26,301	8,4306	84,843	8,2898	0,67949	67,949	20,49
499,4	26,171	8,4409	84,424	8,3002	0,68034	68,034	20,5
500,1	26,141	8,452	84,325	8,3112	0,68125	68,125	20,511
500,7	26,219	8,4631	84,576	8,3223	0,68216	68,216	20,522
501,4	26,19	8,4745	84,482	8,3338	0,6831	68,31	20,534
502	26,101	8,4827	84,197	8,3419	0,68376	68,376	20,542
502,7	26,139	8,4955	84,319	8,3547	0,68482	68,482	20,555
503,4	26,519	8,5133	85,547	8,3725	0,68627	68,627	20,572
504	25,928	8,5134	83,638	8,3726	0,68628	68,628	20,573
504,7	26,082	8,526	84,136	8,3853	0,68732	68,732	20,585
505,3	26,124	8,5391	84,27	8,3983	0,68839	68,839	20,598
506	26,133	8,5511	84,301	8,4103	0,68937	68,937	20,61
506,7	26,092	8,5617	84,168	8,4209	0,69024	69,024	20,621
507,3	26,094	8,5732	84,174	8,4324	0,69118	69,118	20,632
508	25,977	8,5823	83,797	8,4415	0,69193	69,193	20,642
508,6	25,863	8,5929	83,429	8,4521	0,69279	69,279	20,652
509,3	25,959	8,6064	83,738	8,4656	0,69391	69,391	20,666
509,9	25,96	8,6195	83,741	8,4787	0,69498	69,498	20,679
510,6	25,664	8,6248	82,788	8,4841	0,69541	69,541	20,684
511,3	25,725	8,6377	82,983	8,4969	0,69647	69,647	20,697
511,9	26,012	8,6559	83,909	8,5152	0,69796	69,796	20,715
512,6	25,276	8,656	81,535	8,5152	0,69797	69,797	20,715
513,2	25,369	8,6691	81,837	8,5283	0,69904	69,904	20,728
513,9	25,395	8,6821	81,92	8,5413	0,70011	70,011	20,741
514,6	25,43	8,6961	82,033	8,5554	0,70126	70,126	20,755
515,2	25,372	8,7067	81,846	8,5659	0,70213	70,213	20,766
515,9	25,142	8,7151	81,104	8,5744	0,70282	70,282	20,774
516,5	24,985	8,7259	80,597	8,5851	0,7037	70,37	20,785
517,2	24,733	8,7371	79,785	8,5963	0,70462	70,462	20,796
517,8	24,453	8,7481	78,879	8,6074	0,70552	70,552	20,807
518,5	24,259	8,7585	78,254	8,6177	0,70637	70,637	20,818
519,2	23,881	8,7683	77,035	8,6276	0,70718	70,718	20,828
519,8	23,492	8,7805	75,779	8,6397	0,70817	70,817	20,84
520,5	21,399	8,7985	69,029	8,6578	0,70965	70,965	20,858
521,1	17,757	8,7988	57,282	8,658	0,70967	70,967	20,858
521,8	16,453	8,8116	53,073	8,6709	0,71073	71,073	20,871
522,4	14,926	8,8242	48,149	8,6834	0,71175	71,175	20,883
523,1	11,452	8,8362	36,943	8,6954	0,71274	71,274	20,895
523,8	10,205	8,8449	32,92	8,7041	0,71345	71,345	20,904
524,4	9,5371	8,8574	30,765	8,7166	0,71447	71,447	20,917
525,1	8,922	8,8682	28,781	8,7274	0,71536	71,536	20,927
525,7	8,5534	8,8801	27,592	8,7393	0,71634	71,634	20,939
526,4	8,1334	8,8954	26,237	8,7546	0,71759	71,759	20,955
527,1	7,7017	8,8955	24,844	8,7547	0,7176	71,76	20,955
527,7	7,5175	8,9096	24,25	8,7688	0,71876	71,876	20,969
528,4	7,1413	8,9221	23,036	8,7813	0,71978	71,978	20,981
529	6,7514	8,9371	21,779	8,7963	0,72101	72,101	20,996
529,7	6,4128	8,9447	20,686	8,8039	0,72164	72,164	21,004
530,3	6,1017	8,9544	19,683	8,8137	0,72243	72,243	21,014
531	5,851	8,9666	18,874	8,8258	0,72343	72,343	21,026
531,7	5,5943	8,979	18,046	8,8382	0,72445	72,445	21,038
532,3	5,2105	8,99	16,808	8,8492	0,72535	72,535	21,049
533	5,1113	9,0008	16,488	8,86	0,72623	72,623	21,06
533,6	4,6742	9,0109	15,078	8,8701	0,72706	72,706	21,07
534,3	4,2251	9,0219	13,629	8,8811	0,72796	72,796	21,081
534,9	3,8245	9,0373	12,337	8,8965	0,72922	72,922	21,096
535,6	3,5797	9,0375	11,548	8,8968	0,72924	72,924	21,097
536,3	3,1725	9,0534	10,234	8,9126	0,73054	73,054	21,113
536,9	2,7872	9,065	8,9908	8,9243	0,7315	73,15	21,124
537,6	2,3616	9,0799	7,618	8,9391	0,73271	73,271	21,139
538,2	2,0499	9,0876	6,6127	8,9468	0,73335	73,335	21,147
538,9	1,8398	9,097	5,9348	8,9563	0,73412	73,412	21,156
539,6	1,6978	9,1101	5,4767	8,9693	0,73519	73,519	21,169
540,2	1,5792	9,1216	5,0943	8,9808	0,73613	73,613	21,181
540,9	1,5216	9,1329	4,9085	8,9922	0,73706	73,706	21,192
541,5	1,4495	9,1425	4,6757	9,0018	0,73785	73,785	21,202
542,2	1,3688	9,1526	4,4154	9,0119	0,73868	73,868	21,212
542,8	1,318	9,165	4,2517	9,0242	0,73969	73,969	21,224
543,5	1,3003	9,1788	4,1947	9,0381	0,74082	74,082	21,238
544,2	1,222	9,1882	3,9419	9,0474	0,74159	74,159	21,247
544,8	1,182	9,1959	3,8128	9,0551	0,74222	74,222	21,255
545,5	1,1311	9,2082	3,6488	9,0674	0,74323	74,323	21,267
546,1	1,1078	9,2215	3,5736	9,0807	0,74432	74,432	21,281
546,8	1,0686	9,2296	3,4471	9,0888	0,74498	74,498	21,289
547,5	0,99369	9,2391	3,2055	9,0983	0,74577	74,577	21,298
548,1	1,0203	9,2521	3,2914	9,1113	0,74683	74,683	21,311
548,8	0,98762	9,2635	3,1859	9,1227	0,74776	74,776	21,323
549,4	0,84051	9,2766	2,7113	9,1359	0,74884	74,884	21,336
550,1	0,90853	9,284	2,9308	9,1432	0,74945	74,945	21,343
550,7	0,82887	9,2965	2,6738	9,1557	0,75047	75,047	21,356
551,4	0,83818	9,307	2,7038	9,1663	0,75133	75,133	21,366
552,1	0,74949	9,3184	2,4177	9,1776	0,75226	75,226	21,378
552,7	0,75379	9,3321	2,4316	9,1913	0,75338	75,338	21,391
553,4	0,70862	9,3372	2,2859	9,1965	0,75381	75,381	21,396
554	0,68675	9,3503	2,2153	9,2095	0,75488	75,488	21,409
554,7	0,64123	9,3683	2,0685	9,2275	0,75635	75,635	21,428
555,3	0,63282	9,3694	2,0414	9,2286	0,75644	75,644	21,429
556	0,6014	9,3822	1,94	9,2414	0,75749	75,749	21,441
556,7	0,5504	9,3948	1,7755	9,254	0,75852	75,852	21,454
557,3	0,54582	9,4066	1,7607	9,2658	0,75949	75,949	21,466
558	0,52237	9,4189	1,6851	9,2781	0,7605	76,05	21,478
558,6	0,49323	9,4284	1,5911	9,2876	0,76128	76,128	21,488
559,3	0,4937	9,4378	1,5926	9,297	0,76205	76,205	21,497
560	0,48708	9,4486	1,5712	9,3078	0,76293	76,293	21,508
560,6	0,43487	9,4658	1,4028	9,325	0,76435	76,435	21,525
561,3	0,37155	9,4695	1,1986	9,3287	0,76465	76,465	21,529
561,9	0,3668	9,4809	1,1832	9,3401	0,76558	76,558	21,54
562,6	0,35769	9,4926	1,1538	9,3518	0,76654	76,654	21,552
563,2	0,1848	9,509	0,59611	9,3682	0,76789	76,789	21,568
563,9	0,17686	9,5165	0,57053	9,3757	0,7685	76,85	21,576
564,6	0,16893	9,5255	0,54495	9,3847	0,76924	76,924	21,585
565,2	0,16829	9,5375	0,54286	9,3968	0,77023	77,023	21,597
565,9	0,18398	9,5486	0,59349	9,4078	0,77114	77,114	21,608
566,5	0,16662	9,562	0,5375	9,4212	0,77223	77,223	21,621
567,2	0,17004	9,5692	0,54853	9,4285	0,77282	77,282	21,628
567,3	0,1704		0,54969