File: Tests de traction/Fichiers source/04_12_2016/10.txt
Time (s)	Load (N)	Machine Extension (mm)	Extension (mm)	Stress (MPa)	Strain	Percentage Strain	Gauge Length (mm)
0
0,3231	0,0059385	0,000076064	0,000076064	0,11877	2,5355E-06	0,00025355	30
0,6462	0,0095145	0,0023298	0,0023298	0,19029	0,000077659	0,0077659	30,002
0,9693	0,57177	0,033645	0,033645	11,435	0,0011215	0,11215	30,034
1,292	0,64323	0,037902	0,037902	12,865	0,0012634	0,12634	30,038
1,616	1,4621	0,062251	0,062251	29,242	0,002075	0,2075	30,062
1,939	2,0383	0,076172	0,076172	40,765	0,0025391	0,25391	30,076
2,262	2,386	0,08668	0,08668	47,72	0,0028893	0,28893	30,087
2,585	3,5325	0,11064	0,11064	70,649	0,0036881	0,36881	30,111
2,908	4,2175	0,124	0,124	84,35	0,0041333	0,41333	30,124
3,231	4,7515	0,13587	0,13587	95,03	0,0045291	0,45291	30,136
3,554	5,9683	0,15938	0,15938	119,37	0,0053128	0,53128	30,159
3,877	7,006	0,1716	0,1716	140,12	0,0057199	0,57199	30,172
4,2	7,9196	0,18539	0,18539	158,39	0,0061797	0,61797	30,185
4,523	9,791	0,20988	0,20988	195,82	0,0069962	0,69962	30,21
4,847	10,555	0,22133	0,22133	211,11	0,0073777	0,73777	30,221
5,17	11,449	0,23341	0,23341	228,99	0,0077802	0,77802	30,233
5,493	13,643	0,2618	0,2618	272,86	0,0087268	0,87268	30,262
5,816	14,015	0,26761	0,26761	280,3	0,0089202	0,89202	30,268
6,139	15,27	0,28314	0,28314	305,4	0,009438	0,9438	30,283
6,462	17,088	0,30944	0,30944	341,76	0,010315	1,0315	30,309
6,785	17,723	0,31966	0,31966	354,47	0,010655	1,0655	30,32
7,108	18,809	0,33268	0,33268	376,18	0,011089	1,1089	30,333
7,431	20,51	0,35798	0,35798	410,19	0,011933	1,1933	30,358
7,754	20,922	0,36587	0,36587	418,44	0,012196	1,2196	30,366
8,078	22,116	0,38062	0,38062	442,33	0,012687	1,2687	30,381
8,401	24,044	0,40858	0,40858	480,88	0,013619	1,3619	30,409
8,724	24,191	0,41475	0,41475	483,82	0,013825	1,3825	30,415
9,047	25,252	0,4289	0,4289	505,04	0,014297	1,4297	30,429
9,37	27,078	0,45705	0,45705	541,56	0,015235	1,5235	30,457
9,693	27,172	0,46319	0,46319	543,43	0,01544	1,544	30,463
10,02	28,067	0,47686	0,47686	561,33	0,015895	1,5895	30,477
10,34	29,948	0,50496	0,50496	598,97	0,016832	1,6832	30,505
10,66	30,156	0,51114	0,51114	603,13	0,017038	1,7038	30,511
10,99	31,091	0,52594	0,52594	621,83	0,017531	1,7531	30,526
11,31	32,373	0,55081	0,55081	647,46	0,01836	1,836	30,551
11,63	32,895	0,56016	0,56016	657,9	0,018672	1,8672	30,56
11,95	33,865	0,57581	0,57581	677,29	0,019194	1,9194	30,576
12,28	35,167	0,5983	0,5983	703,35	0,019943	1,9943	30,598
12,6	35,455	0,60604	0,60604	709,1	0,020201	2,0201	30,606
12,92	36,345	0,62394	0,62394	726,89	0,020798	2,0798	30,624
13,25	37,668	0,64763	0,64763	753,37	0,021588	2,1588	30,648
13,57	37,693	0,65478	0,65478	753,86	0,021826	2,1826	30,655
13,89	38,639	0,67338	0,67338	772,77	0,022446	2,2446	30,673
14,22	39,746	0,69557	0,69557	794,93	0,023186	2,3186	30,696
14,54	39,982	0,70387	0,70387	799,63	0,023462	2,3462	30,704
14,86	40,714	0,72171	0,72171	814,28	0,024057	2,4057	30,722
15,19	41,631	0,74368	0,74368	832,61	0,024789	2,4789	30,744
15,51	41,775	0,75323	0,75323	835,5	0,025108	2,5108	30,753
15,83	42,493	0,77131	0,77131	849,87	0,02571	2,571	30,771
16,16	43,258	0,79105	0,79105	865,17	0,026368	2,6368	30,791
16,48	43,431	0,79955	0,79955	868,62	0,026652	2,6652	30,8
16,8	44,062	0,81942	0,81942	881,24	0,027314	2,7314	30,819
17,12	44,508	0,83727	0,83727	890,16	0,027909	2,7909	30,837
17,45	44,812	0,85115	0,85115	896,23	0,028372	2,8372	30,851
17,77	45,367	0,86918	0,86918	907,34	0,028973	2,8973	30,869
18,09	45,676	0,88577	0,88577	913,52	0,029526	2,9526	30,886
18,42	45,867	0,89723	0,89723	917,34	0,029908	2,9908	30,897
18,74	46,399	0,91616	0,91616	927,98	0,030539	3,0539	30,916
19,06	46,648	0,93426	0,93426	932,96	0,031142	3,1142	30,934
19,39	46,559	0,94313	0,94313	931,19	0,031438	3,1438	30,943
19,71	47,178	0,96571	0,96571	943,57	0,03219	3,219	30,966
20,03	47,363	0,9817	0,9817	947,26	0,032723	3,2723	30,982
20,36	47,594	0,99616	0,99616	951,87	0,033205	3,3205	30,996
20,68	48,111	1,0154	1,0154	962,22	0,033847	3,3847	31,015
21	48,257	1,0316	1,0316	965,13	0,034387	3,4387	31,032
21,32	48,173	1,0417	1,0417	963,46	0,034724	3,4724	31,042
21,65	48,638	1,0621	1,0621	972,75	0,035402	3,5402	31,062
21,97	48,562	1,0774	1,0774	971,24	0,035912	3,5912	31,077
22,29	48,546	1,0901	1,0901	970,92	0,036338	3,6338	31,09
22,62	49,383	1,1148	1,1148	987,66	0,037158	3,7158	31,115
22,94	48,913	1,1273	1,1273	978,26	0,037576	3,7576	31,127
23,26	49,017	1,1397	1,1397	980,35	0,037992	3,7992	31,14
23,59	49,622	1,1655	1,1655	992,43	0,038851	3,8851	31,166
23,91	49,163	1,1743	1,1743	983,26	0,039143	3,9143	31,174
24,23	49,15	1,1873	1,1873	983,01	0,039577	3,9577	31,187
24,56	49,917	1,2148	1,2148	998,35	0,040495	4,0495	31,215
24,88	49,324	1,2217	1,2217	986,48	0,040723	4,0723	31,222
25,2	49,442	1,2369	1,2369	988,83	0,04123	4,123	31,237
25,53	50,23	1,2645	1,2645	1004,6	0,042151	4,2151	31,265
25,85	49,531	1,2698	1,2698	990,63	0,042328	4,2328	31,27
26,17	49,696	1,2868	1,2868	993,91	0,042895	4,2895	31,287
26,49	50,34	1,3128	1,3128	1006,8	0,043759	4,3759	31,313
26,82	49,648	1,3205	1,3205	992,96	0,044017	4,4017	31,321
27,14	49,792	1,3348	1,3348	995,84	0,044492	4,4492	31,335
27,46	50,301	1,3602	1,3602	1006	0,04534	4,534	31,36
27,79	49,822	1,3688	1,3688	996,44	0,045627	4,5627	31,369
28,11	49,849	1,3837	1,3837	996,97	0,046124	4,6124	31,384
28,43	49,999	1,4056	1,4056	999,98	0,046855	4,6855	31,406
28,76	49,842	1,4163	1,4163	996,85	0,047211	4,7211	31,416
29,08	49,833	1,4312	1,4312	996,66	0,047707	4,7707	31,431
29,4	50,285	1,456	1,456	1005,7	0,048535	4,8535	31,456
29,73	49,863	1,4648	1,4648	997,27	0,048828	4,8828	31,465
30,05	49,947	1,4806	1,4806	998,94	0,049355	4,9355	31,481
30,37	50,427	1,5044	1,5044	1008,5	0,050146	5,0146	31,504
30,69	49,907	1,5133	1,5133	998,14	0,050444	5,0444	31,513
31,02	50,11	1,5284	1,5284	1002,2	0,050946	5,0946	31,528
31,34	50,425	1,552	1,552	1008,5	0,051734	5,1734	31,552
31,66	49,961	1,5604	1,5604	999,23	0,052012	5,2012	31,56
31,99	49,971	1,5757	1,5757	999,43	0,052524	5,2524	31,576
32,31	50,535	1,6015	1,6015	1010,7	0,053384	5,3384	31,602
32,63	50,01	1,6087	1,6087	1000,2	0,053625	5,3625	31,609
32,96	50,303	1,6272	1,6272	1006,1	0,054241	5,4241	31,627
33,28	50,484	1,6473	1,6473	1009,7	0,054909	5,4909	31,647
33,6	50,145	1,6572	1,6572	1002,9	0,055238	5,5238	31,657
33,93	50,317	1,6756	1,6756	1006,3	0,055854	5,5854	31,676
34,25	50,464	1,6945	1,6945	1009,3	0,056482	5,6482	31,694
34,57	50,06	1,7033	1,7033	1001,2	0,056775	5,6775	31,703
34,9	50,52	1,7239	1,7239	1010,4	0,057463	5,7463	31,724
35,22	50,585	1,7425	1,7425	1011,7	0,058083	5,8083	31,742
35,54	50,315	1,7526	1,7526	1006,3	0,05842	5,842	31,753
35,86	50,695	1,773	1,773	1013,9	0,059099	5,9099	31,773
36,19	50,708	1,7912	1,7912	1014,2	0,059707	5,9707	31,791
36,51	50,35	1,8011	1,8011	1007	0,060037	6,0037	31,801
36,83	50,728	1,8211	1,8211	1014,6	0,060704	6,0704	31,821
37,16	50,692	1,8383	1,8383	1013,8	0,061275	6,1275	31,838
37,48	50,426	1,8484	1,8484	1008,5	0,061612	6,1612	31,848
37,8	50,757	1,8717	1,8717	1015,1	0,062389	6,2389	31,872
38,13	50,755	1,8866	1,8866	1015,1	0,062888	6,2888	31,887
38,45	50,465	1,897	1,897	1009,3	0,063234	6,3234	31,897
38,77	50,939	1,9198	1,9198	1018,8	0,063994	6,3994	31,92
39,1	50,71	1,9342	1,9342	1014,2	0,064474	6,4474	31,934
39,42	50,639	1,9465	1,9465	1012,8	0,064885	6,4885	31,947
39,74	50,868	1,9672	1,9672	1017,4	0,065572	6,5572	31,967
40,06	50,753	1,9832	1,9832	1015,1	0,066105	6,6105	31,983
40,39	50,582	1,9953	1,9953	1011,6	0,06651	6,651	31,995
40,71	50,965	2,0171	2,0171	1019,3	0,067237	6,7237	32,017
41,03	50,728	2,0314	2,0314	1014,6	0,067714	6,7714	32,031
41,36	50,605	2,043	2,043	1012,1	0,068099	6,8099	32,043
41,68	51,266	2,0675	2,0675	1025,3	0,068916	6,8916	32,067
42	50,874	2,0784	2,0784	1017,5	0,069281	6,9281	32,078
42,33	50,854	2,0939	2,0939	1017,1	0,069797	6,9797	32,094
42,65	51,534	2,1182	2,1182	1030,7	0,070607	7,0607	32,118
42,97	51,063	2,1287	2,1287	1021,3	0,070956	7,0956	32,129
43,3	50,939	2,1416	2,1416	1018,8	0,071385	7,1385	32,142
43,62	51,571	2,1641	2,1641	1031,4	0,072135	7,2135	32,164
43,94	51,102	2,1748	2,1748	1022	0,072492	7,2492	32,175
44,26	51,071	2,1908	2,1908	1021,4	0,073028	7,3028	32,191
44,59	51,96	2,2193	2,2193	1039,2	0,073976	7,3976	32,219
44,91	51,151	2,2231	2,2231	1023	0,074102	7,4102	32,223
45,23	51,22	2,2384	2,2384	1024,4	0,074614	7,4614	32,238
45,56	51,82	2,2641	2,2641	1036,4	0,07547	7,547	32,264
45,88	51,503	2,274	2,274	1030,1	0,075799	7,5799	32,274
46,2	51,465	2,2878	2,2878	1029,3	0,076259	7,6259	32,288
46,53	52,176	2,3152	2,3152	1043,5	0,077175	7,7175	32,315
46,85	51,412	2,3198	2,3198	1028,2	0,077328	7,7328	32,32
47,17	51,564	2,3356	2,3356	1031,3	0,077852	7,7852	32,336
47,5	52,2	2,3619	2,3619	1044	0,078729	7,8729	32,362
47,82	51,379	2,3668	2,3668	1027,6	0,078893	7,8893	32,367
48,14	51,64	2,3852	2,3852	1032,8	0,079506	7,9506	32,385
48,47	52,069	2,4085	2,4085	1041,4	0,080282	8,0282	32,408
48,79	51,628	2,4159	2,4159	1032,6	0,080529	8,0529	32,416
49,11	51,685	2,4358	2,4358	1033,7	0,081192	8,1192	32,436
49,43	52,012	2,4562	2,4562	1040,2	0,081873	8,1873	32,456
49,76	51,604	2,4644	2,4644	1032,1	0,082146	8,2146	32,464
50,08	51,779	2,4827	2,4827	1035,6	0,082758	8,2758	32,483
50,4	52,028	2,5036	2,5036	1040,6	0,083452	8,3452	32,504
50,73	51,698	2,513	2,513	1034	0,083768	8,3768	32,513
51,05	51,811	2,5303	2,5303	1036,2	0,084345	8,4345	32,53
51,37	52,236	2,5528	2,5528	1044,7	0,085094	8,5094	32,553
51,7	51,846	2,5605	2,5605	1036,9	0,085349	8,5349	32,56
52,02	52,053	2,58	2,58	1041,1	0,085999	8,5999	32,58
52,34	52,368	2,6007	2,6007	1047,4	0,086689	8,6689	32,601
52,67	51,886	2,608	2,608	1037,7	0,086933	8,6933	32,608
52,99	52,205	2,628	2,628	1044,1	0,087602	8,7602	32,628
53,31	52,396	2,6495	2,6495	1047,9	0,088316	8,8316	32,649
53,63	52,114	2,6577	2,6577	1042,3	0,08859	8,859	32,658
53,96	52,281	2,6756	2,6756	1045,6	0,089186	8,9186	32,676
54,28	52,516	2,6976	2,6976	1050,3	0,089919	8,9919	32,698
54,6	52,044	2,7055	2,7055	1040,9	0,090184	9,0184	32,706
54,93	52,263	2,7259	2,7259	1045,3	0,090862	9,0862	32,726
55,25	52,425	2,7439	2,7439	1048,5	0,091464	9,1464	32,744
55,57	52,079	2,7533	2,7533	1041,6	0,091777	9,1777	32,753
55,9	52,568	2,7752	2,7752	1051,4	0,092506	9,2506	32,775
56,22	52,497	2,7911	2,7911	1049,9	0,093035	9,3035	32,791
56,54	52,192	2,8032	2,8032	1043,8	0,09344	9,344	32,803
56,87	52,742	2,8269	2,8269	1054,8	0,094231	9,4231	32,827
57,19	52,59	2,8387	2,8387	1051,8	0,094623	9,4623	32,839
57,51	52,379	2,85	2,85	1047,6	0,095001	9,5001	32,85
57,84	52,944	2,8755	2,8755	1058,9	0,09585	9,585	32,875
58,16	52,638	2,8874	2,8874	1052,8	0,096245	9,6245	32,887
58,48	52,546	2,9002	2,9002	1050,9	0,096674	9,6674	32,9
58,8	53,038	2,9237	2,9237	1060,8	0,097456	9,7456	32,924
59,13	52,671	2,9346	2,9346	1053,4	0,097822	9,7822	32,935
59,45	52,664	2,947	2,947	1053,3	0,098235	9,8235	32,947
59,77	53,327	2,9757	2,9757	1066,5	0,099191	9,9191	32,976
60,1	52,674	2,9812	2,9812	1053,5	0,099373	9,9373	32,981
60,42	52,726	2,9979	2,9979	1054,5	0,09993	9,993	32,998
60,74	53,445	3,0242	3,0242	1068,9	0,10081	10,081	33,024
61,07	52,942	3,0336	3,0336	1058,8	0,10112	10,112	33,034
61,39	52,974	3,0465	3,0465	1059,5	0,10155	10,155	33,047
61,71	53,65	3,0732	3,0732	1073	0,10244	10,244	33,073
62,04	53,098	3,0803	3,0803	1062	0,10268	10,268	33,08
62,36	53,213	3,0968	3,0968	1064,3	0,10323	10,323	33,097
62,68	53,778	3,1216	3,1216	1075,6	0,10405	10,405	33,122
63	53,191	3,1295	3,1295	1063,8	0,10432	10,432	33,13
63,33	53,242	3,1442	3,1442	1064,8	0,10481	10,481	33,144
63,65	53,689	3,1681	3,1681	1073,8	0,1056	10,56	33,168
63,97	53,231	3,1771	3,1771	1064,6	0,1059	10,59	33,177
64,3	53,258	3,1924	3,1924	1065,2	0,10641	10,641	33,192
64,62	53,848	3,2176	3,2176	1077	0,10725	10,725	33,218
64,94	53,351	3,2251	3,2251	1067	0,1075	10,75	33,225
65,27	53,326	3,2413	3,2413	1066,5	0,10804	10,804	33,241
65,59	53,998	3,2662	3,2662	1080	0,10887	10,887	33,266
65,91	53,471	3,2738	3,2738	1069,4	0,10913	10,913	33,274
66,24	53,494	3,2887	3,2887	1069,9	0,10962	10,962	33,289
66,56	53,949	3,3116	3,3116	1079	0,11039	11,039	33,312
66,88	53,598	3,3215	3,3215	1072	0,11072	11,072	33,322
67,21	53,862	3,34	3,34	1077,2	0,11133	11,133	33,34
67,53	54,244	3,3624	3,3624	1084,9	0,11208	11,208	33,362
67,85	53,73	3,3707	3,3707	1074,6	0,11236	11,236	33,371
68,17	53,803	3,3878	3,3878	1076,1	0,11293	11,293	33,388
68,5	54,199	3,4092	3,4092	1084	0,11364	11,364	33,409
68,82	53,815	3,4188	3,4188	1076,3	0,11396	11,396	33,419
69,14	54,111	3,4375	3,4375	1082,2	0,11458	11,458	33,438
69,47	54,391	3,4588	3,4588	1087,8	0,11529	11,529	33,459
69,79	53,933	3,4662	3,4662	1078,7	0,11554	11,554	33,466
70,11	54,105	3,4857	3,4857	1082,1	0,11619	11,619	33,486
70,44	54,275	3,5038	3,5038	1085,5	0,11679	11,679	33,504
70,76	53,915	3,5138	3,5138	1078,3	0,11713	11,713	33,514
71,08	54,379	3,5341	3,5341	1087,6	0,1178	11,78	33,534
71,41	54,467	3,5512	3,5512	1089,3	0,11837	11,837	33,551
71,73	54,103	3,5635	3,5635	1082,1	0,11878	11,878	33,563
72,05	54,51	3,5834	3,5834	1090,2	0,11945	11,945	33,583
72,37	54,519	3,5994	3,5994	1090,4	0,11998	11,998	33,599
72,7	54,23	3,6096	3,6096	1084,6	0,12032	12,032	33,61
73,02	54,778	3,6334	3,6334	1095,6	0,12111	12,111	33,633
73,34	54,593	3,647	3,647	1091,9	0,12157	12,157	33,647
73,67	54,499	3,6607	3,6607	1090	0,12202	12,202	33,661
73,99	54,614	3,6783	3,6783	1092,3	0,12261	12,261	33,678
74,31	54,845	3,6982	3,6982	1096,9	0,12327	12,327	33,698
74,64	54,506	3,708	3,708	1090,1	0,1236	12,36	33,708
74,96	54,809	3,7289	3,7289	1096,2	0,1243	12,43	33,729
75,28	54,75	3,7436	3,7436	1095	0,12479	12,479	33,744
75,61	54,661	3,7565	3,7565	1093,2	0,12522	12,522	33,756
75,93	55,117	3,7756	3,7756	1102,3	0,12585	12,585	33,776
76,25	54,909	3,792	3,792	1098,2	0,1264	12,64	33,792
76,58	54,699	3,8025	3,8025	1094	0,12675	12,675	33,803
76,9	55,337	3,8274	3,8274	1106,7	0,12758	12,758	33,827
77,22	55,193	3,8419	3,8419	1103,9	0,12806	12,806	33,842
77,54	54,993	3,854	3,854	1099,9	0,12847	12,847	33,854
77,87	55,372	3,8753	3,8753	1107,4	0,12918	12,918	33,875
78,19	55,359	3,8902	3,8902	1107,2	0,12967	12,967	33,89
78,51	55,093	3,9015	3,9015	1101,9	0,13005	13,005	33,902
78,84	55,828	3,9285	3,9285	1116,6	0,13095	13,095	33,929
79,16	55,243	3,9374	3,9374	1104,9	0,13125	13,125	33,937
79,48	55,365	3,9515	3,9515	1107,3	0,13172	13,172	33,951
79,81	55,847	3,9768	3,9768	1116,9	0,13256	13,256	33,977
80,13	55,594	3,9867	3,9867	1111,9	0,13289	13,289	33,987
80,45	55,445	3,9992	3,9992	1108,9	0,13331	13,331	33,999
80,78	56,451	4,0299	4,0299	1129	0,13433	13,433	34,03
81,1	55,585	4,0313	4,0313	1111,7	0,13438	13,438	34,031
81,42	55,744	4,0497	4,0497	1114,9	0,13499	13,499	34,05
81,74	56,398	4,0753	4,0753	1128	0,13584	13,584	34,075
82,07	55,677	4,0804	4,0804	1113,5	0,13601	13,601	34,08
82,39	55,77	4,097	4,097	1115,4	0,13657	13,657	34,097
82,71	56,429	4,1227	4,1227	1128,6	0,13742	13,742	34,123
83,04	55,826	4,1294	4,1294	1116,5	0,13765	13,765	34,129
83,36	55,858	4,1469	4,1469	1117,2	0,13823	13,823	34,147
83,68	56,29	4,1684	4,1684	1125,8	0,13895	13,895	34,168
84,01	55,853	4,1784	4,1784	1117,1	0,13928	13,928	34,178
84,33	56,008	4,1953	4,1953	1120,2	0,13984	13,984	34,195
84,65	56,177	4,2158	4,2158	1123,5	0,14053	14,053	34,216
84,98	55,877	4,2262	4,2262	1117,5	0,14087	14,087	34,226
85,3	56,142	4,2443	4,2443	1122,8	0,14148	14,148	34,244
85,62	56,355	4,2651	4,2651	1127,1	0,14217	14,217	34,265
85,95	55,969	4,2743	4,2743	1119,4	0,14248	14,248	34,274
86,27	56,216	4,2927	4,2927	1124,3	0,14309	14,309	34,293
86,59	56,522	4,3135	4,3135	1130,4	0,14378	14,378	34,313
86,91	56,118	4,3223	4,3223	1122,4	0,14408	14,408	34,322
87,24	56,383	4,3415	4,3415	1127,7	0,14472	14,472	34,342
87,56	56,768	4,3638	4,3638	1135,4	0,14546	14,546	34,364
87,88	56,244	4,3705	4,3705	1124,9	0,14568	14,568	34,37
88,21	56,313	4,3875	4,3875	1126,3	0,14625	14,625	34,388
88,53	56,834	4,411	4,411	1136,7	0,14703	14,703	34,411
88,85	56,414	4,4198	4,4198	1128,3	0,14733	14,733	34,42
89,18	56,648	4,4383	4,4383	1133	0,14794	14,794	34,438
89,5	56,718	4,4568	4,4568	1134,4	0,14856	14,856	34,457
89,82	56,356	4,4658	4,4658	1127,1	0,14886	14,886	34,466
90,15	56,68	4,4861	4,4861	1133,6	0,14954	14,954	34,486
90,47	56,892	4,5056	4,5056	1137,8	0,15019	15,019	34,506
90,79	56,511	4,5151	4,5151	1130,2	0,1505	15,05	34,515
91,11	56,991	4,5368	4,5368	1139,8	0,15123	15,123	34,537
91,44	57,039	4,554	4,554	1140,8	0,1518	15,18	34,554
91,76	56,769	4,5643	4,5643	1135,4	0,15214	15,214	34,564
92,08	57,132	4,5851	4,5851	1142,6	0,15284	15,284	34,585
92,41	57,122	4,6018	4,6018	1142,4	0,15339	15,339	34,602
92,73	56,824	4,6123	4,6123	1136,5	0,15374	15,374	34,612
93,05	57,214	4,6332	4,6332	1144,3	0,15444	15,444	34,633
93,38	57,07	4,647	4,647	1141,4	0,1549	15,49	34,647
93,7	56,886	4,66	4,66	1137,7	0,15533	15,533	34,66
94,02	57,262	4,683	4,683	1145,2	0,1561	15,61	34,683
94,35	57,128	4,6952	4,6952	1142,6	0,15651	15,651	34,695
94,67	56,982	4,7093	4,7093	1139,6	0,15698	15,698	34,709
94,99	57,553	4,7314	4,7314	1151,1	0,15771	15,771	34,731
95,32	57,278	4,7445	4,7445	1145,6	0,15815	15,815	34,745
95,64	57,129	4,7567	4,7567	1142,6	0,15856	15,856	34,757
95,96	57,74	4,7817	4,7817	1154,8	0,15939	15,939	34,782
96,28	57,493	4,7944	4,7944	1149,9	0,15981	15,981	34,794
96,61	57,455	4,8067	4,8067	1149,1	0,16022	16,022	34,807
96,93	57,92	4,8305	4,8305	1158,4	0,16102	16,102	34,83
97,25	57,77	4,844	4,844	1155,4	0,16147	16,147	34,844
97,58	57,613	4,8562	4,8562	1152,3	0,16187	16,187	34,856
97,9	58,128	4,8797	4,8797	1162,6	0,16266	16,266	34,88
98,22	57,887	4,8918	4,8918	1157,7	0,16306	16,306	34,892
98,55	57,716	4,9043	4,9043	1154,3	0,16348	16,348	34,904
98,87	58,283	4,9287	4,9287	1165,7	0,16429	16,429	34,929
99,19	57,841	4,9384	4,9384	1156,8	0,16461	16,461	34,938
99,52	57,837	4,9528	4,9528	1156,7	0,16509	16,509	34,953
99,84	58,622	4,9805	4,9805	1172,4	0,16602	16,602	34,98
100,2	58,036	4,9867	4,9867	1160,7	0,16622	16,622	34,987
100,5	57,994	5,0032	5,0032	1159,9	0,16677	16,677	35,003
100,8	58,6	5,0254	5,0254	1172	0,16751	16,751	35,025
101,1	58,062	5,0345	5,0345	1161,2	0,16782	16,782	35,035
101,5	58,166	5,0493	5,0493	1163,3	0,16831	16,831	35,049
101,8	59,022	5,0792	5,0792	1180,4	0,16931	16,931	35,079
102,1	58,119	5,0807	5,0807	1162,4	0,16936	16,936	35,081
102,4	58,267	5,1	5,1	1165,3	0,17	17	35,1
102,7	58,578	5,122	5,122	1171,6	0,17073	17,073	35,122
103,1	58,35	5,1307	5,1307	1167	0,17102	17,102	35,131
103,4	58,474	5,1479	5,1479	1169,5	0,1716	17,16	35,148
103,7	59,018	5,1723	5,1723	1180,4	0,17241	17,241	35,172
104	58,376	5,1788	5,1788	1167,5	0,17263	17,263	35,179
104,4	58,601	5,1973	5,1973	1172	0,17324	17,324	35,197
104,7	58,964	5,219	5,219	1179,3	0,17397	17,397	35,219
105	58,515	5,2271	5,2271	1170,3	0,17424	17,424	35,227
105,3	58,619	5,2439	5,2439	1172,4	0,1748	17,48	35,244
105,7	59,021	5,2661	5,2661	1180,4	0,17554	17,554	35,266
106	58,571	5,2743	5,2743	1171,4	0,17581	17,581	35,274
106,3	58,961	5,2959	5,2959	1179,2	0,17653	17,653	35,296
106,6	59,082	5,3144	5,3144	1181,6	0,17715	17,715	35,314
106,9	58,729	5,3245	5,3245	1174,6	0,17748	17,748	35,324
107,3	58,933	5,3429	5,3429	1178,7	0,1781	17,81	35,343
107,6	59,182	5,362	5,362	1183,6	0,17873	17,873	35,362
107,9	58,853	5,3708	5,3708	1177,1	0,17903	17,903	35,371
108,2	59,117	5,3926	5,3926	1182,3	0,17975	17,975	35,393
108,6	59,223	5,4103	5,4103	1184,5	0,18034	18,034	35,41
108,9	58,855	5,4193	5,4193	1177,1	0,18064	18,064	35,419
109,2	59,28	5,4421	5,4421	1185,6	0,1814	18,14	35,442
109,5	59,173	5,4572	5,4572	1183,5	0,18191	18,191	35,457
109,9	59,084	5,4714	5,4714	1181,7	0,18238	18,238	35,471
110,2	59,278	5,4904	5,4904	1185,6	0,18301	18,301	35,49
110,5	59,375	5,5076	5,5076	1187,5	0,18359	18,359	35,508
110,8	58,968	5,5166	5,5166	1179,4	0,18389	18,389	35,517
111,1	59,398	5,537	5,537	1188	0,18457	18,457	35,537
111,5	59,582	5,555	5,555	1191,6	0,18517	18,517	35,555
111,8	59,278	5,5651	5,5651	1185,6	0,1855	18,55	35,565
112,1	59,605	5,5857	5,5857	1192,1	0,18619	18,619	35,586
112,4	59,623	5,6029	5,6029	1192,5	0,18676	18,676	35,603
112,8	59,342	5,613	5,613	1186,8	0,1871	18,71	35,613
113,1	59,911	5,6362	5,6362	1198,2	0,18787	18,787	35,636
113,4	59,695	5,6503	5,6503	1193,9	0,18834	18,834	35,65
113,7	59,467	5,6622	5,6622	1189,3	0,18874	18,874	35,662
114,1	60,058	5,6873	5,6873	1201,2	0,18958	18,958	35,687
114,4	59,909	5,7004	5,7004	1198,2	0,19001	19,001	35,7
114,7	59,845	5,7125	5,7125	1196,9	0,19042	19,042	35,712
115	60,303	5,736	5,736	1206,1	0,1912	19,12	35,736
115,3	59,863	5,7462	5,7462	1197,3	0,19154	19,154	35,746
115,7	59,794	5,7601	5,7601	1195,9	0,192	19,2	35,76
116	60,548	5,7888	5,7888	1211	0,19296	19,296	35,789
116,3	59,957	5,7945	5,7945	1199,1	0,19315	19,315	35,795
116,6	59,885	5,8084	5,8084	1197,7	0,19361	19,361	35,808
117	60,578	5,8346	5,8346	1211,6	0,19449	19,449	35,835
117,3	60,104	5,8428	5,8428	1202,1	0,19476	19,476	35,843
117,6	60,188	5,8582	5,8582	1203,8	0,19527	19,527	35,858
117,9	60,636	5,8829	5,8829	1212,7	0,1961	19,61	35,883
118,3	60,255	5,8929	5,8929	1205,1	0,19643	19,643	35,893
118,6	60,143	5,9066	5,9066	1202,9	0,19689	19,689	35,907
118,9	60,529	5,9281	5,9281	1210,6	0,1976	19,76	35,928
119,2	60,052	5,9402	5,9402	1201	0,19801	19,801	35,94
119,5	60,256	5,956	5,956	1205,1	0,19853	19,853	35,956
119,9	60,618	5,9785	5,9785	1212,4	0,19928	19,928	35,978
120,2	60,299	5,9874	5,9874	1206	0,19958	19,958	35,987
120,5	60,307	6,0036	6,0036	1206,1	0,20012	20,012	36,004
120,8	60,779	6,026	6,026	1215,6	0,20087	20,087	36,026
121,2	60,325	6,0352	6,0352	1206,5	0,20117	20,117	36,035
121,5	60,609	6,0534	6,0534	1212,2	0,20178	20,178	36,053
121,8	60,943	6,0755	6,0755	1218,9	0,20252	20,252	36,075
122,1	60,412	6,0833	6,0833	1208,2	0,20278	20,278	36,083
122,5	60,551	6,0999	6,0999	1211	0,20333	20,333	36,1
122,8	60,977	6,1231	6,1231	1219,5	0,2041	20,41	36,123
123,1	60,64	6,1334	6,1334	1212,8	0,20445	20,445	36,133
123,4	60,661	6,1503	6,1503	1213,2	0,20501	20,501	36,15
123,7	61,064	6,1721	6,1721	1221,3	0,20574	20,574	36,172
124,1	60,624	6,1802	6,1802	1212,5	0,20601	20,601	36,18
124,4	60,788	6,1977	6,1977	1215,8	0,20659	20,659	36,198
124,7	61,113	6,2192	6,2192	1222,3	0,20731	20,731	36,219
125	60,713	6,2288	6,2288	1214,3	0,20763	20,763	36,229
125,4	61,093	6,2489	6,2489	1221,9	0,2083	20,83	36,249
125,7	60,983	6,2668	6,2668	1219,7	0,20889	20,889	36,267
126	60,65	6,2786	6,2786	1213	0,20929	20,929	36,279
126,3	61,133	6,294	6,294	1222,7	0,2098	20,98	36,294
126,7	61,306	6,3154	6,3154	1226,1	0,21051	21,051	36,315
127	60,947	6,3251	6,3251	1218,9	0,21084	21,084	36,325
127,3	61,278	6,3454	6,3454	1225,6	0,21151	21,151	36,345
127,6	61,314	6,363	6,363	1226,3	0,2121	21,21	36,363
127,9	61,017	6,3731	6,3731	1220,3	0,21244	21,244	36,373
128,3	61,303	6,393	6,393	1226,1	0,2131	21,31	36,393
128,6	61,214	6,4092	6,4092	1224,3	0,21364	21,364	36,409
128,9	61,11	6,4217	6,4217	1222,2	0,21406	21,406	36,422
129,2	61,534	6,444	6,444	1230,7	0,2148	21,48	36,444
129,6	61,263	6,4571	6,4571	1225,3	0,21524	21,524	36,457
129,9	61,214	6,4682	6,4682	1224,3	0,21561	21,561	36,468
130,2	61,599	6,4937	6,4937	1232	0,21646	21,646	36,494
130,5	61,408	6,507	6,507	1228,2	0,2169	21,69	36,507
130,9	61,201	6,519	6,519	1224	0,2173	21,73	36,519
131,2	61,74	6,5417	6,5417	1234,8	0,21806	21,806	36,542
131,5	61,505	6,5555	6,5555	1230,1	0,21852	21,852	36,555
131,8	61,392	6,5677	6,5677	1227,8	0,21892	21,892	36,568
132,1	61,783	6,5897	6,5897	1235,7	0,21966	21,966	36,59
132,5	61,557	6,6032	6,6032	1231,1	0,22011	22,011	36,603
132,8	61,523	6,6153	6,6153	1230,5	0,22051	22,051	36,615
133,1	61,977	6,6403	6,6403	1239,5	0,22134	22,134	36,64
133,4	61,603	6,6522	6,6522	1232,1	0,22174	22,174	36,652
133,8	61,581	6,6651	6,6651	1231,6	0,22217	22,217	36,665
134,1	62,003	6,6879	6,6879	1240,1	0,22293	22,293	36,688
134,4	61,816	6,6993	6,6993	1236,3	0,22331	22,331	36,699
134,7	61,686	6,7144	6,7144	1233,7	0,22381	22,381	36,714
135,1	62,294	6,7395	6,7395	1245,9	0,22465	22,465	36,739
135,4	61,803	6,7476	6,7476	1236,1	0,22492	22,492	36,748
135,7	61,761	6,7612	6,7612	1235,2	0,22537	22,537	36,761
136	62,44	6,7888	6,7888	1248,8	0,22629	22,629	36,789
136,3	61,923	6,796	6,796	1238,5	0,22653	22,653	36,796
136,7	62,024	6,812	6,812	1240,5	0,22707	22,707	36,812
137	62,458	6,8349	6,8349	1249,2	0,22783	22,783	36,835
137,3	62,013	6,8435	6,8435	1240,3	0,22812	22,812	36,844
137,6	62,098	6,8601	6,8601	1242	0,22867	22,867	36,86
138	62,617	6,885	6,885	1252,3	0,2295	22,95	36,885
138,3	62,037	6,8916	6,8916	1240,7	0,22972	22,972	36,892
138,6	62,111	6,9082	6,9082	1242,2	0,23027	23,027	36,908
138,9	62,675	6,9331	6,9331	1253,5	0,2311	23,11	36,933
139,3	62,073	6,94	6,94	1241,5	0,23133	23,133	36,94
139,6	62,224	6,9573	6,9573	1244,5	0,23191	23,191	36,957
139,9	62,612	6,9787	6,9787	1252,2	0,23262	23,262	36,979
140,2	62,26	6,9881	6,9881	1245,2	0,23294	23,294	36,988
140,5	62,339	7,0067	7,0067	1246,8	0,23356	23,356	37,007
140,9	62,676	7,027	7,027	1253,5	0,23423	23,423	37,027
141,2	62,249	7,0356	7,0356	1245	0,23452	23,452	37,036
141,5	62,655	7,0565	7,0565	1253,1	0,23522	23,522	37,056
141,8	62,754	7,0756	7,0756	1255,1	0,23585	23,585	37,076
142,2	62,366	7,0859	7,0859	1247,3	0,2362	23,62	37,086
142,5	62,569	7,104	7,104	1251,4	0,2368	23,68	37,104
142,8	62,778	7,1238	7,1238	1255,6	0,23746	23,746	37,124
143,1	62,399	7,1338	7,1338	1248	0,23779	23,779	37,134
143,5	62,634	7,1501	7,1501	1252,7	0,23834	23,834	37,15
143,8	62,747	7,1714	7,1714	1254,9	0,23905	23,905	37,171
144,1	62,511	7,1823	7,1823	1250,2	0,23941	23,941	37,182
144,4	62,765	7,2012	7,2012	1255,3	0,24004	24,004	37,201
144,7	62,97	7,2212	7,2212	1259,4	0,24071	24,071	37,221
145,1	62,549	7,2292	7,2292	1251	0,24097	24,097	37,229
145,4	62,772	7,2489	7,2489	1255,4	0,24163	24,163	37,249
145,7	62,902	7,267	7,267	1258	0,24223	24,223	37,267
146	62,554	7,2793	7,2793	1251,1	0,24264	24,264	37,279
146,4	63,005	7,2965	7,2965	1260,1	0,24322	24,322	37,296
146,7	63,08	7,3165	7,3165	1261,6	0,24388	24,388	37,317
147	62,699	7,3258	7,3258	1254	0,24419	24,419	37,326
147,3	63,154	7,3482	7,3482	1263,1	0,24494	24,494	37,348
147,7	62,963	7,3625	7,3625	1259,3	0,24542	24,542	37,362
148	62,825	7,3754	7,3754	1256,5	0,24585	24,585	37,375
148,3	63,125	7,3966	7,3966	1262,5	0,24655	24,655	37,397
148,6	63,125	7,4134	7,4134	1262,5	0,24711	24,711	37,413
149	62,868	7,4241	7,4241	1257,4	0,24747	24,747	37,424
149,3	63,352	7,4457	7,4457	1267	0,24819	24,819	37,446
149,6	63,121	7,4602	7,4602	1262,4	0,24867	24,867	37,46
149,9	62,993	7,4724	7,4724	1259,9	0,24908	24,908	37,472
150,2	63,517	7,4967	7,4967	1270,3	0,24989	24,989	37,497
150,6	63,093	7,507	7,507	1261,9	0,25023	25,023	37,507
150,9	63,025	7,5206	7,5206	1260,5	0,25069	25,069	37,521
151,2	63,844	7,5485	7,5485	1276,9	0,25162	25,162	37,548
151,5	63,342	7,557	7,557	1266,8	0,2519	25,19	37,557
151,9	63,248	7,5702	7,5702	1265	0,25234	25,234	37,57
152,2	63,68	7,5932	7,5932	1273,6	0,25311	25,311	37,593
152,5	63,366	7,6044	7,6044	1267,3	0,25348	25,348	37,604
152,8	63,334	7,6186	7,6186	1266,7	0,25395	25,395	37,619
153,2	63,831	7,6428	7,6428	1276,6	0,25476	25,476	37,643
153,5	63,456	7,6538	7,6538	1269,1	0,25513	25,513	37,654
153,8	63,375	7,6677	7,6677	1267,5	0,25559	25,559	37,668
154,1	63,766	7,6907	7,6907	1275,3	0,25636	25,636	37,691
154,4	63,36	7,7001	7,7001	1267,2	0,25667	25,667	37,7
154,8	63,453	7,7167	7,7167	1269,1	0,25722	25,722	37,717
155,1	63,88	7,7402	7,7402	1277,6	0,25801	25,801	37,74
155,4	63,388	7,7481	7,7481	1267,8	0,25827	25,827	37,748
155,7	63,563	7,7657	7,7657	1271,3	0,25886	25,886	37,766
156,1	64,106	7,7906	7,7906	1282,1	0,25969	25,969	37,791
156,4	63,584	7,7982	7,7982	1271,7	0,25994	25,994	37,798
156,7	63,611	7,8131	7,8131	1272,2	0,26044	26,044	37,813
157	64,105	7,8378	7,8378	1282,1	0,26126	26,126	37,838
157,4	63,582	7,8458	7,8458	1271,6	0,26153	26,153	37,846
157,7	63,759	7,8606	7,8606	1275,2	0,26202	26,202	37,861
158	64,114	7,8845	7,8845	1282,3	0,26282	26,282	37,884
158,3	63,678	7,8934	7,8934	1273,6	0,26311	26,311	37,893
158,6	63,847	7,9112	7,9112	1276,9	0,26371	26,371	37,911
159	64,363	7,9352	7,9352	1287,3	0,26451	26,451	37,935
159,3	63,648	7,9393	7,9393	1273	0,26464	26,464	37,939
159,6	63,952	7,9601	7,9601	1279	0,26534	26,534	37,96
159,9	64,161	7,9804	7,9804	1283,2	0,26601	26,601	37,98
160,3	63,81	7,9904	7,9904	1276,2	0,26635	26,635	37,99
160,6	63,989	8,0099	8,0099	1279,8	0,267	26,7	38,01
160,9	64,34	8,0292	8,0292	1286,8	0,26764	26,764	38,029
161,2	64,019	8,0393	8,0393	1280,4	0,26798	26,798	38,039
161,6	64,223	8,0572	8,0572	1284,5	0,26857	26,857	38,057
161,9	64,392	8,0763	8,0763	1287,8	0,26921	26,921	38,076
162,2	64,097	8,0866	8,0866	1281,9	0,26955	26,955	38,087
162,5	64,287	8,1047	8,1047	1285,7	0,27016	27,016	38,105
162,8	64,374	8,1215	8,1215	1287,5	0,27072	27,072	38,122
163,2	64,205	8,1342	8,1342	1284,1	0,27114	27,114	38,134
163,5	64,488	8,1551	8,1551	1289,8	0,27184	27,184	38,155
163,8	64,457	8,1709	8,1709	1289,1	0,27236	27,236	38,171
164,1	64,283	8,1828	8,1828	1285,7	0,27276	27,276	38,183
164,5	64,509	8,2053	8,2053	1290,2	0,27351	27,351	38,205
164,8	64,495	8,2218	8,2218	1289,9	0,27406	27,406	38,222
165,1	64,234	8,2323	8,2323	1284,7	0,27441	27,441	38,232
165,4	64,338	8,2504	8,2504	1286,8	0,27501	27,501	38,25
165,8	64,524	8,2687	8,2687	1290,5	0,27562	27,562	38,269
166,1	64,303	8,2798	8,2798	1286,1	0,27599	27,599	38,28
166,4	64,756	8,302	8,302	1295,1	0,27673	27,673	38,302
166,7	64,626	8,3168	8,3168	1292,5	0,27723	27,723	38,317
167	64,422	8,3277	8,3277	1288,4	0,27759	27,759	38,328
167,4	64,881	8,3504	8,3504	1297,6	0,27835	27,835	38,35
167,7	64,746	8,3654	8,3654	1294,9	0,27885	27,885	38,365
168	64,4	8,3753	8,3753	1288	0,27918	27,918	38,375
168,3	65,046	8,4015	8,4015	1300,9	0,28005	28,005	38,402
168,7	64,883	8,4126	8,4126	1297,7	0,28042	28,042	38,413
169	64,697	8,4244	8,4244	1293,9	0,28081	28,081	38,424
169,3	65,1	8,4495	8,4495	1302	0,28165	28,165	38,45
169,6	64,73	8,4603	8,4603	1294,6	0,28201	28,201	38,46
170	64,595	8,4731	8,4731	1291,9	0,28244	28,244	38,473
170,3	65,211	8,4991	8,4991	1304,2	0,2833	28,33	38,499
170,6	64,757	8,5102	8,5102	1295,1	0,28367	28,367	38,51
170,9	64,811	8,5235	8,5235	1296,2	0,28412	28,412	38,524
171,2	65,253	8,547	8,547	1305,1	0,2849	28,49	38,547
171,6	64,822	8,5559	8,5559	1296,4	0,2852	28,52	38,556
171,9	64,908	8,5738	8,5738	1298,2	0,28579	28,579	38,574
172,2	65,499	8,5982	8,5982	1310	0,28661	28,661	38,598
172,5	64,938	8,6052	8,6052	1298,8	0,28684	28,684	38,605
172,9	64,891	8,6199	8,6199	1297,8	0,28733	28,733	38,62
173,2	65,426	8,644	8,644	1308,5	0,28813	28,813	38,644
173,5	64,93	8,6533	8,6533	1298,6	0,28844	28,844	38,653
173,8	64,906	8,6679	8,6679	1298,1	0,28893	28,893	38,668
174,2	65,408	8,6932	8,6932	1308,2	0,28977	28,977	38,693
174,5	64,814	8,7004	8,7004	1296,3	0,29001	29,001	38,7
174,8	65,011	8,7191	8,7191	1300,2	0,29064	29,064	38,719
175,1	65,293	8,7407	8,7407	1305,9	0,29136	29,136	38,741
175,4	64,851	8,7499	8,7499	1297	0,29166	29,166	38,75
175,8	64,971	8,7681	8,7681	1299,4	0,29227	29,227	38,768
176,1	65,22	8,7893	8,7893	1304,4	0,29298	29,298	38,789
176,4	64,761	8,7986	8,7986	1295,2	0,29329	29,329	38,799
176,7	65,004	8,8145	8,8145	1300,1	0,29382	29,382	38,815
177,1	65,215	8,8351	8,8351	1304,3	0,2945	29,45	38,835
177,4	64,843	8,8449	8,8449	1296,9	0,29483	29,483	38,845
177,7	65,095	8,8635	8,8635	1301,9	0,29545	29,545	38,864
178	65,37	8,8851	8,8851	1307,4	0,29617	29,617	38,885
178,4	64,921	8,8953	8,8953	1298,4	0,29651	29,651	38,895
178,7	65,154	8,9129	8,9129	1303,1	0,2971	29,71	38,913
179	65,392	8,9342	8,9342	1307,8	0,29781	29,781	38,934
179,3	64,938	8,9422	8,9422	1298,8	0,29807	29,807	38,942
179,6	65,206	8,9604	8,9604	1304,1	0,29868	29,868	38,96
180	65,371	8,9804	8,9804	1307,4	0,29935	29,935	38,98
180,3	65,1	8,9925	8,9925	1302	0,29975	29,975	38,993
180,6	65,28	9,0095	9,0095	1305,6	0,30032	30,032	39,01
180,9	65,505	9,0295	9,0295	1310,1	0,30098	30,098	39,029
181,3	65,211	9,0394	9,0394	1304,2	0,30131	30,131	39,039
181,6	65,59	9,0598	9,0598	1311,8	0,30199	30,199	39,06
181,9	65,725	9,0774	9,0774	1314,5	0,30258	30,258	39,077
182,2	65,434	9,0867	9,0867	1308,7	0,30289	30,289	39,087
182,6	65,698	9,1083	9,1083	1314	0,30361	30,361	39,108
182,9	65,713	9,1245	9,1245	1314,3	0,30415	30,415	39,124
183,2	65,468	9,1355	9,1355	1309,4	0,30452	30,452	39,136
183,5	65,789	9,1567	9,1567	1315,8	0,30522	30,522	39,157
183,8	65,872	9,174	9,174	1317,4	0,3058	30,58	39,174
184,2	65,516	9,1817	9,1817	1310,3	0,30606	30,606	39,182
184,5	65,791	9,2063	9,2063	1315,8	0,30688	30,688	39,206
184,8	65,739	9,22	9,22	1314,8	0,30733	30,733	39,22
185,1	65,544	9,2314	9,2314	1310,9	0,30771	30,771	39,231
185,5	66,141	9,2586	9,2586	1322,8	0,30862	30,862	39,259
185,8	65,707	9,2676	9,2676	1314,1	0,30892	30,892	39,268
186,1	65,817	9,2814	9,2814	1316,3	0,30938	30,938	39,281
186,4	66,127	9,3054	9,3054	1322,5	0,31018	31,018	39,305
186,8	65,821	9,3183	9,3183	1316,4	0,31061	31,061	39,318
187,1	65,775	9,3293	9,3293	1315,5	0,31098	31,098	39,329
187,4	66,26	9,3542	9,3542	1325,2	0,31181	31,181	39,354
187,7	65,984	9,3656	9,3656	1319,7	0,31219	31,219	39,366
188	65,781	9,3785	9,3785	1315,6	0,31262	31,262	39,379
188,4	66,264	9,4017	9,4017	1325,3	0,31339	31,339	39,402
188,7	65,884	9,4145	9,4145	1317,7	0,31382	31,382	39,415
189	65,894	9,4289	9,4289	1317,9	0,3143	31,43	39,429
189,3	66,403	9,4537	9,4537	1328,1	0,31512	31,512	39,454
189,7	65,95	9,4625	9,4625	1319	0,31542	31,542	39,462
190	65,84	9,4759	9,4759	1316,8	0,31586	31,586	39,476
190,3	66,589	9,5028	9,5028	1331,8	0,31676	31,676	39,503
190,6	65,937	9,5098	9,5098	1318,7	0,31699	31,699	39,51
191	66,058	9,5247	9,5247	1321,2	0,31749	31,749	39,525
191,3	66,735	9,5524	9,5524	1334,7	0,31841	31,841	39,552
191,6	66,04	9,5579	9,5579	1320,8	0,3186	31,86	39,558
191,9	66,04	9,5729	9,5729	1320,8	0,3191	31,91	39,573
192,2	66,56	9,5965	9,5965	1331,2	0,31988	31,988	39,597
192,6	66,225	9,6075	9,6075	1324,5	0,32025	32,025	39,607
192,9	66,189	9,6223	9,6223	1323,8	0,32074	32,074	39,622
193,2	66,719	9,6455	9,6455	1334,4	0,32152	32,152	39,645
193,5	66,367	9,6557	9,6557	1327,3	0,32186	32,186	39,656
193,9	66,45	9,6719	9,6719	1329	0,3224	32,24	39,672
194,2	66,777	9,6937	9,6937	1335,5	0,32312	32,312	39,694
194,5	66,382	9,7025	9,7025	1327,6	0,32342	32,342	39,702
194,8	66,562	9,7199	9,7199	1331,2	0,324	32,4	39,72
195,2	67,124	9,7442	9,7442	1342,5	0,32481	32,481	39,744
195,5	66,374	9,7481	9,7481	1327,5	0,32494	32,494	39,748
195,8	66,727	9,7692	9,7692	1334,5	0,32564	32,564	39,769
196,1	67,096	9,7914	9,7914	1341,9	0,32638	32,638	39,791
196,4	66,542	9,7983	9,7983	1330,8	0,32661	32,661	39,798
196,8	66,85	9,8178	9,8178	1337	0,32726	32,726	39,818
197,1	66,935	9,8364	9,8364	1338,7	0,32788	32,788	39,836
197,4	66,723	9,849	9,849	1334,5	0,3283	32,83	39,849
197,7	67,012	9,8688	9,8688	1340,2	0,32896	32,896	39,869
198,1	67,03	9,8855	9,8855	1340,6	0,32952	32,952	39,885
198,4	66,634	9,8952	9,8952	1332,7	0,32984	32,984	39,895
198,7	67,033	9,9173	9,9173	1340,7	0,33058	33,058	39,917
199	66,955	9,9341	9,9341	1339,1	0,33114	33,114	39,934
199,4	66,693	9,9438	9,9438	1333,9	0,33146	33,146	39,944
199,7	66,92	9,9632	9,9632	1338,4	0,33211	33,211	39,963
200	66,958	9,982	9,982	1339,2	0,33273	33,273	39,982
200,3	66,667	9,9923	9,9923	1333,3	0,33308	33,308	39,992
200,6	66,905	10,013	10,013	1338,1	0,33375	33,375	40,013
201	67,077	10,031	10,031	1341,5	0,33438	33,438	40,031
201,3	66,696	10,04	10,04	1333,9	0,33467	33,467	40,04
201,6	67,07	10,062	10,062	1341,4	0,33541	33,541	40,062
201,9	67,043	10,078	10,078	1340,9	0,33593	33,593	40,078
202,3	66,757	10,089	10,089	1335,1	0,33629	33,629	40,089
202,6	67,083	10,11	10,11	1341,7	0,33699	33,699	40,11
202,9	67,046	10,126	10,126	1340,9	0,33753	33,753	40,126
203,2	66,777	10,137	10,137	1335,5	0,33791	33,791	40,137
203,6	67,293	10,16	10,16	1345,9	0,33867	33,867	40,16
203,9	67,283	10,177	10,177	1345,7	0,33922	33,922	40,177
204,2	66,929	10,187	10,187	1338,6	0,33956	33,956	40,187
204,5	67,349	10,209	10,209	1347	0,34029	34,029	40,209
204,8	67,12	10,221	10,221	1342,4	0,3407	34,07	40,221
205,2	66,989	10,234	10,234	1339,8	0,34113	34,113	40,234
205,5	67,436	10,258	10,258	1348,7	0,34194	34,194	40,258
205,8	67,227	10,272	10,272	1344,5	0,34239	34,239	40,272
206,1	67,201	10,284	10,284	1344	0,3428	34,28	40,284
206,5	67,91	10,311	10,311	1358,2	0,34371	34,371	40,311
206,8	67,278	10,318	10,318	1345,6	0,34392	34,392	40,318
207,1	67,234	10,333	10,333	1344,7	0,34443	34,443	40,333
207,4	68,07	10,361	10,361	1361,4	0,34537	34,537	40,361
207,8	67,316	10,365	10,365	1346,3	0,34549	34,549	40,365
208,1	67,349	10,381	10,381	1347	0,34603	34,603	40,381
208,4	68,078	10,407	10,407	1361,6	0,34691	34,691	40,407
208,7	67,563	10,417	10,417	1351,3	0,34722	34,722	40,417
209	67,505	10,429	10,429	1350,1	0,34765	34,765	40,429
209,4	67,878	10,454	10,454	1357,6	0,34846	34,846	40,454
209,7	67,503	10,463	10,463	1350,1	0,34878	34,878	40,463
210	67,539	10,479	10,479	1350,8	0,34929	34,929	40,479
210,3	67,808	10,504	10,504	1356,2	0,35013	35,013	40,504
210,7	67,411	10,511	10,511	1348,2	0,35037	35,037	40,511
211	67,646	10,529	10,529	1352,9	0,35095	35,095	40,529
211,3	67,994	10,551	10,551	1359,9	0,35169	35,169	40,551
211,6	67,571	10,559	10,559	1351,4	0,35198	35,198	40,559
212	67,607	10,576	10,576	1352,1	0,35253	35,253	40,576
212,3	68,12	10,6	10,6	1362,4	0,35332	35,332	40,6
212,6	67,699	10,609	10,609	1354	0,35362	35,362	40,609
212,9	67,717	10,624	10,624	1354,3	0,35413	35,413	40,624
213,2	68,246	10,648	10,648	1364,9	0,35494	35,494	40,648
213,6	67,679	10,656	10,656	1353,6	0,3552	35,52	40,656
213,9	67,743	10,673	10,673	1354,9	0,35575	35,575	40,673
214,2	68,27	10,696	10,696	1365,4	0,35653	35,653	40,696
214,5	67,703	10,701	10,701	1354,1	0,3567	35,67	40,701
214,9	67,867	10,721	10,721	1357,3	0,35736	35,736	40,721
215,2	68,18	10,743	10,743	1363,6	0,35808	35,808	40,743
215,5	67,765	10,751	10,751	1355,3	0,35838	35,838	40,751
215,8	68,075	10,772	10,772	1361,5	0,35905	35,905	40,772
216,2	68,381	10,792	10,792	1367,6	0,35975	35,975	40,792
216,5	67,82	10,799	10,799	1356,4	0,35997	35,997	40,799
216,8	68,24	10,821	10,821	1364,8	0,36069	36,069	40,821
217,1	68,366	10,839	10,839	1367,3	0,36129	36,129	40,839
217,4	67,942	10,848	10,848	1358,8	0,36159	36,159	40,848
217,8	68,318	10,869	10,869	1366,4	0,36229	36,229	40,869
218,1	68,299	10,885	10,885	1366	0,36284	36,284	40,885
218,4	67,955	10,896	10,896	1359,1	0,36321	36,321	40,896
218,7	68,326	10,918	10,918	1366,5	0,36393	36,393	40,918
219,1	68,162	10,933	10,933	1363,2	0,36443	36,443	40,933
219,4	67,999	10,944	10,944	1360	0,36479	36,479	40,944
219,7	68,323	10,967	10,967	1366,5	0,36558	36,558	40,967
220	68,135	10,982	10,982	1362,7	0,36605	36,605	40,982
220,4	68,065	10,992	10,992	1361,3	0,3664	36,64	40,992
220,7	68,533	11,017	11,017	1370,7	0,36724	36,724	41,017
221	68,294	11,03	11,03	1365,9	0,36767	36,767	41,03
221,3	68,104	11,043	11,043	1362,1	0,36809	36,809	41,043
221,6	68,473	11,064	11,064	1369,5	0,36879	36,879	41,064
222	68,363	11,078	11,078	1367,3	0,36927	36,927	41,078
222,3	68,161	11,09	11,09	1363,2	0,36967	36,967	41,09
222,6	68,679	11,114	11,114	1373,6	0,37047	37,047	41,114
222,9	68,394	11,126	11,126	1367,9	0,37088	37,088	41,126
223,3	68,265	11,14	11,14	1365,3	0,37132	37,132	41,14
223,6	68,762	11,164	11,164	1375,2	0,37213	37,213	41,164
223,9	68,416	11,175	11,175	1368,3	0,3725	37,25	41,175
224,2	68,263	11,188	11,188	1365,3	0,37292	37,292	41,188
224,6	68,853	11,213	11,213	1377,1	0,37378	37,378	41,213
224,9	68,449	11,223	11,223	1369	0,37411	37,411	41,223
225,2	68,341	11,236	11,236	1366,8	0,37455	37,455	41,236
225,5	68,859	11,26	11,26	1377,2	0,37535	37,535	41,26
225,8	68,545	11,273	11,273	1370,9	0,37575	37,575	41,273
226,2	68,466	11,286	11,286	1369,3	0,3762	37,62	41,286
226,5	69,062	11,311	11,311	1381,2	0,37703	37,703	41,311
226,8	68,556	11,319	11,319	1371,1	0,37731	37,731	41,319
227,1	68,598	11,335	11,335	1372	0,37782	37,782	41,335
227,5	69,262	11,361	11,361	1385,2	0,37869	37,869	41,361
227,8	68,644	11,368	11,368	1372,9	0,37892	37,892	41,368
228,1	68,623	11,382	11,382	1372,5	0,3794	37,94	41,382
228,4	69,176	11,406	11,406	1383,5	0,38021	38,021	41,406
228,8	68,623	11,414	11,414	1372,5	0,38047	38,047	41,414
229,1	68,873	11,434	11,434	1377,5	0,38112	38,112	41,434
229,4	69,189	11,456	11,456	1383,8	0,38185	38,185	41,456
229,7	68,728	11,464	11,464	1374,6	0,38214	38,214	41,464
230	68,898	11,482	11,482	1378	0,38273	38,273	41,482
230,4	69,201	11,504	11,504	1384	0,38345	38,345	41,504
230,7	68,742	11,512	11,512	1374,8	0,38372	38,372	41,512
231	68,834	11,529	11,529	1376,7	0,3843	38,43	41,529
231,3	69,176	11,551	11,551	1383,5	0,38502	38,502	41,551
231,7	68,799	11,56	11,56	1376	0,38535	38,535	41,56
232	69,037	11,579	11,579	1380,7	0,38597	38,597	41,579
232,3	69,178	11,599	11,599	1383,6	0,38662	38,662	41,599
232,6	68,909	11,609	11,609	1378,2	0,38697	38,697	41,609
233	69,127	11,627	11,627	1382,5	0,38756	38,756	41,627
233,3	69,18	11,646	11,646	1383,6	0,3882	38,82	41,646
233,6	68,878	11,657	11,657	1377,6	0,38858	38,858	41,657
233,9	68,984	11,674	11,674	1379,7	0,38912	38,912	41,674
234,2	69,215	11,696	11,696	1384,3	0,38986	38,986	41,696
234,6	68,812	11,705	11,705	1376,2	0,39017	39,017	41,705
234,9	69,019	11,724	11,724	1380,4	0,39082	39,082	41,724
235,2	69,235	11,745	11,745	1384,7	0,39149	39,149	41,745
235,5	68,892	11,753	11,753	1377,8	0,39177	39,177	41,753
235,9	69,059	11,774	11,774	1381,2	0,39245	39,245	41,774
236,2	69,289	11,792	11,792	1385,8	0,39308	39,308	41,792
236,5	68,937	11,802	11,802	1378,7	0,39341	39,341	41,802
236,8	69,19	11,822	11,822	1383,8	0,39406	39,406	41,822
237,2	69,261	11,839	11,839	1385,2	0,39464	39,464	41,839
237,5	68,879	11,849	11,849	1377,6	0,39495	39,495	41,849
237,8	69,281	11,871	11,871	1385,6	0,39572	39,572	41,871
238,1	69,338	11,888	11,888	1386,8	0,39626	39,626	41,888
238,4	68,934	11,897	11,897	1378,7	0,39657	39,657	41,897
238,8	69,509	11,921	11,921	1390,2	0,39735	39,735	41,921
239,1	69,421	11,936	11,936	1388,4	0,39786	39,786	41,936
239,4	69,117	11,946	11,946	1382,3	0,3982	39,82	41,946
239,7	69,611	11,968	11,968	1392,2	0,39894	39,894	41,968
240,1	69,485	11,984	11,984	1389,7	0,39945	39,945	41,984
240,4	69,32	11,996	11,996	1386,4	0,39985	39,985	41,996
240,7	69,811	12,018	12,018	1396,2	0,40061	40,061	42,018
241	69,501	12,03	12,03	1390	0,40101	40,101	42,03
241,4	69,385	12,043	12,043	1387,7	0,40144	40,144	42,043
241,7	70,039	12,069	12,069	1400,8	0,40231	40,231	42,069
242	69,59	12,079	12,079	1391,8	0,40263	40,263	42,079
242,3	69,496	12,092	12,092	1389,9	0,40308	40,308	42,092
242,6	70,143	12,118	12,118	1402,9	0,40394	40,394	42,118
243	69,587	12,127	12,127	1391,7	0,40424	40,424	42,127
243,3	69,703	12,142	12,142	1394,1	0,40473	40,473	42,142
243,6	70,164	12,168	12,168	1403,3	0,4056	40,56	42,168
243,9	69,772	12,177	12,177	1395,4	0,40591	40,591	42,177
244,3	69,667	12,19	12,19	1393,3	0,40634	40,634	42,19
244,6	70,109	12,214	12,214	1402,2	0,40714	40,714	42,214
244,9	69,683	12,226	12,226	1393,7	0,40752	40,752	42,226
245,2	69,761	12,238	12,238	1395,2	0,40794	40,794	42,238
245,6	70,381	12,264	12,264	1407,6	0,40879	40,879	42,264
245,9	69,723	12,269	12,269	1394,5	0,40897	40,897	42,269
246,2	69,748	12,289	12,289	1395	0,40962	40,962	42,289
246,5	70,356	12,314	12,314	1407,1	0,41045	41,045	42,314
246,9	69,888	12,322	12,322	1397,8	0,41074	41,074	42,322
247,2	69,867	12,337	12,337	1397,3	0,41122	41,122	42,337
247,5	70,41	12,362	12,362	1408,2	0,41206	41,206	42,362
247,8	69,848	12,369	12,369	1397	0,4123	41,23	42,369
248,1	69,824	12,384	12,384	1396,5	0,4128	41,28	42,384
248,5	70,333	12,408	12,408	1406,7	0,4136	41,36	42,408
248,8	69,869	12,418	12,418	1397,4	0,41392	41,392	42,418
249,1	69,983	12,433	12,433	1399,7	0,41443	41,443	42,433
249,4	70,339	12,456	12,456	1406,8	0,41519	41,519	42,456
249,8	69,969	12,466	12,466	1399,4	0,41553	41,553	42,466
250,1	70,138	12,483	12,483	1402,8	0,41608	41,608	42,483
250,4	70,458	12,506	12,506	1409,2	0,41686	41,686	42,506
250,7	69,966	12,514	12,514	1399,3	0,41712	41,712	42,514
251,1	70,106	12,531	12,531	1402,1	0,41769	41,769	42,531
251,4	70,417	12,552	12,552	1408,3	0,41841	41,841	42,552
251,7	69,997	12,562	12,562	1399,9	0,41875	41,875	42,562
252	70,322	12,582	12,582	1406,4	0,41939	41,939	42,582
252,3	70,433	12,601	12,601	1408,7	0,42002	42,002	42,601
252,7	70,046	12,609	12,609	1400,9	0,42031	42,031	42,609
253	70,284	12,629	12,629	1405,7	0,42095	42,095	42,629
253,3	70,381	12,648	12,648	1407,6	0,4216	42,16	42,648
253,6	70,019	12,658	12,658	1400,4	0,42192	42,192	42,658
254	70,37	12,679	12,679	1407,4	0,42263	42,263	42,679
254,3	70,323	12,695	12,695	1406,5	0,42317	42,317	42,695
254,6	69,983	12,705	12,705	1399,7	0,4235	42,35	42,705
254,9	70,401	12,727	12,727	1408	0,42424	42,424	42,727
255,3	70,314	12,742	12,742	1406,3	0,42474	42,474	42,742
255,6	70,08	12,755	12,755	1401,6	0,42515	42,515	42,755
255,9	70,519	12,777	12,777	1410,4	0,42589	42,589	42,777
256,2	70,386	12,791	12,791	1407,7	0,42638	42,638	42,791
256,5	70,165	12,803	12,803	1403,3	0,42676	42,676	42,803
256,9	70,553	12,825	12,825	1411,1	0,4275	42,75	42,825
257,2	70,366	12,839	12,839	1407,3	0,42798	42,798	42,839
257,5	70,22	12,852	12,852	1404,4	0,4284	42,84	42,852
257,8	70,567	12,871	12,871	1411,3	0,42904	42,904	42,871
258,2	70,618	12,891	12,891	1412,4	0,42969	42,969	42,891
258,5	70,304	12,9	12,9	1406,1	0,43	43	42,9
258,8	70,599	12,921	12,921	1412	0,43071	43,071	42,921
259,1	70,427	12,936	12,936	1408,5	0,43121	43,121	42,936
259,5	70,234	12,948	12,948	1404,7	0,43161	43,161	42,948
259,8	70,669	12,972	12,972	1413,4	0,43239	43,239	42,972
260,1	70,421	12,983	12,983	1408,4	0,43278	43,278	42,983
260,4	70,428	12,998	12,998	1408,6	0,43326	43,326	42,998
260,7	70,91	13,022	13,022	1418,2	0,43406	43,406	43,022
261,1	70,512	13,032	13,032	1410,2	0,43439	43,439	43,032
261,4	70,441	13,045	13,045	1408,8	0,43484	43,484	43,045
261,7	71,068	13,071	13,071	1421,4	0,43571	43,571	43,071
262	70,572	13,08	13,08	1411,4	0,436	43,6	43,08
262,4	70,523	13,095	13,095	1410,5	0,4365	43,65	43,095
262,7	71,064	13,12	13,12	1421,3	0,43732	43,732	43,12
263	70,563	13,128	13,128	1411,3	0,43761	43,761	43,128
263,3	70,733	13,146	13,146	1414,7	0,4382	43,82	43,146
263,7	71,356	13,172	13,172	1427,1	0,43907	43,907	43,172
264	70,45	13,175	13,175	1409	0,43916	43,916	43,175
264,3	70,701	13,194	13,194	1414	0,4398	43,98	43,194
264,6	71,171	13,218	13,218	1423,4	0,44061	44,061	43,218
264,9	70,574	13,225	13,225	1411,5	0,44083	44,083	43,225
265,3	70,681	13,241	13,241	1413,6	0,44138	44,138	43,241
265,6	71,279	13,266	13,266	1425,6	0,44221	44,221	43,266
265,9	70,624	13,273	13,273	1412,5	0,44243	44,243	43,273
266,2	70,772	13,291	13,291	1415,4	0,44302	44,302	43,291
266,6	71,168	13,314	13,314	1423,4	0,44379	44,379	43,314
266,9	70,736	13,323	13,323	1414,7	0,4441	44,41	43,323
267,2	70,682	13,338	13,338	1413,6	0,4446	44,46	43,338
267,5	70,949	13,361	13,361	1419	0,44535	44,535	43,361
267,9	70,547	13,371	13,371	1410,9	0,44569	44,569	43,371
268,2	70,585	13,387	13,387	1411,7	0,44624	44,624	43,387
268,5	70,723	13,408	13,408	1414,5	0,44693	44,693	43,408
268,8	70,264	13,418	13,418	1405,3	0,44725	44,725	43,418
269,1	70,417	13,437	13,437	1408,3	0,4479	44,79	43,437
269,5	70,589	13,458	13,458	1411,8	0,44859	44,859	43,458
269,8	70,067	13,467	13,467	1401,3	0,44892	44,892	43,467
270,1	70,232	13,486	13,486	1404,6	0,44954	44,954	43,486
270,4	70,103	13,505	13,505	1402,1	0,45015	45,015	43,505
270,8	69,411	13,514	13,514	1388,2	0,45046	45,046	43,514
271,1	69,36	13,535	13,535	1387,2	0,45116	45,116	43,535
271,4	68,535	13,554	13,554	1370,7	0,4518	45,18	43,554
271,7	66,403	13,563	13,563	1328,1	0,4521	45,21	43,563
272,1	65,551	13,583	13,583	1311	0,45276	45,276	43,583
272,4	64,363	13,602	13,602	1287,3	0,4534	45,34	43,602
272,7	62,987	13,611	13,611	1259,7	0,45369	45,369	43,611
273	62,427	13,631	13,631	1248,5	0,45438	45,438	43,631
273,3	59,576	13,65	13,65	1191,5	0,45501	45,501	43,65
273,7	57,704	13,659	13,659	1154,1	0,45531	45,531	43,659
274	56,526	13,679	13,679	1130,5	0,45595	45,595	43,679
274,3	54,937	13,695	13,695	1098,7	0,45652	45,652	43,695
274,6	53,727	13,706	13,706	1074,5	0,45688	45,688	43,706
275	53,281	13,73	13,73	1065,6	0,45765	45,765	43,73
275,3	52,154	13,746	13,746	1043,1	0,45821	45,821	43,746
275,6	51,444	13,755	13,755	1028,9	0,45851	45,851	43,755
275,9	51,247	13,778	13,778	1024,9	0,45925	45,925	43,778
276,3	50,5	13,791	13,791	1010	0,45971	45,971	43,791
276,6	49,251	13,803	13,803	985,01	0,46009	46,009	43,803
276,9	48,34	13,83	13,83	966,81	0,46099	46,099	43,83
277,2	45,516	13,84	13,84	910,32	0,46135	46,135	43,84
277,5	43,871	13,854	13,854	877,41	0,4618	46,18	43,854
277,9	43,178	13,878	13,878	863,56	0,4626	46,26	43,878
278,2	41,782	13,888	13,888	835,64	0,46293	46,293	43,888
278,5	-0,22039	13,902	13,902	-4,4078	0,46341	46,341	43,902
278,6		13,909	13,909		0,46363	46,363	43,909