File: Tests de traction/Fichiers source/04_12_2016/1bis.txt
Time (s)	Load (N)	Machine Extension (mm)	Extension (mm)	Stress (MPa)	Strain	Percentage Strain	Gauge Length (mm)
0
0,3106	-0,0022267	0,000076522	0,000076522	-0,044533	2,5507E-06	0,00025507	30
0,6212	0,0082167	0,0021769	0,0021769	0,16433	0,000072564	0,0072564	30,002
0,9318	0,8154	0,032863	0,032863	16,308	0,0010954	0,10954	30,033
1,242	0,96767	0,037744	0,037744	19,353	0,0012581	0,12581	30,038
1,553	1,9884	0,05734	0,05734	39,767	0,0019113	0,19113	30,057
1,864	3,031	0,075254	0,075254	60,621	0,0025085	0,25085	30,075
2,174	3,6558	0,085104	0,085104	73,117	0,0028368	0,28368	30,085
2,485	4,7303	0,10376	0,10376	94,605	0,0034586	0,34586	30,104
2,795	6,0992	0,12281	0,12281	121,98	0,0040936	0,40936	30,123
3,106	6,731	0,13243	0,13243	134,62	0,0044144	0,44144	30,132
3,417	7,8523	0,15166	0,15166	157,05	0,0050554	0,50554	30,152
3,727	9,1222	0,1701	0,1701	182,44	0,00567	0,567	30,17
4,038	9,8244	0,1809	0,1809	196,49	0,0060301	0,60301	30,181
4,348	10,755	0,19689	0,19689	215,1	0,0065631	0,65631	30,197
4,659	12,248	0,21852	0,21852	244,97	0,007284	0,7284	30,219
4,97	12,917	0,2283	0,2283	258,34	0,00761	0,761	30,228
5,28	13,713	0,24265	0,24265	274,25	0,0080884	0,80884	30,243
5,591	15,268	0,26478	0,26478	305,35	0,0088261	0,88261	30,265
5,901	15,93	0,27519	0,27519	318,61	0,0091729	0,91729	30,275
6,212	16,803	0,29103	0,29103	336,05	0,0097011	0,97011	30,291
6,523	18,259	0,31317	0,31317	365,19	0,010439	1,0439	30,313
6,833	18,871	0,32317	0,32317	377,41	0,010772	1,0772	30,323
7,144	19,693	0,33692	0,33692	393,85	0,011231	1,1231	30,337
7,454	21,395	0,36284	0,36284	427,9	0,012095	1,2095	30,363
7,765	21,469	0,36642	0,36642	429,38	0,012214	1,2214	30,366
8,076	22,399	0,38116	0,38116	447,99	0,012705	1,2705	30,381
8,386	24,1	0,4089	0,4089	482	0,01363	1,363	30,409
8,697	24,318	0,41395	0,41395	486,36	0,013798	1,3798	30,414
9,007	25,247	0,42831	0,42831	504,95	0,014277	1,4277	30,428
9,318	26,736	0,45456	0,45456	534,72	0,015152	1,5152	30,455
9,629	27,024	0,46262	0,46262	540,48	0,015421	1,5421	30,463
9,939	27,603	0,47338	0,47338	552,06	0,015779	1,5779	30,473
10,25	29,424	0,5028	0,5028	588,49	0,01676	1,676	30,503
10,56	29,505	0,50681	0,50681	590,1	0,016894	1,6894	30,507
10,87	30,25	0,52036	0,52036	605	0,017345	1,7345	30,52
11,18	31,676	0,54447	0,54447	633,51	0,018149	1,8149	30,544
11,49	32,146	0,55714	0,55714	642,92	0,018571	1,8571	30,557
11,8	32,721	0,56794	0,56794	654,43	0,018931	1,8931	30,568
12,11	33,918	0,58963	0,58963	678,35	0,019654	1,9654	30,59
12,42	34,527	0,60317	0,60317	690,54	0,020106	2,0106	30,603
12,73	35,11	0,61505	0,61505	702,19	0,020502	2,0502	30,615
13,05	36,129	0,63564	0,63564	722,58	0,021188	2,1188	30,636
13,36	36,593	0,64769	0,64769	731,87	0,02159	2,159	30,648
13,67	37,17	0,66076	0,66076	743,41	0,022025	2,2025	30,661
13,98	38,04	0,6798	0,6798	760,81	0,02266	2,266	30,68
14,29	38,752	0,69517	0,69517	775,03	0,023172	2,3172	30,695
14,6	39,159	0,70687	0,70687	783,17	0,023562	2,3562	30,707
14,91	39,975	0,7281	0,7281	799,5	0,02427	2,427	30,728
15,22	40,7	0,74359	0,74359	814	0,024786	2,4786	30,744
15,53	41,13	0,75543	0,75543	822,61	0,025181	2,5181	30,755
15,84	41,915	0,77422	0,77422	838,29	0,025807	2,5807	30,774
16,15	42,481	0,79041	0,79041	849,62	0,026347	2,6347	30,79
16,46	42,831	0,80093	0,80093	856,62	0,026698	2,6698	30,801
16,77	43,434	0,81869	0,81869	868,68	0,02729	2,729	30,819
17,08	44,017	0,8373	0,8373	880,33	0,02791	2,791	30,837
17,39	44,281	0,84853	0,84853	885,61	0,028284	2,8284	30,849
17,7	44,691	0,86359	0,86359	893,81	0,028786	2,8786	30,864
18,01	45,398	0,8864	0,8864	907,96	0,029547	2,9547	30,886
18,33	45,453	0,89527	0,89527	909,05	0,029842	2,9842	30,895
18,64	45,842	0,9108	0,9108	916,84	0,03036	3,036	30,911
18,95	46,528	0,93375	0,93375	930,57	0,031125	3,1125	30,934
19,26	46,561	0,94218	0,94218	931,21	0,031406	3,1406	30,942
19,57	46,84	0,95811	0,95811	936,8	0,031937	3,1937	30,958
19,88	47,558	0,98111	0,98111	951,15	0,032704	3,2704	30,981
20,19	47,392	0,98814	0,98814	947,84	0,032938	3,2938	30,988
20,5	47,813	1,0054	1,0054	956,26	0,033513	3,3513	31,005
20,81	48,415	1,0287	1,0287	968,3	0,034288	3,4288	31,029
21,12	48,132	1,0347	1,0347	962,64	0,034488	3,4488	31,035
21,43	48,441	1,0505	1,0505	968,82	0,035017	3,5017	31,051
21,74	49,133	1,0771	1,0771	982,66	0,035905	3,5905	31,077
22,05	48,675	1,0811	1,0811	973,5	0,036037	3,6037	31,081
22,36	48,876	1,0965	1,0965	977,53	0,03655	3,655	31,097
22,67	49,51	1,1175	1,1175	990,2	0,037249	3,7249	31,117
22,98	49,148	1,1287	1,1287	982,96	0,037624	3,7624	31,129
23,29	49,254	1,1431	1,1431	985,09	0,038104	3,8104	31,143
23,61	49,962	1,1718	1,1718	999,25	0,039059	3,9059	31,172
23,92	49,329	1,1743	1,1743	986,57	0,039143	3,9143	31,174
24,23	49,376	1,1886	1,1886	987,52	0,039619	3,9619	31,189
24,54	49,938	1,2143	1,2143	998,75	0,040476	4,0476	31,214
24,85	49,519	1,2207	1,2207	990,38	0,04069	4,069	31,221
25,16	49,511	1,2358	1,2358	990,23	0,041194	4,1194	31,236
25,47	50,116	1,2613	1,2613	1002,3	0,042043	4,2043	31,261
25,78	49,593	1,2685	1,2685	991,86	0,042283	4,2283	31,269
26,09	49,678	1,2828	1,2828	993,55	0,042759	4,2759	31,283
26,4	50,002	1,3038	1,3038	1000	0,043461	4,3461	31,304
26,71	49,695	1,3149	1,3149	993,9	0,043831	4,3831	31,315
27,02	49,708	1,3292	1,3292	994,17	0,044308	4,4308	31,329
27,33	50,096	1,3511	1,3511	1001,9	0,045036	4,5036	31,351
27,64	49,848	1,3634	1,3634	996,95	0,045446	4,5446	31,363
27,95	49,655	1,3745	1,3745	993,1	0,045815	4,5815	31,374
28,26	49,931	1,3957	1,3957	998,62	0,046522	4,6522	31,396
28,58	49,919	1,4108	1,4108	998,38	0,047028	4,7028	31,411
28,89	49,6	1,4197	1,4197	991,99	0,047323	4,7323	31,42
29,2	49,885	1,4399	1,4399	997,7	0,047997	4,7997	31,44
29,51	49,937	1,4582	1,4582	998,74	0,048606	4,8606	31,458
29,82	49,72	1,4677	1,4677	994,4	0,048922	4,8922	31,468
30,13	49,964	1,4878	1,4878	999,28	0,049593	4,9593	31,488
30,44	50,121	1,507	1,507	1002,4	0,050234	5,0234	31,507
30,75	49,758	1,5152	1,5152	995,15	0,050507	5,0507	31,515
31,06	49,882	1,5316	1,5316	997,64	0,051055	5,1055	31,532
31,37	50,104	1,5521	1,5521	1002,1	0,051736	5,1736	31,552
31,68	49,854	1,5612	1,5612	997,09	0,052039	5,2039	31,561
31,99	50,107	1,581	1,581	1002,1	0,0527	5,27	31,581
32,3	50,264	1,6012	1,6012	1005,3	0,053372	5,3372	31,601
32,61	49,886	1,609	1,609	997,71	0,053633	5,3633	31,609
32,92	50,063	1,6263	1,6263	1001,3	0,054209	5,4209	31,626
33,23	50,394	1,6495	1,6495	1007,9	0,054983	5,4983	31,649
33,54	49,893	1,6555	1,6555	997,86	0,055185	5,5185	31,656
33,86	49,949	1,6711	1,6711	998,98	0,055704	5,5704	31,671
34,17	50,276	1,6941	1,6941	1005,5	0,056471	5,6471	31,694
34,48	49,879	1,7037	1,7037	997,59	0,056789	5,6789	31,704
34,79	50,002	1,719	1,719	1000	0,057299	5,7299	31,719
35,1	50,496	1,7443	1,7443	1009,9	0,058143	5,8143	31,744
35,41	49,847	1,7478	1,7478	996,94	0,05826	5,826	31,748
35,72	50,045	1,7656	1,7656	1000,9	0,058852	5,8852	31,766
36,03	50,45	1,7885	1,7885	1009	0,059616	5,9616	31,788
36,34	49,877	1,7957	1,7957	997,55	0,059857	5,9857	31,796
36,65	50,059	1,8129	1,8129	1001,2	0,06043	6,043	31,813
36,96	50,483	1,8359	1,8359	1009,7	0,061198	6,1198	31,836
37,27	49,955	1,8441	1,8441	999,11	0,061471	6,1471	31,844
37,58	49,977	1,8578	1,8578	999,53	0,061926	6,1926	31,858
37,89	50,359	1,8798	1,8798	1007,2	0,06266	6,266	31,88
38,2	49,995	1,8915	1,8915	999,91	0,063049	6,3049	31,891
38,51	49,895	1,9031	1,9031	997,9	0,063437	6,3437	31,903
38,82	50,449	1,9299	1,9299	1009	0,06433	6,433	31,93
39,14	49,908	1,9359	1,9359	998,15	0,064531	6,4531	31,936
39,45	50,002	1,9523	1,9523	1000	0,065077	6,5077	31,952
39,76	50,422	1,9749	1,9749	1008,4	0,065829	6,5829	31,975
40,07	50,035	1,9837	1,9837	1000,7	0,066122	6,6122	31,984
40,38	49,995	1,9988	1,9988	999,9	0,066627	6,6627	31,999
40,69	50,271	2,0169	2,0169	1005,4	0,067229	6,7229	32,017
41	50,156	2,0317	2,0317	1003,1	0,067722	6,7722	32,032
41,31	49,821	2,0409	2,0409	996,42	0,06803	6,803	32,041
41,62	50,264	2,0625	2,0625	1005,3	0,068748	6,8748	32,062
41,93	50,256	2,0778	2,0778	1005,1	0,069259	6,9259	32,078
42,24	50,007	2,0895	2,0895	1000,1	0,069651	6,9651	32,09
42,55	50,224	2,1086	2,1086	1004,5	0,070288	7,0288	32,109
42,86	50,17	2,1249	2,1249	1003,4	0,070828	7,0828	32,125
43,17	49,871	2,1345	2,1345	997,42	0,071151	7,1151	32,135
43,48	50,225	2,1558	2,1558	1004,5	0,071861	7,1861	32,156
43,79	50,262	2,1736	2,1736	1005,2	0,072453	7,2453	32,174
44,11	49,958	2,1833	2,1833	999,16	0,072776	7,2776	32,183
44,42	50,187	2,2018	2,2018	1003,7	0,073392	7,3392	32,202
44,73	50,358	2,2214	2,2214	1007,2	0,074046	7,4046	32,221
45,04	49,982	2,2288	2,2288	999,65	0,074294	7,4294	32,229
45,35	50,284	2,2485	2,2485	1005,7	0,074949	7,4949	32,248
45,66	50,375	2,2664	2,2664	1007,5	0,075547	7,5547	32,266
45,97	50,105	2,2756	2,2756	1002,1	0,075853	7,5853	32,276
46,28	50,358	2,2949	2,2949	1007,2	0,076496	7,6496	32,295
46,59	50,63	2,3153	2,3153	1012,6	0,077178	7,7178	32,315
46,9	50,184	2,3222	2,3222	1003,7	0,077407	7,7407	32,322
47,21	50,308	2,3405	2,3405	1006,2	0,078016	7,8016	32,34
47,52	50,572	2,3621	2,3621	1011,4	0,078737	7,8737	32,362
47,83	50,14	2,3697	2,3697	1002,8	0,07899	7,899	32,37
48,14	50,288	2,3868	2,3868	1005,8	0,079559	7,9559	32,387
48,45	50,476	2,4082	2,4082	1009,5	0,080272	8,0272	32,408
48,76	50,147	2,4173	2,4173	1002,9	0,080576	8,0576	32,417
49,07	50,212	2,4346	2,4346	1004,2	0,081155	8,1155	32,435
49,39	50,334	2,4535	2,4535	1006,7	0,081783	8,1783	32,454
49,7	50,072	2,4637	2,4637	1001,4	0,082122	8,2122	32,464
50,01	50,099	2,4799	2,4799	1002	0,082662	8,2662	32,48
50,32	50,775	2,5067	2,5067	1015,5	0,083555	8,3555	32,507
50,63	49,997	2,5077	2,5077	999,94	0,08359	8,359	32,508
50,94	50,195	2,5267	2,5267	1003,9	0,084222	8,4222	32,527
51,25	50,584	2,5485	2,5485	1011,7	0,084949	8,4949	32,548
51,56	50,337	2,5594	2,5594	1006,7	0,085312	8,5312	32,559
51,87	50,216	2,5725	2,5725	1004,3	0,085751	8,5751	32,573
52,18	50,791	2,5979	2,5979	1015,8	0,086598	8,6598	32,598
52,49	50,315	2,6052	2,6052	1006,3	0,086839	8,6839	32,605
52,8	50,258	2,6185	2,6185	1005,2	0,087284	8,7284	32,619
53,11	50,804	2,6439	2,6439	1016,1	0,08813	8,813	32,644
53,42	50,183	2,6496	2,6496	1003,7	0,088321	8,8321	32,65
53,73	50,327	2,6635	2,6635	1006,5	0,088784	8,8784	32,664
54,04	50,62	2,6872	2,6872	1012,4	0,089574	8,9574	32,687
54,35	50,403	2,6984	2,6984	1008,1	0,089947	8,9947	32,698
54,67	50,264	2,7102	2,7102	1005,3	0,090338	9,0338	32,71
54,98	50,607	2,7317	2,7317	1012,1	0,091057	9,1057	32,732
55,29	50,474	2,7463	2,7463	1009,5	0,091545	9,1545	32,746
55,6	50,221	2,7563	2,7563	1004,4	0,091875	9,1875	32,756
55,91	50,701	2,7791	2,7791	1014	0,092635	9,2635	32,779
56,22	50,568	2,7921	2,7921	1011,4	0,09307	9,307	32,792
56,53	50,366	2,8024	2,8024	1007,3	0,093415	9,3415	32,802
56,84	50,709	2,8238	2,8238	1014,2	0,094126	9,4126	32,824
57,15	50,632	2,8384	2,8384	1012,6	0,094613	9,4613	32,838
57,46	50,41	2,8483	2,8483	1008,2	0,094942	9,4942	32,848
57,77	50,751	2,8686	2,8686	1015	0,095621	9,5621	32,869
58,08	50,764	2,8861	2,8861	1015,3	0,096203	9,6203	32,886
58,39	50,43	2,8952	2,8952	1008,6	0,096506	9,6506	32,895
58,7	50,763	2,9162	2,9162	1015,3	0,097206	9,7206	32,916
59,01	50,719	2,9315	2,9315	1014,4	0,097716	9,7716	32,931
59,32	50,487	2,9441	2,9441	1009,7	0,098137	9,8137	32,944
59,64	50,787	2,9624	2,9624	1015,7	0,098748	9,8748	32,962
59,95	50,783	2,9802	2,9802	1015,7	0,099338	9,9338	32,98
60,26	50,375	2,9899	2,9899	1007,5	0,099663	9,9663	32,99
60,57	50,742	3,0097	3,0097	1014,8	0,10032	10,032	33,01
60,88	50,815	3,028	3,028	1016,3	0,10093	10,093	33,028
61,19	50,558	3,0381	3,0381	1011,2	0,10127	10,127	33,038
61,5	50,604	3,0544	3,0544	1012,1	0,10181	10,181	33,054
61,81	50,934	3,0771	3,0771	1018,7	0,10257	10,257	33,077
62,12	50,757	3,0848	3,0848	1015,1	0,10283	10,283	33,085
62,43	50,74	3,1019	3,1019	1014,8	0,1034	10,34	33,102
62,74	50,96	3,1221	3,1221	1019,2	0,10407	10,407	33,122
63,05	50,637	3,1306	3,1306	1012,7	0,10435	10,435	33,131
63,36	50,76	3,1492	3,1492	1015,2	0,10497	10,497	33,149
63,67	51,183	3,1715	3,1715	1023,7	0,10572	10,572	33,172
63,98	50,672	3,1777	3,1777	1013,4	0,10592	10,592	33,178
64,29	50,727	3,1946	3,1946	1014,5	0,10649	10,649	33,195
64,6	51,233	3,2202	3,2202	1024,7	0,10734	10,734	33,22
64,92	50,638	3,2252	3,2252	1012,8	0,10751	10,751	33,225
65,23	50,609	3,2395	3,2395	1012,2	0,10798	10,798	33,239
65,54	51,216	3,2655	3,2655	1024,3	0,10885	10,885	33,265
65,85	50,705	3,2715	3,2715	1014,1	0,10905	10,905	33,272
66,16	50,761	3,2867	3,2867	1015,2	0,10956	10,956	33,287
66,47	51,449	3,3131	3,3131	1029	0,11044	11,044	33,313
66,78	50,801	3,3175	3,3175	1016	0,11058	11,058	33,317
67,09	50,824	3,3328	3,3328	1016,5	0,11109	11,109	33,333
67,4	51,445	3,3604	3,3604	1028,9	0,11201	11,201	33,36
67,71	50,87	3,3643	3,3643	1017,4	0,11214	11,214	33,364
68,02	50,794	3,3788	3,3788	1015,9	0,11263	11,263	33,379
68,33	51,291	3,4032	3,4032	1025,8	0,11344	11,344	33,403
68,64	50,995	3,412	3,412	1019,9	0,11373	11,373	33,412
68,95	50,871	3,425	3,425	1017,4	0,11417	11,417	33,425
69,26	51,276	3,4482	3,4482	1025,5	0,11494	11,494	33,448
69,57	50,994	3,459	3,459	1019,9	0,1153	11,53	33,459
69,88	50,843	3,4723	3,4723	1016,9	0,11574	11,574	33,472
70,2	51,152	3,4927	3,4927	1023	0,11642	11,642	33,493
70,51	51,093	3,5067	3,5067	1021,9	0,11689	11,689	33,507
70,82	50,852	3,5174	3,5174	1017	0,11725	11,725	33,517
71,13	51,323	3,5397	3,5397	1026,5	0,11799	11,799	33,54
71,44	51,08	3,5515	3,5515	1021,6	0,11838	11,838	33,552
71,75	51,009	3,5647	3,5647	1020,2	0,11882	11,882	33,565
72,06	51,299	3,5843	3,5843	1026	0,11948	11,948	33,584
72,37	51,237	3,5997	3,5997	1024,7	0,11999	11,999	33,6
72,68	51,096	3,6117	3,6117	1021,9	0,12039	12,039	33,612
72,99	51,284	3,6295	3,6295	1025,7	0,12098	12,098	33,63
73,3	51,336	3,6475	3,6475	1026,7	0,12158	12,158	33,647
73,61	51,059	3,6573	3,6573	1021,2	0,12191	12,191	33,657
73,92	51,273	3,6761	3,6761	1025,5	0,12254	12,254	33,676
74,23	51,316	3,694	3,694	1026,3	0,12313	12,313	33,694
74,54	51,1	3,7052	3,7052	1022	0,12351	12,351	33,705
74,85	51,276	3,7236	3,7236	1025,5	0,12412	12,412	33,724
75,16	51,451	3,7432	3,7432	1029	0,12477	12,477	33,743
75,48	51,084	3,7518	3,7518	1021,7	0,12506	12,506	33,752
75,79	51,367	3,7706	3,7706	1027,3	0,12569	12,569	33,771
76,1	51,617	3,7913	3,7913	1032,3	0,12638	12,638	33,791
76,41	51,189	3,7993	3,7993	1023,8	0,12664	12,664	33,799
76,72	51,406	3,8167	3,8167	1028,1	0,12722	12,722	33,817
77,03	51,676	3,8373	3,8373	1033,5	0,12791	12,791	33,837
77,34	51,353	3,8458	3,8458	1027,1	0,12819	12,819	33,846
77,65	51,324	3,8604	3,8604	1026,5	0,12868	12,868	33,86
77,96	51,609	3,8842	3,8842	1032,2	0,12947	12,947	33,884
78,27	51,269	3,8924	3,8924	1025,4	0,12975	12,975	33,892
78,58	51,399	3,9092	3,9092	1028	0,13031	13,031	33,909
78,89	51,749	3,9322	3,9322	1035	0,13107	13,107	33,932
79,2	51,266	3,9391	3,9391	1025,3	0,1313	13,13	33,939
79,51	51,398	3,9557	3,9557	1028	0,13186	13,186	33,956
79,82	51,876	3,9806	3,9806	1037,5	0,13269	13,269	33,981
80,13	51,292	3,9851	3,9851	1025,8	0,13284	13,284	33,985
80,45	51,393	4,0025	4,0025	1027,9	0,13342	13,342	34,003
80,76	51,828	4,0252	4,0252	1036,6	0,13417	13,417	34,025
81,07	51,442	4,0332	4,0332	1028,8	0,13444	13,444	34,033
81,38	51,422	4,0468	4,0468	1028,4	0,13489	13,489	34,047
81,69	52,054	4,0735	4,0735	1041,1	0,13578	13,578	34,074
82	51,499	4,0791	4,0791	1030	0,13597	13,597	34,079
82,31	51,405	4,0919	4,0919	1028,1	0,1364	13,64	34,092
82,62	52,044	4,1187	4,1187	1040,9	0,13729	13,729	34,119
82,93	51,547	4,1266	4,1266	1030,9	0,13755	13,755	34,127
83,24	51,388	4,1409	4,1409	1027,8	0,13803	13,803	34,141
83,55	51,718	4,1626	4,1626	1034,4	0,13875	13,875	34,163
83,86	51,504	4,1742	4,1742	1030,1	0,13914	13,914	34,174
84,17	51,246	4,1864	4,1864	1024,9	0,13955	13,955	34,186
84,48	51,725	4,208	4,208	1034,5	0,14027	14,027	34,208
84,79	51,431	4,2206	4,2206	1028,6	0,14069	14,069	34,221
85,1	51,247	4,2321	4,2321	1024,9	0,14107	14,107	34,232
85,41	51,673	4,2541	4,2541	1033,5	0,1418	14,18	34,254
85,73	51,555	4,2682	4,2682	1031,1	0,14227	14,227	34,268
86,04	51,278	4,2777	4,2777	1025,6	0,14259	14,259	34,278
86,35	51,613	4,2986	4,2986	1032,3	0,14329	14,329	34,299
86,66	51,662	4,3149	4,3149	1033,2	0,14383	14,383	34,315
86,97	51,411	4,3248	4,3248	1028,2	0,14416	14,416	34,325
87,28	51,771	4,3455	4,3455	1035,4	0,14485	14,485	34,345
87,59	51,941	4,3641	4,3641	1038,8	0,14547	14,547	34,364
87,9	51,587	4,3724	4,3724	1031,7	0,14575	14,575	34,372
88,21	51,769	4,3908	4,3908	1035,4	0,14636	14,636	34,391
88,52	52,057	4,4092	4,4092	1041,1	0,14697	14,697	34,409
88,83	51,65	4,4196	4,4196	1033	0,14732	14,732	34,42
89,14	51,887	4,4384	4,4384	1037,7	0,14795	14,795	34,438
89,45	52,027	4,4567	4,4567	1040,5	0,14856	14,856	34,457
89,76	51,666	4,4656	4,4656	1033,3	0,14885	14,885	34,466
90,07	51,949	4,4836	4,4836	1039	0,14945	14,945	34,484
90,38	52,212	4,505	4,505	1044,2	0,15017	15,017	34,505
90,69	51,924	4,5145	4,5145	1038,5	0,15048	15,048	34,514
91,01	52,031	4,531	4,531	1040,6	0,15103	15,103	34,531
91,32	52,242	4,547	4,547	1044,8	0,15157	15,157	34,547
91,63	51,894	4,5599	4,5599	1037,9	0,152	15,2	34,56
91,94	52,235	4,5784	4,5784	1044,7	0,15261	15,261	34,578
92,25	52,524	4,5997	4,5997	1050,5	0,15332	15,332	34,6
92,56	52,125	4,6072	4,6072	1042,5	0,15357	15,357	34,607
92,87	52,141	4,6231	4,6231	1042,8	0,1541	15,41	34,623
93,18	52,599	4,6465	4,6465	1052	0,15488	15,488	34,647
93,49	52,124	4,6533	4,6533	1042,5	0,15511	15,511	34,653
93,8	52,176	4,6689	4,6689	1043,5	0,15563	15,563	34,669
94,11	52,706	4,6943	4,6943	1054,1	0,15648	15,648	34,694
94,42	52,121	4,6989	4,6989	1042,4	0,15663	15,663	34,699
94,73	52,14	4,7154	4,7154	1042,8	0,15718	15,718	34,715
95,04	52,772	4,743	4,743	1055,4	0,1581	15,81	34,743
95,35	52,03	4,7454	4,7454	1040,6	0,15818	15,818	34,745
95,66	52,136	4,7618	4,7618	1042,7	0,15873	15,873	34,762
95,98	52,532	4,7854	4,7854	1050,6	0,15951	15,951	34,785
96,29	52,144	4,7937	4,7937	1042,9	0,15979	15,979	34,794
96,6	52,164	4,8086	4,8086	1043,3	0,16029	16,029	34,809
96,91	52,596	4,8323	4,8323	1051,9	0,16108	16,108	34,832
97,22	52,246	4,8416	4,8416	1044,9	0,16139	16,139	34,842
97,53	52,183	4,8547	4,8547	1043,7	0,16182	16,182	34,855
97,84	52,478	4,8753	4,8753	1049,6	0,16251	16,251	34,875
98,15	52,329	4,8892	4,8892	1046,6	0,16297	16,297	34,889
98,46	52,057	4,899	4,899	1041,1	0,1633	16,33	34,899
98,77	52,552	4,9224	4,9224	1051	0,16408	16,408	34,922
99,08	52,398	4,9364	4,9364	1048	0,16455	16,455	34,936
99,39	52,096	4,9459	4,9459	1041,9	0,16486	16,486	34,946
99,7	52,546	4,9658	4,9658	1050,9	0,16553	16,553	34,966
100	52,503	4,9833	4,9833	1050,1	0,16611	16,611	34,983
100,3	52,179	4,9933	4,9933	1043,6	0,16644	16,644	34,993
100,6	52,551	5,0144	5,0144	1051	0,16715	16,715	35,014
100,9	52,607	5,0314	5,0314	1052,1	0,16771	16,771	35,031
101,3	52,298	5,0413	5,0413	1046	0,16804	16,804	35,041
101,6	52,559	5,0591	5,0591	1051,2	0,16864	16,864	35,059
101,9	52,796	5,0793	5,0793	1055,9	0,16931	16,931	35,079
102,2	52,341	5,0848	5,0848	1046,8	0,16949	16,949	35,085
102,5	52,692	5,1048	5,1048	1053,8	0,17016	17,016	35,105
102,8	52,656	5,1238	5,1238	1053,1	0,17079	17,079	35,124
103,1	52,357	5,1335	5,1335	1047,1	0,17112	17,112	35,134
103,4	52,66	5,1523	5,1523	1053,2	0,17174	17,174	35,152
103,7	52,963	5,1737	5,1737	1059,3	0,17246	17,246	35,174
104,1	52,451	5,1789	5,1789	1049	0,17263	17,263	35,179
104,4	52,732	5,1987	5,1987	1054,6	0,17329	17,329	35,199
104,7	52,985	5,2191	5,2191	1059,7	0,17397	17,397	35,219
105	52,525	5,227	5,227	1050,5	0,17423	17,423	35,227
105,3	52,743	5,2451	5,2451	1054,9	0,17484	17,484	35,245
105,6	52,985	5,2655	5,2655	1059,7	0,17552	17,552	35,265
105,9	52,593	5,273	5,273	1051,9	0,17577	17,577	35,273
106,2	52,87	5,2924	5,2924	1057,4	0,17641	17,641	35,292
106,5	52,95	5,3127	5,3127	1059	0,17709	17,709	35,313
106,8	52,756	5,3212	5,3212	1055,1	0,17737	17,737	35,321
107,2	52,861	5,336	5,336	1057,2	0,17787	17,787	35,336
107,5	53,132	5,3593	5,3593	1062,6	0,17864	17,864	35,359
107,8	52,777	5,3673	5,3673	1055,5	0,17891	17,891	35,367
108,1	52,828	5,3832	5,3832	1056,6	0,17944	17,944	35,383
108,4	53,166	5,4061	5,4061	1063,3	0,1802	18,02	35,406
108,7	52,773	5,4144	5,4144	1055,5	0,18048	18,048	35,414
109	52,868	5,4306	5,4306	1057,4	0,18102	18,102	35,431
109,3	53,232	5,4529	5,4529	1064,6	0,18176	18,176	35,453
109,6	52,889	5,4623	5,4623	1057,8	0,18208	18,208	35,462
110	52,878	5,4757	5,4757	1057,6	0,18252	18,252	35,476
110,3	53,36	5,5005	5,5005	1067,2	0,18335	18,335	35,501
110,6	52,972	5,5098	5,5098	1059,4	0,18366	18,366	35,51
110,9	52,889	5,521	5,521	1057,8	0,18403	18,403	35,521
111,2	53,293	5,5449	5,5449	1065,9	0,18483	18,483	35,545
111,5	53,187	5,557	5,557	1063,7	0,18523	18,523	35,557
111,8	52,979	5,5677	5,5677	1059,6	0,18559	18,559	35,568
112,1	53,397	5,5919	5,5919	1067,9	0,1864	18,64	35,592
112,4	53,252	5,6026	5,6026	1065	0,18675	18,675	35,603
112,7	52,994	5,6126	5,6126	1059,9	0,18709	18,709	35,613
113,1	53,344	5,6362	5,6362	1066,9	0,18787	18,787	35,636
113,4	53,249	5,6508	5,6508	1065	0,18836	18,836	35,651
113,7	53,01	5,6616	5,6616	1060,2	0,18872	18,872	35,662
114	53,466	5,6809	5,6809	1069,3	0,18936	18,936	35,681
114,3	53,262	5,6961	5,6961	1065,2	0,18987	18,987	35,696
114,6	53,069	5,7067	5,7067	1061,4	0,19022	19,022	35,707
114,9	53,404	5,7293	5,7293	1068,1	0,19098	19,098	35,729
115,2	53,301	5,7442	5,7442	1066	0,19147	19,147	35,744
115,5	53,086	5,7547	5,7547	1061,7	0,19182	19,182	35,755
115,9	53,25	5,7728	5,7728	1065	0,19243	19,243	35,773
116,2	53,328	5,7909	5,7909	1066,6	0,19303	19,303	35,791
116,5	53,058	5,8005	5,8005	1061,2	0,19335	19,335	35,801
116,8	53,23	5,8196	5,8196	1064,6	0,19399	19,399	35,82
117,1	53,402	5,8394	5,8394	1068	0,19465	19,465	35,839
117,4	52,949	5,8465	5,8465	1059	0,19488	19,488	35,846
117,7	53,254	5,866	5,866	1065,1	0,19553	19,553	35,866
118	53,459	5,8866	5,8866	1069,2	0,19622	19,622	35,887
118,3	53,035	5,8942	5,8942	1060,7	0,19647	19,647	35,894
118,6	53,346	5,914	5,914	1066,9	0,19713	19,713	35,914
119	53,45	5,9321	5,9321	1069	0,19774	19,774	35,932
119,3	53,132	5,941	5,941	1062,6	0,19803	19,803	35,941
119,6	53,395	5,9609	5,9609	1067,9	0,1987	19,87	35,961
119,9	53,504	5,979	5,979	1070,1	0,1993	19,93	35,979
120,2	53,171	5,9874	5,9874	1063,4	0,19958	19,958	35,987
120,5	53,369	6,0054	6,0054	1067,4	0,20018	20,018	36,005
120,8	53,736	6,0281	6,0281	1074,7	0,20094	20,094	36,028
121,1	53,325	6,037	6,037	1066,5	0,20123	20,123	36,037
121,4	53,462	6,0527	6,0527	1069,2	0,20176	20,176	36,053
121,8	53,857	6,0756	6,0756	1077,1	0,20252	20,252	36,076
122,1	53,392	6,0829	6,0829	1067,8	0,20276	20,276	36,083
122,4	53,415	6,0965	6,0965	1068,3	0,20322	20,322	36,097
122,7	53,879	6,1207	6,1207	1077,6	0,20402	20,402	36,121
123	53,512	6,1277	6,1277	1070,2	0,20426	20,426	36,128
123,3	53,473	6,1455	6,1455	1069,5	0,20485	20,485	36,145
123,6	54,049	6,1679	6,1679	1081	0,2056	20,56	36,168
123,9	53,564	6,1765	6,1765	1071,3	0,20588	20,588	36,176
124,2	53,505	6,1887	6,1887	1070,1	0,20629	20,629	36,189
124,6	54,076	6,2148	6,2148	1081,5	0,20716	20,716	36,215
124,9	53,609	6,2224	6,2224	1072,2	0,20741	20,741	36,222
125,2	53,528	6,2352	6,2352	1070,6	0,20784	20,784	36,235
125,5	53,997	6,2619	6,2619	1079,9	0,20873	20,873	36,262
125,8	53,792	6,2695	6,2695	1075,8	0,20898	20,898	36,27
126,1	53,656	6,2816	6,2816	1073,1	0,20939	20,939	36,282
126,4	54,056	6,3067	6,3067	1081,1	0,21022	21,022	36,307
126,7	53,812	6,3165	6,3165	1076,2	0,21055	21,055	36,316
127	53,728	6,3289	6,3289	1074,6	0,21096	21,096	36,329
127,3	53,982	6,3485	6,3485	1079,6	0,21162	21,162	36,349
127,7	53,906	6,3639	6,3639	1078,1	0,21213	21,213	36,364
128	53,757	6,3752	6,3752	1075,1	0,21251	21,251	36,375
128,3	54,059	6,3967	6,3967	1081,2	0,21322	21,322	36,397
128,6	53,811	6,4097	6,4097	1076,2	0,21366	21,366	36,41
128,9	53,753	6,4221	6,4221	1075,1	0,21407	21,407	36,422
129,2	53,928	6,443	6,443	1078,6	0,21477	21,477	36,443
129,5	53,877	6,457	6,457	1077,5	0,21523	21,523	36,457
129,8	53,791	6,4696	6,4696	1075,8	0,21565	21,565	36,47
130,1	54,115	6,4908	6,4908	1082,3	0,21636	21,636	36,491
130,5	53,864	6,5027	6,5027	1077,3	0,21676	21,676	36,503
130,8	53,854	6,5173	6,5173	1077,1	0,21724	21,724	36,517
131,1	53,92	6,5336	6,5336	1078,4	0,21779	21,779	36,534
131,4	54,166	6,5543	6,5543	1083,3	0,21848	21,848	36,554
131,7	53,876	6,5617	6,5617	1077,5	0,21872	21,872	36,562
132	54,051	6,5818	6,5818	1081	0,21939	21,939	36,582
132,3	54,28	6,602	6,602	1085,6	0,22007	22,007	36,602
132,6	53,848	6,6089	6,6089	1077	0,2203	22,03	36,609
132,9	53,996	6,6277	6,6277	1079,9	0,22092	22,092	36,628
133,2	54,231	6,647	6,647	1084,6	0,22157	22,157	36,647
133,6	53,973	6,6566	6,6566	1079,5	0,22189	22,189	36,657
133,9	53,998	6,6727	6,6727	1080	0,22242	22,242	36,673
134,2	54,282	6,694	6,694	1085,6	0,22313	22,313	36,694
134,5	53,874	6,7042	6,7042	1077,5	0,22347	22,347	36,704
134,8	54,072	6,7183	6,7183	1081,4	0,22394	22,394	36,718
135,1	54,373	6,7412	6,7412	1087,5	0,22471	22,471	36,741
135,4	54,017	6,7514	6,7514	1080,3	0,22505	22,505	36,751
135,7	54,119	6,7668	6,7668	1082,4	0,22556	22,556	36,767
136	54,619	6,7916	6,7916	1092,4	0,22639	22,639	36,792
136,4	54,089	6,7982	6,7982	1081,8	0,22661	22,661	36,798
136,7	54,055	6,8116	6,8116	1081,1	0,22705	22,705	36,812
137	54,454	6,8325	6,8325	1089,1	0,22775	22,775	36,832
137,3	54,192	6,8441	6,8441	1083,8	0,22814	22,814	36,844
137,6	54,201	6,8586	6,8586	1084	0,22862	22,862	36,859
137,9	54,675	6,884	6,884	1093,5	0,22947	22,947	36,884
138,2	54,115	6,8891	6,8891	1082,3	0,22964	22,964	36,889
138,5	54,152	6,9043	6,9043	1083	0,23014	23,014	36,904
138,8	54,657	6,9301	6,9301	1093,1	0,231	23,1	36,93
139,1	54,179	6,9368	6,9368	1083,6	0,23123	23,123	36,937
139,5	54,172	6,9501	6,9501	1083,4	0,23167	23,167	36,95
139,8	54,784	6,9771	6,9771	1095,7	0,23257	23,257	36,977
140,1	54,341	6,9844	6,9844	1086,8	0,23281	23,281	36,984
140,4	54,217	6,9976	6,9976	1084,3	0,23325	23,325	36,998
140,7	54,781	7,023	7,023	1095,6	0,2341	23,41	37,023
141	54,29	7,0305	7,0305	1085,8	0,23435	23,435	37,031
141,3	54,258	7,043	7,043	1085,2	0,23477	23,477	37,043
141,6	54,842	7,0657	7,0657	1096,8	0,23552	23,552	37,066
141,9	54,459	7,0799	7,0799	1089,2	0,236	23,6	37,08
142,3	54,245	7,0911	7,0911	1084,9	0,23637	23,637	37,091
142,6	54,55	7,1088	7,1088	1091	0,23696	23,696	37,109
142,9	54,511	7,126	7,126	1090,2	0,23753	23,753	37,126
143,2	54,283	7,1362	7,1362	1085,7	0,23787	23,787	37,136
143,5	54,53	7,156	7,156	1090,6	0,23853	23,853	37,156
143,8	54,586	7,1734	7,1734	1091,7	0,23911	23,911	37,173
144,1	54,265	7,1819	7,1819	1085,3	0,2394	23,94	37,182
144,4	54,563	7,2036	7,2036	1091,3	0,24012	24,012	37,204
144,7	54,583	7,2199	7,2199	1091,7	0,24066	24,066	37,22
145	54,405	7,2312	7,2312	1088,1	0,24104	24,104	37,231
145,4	54,519	7,248	7,248	1090,4	0,2416	24,16	37,248
145,7	54,681	7,2671	7,2671	1093,6	0,24224	24,224	37,267
146	54,435	7,2756	7,2756	1088,7	0,24252	24,252	37,276
146,3	54,561	7,2954	7,2954	1091,2	0,24318	24,318	37,295
146,6	54,857	7,3156	7,3156	1097,1	0,24385	24,385	37,316
146,9	54,521	7,3239	7,3239	1090,4	0,24413	24,413	37,324
147,2	54,621	7,3409	7,3409	1092,4	0,2447	24,47	37,341
147,5	54,871	7,3621	7,3621	1097,4	0,2454	24,54	37,362
147,8	54,47	7,3702	7,3702	1089,4	0,24567	24,567	37,37
148,2	54,695	7,3886	7,3886	1093,9	0,24629	24,629	37,389
148,5	54,854	7,408	7,408	1097,1	0,24693	24,693	37,408
148,8	54,591	7,4188	7,4188	1091,8	0,24729	24,729	37,419
149,1	54,664	7,4339	7,4339	1093,3	0,2478	24,78	37,434
149,4	54,966	7,4562	7,4562	1099,3	0,24854	24,854	37,456
149,7	54,524	7,4633	7,4633	1090,5	0,24878	24,878	37,463
150	54,748	7,482	7,482	1095	0,2494	24,94	37,482
150,3	55,202	7,5064	7,5064	1104	0,25021	25,021	37,506
150,6	54,543	7,5094	7,5094	1090,9	0,25031	25,031	37,509
151	54,676	7,526	7,526	1093,5	0,25087	25,087	37,526
151,3	55,24	7,5527	7,5527	1104,8	0,25176	25,176	37,553
151,6	54,59	7,558	7,558	1091,8	0,25193	25,193	37,558
151,9	54,731	7,573	7,573	1094,6	0,25243	25,243	37,573
152,2	55,14	7,597	7,597	1102,8	0,25323	25,323	37,597
152,5	54,77	7,6052	7,6052	1095,4	0,25351	25,351	37,605
152,8	54,709	7,6189	7,6189	1094,2	0,25396	25,396	37,619
153,1	55,178	7,6436	7,6436	1103,6	0,25479	25,479	37,644
153,4	54,725	7,6522	7,6522	1094,5	0,25507	25,507	37,652
153,7	54,641	7,6658	7,6658	1092,8	0,25553	25,553	37,666
154,1	55,101	7,6899	7,6899	1102	0,25633	25,633	37,69
154,4	54,716	7,698	7,698	1094,3	0,2566	25,66	37,698
154,7	54,616	7,7123	7,7123	1092,3	0,25708	25,708	37,712
155	54,961	7,7341	7,7341	1099,2	0,2578	25,78	37,734
155,3	54,739	7,7455	7,7455	1094,8	0,25818	25,818	37,746
155,6	54,648	7,7582	7,7582	1093	0,25861	25,861	37,758
155,9	55,055	7,7801	7,7801	1101,1	0,25934	25,934	37,78
156,2	54,767	7,7918	7,7918	1095,3	0,25973	25,973	37,792
156,5	54,709	7,8045	7,8045	1094,2	0,26015	26,015	37,804
156,9	54,944	7,8237	7,8237	1098,9	0,26079	26,079	37,824
157,2	54,849	7,8386	7,8386	1097	0,26129	26,129	37,839
157,5	54,826	7,8515	7,8515	1096,5	0,26172	26,172	37,852
157,8	54,849	7,8708	7,8708	1097	0,26236	26,236	37,871
158,1	54,998	7,8851	7,8851	1100	0,26284	26,284	37,885
158,4	54,748	7,8945	7,8945	1095	0,26315	26,315	37,895
158,7	55,021	7,9156	7,9156	1100,4	0,26385	26,385	37,916
159	55,04	7,9342	7,9342	1100,8	0,26447	26,447	37,934
159,3	54,738	7,9456	7,9456	1094,8	0,26485	26,485	37,946
159,6	54,922	7,9657	7,9657	1098,4	0,26552	26,552	37,966
160	55,031	7,9793	7,9793	1100,6	0,26598	26,598	37,979
160,3	54,776	7,9893	7,9893	1095,5	0,26631	26,631	37,989
160,6	55,037	8,0105	8,0105	1100,7	0,26702	26,702	38,01
160,9	55,202	8,0298	8,0298	1104	0,26766	26,766	38,03
161,2	54,89	8,0389	8,0389	1097,8	0,26796	26,796	38,039
161,5	55,048	8,0569	8,0569	1101	0,26856	26,856	38,057
161,8	55,252	8,0755	8,0755	1105	0,26918	26,918	38,076
162,1	54,9	8,0834	8,0834	1098	0,26945	26,945	38,083
162,4	55,059	8,1021	8,1021	1101,2	0,27007	27,007	38,102
162,8	55,31	8,1213	8,1213	1106,2	0,27071	27,071	38,121
163,1	55,031	8,1318	8,1318	1100,6	0,27106	27,106	38,132
163,4	55,019	8,1491	8,1491	1100,4	0,27164	27,164	38,149
163,7	55,371	8,1703	8,1703	1107,4	0,27234	27,234	38,17
164	54,947	8,1792	8,1792	1098,9	0,27264	27,264	38,179
164,3	55,06	8,1949	8,1949	1101,2	0,27316	27,316	38,195
164,6	55,381	8,2181	8,2181	1107,6	0,27394	27,394	38,218
164,9	54,988	8,2253	8,2253	1099,8	0,27418	27,418	38,225
165,2	54,987	8,2417	8,2417	1099,7	0,27472	27,472	38,242
165,5	55,401	8,2652	8,2652	1108	0,27551	27,551	38,265
165,9	54,925	8,2713	8,2713	1098,5	0,27571	27,571	38,271
166,2	54,974	8,2867	8,2867	1099,5	0,27622	27,622	38,287
166,5	55,485	8,3115	8,3115	1109,7	0,27705	27,705	38,312
166,8	55,199	8,3219	8,3219	1104	0,2774	27,74	38,322
167,1	55,065	8,333	8,333	1101,3	0,27777	27,777	38,333
167,4	55,614	8,3591	8,3591	1112,3	0,27864	27,864	38,359
167,7	55,155	8,3662	8,3662	1103,1	0,27887	27,887	38,366
168	55,194	8,3793	8,3793	1103,9	0,27931	27,931	38,379
168,3	55,556	8,4031	8,4031	1111,1	0,2801	28,01	38,403
168,7	55,266	8,4137	8,4137	1105,3	0,28046	28,046	38,414
169	55,2	8,4255	8,4255	1104	0,28085	28,085	38,426
169,3	55,46	8,4476	8,4476	1109,2	0,28159	28,159	38,448
169,6	55,223	8,4587	8,4587	1104,5	0,28196	28,196	38,459
169,9	55,118	8,4714	8,4714	1102,4	0,28238	28,238	38,471
170,2	55,562	8,495	8,495	1111,2	0,28317	28,317	38,495
170,5	55,349	8,5072	8,5072	1107	0,28357	28,357	38,507
170,8	55,146	8,5178	8,5178	1102,9	0,28393	28,393	38,518
171,1	55,591	8,5389	8,5389	1111,8	0,28463	28,463	38,539
171,5	55,561	8,554	8,554	1111,2	0,28513	28,513	38,554
171,8	55,323	8,564	8,564	1106,5	0,28547	28,547	38,564
172,1	55,668	8,5864	8,5864	1113,4	0,28621	28,621	38,586
172,4	55,609	8,6009	8,6009	1112,2	0,2867	28,67	38,601
172,7	55,419	8,6113	8,6113	1108,4	0,28704	28,704	38,611
173	55,654	8,6326	8,6326	1113,1	0,28775	28,775	38,633
173,3	55,733	8,6486	8,6486	1114,7	0,28829	28,829	38,649
173,6	55,449	8,6583	8,6583	1109	0,28861	28,861	38,658
173,9	55,639	8,6772	8,6772	1112,8	0,28924	28,924	38,677
174,2	55,616	8,6938	8,6938	1112,3	0,28979	28,979	38,694
174,6	55,439	8,7055	8,7055	1108,8	0,29018	29,018	38,706
174,9	55,669	8,7249	8,7249	1113,4	0,29083	29,083	38,725
175,2	55,704	8,7422	8,7422	1114,1	0,29141	29,141	38,742
175,5	55,468	8,7535	8,7535	1109,4	0,29178	29,178	38,753
175,8	55,597	8,7699	8,7699	1111,9	0,29233	29,233	38,77
176,1	55,792	8,7892	8,7892	1115,8	0,29297	29,297	38,789
176,4	55,486	8,7987	8,7987	1109,7	0,29329	29,329	38,799
176,7	55,624	8,8162	8,8162	1112,5	0,29387	29,387	38,816
177	55,91	8,8343	8,8343	1118,2	0,29448	29,448	38,834
177,4	55,544	8,844	8,844	1110,9	0,2948	29,48	38,844
177,7	55,689	8,8613	8,8613	1113,8	0,29538	29,538	38,861
178	56,01	8,885	8,885	1120,2	0,29617	29,617	38,885
178,3	55,661	8,8938	8,8938	1113,2	0,29646	29,646	38,894
178,6	55,676	8,9083	8,9083	1113,5	0,29694	29,694	38,908
178,9	56,164	8,9293	8,9293	1123,3	0,29764	29,764	38,929
179,2	55,616	8,9412	8,9412	1112,3	0,29804	29,804	38,941
179,5	55,714	8,9547	8,9547	1114,3	0,29849	29,849	38,955
179,8	56,168	8,9793	8,9793	1123,4	0,29931	29,931	38,979
180,1	55,731	8,9868	8,9868	1114,6	0,29956	29,956	38,987
180,5	55,647	9,0024	9,0024	1112,9	0,30008	30,008	39,002
180,8	56,003	9,0255	9,0255	1120,1	0,30085	30,085	39,025
181,1	55,8	9,034	9,034	1116	0,30113	30,113	39,034
181,4	55,705	9,047	9,047	1114,1	0,30157	30,157	39,047
181,7	56,088	9,0709	9,0709	1121,8	0,30236	30,236	39,071
182	55,796	9,0828	9,0828	1115,9	0,30276	30,276	39,083
182,3	55,657	9,0951	9,0951	1113,1	0,30317	30,317	39,095
182,6	56,116	9,117	9,117	1122,3	0,3039	30,39	39,117
182,9	55,84	9,1274	9,1274	1116,8	0,30425	30,425	39,127
183,3	55,788	9,1413	9,1413	1115,8	0,30471	30,471	39,141
183,6	56,145	9,1641	9,1641	1122,9	0,30547	30,547	39,164
183,9	55,802	9,1743	9,1743	1116	0,30581	30,581	39,174
184,2	55,637	9,1855	9,1855	1112,7	0,30618	30,618	39,186
184,5	56,097	9,2104	9,2104	1121,9	0,30701	30,701	39,21
184,8	55,752	9,2199	9,2199	1115	0,30733	30,733	39,22
185,1	55,548	9,2309	9,2309	1111	0,3077	30,77	39,231
185,4	55,997	9,2545	9,2545	1119,9	0,30848	30,848	39,254
185,7	55,886	9,2669	9,2669	1117,7	0,3089	30,89	39,267
186	55,642	9,279	9,279	1112,8	0,3093	30,93	39,279
186,4	56,063	9,3025	9,3025	1121,3	0,31008	31,008	39,303
186,7	55,825	9,3141	9,3141	1116,5	0,31047	31,047	39,314
187	55,756	9,3265	9,3265	1115,1	0,31088	31,088	39,327
187,3	55,969	9,346	9,346	1119,4	0,31153	31,153	39,346
187,6	56,009	9,3629	9,3629	1120,2	0,3121	31,21	39,363
187,9	55,733	9,3728	9,3728	1114,7	0,31243	31,243	39,373
188,2	55,96	9,3927	9,3927	1119,2	0,31309	31,309	39,393
188,5	55,986	9,4096	9,4096	1119,7	0,31365	31,365	39,41
188,8	55,677	9,4187	9,4187	1113,5	0,31396	31,396	39,419
189,2	55,914	9,4387	9,4387	1118,3	0,31462	31,462	39,439
189,5	56,082	9,4587	9,4587	1121,6	0,31529	31,529	39,459
189,8	55,762	9,4678	9,4678	1115,2	0,31559	31,559	39,468
190,1	55,971	9,485	9,485	1119,4	0,31617	31,617	39,485
190,4	56,106	9,5035	9,5035	1122,1	0,31678	31,678	39,503
190,7	55,761	9,5144	9,5144	1115,2	0,31715	31,715	39,514
191	56,003	9,5307	9,5307	1120,1	0,31769	31,769	39,531
191,3	56,296	9,5534	9,5534	1125,9	0,31845	31,845	39,553
191,6	55,864	9,561	9,561	1117,3	0,3187	31,87	39,561
192	56,009	9,5767	9,5767	1120,2	0,31922	31,922	39,577
192,3	56,411	9,6004	9,6004	1128,2	0,32001	32,001	39,6
192,6	55,853	9,6058	9,6058	1117,1	0,32019	32,019	39,606
192,9	56,033	9,6236	9,6236	1120,7	0,32079	32,079	39,624
193,2	56,523	9,6488	9,6488	1130,5	0,32163	32,163	39,649
193,5	56,003	9,6539	9,6539	1120,1	0,3218	32,18	39,654
193,8	56,116	9,6693	9,6693	1122,3	0,32231	32,231	39,669
194,1	56,403	9,6921	9,6921	1128,1	0,32307	32,307	39,692
194,4	56,137	9,7023	9,7023	1122,7	0,32341	32,341	39,702
194,7	56,208	9,7182	9,7182	1124,2	0,32394	32,394	39,718
195,1	56,705	9,7434	9,7434	1134,1	0,32478	32,478	39,743
195,4	55,968	9,7453	9,7453	1119,4	0,32484	32,484	39,745
195,7	56,048	9,7617	9,7617	1121	0,32539	32,539	39,762
196	56,735	9,79	9,79	1134,7	0,32633	32,633	39,79
196,3	56,068	9,793	9,793	1121,4	0,32643	32,643	39,793
196,6	56,139	9,808	9,808	1122,8	0,32693	32,693	39,808
196,9	56,833	9,8365	9,8365	1136,7	0,32788	32,788	39,837
197,2	56,167	9,8401	9,8401	1123,3	0,328	32,8	39,84
197,5	56,213	9,8558	9,8558	1124,3	0,32853	32,853	39,856
197,9	56,674	9,8801	9,8801	1133,5	0,32934	32,934	39,88
198,2	56,262	9,8876	9,8876	1125,2	0,32959	32,959	39,888
198,5	56,176	9,9006	9,9006	1123,5	0,33002	33,002	39,901
198,8	56,442	9,9219	9,9219	1128,8	0,33073	33,073	39,922
199,1	56,237	9,9346	9,9346	1124,7	0,33115	33,115	39,935
199,4	56,095	9,947	9,947	1121,9	0,33157	33,157	39,947
199,7	56,438	9,9694	9,9694	1128,8	0,33231	33,231	39,969
200	56,229	9,9815	9,9815	1124,6	0,33272	33,272	39,982
200,3	56,155	9,9944	9,9944	1123,1	0,33315	33,315	39,994
200,6	56,405	10,014	10,014	1128,1	0,33379	33,379	40,014
201	56,407	10,031	10,031	1128,1	0,33436	33,436	40,031
201,3	56,168	10,042	10,042	1123,4	0,33472	33,472	40,042
201,6	56,43	10,059	10,059	1128,6	0,33531	33,531	40,059
201,9	56,449	10,077	10,077	1129	0,33591	33,591	40,077
202,2	56,133	10,086	10,086	1122,7	0,3362	33,62	40,086
202,5	56,489	10,108	10,108	1129,8	0,33692	33,692	40,108
202,8	56,564	10,125	10,125	1131,3	0,33749	33,749	40,125
203,1	56,238	10,134	10,134	1124,8	0,3378	33,78	40,134
203,4	56,434	10,152	10,152	1128,7	0,3384	33,84	40,152
203,8	56,556	10,172	10,172	1131,1	0,33905	33,905	40,172
204,1	56,209	10,18	10,18	1124,2	0,33934	33,934	40,18
204,4	56,461	10,2	10,2	1129,2	0,34	34	40,2
204,7	56,632	10,219	10,219	1132,6	0,34065	34,065	40,219
205	56,227	10,227	10,227	1124,5	0,3409	34,09	40,227
205,3	56,464	10,245	10,245	1129,3	0,34151	34,151	40,245
205,6	56,659	10,265	10,265	1133,2	0,34217	34,217	40,265
205,9	56,373	10,276	10,276	1127,5	0,34252	34,252	40,276
206,2	56,516	10,292	10,292	1130,3	0,34306	34,306	40,292
206,5	56,814	10,313	10,313	1136,3	0,34377	34,377	40,313
206,9	56,421	10,321	10,321	1128,4	0,34403	34,403	40,321
207,2	56,513	10,337	10,337	1130,3	0,34458	34,458	40,337
207,5	56,9	10,361	10,361	1138	0,34536	34,536	40,361
207,8	56,503	10,369	10,369	1130,1	0,34564	34,564	40,369
208,1	56,569	10,385	10,385	1131,4	0,34617	34,617	40,385
208,4	56,923	10,406	10,406	1138,5	0,34686	34,686	40,406
208,7	56,658	10,416	10,416	1133,2	0,3472	34,72	40,416
209	56,62	10,431	10,431	1132,4	0,3477	34,77	40,431
209,3	56,977	10,454	10,454	1139,5	0,34847	34,847	40,454
209,7	56,618	10,462	10,462	1132,4	0,34873	34,873	40,462
210	56,63	10,478	10,478	1132,6	0,34927	34,927	40,478
210,3	57,025	10,501	10,501	1140,5	0,35003	35,003	40,501
210,6	56,571	10,51	10,51	1131,4	0,35032	35,032	40,51
210,9	56,615	10,523	10,523	1132,3	0,35077	35,077	40,523
211,2	57,02	10,546	10,546	1140,4	0,35154	35,154	40,546
211,5	56,672	10,556	10,556	1133,4	0,35186	35,186	40,556
211,8	56,702	10,57	10,57	1134	0,35232	35,232	40,57
212,1	57,178	10,593	10,593	1143,6	0,35311	35,311	40,593
212,4	56,81	10,604	10,604	1136,2	0,35345	35,345	40,604
212,8	56,668	10,615	10,615	1133,4	0,35382	35,382	40,615
213,1	57,041	10,637	10,637	1140,8	0,35456	35,456	40,637
213,4	56,841	10,65	10,65	1136,8	0,355	35,5	40,65
213,7	56,732	10,663	10,663	1134,6	0,35542	35,542	40,663
214	56,928	10,682	10,682	1138,6	0,35607	35,607	40,682
214,3	56,84	10,697	10,697	1136,8	0,35658	35,658	40,697
214,6	56,667	10,709	10,709	1133,3	0,35696	35,696	40,709
214,9	56,957	10,73	10,73	1139,1	0,35766	35,766	40,73
215,2	56,846	10,744	10,744	1136,9	0,35813	35,813	40,744
215,6	56,568	10,753	10,753	1131,4	0,35844	35,844	40,753
215,9	56,89	10,775	10,775	1137,8	0,35917	35,917	40,775
216,2	57,052	10,793	10,793	1141	0,35978	35,978	40,793
216,5	56,695	10,802	10,802	1133,9	0,36005	36,005	40,802
216,8	56,998	10,82	10,82	1140	0,36067	36,067	40,82
217,1	57,079	10,838	10,838	1141,6	0,36127	36,127	40,838
217,4	56,815	10,848	10,848	1136,3	0,36159	36,159	40,848
217,7	57,122	10,869	10,869	1142,4	0,3623	36,23	40,869
218	57,233	10,887	10,887	1144,7	0,36288	36,288	40,887
218,4	56,924	10,896	10,896	1138,5	0,36318	36,318	40,896
218,7	57,035	10,913	10,913	1140,7	0,36377	36,377	40,913
219	57,258	10,934	10,934	1145,2	0,36445	36,445	40,934
219,3	56,901	10,942	10,942	1138	0,36475	36,475	40,942
219,6	56,985	10,959	10,959	1139,7	0,36531	36,531	40,959
219,9	57,243	10,98	10,98	1144,9	0,36601	36,601	40,98
220,2	56,887	10,989	10,989	1137,7	0,3663	36,63	40,989
220,5	57,023	11,006	11,006	1140,5	0,36688	36,688	41,006
220,8	57,289	11,027	11,027	1145,8	0,36756	36,756	41,027
221,1	56,983	11,036	11,036	1139,7	0,36788	36,788	41,036
221,5	57,025	11,053	11,053	1140,5	0,36842	36,842	41,053
221,8	57,382	11,075	11,075	1147,6	0,36917	36,917	41,075
222,1	56,99	11,083	11,083	1139,8	0,36942	36,942	41,083
222,4	57,03	11,099	11,099	1140,6	0,36997	36,997	41,099
222,7	57,366	11,121	11,121	1147,3	0,3707	37,07	41,121
223	56,957	11,129	11,129	1139,1	0,37096	37,096	41,129
223,3	57,084	11,146	11,146	1141,7	0,37153	37,153	41,146
223,6	57,456	11,17	11,17	1149,1	0,37233	37,233	41,17
223,9	57,047	11,177	11,177	1140,9	0,37257	37,257	41,177
224,3	56,962	11,191	11,191	1139,2	0,37302	37,302	41,191
224,6	57,507	11,217	11,217	1150,1	0,3739	37,39	41,217
224,9	56,935	11,222	11,222	1138,7	0,37408	37,408	41,222
225,2	56,912	11,237	11,237	1138,2	0,37456	37,456	41,237
225,5	57,468	11,263	11,263	1149,4	0,37542	37,542	41,263
225,8	57,199	11,273	11,273	1144	0,37576	37,576	41,273
226,1	57	11,284	11,284	1140	0,37612	37,612	41,284
226,4	57,575	11,309	11,309	1151,5	0,37697	37,697	41,309
226,7	57,126	11,316	11,316	1142,5	0,37722	37,722	41,316
227	56,978	11,328	11,328	1139,6	0,37759	37,759	41,328
227,4	57,496	11,353	11,353	1149,9	0,37843	37,843	41,353
227,7	57,253	11,364	11,364	1145,1	0,37879	37,879	41,364
228	57,044	11,377	11,377	1140,9	0,37923	37,923	41,377
228,3	57,537	11,399	11,399	1150,7	0,37995	37,995	41,399
228,6	57,205	11,412	11,412	1144,1	0,38041	38,041	41,412
228,9	57,179	11,423	11,423	1143,6	0,38078	38,078	41,423
229,2	57,341	11,444	11,444	1146,8	0,38147	38,147	41,444
229,5	57,294	11,457	11,457	1145,9	0,38191	38,191	41,457
229,8	57,071	11,468	11,468	1141,4	0,38226	38,226	41,468
230,2	57,481	11,491	11,491	1149,6	0,38303	38,303	41,491
230,5	57,346	11,505	11,505	1146,9	0,38349	38,349	41,505
230,8	57,137	11,515	11,515	1142,7	0,38384	38,384	41,515
231,1	57,481	11,535	11,535	1149,6	0,3845	38,45	41,535
231,4	57,573	11,554	11,554	1151,5	0,38512	38,512	41,554
231,7	57,223	11,563	11,563	1144,5	0,38543	38,543	41,563
232	57,475	11,582	11,582	1149,5	0,38605	38,605	41,582
232,3	57,585	11,6	11,6	1151,7	0,38667	38,667	41,6
232,6	57,254	11,608	11,608	1145,1	0,38694	38,694	41,608
232,9	57,518	11,629	11,629	1150,4	0,38762	38,762	41,629
233,3	57,534	11,646	11,646	1150,7	0,3882	38,82	41,646
233,6	57,358	11,658	11,658	1147,2	0,3886	38,86	41,658
233,9	57,384	11,673	11,673	1147,7	0,38909	38,909	41,673
234,2	57,616	11,695	11,695	1152,3	0,38982	38,982	41,695
234,5	57,306	11,704	11,704	1146,1	0,39014	39,014	41,704
234,8	57,356	11,719	11,719	1147,1	0,39065	39,065	41,719
235,1	57,635	11,742	11,742	1152,7	0,39139	39,139	41,742
235,4	57,266	11,75	11,75	1145,3	0,39167	39,167	41,75
235,7	57,389	11,767	11,767	1147,8	0,39223	39,223	41,767
236,1	57,893	11,793	11,793	1157,9	0,39309	39,309	41,793
236,4	57,317	11,797	11,797	1146,3	0,39322	39,322	41,797
236,7	57,355	11,812	11,812	1147,1	0,39374	39,374	41,812
237	57,96	11,84	11,84	1159,2	0,39466	39,466	41,84
237,3	57,347	11,843	11,843	1146,9	0,39478	39,478	41,843
237,6	57,443	11,859	11,859	1148,9	0,3953	39,53	41,859
237,9	57,803	11,881	11,881	1156,1	0,39602	39,602	41,881
238,2	57,438	11,893	11,893	1148,8	0,39644	39,644	41,893
238,5	57,437	11,905	11,905	1148,7	0,39684	39,684	41,905
238,9	57,906	11,931	11,931	1158,1	0,39771	39,771	41,931
239,2	57,494	11,938	11,938	1149,9	0,39794	39,794	41,938
239,5	57,449	11,953	11,953	1149	0,39842	39,842	41,953
239,8	57,968	11,977	11,977	1159,4	0,39923	39,923	41,977
240,1	57,582	11,986	11,986	1151,6	0,39952	39,952	41,986
240,4	57,54	11,999	11,999	1150,8	0,39996	39,996	41,999
240,7	58,027	12,023	12,023	1160,5	0,40077	40,077	42,023
241	57,571	12,032	12,032	1151,4	0,40106	40,106	42,032
241,3	57,508	12,044	12,044	1150,2	0,40145	40,145	42,044
241,6	57,938	12,068	12,068	1158,8	0,40226	40,226	42,068
242	57,622	12,078	12,078	1152,4	0,40258	40,258	42,078
242,3	57,497	12,091	12,091	1149,9	0,40303	40,303	42,091
242,6	57,938	12,114	12,114	1158,8	0,40381	40,381	42,114
242,9	57,627	12,124	12,124	1152,5	0,40414	40,414	42,124
243,2	57,582	12,137	12,137	1151,6	0,40456	40,456	42,137
243,5	57,838	12,156	12,156	1156,8	0,40521	40,521	42,156
243,8	57,69	12,172	12,172	1153,8	0,40575	40,575	42,172
244,1	57,487	12,183	12,183	1149,7	0,40611	40,611	42,183
244,4	57,588	12,201	12,201	1151,8	0,40669	40,669	42,201
244,8	57,693	12,221	12,221	1153,9	0,40735	40,735	42,221
245,1	57,402	12,23	12,23	1148	0,40766	40,766	42,23
245,4	57,782	12,249	12,249	1155,6	0,40831	40,831	42,249
245,7	57,782	12,267	12,267	1155,6	0,40892	40,892	42,267
246	57,484	12,276	12,276	1149,7	0,40921	40,921	42,276
246,3	57,673	12,295	12,295	1153,5	0,40985	40,985	42,295
246,6	57,903	12,316	12,316	1158,1	0,41054	41,054	42,316
246,9	57,457	12,324	12,324	1149,1	0,4108	41,08	42,324
247,2	57,692	12,342	12,342	1153,8	0,4114	41,14	42,342
247,5	57,905	12,363	12,363	1158,1	0,41209	41,209	42,363
247,9	57,6	12,372	12,372	1152	0,4124	41,24	42,372
248,2	57,668	12,387	12,387	1153,4	0,41291	41,291	42,387
248,5	58,041	12,411	12,411	1160,8	0,4137	41,37	42,411
248,8	57,52	12,416	12,416	1150,4	0,41386	41,386	42,416
249,1	57,7	12,435	12,435	1154	0,41451	41,451	42,435
249,4	57,877	12,455	12,455	1157,5	0,41516	41,516	42,455
249,7	57,589	12,464	12,464	1151,8	0,41546	41,546	42,464
250	57,758	12,483	12,483	1155,2	0,41609	41,609	42,483
250,3	58,049	12,504	12,504	1161	0,41681	41,681	42,504
250,7	57,587	12,512	12,512	1151,7	0,41708	41,708	42,512
251	57,645	12,527	12,527	1152,9	0,41756	41,756	42,527
251,3	57,968	12,55	12,55	1159,4	0,41832	41,832	42,55
251,6	57,644	12,558	12,558	1152,9	0,41859	41,859	42,558
251,9	57,746	12,575	12,575	1154,9	0,41917	41,917	42,575
252,2	58,226	12,601	12,601	1164,5	0,42002	42,002	42,601
252,5	57,608	12,604	12,604	1152,2	0,42015	42,015	42,604
252,8	57,623	12,62	12,62	1152,5	0,42065	42,065	42,62
253,1	58,027	12,645	12,645	1160,5	0,42149	42,149	42,645
253,4	57,532	12,651	12,651	1150,6	0,4217	42,17	42,651
253,8	57,464	12,665	12,665	1149,3	0,42218	42,218	42,665
254,1	58,042	12,694	12,694	1160,8	0,42313	42,313	42,694
254,4	57,297	12,697	12,697	1145,9	0,42323	42,323	42,697
254,7	57,264	12,713	12,713	1145,3	0,42377	42,377	42,713
255	57,599	12,736	12,736	1152	0,42454	42,454	42,736
255,3	57,092	12,745	12,745	1141,8	0,42485	42,485	42,745
255,6	56,778	12,758	12,758	1135,6	0,42525	42,525	42,758
255,9	56,807	12,784	12,784	1136,1	0,42615	42,615	42,784
256,2	55,457	12,79	12,79	1109,1	0,42634	42,634	42,79
256,6	51,604	12,805	12,805	1032,1	0,42684	42,684	42,805
256,9	50,15	12,825	12,825	1003	0,4275	42,75	42,825
257,2	49,139	12,841	12,841	982,77	0,42802	42,802	42,841
257,5	48,241	12,85	12,85	964,81	0,42835	42,835	42,85
257,8	47,952	12,872	12,872	959,05	0,42908	42,908	42,872
258,1	47,219	12,886	12,886	944,38	0,42954	42,954	42,886
258,4	46,502	12,897	12,897	930,05	0,42989	42,989	42,897
258,7	46,377	12,917	12,917	927,55	0,43057	43,057	42,917
259	45,786	12,935	12,935	915,71	0,43116	43,116	42,935
259,4	45,051	12,946	12,946	901,01	0,43153	43,153	42,946
259,7	44,851	12,965	12,965	897,03	0,43215	43,215	42,965
260	44,661	12,982	12,982	893,22	0,43273	43,273	42,982
260,3	44,169	12,991	12,991	883,38	0,43303	43,303	42,991
260,6	44,288	13,012	13,012	885,76	0,43374	43,374	43,012
260,9	44,165	13,03	13,03	883,31	0,43432	43,432	43,03
261,2	43,745	13,038	13,038	874,9	0,4346	43,46	43,038
261,5	43,74	13,057	13,057	874,8	0,43523	43,523	43,057
261,8	43,167	13,077	13,077	863,35	0,43589	43,589	43,077
262,1	41,975	13,085	13,085	839,5	0,43616	43,616	43,085
262,5	41,419	13,102	13,102	828,37	0,43674	43,674	43,102
262,8	40,593	13,123	13,123	811,86	0,43743	43,743	43,123
263,1	39,522	13,131	13,131	790,45	0,43771	43,771	43,131
263,4	39,112	13,15	13,15	782,24	0,43832	43,832	43,15
263,7	38,923	13,171	13,171	778,47	0,43903	43,903	43,171
264	38,122	13,178	13,178	762,44	0,43926	43,926	43,178
264,3	37,841	13,195	13,195	756,82	0,43985	43,985	43,195
264,6	37,347	13,219	13,219	746,94	0,44063	44,063	43,219
264,9	35,859	13,224	13,224	717,18	0,44079	44,079	43,224
265,3	35,186	13,242	13,242	703,72	0,44139	44,139	43,242
265,6	34,383	13,267	13,267	687,67	0,44222	44,222	43,267
265,9	32,758	13,272	13,272	655,16	0,44239	44,239	43,272
266,2	32,1	13,289	13,289	642	0,44297	44,297	43,289
266,5	31,197	13,312	13,312	623,93	0,44375	44,375	43,312
266,8	28,119	13,32	13,32	562,38	0,444	44,4	43,32
267,1	25,122	13,334	13,334	502,44	0,44448	44,448	43,334
267,4	20,735	13,36	13,36	414,7	0,44532	44,532	43,36
267,7	-0,48427	13,367	13,367	-9,6854	0,44557	44,557	43,367
267,8		13,37	13,37		0,44565	44,565	43,37