File: Tests de traction/Fichiers source/04_12_2016/2.txt
Time (s)	Load (N)	Machine Extension (mm)	Extension (mm)	Stress (MPa)	Strain	Percentage Strain	Gauge Length (mm)
0
0,5954	0,0017661	0,0021126	0,0021126	0,035321	0,00007042	0,007042	30,002
1,191	0,49317	0,037519	0,037519	9,8635	0,0012506	0,12506	30,038
1,786	2,2538	0,067016	0,067016	45,076	0,0022339	0,22339	30,067
2,382	4,508	0,094224	0,094224	90,161	0,0031408	0,31408	30,094
2,977	8,0267	0,13195	0,13195	160,53	0,0043983	0,43983	30,132
3,573	10,018	0,15426	0,15426	200,36	0,0051421	0,51421	30,154
4,168	12,536	0,18421	0,18421	250,71	0,0061402	0,61402	30,184
4,764	16,274	0,2308	0,2308	325,49	0,0076934	0,76934	30,231
5,359	17,094	0,24228	0,24228	341,88	0,0080761	0,80761	30,242
5,954	19,587	0,27702	0,27702	391,74	0,0092339	0,92339	30,277
6,55	21,782	0,30493	0,30493	435,63	0,010164	1,0164	30,305
7,145	23,711	0,33424	0,33424	474,23	0,011141	1,1141	30,334
7,741	26,312	0,37128	0,37128	526,25	0,012376	1,2376	30,371
8,336	27,729	0,39514	0,39514	554,59	0,013171	1,3171	30,395
8,932	29,41	0,42359	0,42359	588,21	0,01412	1,412	30,424
9,527	32,214	0,46431	0,46431	644,27	0,015477	1,5477	30,464
10,12	32,87	0,48021	0,48021	657,39	0,016007	1,6007	30,48
10,72	34,892	0,51511	0,51511	697,85	0,01717	1,717	30,515
11,31	36,395	0,54606	0,54606	727,91	0,018202	1,8202	30,546
11,91	37,815	0,57249	0,57249	756,29	0,019083	1,9083	30,572
12,5	39,824	0,60929	0,60929	796,47	0,02031	2,031	30,609
13,1	40,772	0,63148	0,63148	815,44	0,021049	2,1049	30,631
13,7	42,166	0,66279	0,66279	843,33	0,022093	2,2093	30,663
14,29	43,983	0,70228	0,70228	879,67	0,023409	2,3409	30,702
14,89	44,389	0,72093	0,72093	887,78	0,024031	2,4031	30,721
15,48	45,427	0,75266	0,75266	908,54	0,025089	2,5089	30,753
16,08	46,638	0,78282	0,78282	932,77	0,026094	2,6094	30,783
16,67	47,267	0,81019	0,81019	945,34	0,027006	2,7006	30,81
17,27	48,504	0,84887	0,84887	970,08	0,028296	2,8296	30,849
17,86	48,778	0,87055	0,87055	975,56	0,029018	2,9018	30,871
18,46	49,453	0,90189	0,90189	989,06	0,030063	3,0063	30,902
19,05	50,438	0,94024	0,94024	1008,8	0,031341	3,1341	30,94
19,65	50,189	0,95669	0,95669	1003,8	0,03189	3,189	30,957
20,25	50,601	0,99328	0,99328	1012	0,033109	3,3109	30,993
20,84	50,93	1,0208	1,0208	1018,6	0,034027	3,4027	31,021
21,44	50,877	1,0485	1,0485	1017,5	0,034951	3,4951	31,049
22,03	51,64	1,0851	1,0851	1032,8	0,036169	3,6169	31,085
22,63	51,822	1,1085	1,1085	1036,4	0,03695	3,695	31,108
23,22	51,562	1,1375	1,1375	1031,2	0,037918	3,7918	31,138
23,82	52,523	1,1778	1,1778	1050,5	0,039262	3,9262	31,178
24,41	51,894	1,1958	1,1958	1037,9	0,039861	3,9861	31,196
25,01	52,127	1,2305	1,2305	1042,5	0,041016	4,1016	31,23
25,6	52,705	1,2621	1,2621	1054,1	0,042071	4,2071	31,262
26,2	52,456	1,2877	1,2877	1049,1	0,042924	4,2924	31,288
26,79	52,766	1,3227	1,3227	1055,3	0,044089	4,4089	31,323
27,39	52,599	1,3473	1,3473	1052	0,04491	4,491	31,347
27,99	52,495	1,3777	1,3777	1049,9	0,045924	4,5924	31,378
28,58	52,819	1,414	1,414	1056,4	0,047132	4,7132	31,414
29,18	52,243	1,4346	1,4346	1044,9	0,047819	4,7819	31,435
29,77	51,943	1,4679	1,4679	1038,9	0,048931	4,8931	31,468
30,37	51,975	1,4966	1,4966	1039,5	0,049885	4,9885	31,497
30,96	51,055	1,5227	1,5227	1021,1	0,050757	5,0757	31,523
31,56	51,564	1,5627	1,5627	1031,3	0,05209	5,209	31,563
32,15	51,287	1,585	1,585	1025,7	0,052834	5,2834	31,585
32,75	50,701	1,6153	1,6153	1014	0,053842	5,3842	31,615
33,34	51,658	1,6545	1,6545	1033,2	0,055151	5,5151	31,655
33,94	50,844	1,6735	1,6735	1016,9	0,055783	5,5783	31,673
34,54	50,687	1,7042	1,7042	1013,7	0,056808	5,6808	31,704
35,13	51,11	1,7357	1,7357	1022,2	0,057856	5,7856	31,736
35,73	50,72	1,762	1,762	1014,4	0,058732	5,8732	31,762
36,32	51,673	1,8019	1,8019	1033,5	0,060064	6,0064	31,802
36,92	51,342	1,8238	1,8238	1026,8	0,060795	6,0795	31,824
37,51	51,227	1,8529	1,8529	1024,5	0,061763	6,1763	31,853
38,11	51,85	1,8948	1,8948	1037	0,063159	6,3159	31,895
38,7	50,609	1,9101	1,9101	1012,2	0,063669	6,3669	31,91
39,3	50,865	1,9442	1,9442	1017,3	0,064808	6,4808	31,944
39,89	51,162	1,9734	1,9734	1023,2	0,06578	6,578	31,973
40,49	50,987	2,0004	2,0004	1019,7	0,066681	6,6681	32
41,09	51,537	2,0383	2,0383	1030,7	0,067942	6,7942	32,038
41,68	51,409	2,0616	2,0616	1028,2	0,068721	6,8721	32,062
42,28	51,384	2,0885	2,0885	1027,7	0,069617	6,9617	32,089
42,87	52,281	2,1289	2,1289	1045,6	0,070963	7,0963	32,129
43,47	51,652	2,1482	2,1482	1033	0,071606	7,1606	32,148
44,06	52,063	2,1846	2,1846	1041,3	0,07282	7,282	32,185
44,66	52,281	2,2137	2,2137	1045,6	0,073789	7,3789	32,214
45,25	51,881	2,2386	2,2386	1037,6	0,07462	7,462	32,239
45,85	52,434	2,2754	2,2754	1048,7	0,075847	7,5847	32,275
46,44	52,139	2,2999	2,2999	1042,8	0,076664	7,6664	32,3
47,04	51,99	2,3293	2,3293	1039,8	0,077644	7,7644	32,329
47,64	53,006	2,3708	2,3708	1060,1	0,079026	7,9026	32,371
48,23	52,09	2,3882	2,3882	1041,8	0,079606	7,9606	32,388
48,83	52,264	2,4214	2,4214	1045,3	0,080712	8,0712	32,421
49,42	52,381	2,4498	2,4498	1047,6	0,081659	8,1659	32,45
50,02	51,986	2,4762	2,4762	1039,7	0,082541	8,2541	32,476
50,61	52,521	2,5131	2,5131	1050,4	0,083771	8,3771	32,513
51,21	52,297	2,538	2,538	1045,9	0,0846	8,46	32,538
51,8	52,227	2,5694	2,5694	1044,5	0,085646	8,5646	32,569
52,4	52,83	2,6059	2,6059	1056,6	0,086862	8,6862	32,606
52,99	51,958	2,6271	2,6271	1039,2	0,087569	8,7569	32,627
53,59	52,498	2,6621	2,6621	1050	0,088737	8,8737	32,662
54,19	52,42	2,6897	2,6897	1048,4	0,089658	8,9658	32,69
54,78	52,009	2,7134	2,7134	1040,2	0,090447	9,0447	32,713
55,38	52,681	2,7534	2,7534	1053,6	0,09178	9,178	32,753
55,97	52,282	2,776	2,776	1045,6	0,092532	9,2532	32,776
56,57	52,272	2,805	2,805	1045,4	0,093501	9,3501	32,805
57,16	53,193	2,8469	2,8469	1063,9	0,094896	9,4896	32,847
57,76	52,404	2,8638	2,8638	1048,1	0,095459	9,5459	32,864
58,35	52,594	2,8964	2,8964	1051,9	0,096547	9,6547	32,896
58,95	52,899	2,9279	2,9279	1058	0,097596	9,7596	32,928
59,54	52,579	2,953	2,953	1051,6	0,098434	9,8434	32,953
60,14	53,163	2,991	2,991	1063,3	0,099699	9,9699	32,991
60,74	52,813	3,013	3,013	1056,3	0,10043	10,043	33,013
61,33	52,879	3,0446	3,0446	1057,6	0,10149	10,149	33,045
61,93	53,681	3,0825	3,0825	1073,6	0,10275	10,275	33,082
62,52	53,126	3,1015	3,1015	1062,5	0,10338	10,338	33,102
63,12	53,542	3,1369	3,1369	1070,8	0,10456	10,456	33,137
63,71	53,559	3,1646	3,1646	1071,2	0,10549	10,549	33,165
64,31	53,104	3,1912	3,1912	1062,1	0,10637	10,637	33,191
64,9	53,707	3,2298	3,2298	1074,1	0,10766	10,766	33,23
65,5	52,521	3,2521	3,2521	1050,4	0,1084	10,84	33,252
66,09	52,509	3,2826	3,2826	1050,2	0,10942	10,942	33,283
66,69	53,673	3,3245	3,3245	1073,5	0,11082	11,082	33,324
67,28	52,805	3,3394	3,3394	1056,1	0,11131	11,131	33,339
67,88	53,111	3,3732	3,3732	1062,2	0,11244	11,244	33,373
68,48	53,278	3,4022	3,4022	1065,6	0,11341	11,341	33,402
69,07	53,113	3,4285	3,4285	1062,3	0,11428	11,428	33,429
69,67	53,938	3,4678	3,4678	1078,8	0,11559	11,559	33,468
70,26	53,662	3,49	3,49	1073,2	0,11633	11,633	33,49
70,86	53,617	3,5196	3,5196	1072,3	0,11732	11,732	33,52
71,45	54,546	3,5607	3,5607	1090,9	0,11869	11,869	33,561
72,05	53,794	3,5778	3,5778	1075,9	0,11926	11,926	33,578
72,64	54,045	3,6099	3,6099	1080,9	0,12033	12,033	33,61
73,24	54,466	3,6413	3,6413	1089,3	0,12138	12,138	33,641
73,83	54,09	3,6663	3,6663	1081,8	0,12221	12,221	33,666
74,43	54,739	3,7054	3,7054	1094,8	0,12351	12,351	33,705
75,03	54,346	3,7283	3,7283	1086,9	0,12428	12,428	33,728
75,62	54,342	3,7591	3,7591	1086,8	0,1253	12,53	33,759
76,22	55,285	3,7978	3,7978	1105,7	0,12659	12,659	33,798
76,81	54,622	3,8172	3,8172	1092,4	0,12724	12,724	33,817
77,41	54,87	3,8508	3,8508	1097,4	0,12836	12,836	33,851
78	54,92	3,8787	3,8787	1098,4	0,12929	12,929	33,879
78,6	54,632	3,9037	3,9037	1092,6	0,13012	13,012	33,904
79,19	55,357	3,9429	3,9429	1107,1	0,13143	13,143	33,943
79,79	55,065	3,968	3,968	1101,3	0,13227	13,227	33,968
80,38	54,903	3,9959	3,9959	1098,1	0,1332	13,32	33,996
80,98	55,726	4,0357	4,0357	1114,5	0,13452	13,452	34,036
81,58	55,054	4,0545	4,0545	1101,1	0,13515	13,515	34,055
82,17	55,208	4,087	4,087	1104,2	0,13623	13,623	34,087
82,77	55,594	4,117	4,117	1111,9	0,13723	13,723	34,117
83,36	55,218	4,1439	4,1439	1104,4	0,13813	13,813	34,144
83,96	55,692	4,1803	4,1803	1113,8	0,13934	13,934	34,18
84,55	55,538	4,2066	4,2066	1110,8	0,14022	14,022	34,207
85,15	55,371	4,2344	4,2344	1107,4	0,14115	14,115	34,234
85,74	55,958	4,2722	4,2722	1119,2	0,14241	14,241	34,272
86,34	55,353	4,2918	4,2918	1107,1	0,14306	14,306	34,292
86,93	55,723	4,3264	4,3264	1114,5	0,14421	14,421	34,326
87,53	55,783	4,3543	4,3543	1115,7	0,14514	14,514	34,354
88,13	55,445	4,3812	4,3812	1108,9	0,14604	14,604	34,381
88,72	56,191	4,4197	4,4197	1123,8	0,14732	14,732	34,42
89,32	55,992	4,4451	4,4451	1119,8	0,14817	14,817	34,445
89,91	55,778	4,4717	4,4717	1115,6	0,14906	14,906	34,472
90,51	56,477	4,5122	4,5122	1129,5	0,15041	15,041	34,512
91,1	55,861	4,5313	4,5313	1117,2	0,15104	15,104	34,531
91,7	56,041	4,5636	4,5636	1120,8	0,15212	15,212	34,564
92,29	56,394	4,5949	4,5949	1127,9	0,15316	15,316	34,595
92,89	55,911	4,62	4,62	1118,2	0,154	15,4	34,62
93,48	56,46	4,6582	4,6582	1129,2	0,15527	15,527	34,658
94,08	55,908	4,6826	4,6826	1118,2	0,15609	15,609	34,683
94,68	55,961	4,7115	4,7115	1119,2	0,15705	15,705	34,712
95,27	56,601	4,7496	4,7496	1132	0,15832	15,832	34,75
95,87	56,035	4,7706	4,7706	1120,7	0,15902	15,902	34,771
96,46	56,108	4,8021	4,8021	1122,2	0,16007	16,007	34,802
97,06	56,408	4,8335	4,8335	1128,2	0,16112	16,112	34,834
97,65	56,207	4,8596	4,8596	1124,1	0,16199	16,199	34,86
98,25	56,304	4,8967	4,8967	1126,1	0,16322	16,322	34,897
98,84	55,835	4,9193	4,9193	1116,7	0,16398	16,398	34,919
99,44	55,806	4,9497	4,9497	1116,1	0,16499	16,499	34,95
100	56,621	4,9867	4,9867	1132,4	0,16622	16,622	34,987
100,6	55,94	5,0068	5,0068	1118,8	0,16689	16,689	35,007
101,2	56,249	5,0408	5,0408	1125	0,16803	16,803	35,041
101,8	56,628	5,0723	5,0723	1132,6	0,16908	16,908	35,072
102,4	56,303	5,0947	5,0947	1126,1	0,16982	16,982	35,095
103	57,02	5,1349	5,1349	1140,4	0,17116	17,116	35,135
103,6	56,822	5,1597	5,1597	1136,4	0,17199	17,199	35,16
104,2	56,576	5,1863	5,1863	1131,5	0,17288	17,288	35,186
104,8	57,397	5,2253	5,2253	1147,9	0,17418	17,418	35,225
105,4	56,908	5,2473	5,2473	1138,2	0,17491	17,491	35,247
106	57,112	5,2799	5,2799	1142,2	0,176	17,6	35,28
106,6	57,423	5,3086	5,3086	1148,5	0,17695	17,695	35,309
107,2	56,948	5,3354	5,3354	1139	0,17785	17,785	35,335
107,8	57,464	5,3699	5,3699	1149,3	0,179	17,9	35,37
108,4	57,244	5,3969	5,3969	1144,9	0,1799	17,99	35,397
109	56,977	5,4239	5,4239	1139,5	0,1808	18,08	35,424
109,6	58,015	5,466	5,466	1160,3	0,1822	18,22	35,466
110,2	57,235	5,4844	5,4844	1144,7	0,18281	18,281	35,484
110,8	57,438	5,5171	5,5171	1148,8	0,1839	18,39	35,517
111,3	57,714	5,5465	5,5465	1154,3	0,18488	18,488	35,546
111,9	57,45	5,5728	5,5728	1149	0,18576	18,576	35,573
112,5	57,94	5,6103	5,6103	1158,8	0,18701	18,701	35,61
113,1	57,734	5,6356	5,6356	1154,7	0,18785	18,785	35,636
113,7	57,624	5,6638	5,6638	1152,5	0,18879	18,879	35,664
114,3	58,356	5,7053	5,7053	1167,1	0,19018	19,018	35,705
114,9	57,698	5,7228	5,7228	1154	0,19076	19,076	35,723
115,5	57,897	5,7547	5,7547	1157,9	0,19182	19,182	35,755
116,1	58,444	5,7886	5,7886	1168,9	0,19295	19,295	35,789
116,7	57,76	5,809	5,809	1155,2	0,19363	19,363	35,809
117,3	58,243	5,8465	5,8465	1164,9	0,19488	19,488	35,846
117,9	58,013	5,8738	5,8738	1160,3	0,19579	19,579	35,874
118,5	58,038	5,9027	5,9027	1160,8	0,19676	19,676	35,903
119,1	58,522	5,9389	5,9389	1170,4	0,19796	19,796	35,939
119,7	58,064	5,9612	5,9612	1161,3	0,19871	19,871	35,961
120,3	58,221	5,9935	5,9935	1164,4	0,19978	19,978	35,994
120,9	58,539	6,0258	6,0258	1170,8	0,20086	20,086	36,026
121,5	58,233	6,0504	6,0504	1164,7	0,20168	20,168	36,05
122,1	58,59	6,0852	6,0852	1171,8	0,20284	20,284	36,085
122,7	58,456	6,1104	6,1104	1169,1	0,20368	20,368	36,11
123,3	58,248	6,1406	6,1406	1165	0,20469	20,469	36,141
123,9	59,077	6,1812	6,1812	1181,5	0,20604	20,604	36,181
124,4	58,406	6,1983	6,1983	1168,1	0,20661	20,661	36,198
125	58,453	6,2301	6,2301	1169,1	0,20767	20,767	36,23
125,6	58,909	6,2634	6,2634	1178,2	0,20878	20,878	36,263
126,2	58,436	6,2861	6,2861	1168,7	0,20954	20,954	36,286
126,8	59,022	6,3231	6,3231	1180,4	0,21077	21,077	36,323
127,4	58,716	6,3497	6,3497	1174,3	0,21166	21,166	36,35
128	58,516	6,3757	6,3757	1170,3	0,21252	21,252	36,376
128,6	59,425	6,4174	6,4174	1188,5	0,21391	21,391	36,417
129,2	58,719	6,4365	6,4365	1174,4	0,21455	21,455	36,437
129,8	58,97	6,4704	6,4704	1179,4	0,21568	21,568	36,47
130,4	59,069	6,5018	6,5018	1181,4	0,21673	21,673	36,502
131	58,855	6,5231	6,5231	1177,1	0,21744	21,744	36,523
131,6	59,266	6,5632	6,5632	1185,3	0,21877	21,877	36,563
132,2	59,037	6,5876	6,5876	1180,7	0,21959	21,959	36,588
132,8	59,004	6,6168	6,6168	1180,1	0,22056	22,056	36,617
133,4	59,705	6,6563	6,6563	1194,1	0,22188	22,188	36,656
134	58,999	6,6749	6,6749	1180	0,2225	22,25	36,675
134,6	59,102	6,7071	6,7071	1182	0,22357	22,357	36,707
135,2	59,479	6,7394	6,7394	1189,6	0,22465	22,465	36,739
135,8	59,074	6,7618	6,7618	1181,5	0,22539	22,539	36,762
136,4	59,612	6,7993	6,7993	1192,2	0,22664	22,664	36,799
137	59,533	6,8267	6,8267	1190,7	0,22756	22,756	36,827
137,5	59,236	6,8528	6,8528	1184,7	0,22843	22,843	36,853
138,1	60,039	6,8928	6,8928	1200,8	0,22976	22,976	36,893
138,7	59,434	6,9138	6,9138	1188,7	0,23046	23,046	36,914
139,3	59,462	6,9459	6,9459	1189,2	0,23153	23,153	36,946
139,9	59,739	6,9776	6,9776	1194,8	0,23259	23,259	36,978
140,5	59,513	7,0025	7,0025	1190,3	0,23342	23,342	37,003
141,1	59,675	7,0359	7,0359	1193,5	0,23453	23,453	37,036
141,7	59,602	7,063	7,063	1192	0,23543	23,543	37,063
142,3	59,654	7,0937	7,0937	1193,1	0,23646	23,646	37,094
142,9	60,114	7,1305	7,1305	1202,3	0,23768	23,768	37,131
143,5	59,572	7,1532	7,1532	1191,4	0,23844	23,844	37,153
144,1	59,746	7,184	7,184	1194,9	0,23947	23,947	37,184
144,7	59,919	7,2136	7,2136	1198,4	0,24045	24,045	37,214
145,3	59,772	7,2399	7,2399	1195,4	0,24133	24,133	37,24
145,9	59,917	7,2762	7,2762	1198,3	0,24254	24,254	37,276
146,5	60,039	7,3015	7,3015	1200,8	0,24338	24,338	37,302
147,1	59,861	7,33	7,33	1197,2	0,24433	24,433	37,33
147,7	60,474	7,3686	7,3686	1209,5	0,24562	24,562	37,369
148,3	59,995	7,3901	7,3901	1199,9	0,24634	24,634	37,39
148,9	60,133	7,4221	7,4221	1202,7	0,2474	24,74	37,422
149,5	60,373	7,4555	7,4555	1207,5	0,24852	24,852	37,456
150,1	60,026	7,478	7,478	1200,5	0,24927	24,927	37,478
150,6	60,403	7,5151	7,5151	1208,1	0,2505	25,05	37,515
151,2	60,255	7,5406	7,5406	1205,1	0,25135	25,135	37,541
151,8	60,219	7,5696	7,5696	1204,4	0,25232	25,232	37,57
152,4	60,808	7,6076	7,6076	1216,2	0,25359	25,359	37,608
153	60,308	7,6277	7,6277	1206,2	0,25426	25,426	37,628
153,6	60,258	7,6581	7,6581	1205,2	0,25527	25,527	37,658
154,2	60,457	7,6899	7,6899	1209,1	0,25633	25,633	37,69
154,8	60,174	7,7158	7,7158	1203,5	0,25719	25,719	37,716
155,4	60,661	7,753	7,753	1213,2	0,25843	25,843	37,753
156	60,43	7,7787	7,7787	1208,6	0,25929	25,929	37,779
156,6	60,275	7,805	7,805	1205,5	0,26017	26,017	37,805
157,2	61,235	7,8478	7,8478	1224,7	0,26159	26,159	37,848
157,8	60,501	7,8652	7,8652	1210	0,26217	26,217	37,865
158,4	60,6	7,898	7,898	1212	0,26327	26,327	37,898
159	60,918	7,9305	7,9305	1218,4	0,26435	26,435	37,931
159,6	60,471	7,9545	7,9545	1209,4	0,26515	26,515	37,955
160,2	60,979	7,991	7,991	1219,6	0,26637	26,637	37,991
160,8	60,879	8,0177	8,0177	1217,6	0,26726	26,726	38,018
161,4	60,622	8,0447	8,0447	1212,4	0,26816	26,816	38,045
162	61,473	8,0851	8,0851	1229,5	0,2695	26,95	38,085
162,6	60,857	8,1062	8,1062	1217,1	0,27021	27,021	38,106
163,2	60,852	8,1352	8,1352	1217	0,27117	27,117	38,135
163,7	61,027	8,1657	8,1657	1220,5	0,27219	27,219	38,166
164,3	60,798	8,1931	8,1931	1216	0,2731	27,31	38,193
164,9	61,197	8,2292	8,2292	1223,9	0,27431	27,431	38,229
165,5	61,061	8,2556	8,2556	1221,2	0,27519	27,519	38,256
166,1	60,751	8,2807	8,2807	1215	0,27602	27,602	38,281
166,7	61,55	8,3223	8,3223	1231	0,27741	27,741	38,322
167,3	61,01	8,3433	8,3433	1220,2	0,27811	27,811	38,343
167,9	61,141	8,3742	8,3742	1222,8	0,27914	27,914	38,374
168,5	61,307	8,4059	8,4059	1226,1	0,2802	28,02	38,406
169,1	60,836	8,4287	8,4287	1216,7	0,28096	28,096	38,429
169,7	61,443	8,4675	8,4675	1228,9	0,28225	28,225	38,468
170,3	61,102	8,4928	8,4928	1222	0,28309	28,309	38,493
170,9	61,035	8,5193	8,5193	1220,7	0,28398	28,398	38,519
171,5	61,937	8,5628	8,5628	1238,7	0,28543	28,543	38,563
172,1	61,196	8,5802	8,5802	1223,9	0,28601	28,601	38,58
172,7	61,229	8,61	8,61	1224,6	0,287	28,7	38,61
173,3	61,842	8,6475	8,6475	1236,8	0,28825	28,825	38,647
173,9	61,238	8,6688	8,6688	1224,8	0,28896	28,896	38,669
174,5	61,659	8,7046	8,7046	1233,2	0,29015	29,015	38,705
175,1	61,462	8,7307	8,7307	1229,2	0,29102	29,102	38,731
175,7	61,362	8,7595	8,7595	1227,2	0,29198	29,198	38,759
176,3	62,143	8,7998	8,7998	1242,9	0,29333	29,333	38,8
176,8	61,508	8,8193	8,8193	1230,2	0,29398	29,398	38,819
177,4	61,618	8,8494	8,8494	1232,4	0,29498	29,498	38,849
178	61,928	8,8832	8,8832	1238,6	0,29611	29,611	38,883
178,6	61,596	8,9068	8,9068	1231,9	0,29689	29,689	38,907
179,2	62,056	8,9442	8,9442	1241,1	0,29814	29,814	38,944
179,8	61,828	8,9689	8,9689	1236,6	0,29896	29,896	38,969
180,4	61,69	8,9971	8,9971	1233,8	0,2999	29,99	38,997
181	62,393	9,0377	9,0377	1247,9	0,30126	30,126	39,038
181,6	61,819	9,0581	9,0581	1236,4	0,30194	30,194	39,058
182,2	61,91	9,0888	9,0888	1238,2	0,30296	30,296	39,089
182,8	62,201	9,1212	9,1212	1244	0,30404	30,404	39,121
183,4	61,874	9,1448	9,1448	1237,5	0,30483	30,483	39,145
184	62,286	9,1815	9,1815	1245,7	0,30605	30,605	39,182
184,6	62,06	9,2071	9,2071	1241,2	0,3069	30,69	39,207
185,2	61,876	9,2342	9,2342	1237,5	0,30781	30,781	39,234
185,8	62,407	9,2725	9,2725	1248,1	0,30908	30,908	39,272
186,4	62,04	9,2954	9,2954	1240,8	0,30985	30,985	39,295
187	62,122	9,3268	9,3268	1242,4	0,31089	31,089	39,327
187,6	62,624	9,363	9,363	1252,5	0,3121	31,21	39,363
188,2	62,119	9,3847	9,3847	1242,4	0,31282	31,282	39,385
188,8	62,543	9,4204	9,4204	1250,9	0,31401	31,401	39,42
189,4	62,329	9,4456	9,4456	1246,6	0,31485	31,485	39,446
189,9	62,183	9,4738	9,4738	1243,7	0,31579	31,579	39,474
190,5	62,847	9,5133	9,5133	1256,9	0,31711	31,711	39,513
191,1	62,283	9,5342	9,5342	1245,7	0,31781	31,781	39,534
191,7	62,384	9,5651	9,5651	1247,7	0,31884	31,884	39,565
192,3	62,734	9,5966	9,5966	1254,7	0,31989	31,989	39,597
192,9	62,349	9,6196	9,6196	1247	0,32065	32,065	39,62
193,5	62,689	9,6564	9,6564	1253,8	0,32188	32,188	39,656
194,1	62,749	9,6853	9,6853	1255	0,32284	32,284	39,685
194,7	62,494	9,7114	9,7114	1249,9	0,32371	32,371	39,711
195,3	62,987	9,7496	9,7496	1259,7	0,32499	32,499	39,75
195,9	62,462	9,7721	9,7721	1249,2	0,32574	32,574	39,772
196,5	62,647	9,8026	9,8026	1252,9	0,32675	32,675	39,803
197,1	62,955	9,8383	9,8383	1259,1	0,32794	32,794	39,838
197,7	62,54	9,8596	9,8596	1250,8	0,32865	32,865	39,86
198,3	62,909	9,8945	9,8945	1258,2	0,32982	32,982	39,894
198,9	62,754	9,9223	9,9223	1255,1	0,33074	33,074	39,922
199,5	62,465	9,9492	9,9492	1249,3	0,33164	33,164	39,949
200,1	63,199	9,9899	9,9899	1264	0,333	33,3	39,99
200,7	62,675	10,01	10,01	1253,5	0,33365	33,365	40,01
201,3	62,781	10,041	10,041	1255,6	0,33469	33,469	40,041
201,9	63,144	10,074	10,074	1262,9	0,33581	33,581	40,074
202,5	62,834	10,099	10,099	1256,7	0,33662	33,662	40,099
203	63,103	10,133	10,133	1262,1	0,33777	33,777	40,133
203,6	63,064	10,16	10,16	1261,3	0,33867	33,867	40,16
204,2	62,909	10,188	10,188	1258,2	0,3396	33,96	40,188
204,8	63,47	10,226	10,226	1269,4	0,34086	34,086	40,226
205,4	63,231	10,25	10,25	1264,6	0,34167	34,167	40,25
206	63,142	10,279	10,279	1262,8	0,34263	34,263	40,279
206,6	63,514	10,313	10,313	1270,3	0,34377	34,377	40,313
207,2	62,961	10,335	10,335	1259,2	0,34451	34,451	40,335
207,8	63,508	10,372	10,372	1270,2	0,34573	34,573	40,372
208,4	63,369	10,4	10,4	1267,4	0,34667	34,667	40,4
209	63,187	10,427	10,427	1263,7	0,34756	34,756	40,427
209,6	63,742	10,466	10,466	1274,8	0,34886	34,886	40,466
210,2	63,144	10,486	10,486	1262,9	0,34954	34,954	40,486
210,8	63,142	10,517	10,517	1262,8	0,35055	35,055	40,517
211,4	63,451	10,55	10,55	1269	0,35168	35,168	40,55
212	63,015	10,574	10,574	1260,3	0,35248	35,248	40,574
212,6	63,594	10,61	10,61	1271,9	0,35367	35,367	40,61
213,2	63,384	10,637	10,637	1267,7	0,35456	35,456	40,637
213,8	63,191	10,663	10,663	1263,8	0,35543	35,543	40,663
214,4	63,794	10,702	10,702	1275,9	0,35673	35,673	40,702
215	63,489	10,724	10,724	1269,8	0,35748	35,748	40,724
215,6	63,406	10,755	10,755	1268,1	0,35851	35,851	40,755
216,1	63,846	10,79	10,79	1276,9	0,35968	35,968	40,79
216,7	63,319	10,811	10,811	1266,4	0,36038	36,038	40,811
217,3	63,906	10,85	10,85	1278,1	0,36167	36,167	40,85
217,9	63,674	10,875	10,875	1273,5	0,36249	36,249	40,875
218,5	63,54	10,902	10,902	1270,8	0,36342	36,342	40,902
219,1	64,286	10,944	10,944	1285,7	0,36478	36,478	40,944
219,7	63,591	10,964	10,964	1271,8	0,36546	36,546	40,964
220,3	63,579	10,993	10,993	1271,6	0,36643	36,643	40,993
220,9	64,115	11,031	11,031	1282,3	0,36768	36,768	41,031
221,5	63,526	11,05	11,05	1270,5	0,36834	36,834	41,05
222,1	63,862	11,085	11,085	1277,2	0,36951	36,951	41,085
222,7	63,834	11,114	11,114	1276,7	0,37045	37,045	41,114
223,3	63,678	11,14	11,14	1273,6	0,37134	37,134	41,14
223,9	64,322	11,18	11,18	1286,4	0,37267	37,267	41,18
224,5	63,774	11,2	11,2	1275,5	0,37333	37,333	41,2
225,1	64,031	11,235	11,235	1280,6	0,37449	37,449	41,235
225,7	64,223	11,267	11,267	1284,5	0,37557	37,557	41,267
226,3	63,715	11,288	11,288	1274,3	0,37627	37,627	41,288
226,9	64,259	11,325	11,325	1285,2	0,37751	37,751	41,325
227,5	64,182	11,352	11,352	1283,6	0,37839	37,839	41,352
228,1	63,985	11,379	11,379	1279,7	0,37931	37,931	41,379
228,6	64,639	11,419	11,419	1292,8	0,38063	38,063	41,419
229,2	64,251	11,441	11,441	1285	0,38136	38,136	41,441
229,8	64,06	11,468	11,468	1281,2	0,38226	38,226	41,468
230,4	64,727	11,507	11,507	1294,5	0,38356	38,356	41,507
231	64,055	11,527	11,527	1281,1	0,38423	38,423	41,527
231,6	64,32	11,56	11,56	1286,4	0,38533	38,533	41,56
232,2	64,351	11,588	11,588	1287	0,38628	38,628	41,588
232,8	64,147	11,617	11,617	1282,9	0,38722	38,722	41,617
233,4	64,638	11,654	11,654	1292,8	0,38847	38,847	41,654
234	64,233	11,679	11,679	1284,7	0,38928	38,928	41,679
234,6	64,34	11,709	11,709	1286,8	0,39029	39,029	41,709
235,2	64,742	11,743	11,743	1294,8	0,39145	39,145	41,743
235,8	64,19	11,767	11,767	1283,8	0,39223	39,223	41,767
236,4	64,709	11,802	11,802	1294,2	0,3934	39,34	41,802
237	64,43	11,828	11,828	1288,6	0,39426	39,426	41,828
237,6	64,508	11,855	11,855	1290,2	0,39517	39,517	41,855
238,2	65,358	11,898	11,898	1307,2	0,39659	39,659	41,898
238,8	64,826	11,916	11,916	1296,5	0,3972	39,72	41,916
239,4	64,828	11,947	11,947	1296,6	0,39824	39,824	41,947
240	65,024	11,981	11,981	1300,5	0,39937	39,937	41,981
240,6	64,718	12,003	12,003	1294,4	0,4001	40,01	42,003
241,2	64,935	12,038	12,038	1298,7	0,40128	40,128	42,038
241,7	64,851	12,065	12,065	1297	0,40216	40,216	42,065
242,3	64,769	12,094	12,094	1295,4	0,40313	40,313	42,094
242,9	65,313	12,132	12,132	1306,3	0,4044	40,44	42,132
243,5	64,818	12,153	12,153	1296,4	0,4051	40,51	42,153
244,1	64,934	12,185	12,185	1298,7	0,40616	40,616	42,185
244,7	65,213	12,219	12,219	1304,3	0,40729	40,729	42,219
245,3	64,751	12,24	12,24	1295	0,40802	40,802	42,24
245,9	65,109	12,276	12,276	1302,2	0,40919	40,919	42,276
246,5	65,131	12,305	12,305	1302,6	0,41017	41,017	42,305
247,1	64,948	12,331	12,331	1299	0,41102	41,102	42,331
247,7	65,697	12,372	12,372	1313,9	0,4124	41,24	42,372
248,3	65,145	12,392	12,392	1302,9	0,41307	41,307	42,392
248,9	65,222	12,423	12,423	1304,4	0,41411	41,411	42,423
249,5	65,365	12,454	12,454	1307,3	0,41515	41,515	42,454
250,1	65,09	12,478	12,478	1301,8	0,41593	41,593	42,478
250,7	65,54	12,515	12,515	1310,8	0,41717	41,717	42,515
251,3	65,442	12,542	12,542	1308,8	0,41808	41,808	42,542
251,9	65,265	12,57	12,57	1305,3	0,41899	41,899	42,57
252,5	65,721	12,607	12,607	1314,4	0,42023	42,023	42,607
253,1	65,359	12,631	12,631	1307,2	0,42102	42,102	42,631
253,7	65,243	12,659	12,659	1304,9	0,42198	42,198	42,659
254,3	65,806	12,699	12,699	1316,1	0,42329	42,329	42,699
254,8	65,178	12,717	12,717	1303,6	0,4239	42,39	42,717
255,4	65,68	12,755	12,755	1313,6	0,42516	42,516	42,755
256	65,575	12,782	12,782	1311,5	0,42605	42,605	42,782
256,6	65,362	12,808	12,808	1307,2	0,42692	42,692	42,808
257,2	66,01	12,847	12,847	1320,2	0,42825	42,825	42,847
257,8	65,472	12,868	12,868	1309,4	0,42893	42,893	42,868
258,4	65,523	12,898	12,898	1310,5	0,42994	42,994	42,898
259	65,995	12,934	12,934	1319,9	0,43113	43,113	42,934
259,6	65,622	12,956	12,956	1312,4	0,43186	43,186	42,956
260,2	65,85	12,991	12,991	1317	0,43305	43,305	42,991
260,8	65,831	13,019	13,019	1316,6	0,43395	43,395	43,019
261,4	65,564	13,043	13,043	1311,3	0,43477	43,477	43,043
262	66,273	13,085	13,085	1325,5	0,43615	43,615	43,085
262,6	65,827	13,106	13,106	1316,5	0,43685	43,685	43,106
263,2	65,85	13,136	13,136	1317	0,43787	43,787	43,136
263,8	66,473	13,176	13,176	1329,5	0,43921	43,921	43,176
264,4	65,747	13,193	13,193	1314,9	0,43978	43,978	43,193
265	66,038	13,229	13,229	1320,8	0,44095	44,095	43,229
265,6	66,093	13,258	13,258	1321,9	0,44194	44,194	43,258
266,2	65,926	13,286	13,286	1318,5	0,44286	44,286	43,286
266,8	66,488	13,324	13,324	1329,8	0,44412	44,412	43,324
267,4	65,98	13,345	13,345	1319,6	0,44482	44,482	43,345
267,9	66,007	13,375	13,375	1320,1	0,44585	44,585	43,375
268,5	66,419	13,41	13,41	1328,4	0,44701	44,701	43,41
269,1	65,858	13,432	13,432	1317,2	0,44774	44,774	43,432
269,7	66,217	13,468	13,468	1324,3	0,44893	44,893	43,468
270,3	66,052	13,495	13,495	1321	0,44982	44,982	43,495
270,9	65,91	13,523	13,523	1318,2	0,45076	45,076	43,523
271,5	66,634	13,562	13,562	1332,7	0,45206	45,206	43,562
272,1	66,174	13,582	13,582	1323,5	0,45274	45,274	43,582
272,7	66,157	13,612	13,612	1323,1	0,45375	45,375	43,612
273,3	66,73	13,651	13,651	1334,6	0,45502	45,502	43,651
273,9	66,171	13,672	13,672	1323,4	0,45572	45,572	43,672
274,5	66,519	13,705	13,705	1330,4	0,45684	45,684	43,705
275,1	66,5	13,732	13,732	1330	0,45774	45,774	43,732
275,7	66,182	13,759	13,759	1323,6	0,45863	45,863	43,759
276,3	66,807	13,799	13,799	1336,1	0,45996	45,996	43,799
276,9	66,539	13,822	13,822	1330,8	0,46074	46,074	43,822
277,5	66,438	13,852	13,852	1328,8	0,46173	46,173	43,852
278,1	66,893	13,888	13,888	1337,9	0,46294	46,294	43,888
278,7	66,277	13,908	13,908	1325,5	0,4636	46,36	43,908
279,3	66,482	13,942	13,942	1329,6	0,46472	46,472	43,942
279,9	66,465	13,972	13,972	1329,3	0,46572	46,572	43,972
280,5	66,384	14,001	14,001	1327,7	0,46669	46,669	44,001
281	66,926	14,037	14,037	1338,5	0,46789	46,789	44,037
281,6	66,605	14,059	14,059	1332,1	0,46864	46,864	44,059
282,2	66,642	14,089	14,089	1332,8	0,46963	46,963	44,089
282,8	67,125	14,126	14,126	1342,5	0,47087	47,087	44,126
283,4	66,5	14,145	14,145	1330	0,47151	47,151	44,145
284	66,955	14,183	14,183	1339,1	0,47275	47,275	44,183
284,6	66,844	14,21	14,21	1336,9	0,47366	47,366	44,21
285,2	66,663	14,236	14,236	1333,3	0,47452	47,452	44,236
285,8	67,282	14,277	14,277	1345,6	0,47588	47,588	44,277
286,4	66,824	14,299	14,299	1336,5	0,47663	47,663	44,299
287	66,842	14,327	14,327	1336,8	0,47758	47,758	44,327
287,6	67,444	14,366	14,366	1348,9	0,47887	47,887	44,366
288,2	66,729	14,387	14,387	1334,6	0,47956	47,956	44,387
288,8	67,036	14,419	14,419	1340,7	0,48065	48,065	44,419
289,4	67,057	14,449	14,449	1341,1	0,48163	48,163	44,449
290	66,879	14,476	14,476	1337,6	0,48254	48,254	44,476
290,6	67,31	14,513	14,513	1346,2	0,48375	48,375	44,513
291,2	67,045	14,537	14,537	1340,9	0,48456	48,456	44,537
291,8	67,032	14,567	14,567	1340,6	0,48556	48,556	44,567
292,4	67,406	14,601	14,601	1348,1	0,4867	48,67	44,601
293	67,02	14,622	14,622	1340,4	0,48739	48,739	44,622
293,6	67,405	14,66	14,66	1348,1	0,48866	48,866	44,66
294,1	67,262	14,686	14,686	1345,2	0,48955	48,955	44,686
294,7	67,117	14,713	14,713	1342,3	0,49044	49,044	44,713
295,3	67,872	14,755	14,755	1357,4	0,49183	49,183	44,755
295,9	67,333	14,775	14,775	1346,7	0,4925	49,25	44,775
296,5	67,437	14,806	14,806	1348,7	0,49354	49,354	44,806
297,1	68,029	14,843	14,843	1360,6	0,49478	49,478	44,843
297,7	67,342	14,86	14,86	1346,8	0,49535	49,535	44,86
298,3	67,669	14,896	14,896	1353,4	0,49654	49,654	44,896
298,9	67,582	14,923	14,923	1351,6	0,49744	49,744	44,923
299,5	67,374	14,951	14,951	1347,5	0,49836	49,836	44,951
300,1	67,901	14,988	14,988	1358	0,49959	49,959	44,988
300,7	67,537	15,013	15,013	1350,7	0,50043	50,043	45,013
301,3	67,56	15,042	15,042	1351,2	0,50141	50,141	45,042
301,9	68,037	15,079	15,079	1360,7	0,50265	50,265	45,079
302,5	67,575	15,099	15,099	1351,5	0,50331	50,331	45,099
303,1	67,882	15,134	15,134	1357,6	0,50448	50,448	45,134
303,7	67,965	15,164	15,164	1359,3	0,50546	50,546	45,164
304,3	67,781	15,189	15,189	1355,6	0,5063	50,63	45,189
304,9	68,32	15,229	15,229	1366,4	0,50763	50,763	45,229
305,5	67,811	15,25	15,25	1356,2	0,50833	50,833	45,25
306,1	67,888	15,281	15,281	1357,8	0,50938	50,938	45,281
306,7	68,246	15,315	15,315	1364,9	0,51052	51,052	45,315
307,2	67,818	15,338	15,338	1356,4	0,51128	51,128	45,338
307,8	68,185	15,374	15,374	1363,7	0,51246	51,246	45,374
308,4	68,164	15,399	15,399	1363,3	0,51331	51,331	45,399
309	67,986	15,428	15,428	1359,7	0,51428	51,428	45,428
309,6	68,455	15,465	15,465	1369,1	0,51551	51,551	45,465
310,2	68,044	15,489	15,489	1360,9	0,5163	51,63	45,489
310,8	68,031	15,518	15,518	1360,6	0,51726	51,726	45,518
311,4	68,459	15,554	15,554	1369,2	0,51847	51,847	45,554
312	67,959	15,575	15,575	1359,2	0,51917	51,917	45,575
312,6	68,305	15,61	15,61	1366,1	0,52034	52,034	45,61
313,2	68,362	15,641	15,641	1367,2	0,52136	52,136	45,641
313,8	68,114	15,665	15,665	1362,3	0,52218	52,218	45,665
314,4	68,657	15,704	15,704	1373,1	0,52347	52,347	45,704
315	68,26	15,726	15,726	1365,2	0,52421	52,421	45,726
315,6	68,261	15,756	15,756	1365,2	0,5252	52,52	45,756
316,2	68,751	15,793	15,793	1375	0,52644	52,644	45,793
316,8	68,292	15,815	15,815	1365,8	0,52717	52,717	45,815
317,4	68,548	15,85	15,85	1371	0,52832	52,832	45,85
318	68,605	15,877	15,877	1372,1	0,52923	52,923	45,877
318,6	68,365	15,904	15,904	1367,3	0,53012	53,012	45,904
319,2	68,8	15,942	15,942	1376	0,5314	53,14	45,942
319,8	68,55	15,966	15,966	1371	0,53219	53,219	45,966
320,3	68,418	15,994	15,994	1368,4	0,53312	53,312	45,994
320,9	68,929	16,031	16,031	1378,6	0,53438	53,438	46,031
321,5	68,434	16,052	16,052	1368,7	0,53507	53,507	46,052
322,1	68,587	16,085	16,085	1371,7	0,53616	53,616	46,085
322,7	68,827	16,115	16,115	1376,5	0,53718	53,718	46,115
323,3	68,569	16,141	16,141	1371,4	0,53804	53,804	46,141
323,9	68,911	16,179	16,179	1378,2	0,53931	53,931	46,179
324,5	68,674	16,202	16,202	1373,5	0,54008	54,008	46,202
325,1	68,561	16,233	16,233	1371,2	0,54111	54,111	46,233
325,7	68,941	16,269	16,269	1378,8	0,54229	54,229	46,269
326,3	68,44	16,291	16,291	1368,8	0,54302	54,302	46,291
326,9	68,779	16,326	16,326	1375,6	0,54419	54,419	46,326
327,5	68,821	16,355	16,355	1376,4	0,54515	54,515	46,355
328,1	68,609	16,381	16,381	1372,2	0,54603	54,603	46,381
328,7	69,036	16,418	16,418	1380,7	0,54727	54,727	46,418
329,3	68,688	16,44	16,44	1373,8	0,54801	54,801	46,44
329,9	68,674	16,47	16,47	1373,5	0,54899	54,899	46,47
330,5	69,226	16,509	16,509	1384,5	0,5503	55,03	46,509
331,1	68,86	16,53	16,53	1377,2	0,55099	55,099	46,53
331,7	69,151	16,564	16,564	1383	0,55212	55,212	46,564
332,3	69,116	16,594	16,594	1382,3	0,55312	55,312	46,594
332,9	68,858	16,617	16,617	1377,2	0,5539	55,39	46,617
333,4	69,457	16,656	16,656	1389,1	0,55519	55,519	46,656
334	69,117	16,68	16,68	1382,3	0,55598	55,598	46,68
334,6	69,118	16,709	16,709	1382,4	0,55698	55,698	46,709
335,2	69,785	16,75	16,75	1395,7	0,55833	55,833	46,75
335,8	69,05	16,768	16,768	1381	0,55893	55,893	46,768
336,4	69,204	16,799	16,799	1384,1	0,55997	55,997	46,799
337	69,35	16,831	16,831	1387	0,56102	56,102	46,831
337,6	69,08	16,855	16,855	1381,6	0,56182	56,182	46,855
338,2	69,616	16,894	16,894	1392,3	0,56312	56,312	46,894
338,8	69,218	16,917	16,917	1384,4	0,56391	56,391	46,917
339,4	69,279	16,947	16,947	1385,6	0,56488	56,488	46,947
340	69,827	16,985	16,985	1396,5	0,56618	56,618	46,985
340,6	69,187	17,004	17,004	1383,7	0,5668	56,68	47,004
341,2	69,603	17,041	17,041	1392,1	0,56802	56,802	47,041
341,8	69,521	17,071	17,071	1390,4	0,56902	56,902	47,071
342,4	69,349	17,093	17,093	1387	0,56977	56,977	47,093
343	70,05	17,135	17,135	1401	0,57115	57,115	47,135
343,6	69,592	17,157	17,157	1391,8	0,5719	57,19	47,157
344,2	69,545	17,186	17,186	1390,9	0,57286	57,286	47,186
344,8	70,193	17,227	17,227	1403,9	0,57423	57,423	47,227
345,4	69,558	17,244	17,244	1391,2	0,57479	57,479	47,244
346	69,759	17,278	17,278	1395,2	0,57593	57,593	47,278
346,5	69,812	17,307	17,307	1396,2	0,57689	57,689	47,307
347,1	69,548	17,332	17,332	1391	0,57773	57,773	47,332
347,7	69,938	17,368	17,368	1398,8	0,57894	57,894	47,368
348,3	69,724	17,394	17,394	1394,5	0,57978	57,978	47,394
348,9	69,74	17,424	17,424	1394,8	0,5808	58,08	47,424
349,5	70,094	17,46	17,46	1401,9	0,58199	58,199	47,46
350,1	69,671	17,482	17,482	1393,4	0,58272	58,272	47,482
350,7	70,005	17,517	17,517	1400,1	0,58391	58,391	47,517
351,3	69,978	17,545	17,545	1399,6	0,58484	58,484	47,545
351,9	69,832	17,571	17,571	1396,6	0,5857	58,57	47,571
352,5	70,491	17,611	17,611	1409,8	0,58704	58,704	47,611
353,1	70,045	17,633	17,633	1400,9	0,58778	58,778	47,633
353,7	69,995	17,661	17,661	1399,9	0,58871	58,871	47,661
354,3	70,734	17,702	17,702	1414,7	0,59008	59,008	47,702
354,9	70,047	17,72	17,72	1400,9	0,59066	59,066	47,72
355,5	70,258	17,753	17,753	1405,2	0,59178	59,178	47,753
356,1	70,185	17,781	17,781	1403,7	0,59269	59,269	47,781
356,7	69,953	17,806	17,806	1399,1	0,59355	59,355	47,806
357,3	70,595	17,845	17,845	1411,9	0,59485	59,485	47,845
357,9	70,371	17,87	17,87	1407,4	0,59567	59,567	47,87
358,5	70,459	17,902	17,902	1409,2	0,59674	59,674	47,902
359,1	70,862	17,939	17,939	1417,2	0,59798	59,798	47,939
359,6	70,26	17,958	17,958	1405,2	0,59862	59,862	47,958
360,2	70,497	17,992	17,992	1409,9	0,59973	59,973	47,992
360,8	70,518	18,021	18,021	1410,4	0,60071	60,071	48,021
361,4	70,359	18,048	18,048	1407,2	0,60161	60,161	48,048
362	70,938	18,087	18,087	1418,8	0,6029	60,29	48,087
362,6	70,481	18,109	18,109	1409,6	0,60365	60,365	48,109
363,2	70,545	18,138	18,138	1410,9	0,60458	60,458	48,138
363,8	71,159	18,178	18,178	1423,2	0,60592	60,592	48,178
364,4	70,572	18,197	18,197	1411,4	0,60655	60,655	48,197
365	70,672	18,228	18,228	1413,4	0,6076	60,76	48,228
365,6	70,975	18,261	18,261	1419,5	0,6087	60,87	48,261
366,2	70,715	18,285	18,285	1414,3	0,60952	60,952	48,285
366,8	71,037	18,321	18,321	1420,7	0,6107	61,07	48,321
367,4	70,882	18,347	18,347	1417,6	0,61158	61,158	48,347
368	70,864	18,375	18,375	1417,3	0,61251	61,251	48,375
368,6	71,461	18,415	18,415	1429,2	0,61385	61,385	48,415
369,2	70,902	18,436	18,436	1418	0,61452	61,452	48,436
369,8	71,041	18,469	18,469	1420,8	0,61562	61,562	48,469
370,4	71,161	18,496	18,496	1423,2	0,61652	61,652	48,496
371	70,934	18,525	18,525	1418,7	0,61751	61,751	48,525
371,6	71,234	18,56	18,56	1424,7	0,61867	61,867	48,56
372,2	71,133	18,586	18,586	1422,7	0,61955	61,955	48,586
372,7	71,066	18,615	18,615	1421,3	0,6205	62,05	48,615
373,3	71,638	18,653	18,653	1432,8	0,62178	62,178	48,653
373,9	71,055	18,673	18,673	1421,1	0,62242	62,242	48,673
374,5	71,385	18,708	18,708	1427,7	0,62361	62,361	48,708
375,1	71,401	18,737	18,737	1428	0,62456	62,456	48,737
375,7	71,106	18,761	18,761	1422,1	0,62536	62,536	48,761
376,3	71,549	18,799	18,799	1431	0,62662	62,662	48,799
376,9	71,296	18,823	18,823	1425,9	0,62743	62,743	48,823
377,5	71,249	18,852	18,852	1425	0,62841	62,841	48,852
378,1	71,879	18,892	18,892	1437,6	0,62972	62,972	48,892
378,7	71,255	18,91	18,91	1425,1	0,63034	63,034	48,91
379,3	71,536	18,944	18,944	1430,7	0,63148	63,148	48,944
379,9	71,664	18,976	18,976	1433,3	0,63252	63,252	48,976
380,5	71,175	19,001	19,001	1423,5	0,63337	63,337	49,001
381,1	71,607	19,036	19,036	1432,1	0,63454	63,454	49,036
381,7	71,463	19,061	19,061	1429,3	0,63537	63,537	49,061
382,3	71,419	19,091	19,091	1428,4	0,63637	63,637	49,091
382,9	71,972	19,13	19,13	1439,4	0,63766	63,766	49,13
383,5	71,328	19,148	19,148	1426,6	0,63826	63,826	49,148
384,1	71,556	19,182	19,182	1431,1	0,63939	63,939	49,182
384,7	71,68	19,212	19,212	1433,6	0,6404	64,04	49,212
385,3	71,445	19,238	19,238	1428,9	0,64126	64,126	49,238
385,8	71,937	19,276	19,276	1438,7	0,64252	64,252	49,276
386,4	71,742	19,301	19,301	1434,8	0,64336	64,336	49,301
387	71,761	19,33	19,33	1435,2	0,64434	64,434	49,33
387,6	72,26	19,368	19,368	1445,2	0,6456	64,56	49,368
388,2	71,748	19,388	19,388	1435	0,64626	64,626	49,388
388,8	72,06	19,422	19,422	1441,2	0,64741	64,741	49,422
389,4	72,004	19,451	19,451	1440,1	0,64838	64,838	49,451
390	71,741	19,476	19,476	1434,8	0,64921	64,921	49,476
390,6	72,181	19,513	19,513	1443,6	0,65044	65,044	49,513
391,2	71,907	19,538	19,538	1438,1	0,65128	65,128	49,538
391,8	71,947	19,568	19,568	1438,9	0,65228	65,228	49,568
392,4	72,468	19,606	19,606	1449,4	0,65352	65,352	49,606
393	71,878	19,625	19,625	1437,6	0,65416	65,416	49,625
393,6	72,138	19,66	19,66	1442,8	0,65532	65,532	49,66
394,2	72,072	19,687	19,687	1441,4	0,65622	65,622	49,687
394,8	72,007	19,715	19,715	1440,1	0,65717	65,717	49,715
395,4	72,324	19,752	19,752	1446,5	0,65839	65,839	49,752
396	72,157	19,776	19,776	1443,1	0,6592	65,92	49,776
396,6	72,044	19,806	19,806	1440,9	0,66019	66,019	49,806
397,2	72,596	19,843	19,843	1451,9	0,66142	66,142	49,843
397,8	72,126	19,863	19,863	1442,5	0,6621	66,21	49,863
398,4	72,438	19,898	19,898	1448,8	0,66327	66,327	49,898
398,9	72,57	19,929	19,929	1451,4	0,66429	66,429	49,929
399,5	72,297	19,953	19,953	1445,9	0,6651	66,51	49,953
400,1	72,677	19,992	19,992	1453,5	0,6664	66,64	49,992
400,7	72,475	20,016	20,016	1449,5	0,66719	66,719	50,016
401,3	72,445	20,044	20,044	1448,9	0,66812	66,812	50,044
401,9	73,124	20,083	20,083	1462,5	0,66944	66,944	50,083
402,5	72,651	20,103	20,103	1453	0,67011	67,011	50,103
403,1	72,655	20,135	20,135	1453,1	0,67118	67,118	50,135
403,7	72,785	20,166	20,166	1455,7	0,67221	67,221	50,166
404,3	72,501	20,19	20,19	1450	0,673	67,3	50,19
404,9	72,905	20,228	20,228	1458,1	0,67426	67,426	50,228
405,5	72,667	20,252	20,252	1453,3	0,67506	67,506	50,252
406,1	72,579	20,282	20,282	1451,6	0,67607	67,607	50,282
406,7	73,014	20,319	20,319	1460,3	0,6773	67,73	50,319
407,3	72,602	20,341	20,341	1452	0,67804	67,804	50,341
407,9	72,799	20,373	20,373	1456	0,6791	67,91	50,373
408,5	72,945	20,404	20,404	1458,9	0,68014	68,014	50,404
409,1	72,706	20,428	20,428	1454,1	0,68093	68,093	50,428
409,7	73,227	20,467	20,467	1464,5	0,68224	68,224	50,467
410,3	72,926	20,492	20,492	1458,5	0,68307	68,307	50,492
410,9	72,857	20,52	20,52	1457,1	0,684	68,4	50,52
411,5	73,657	20,562	20,562	1473,1	0,6854	68,54	50,562
412	72,904	20,578	20,578	1458,1	0,68594	68,594	50,578
412,6	73,046	20,611	20,611	1460,9	0,68703	68,703	50,611
413,2	73,268	20,645	20,645	1465,4	0,68817	68,817	50,645
413,8	72,849	20,666	20,666	1457	0,68887	68,887	50,666
414,4	73,334	20,704	20,704	1466,7	0,69012	69,012	50,704
415	73,176	20,729	20,729	1463,5	0,69098	69,098	50,729
415,6	73,094	20,758	20,758	1461,9	0,69193	69,193	50,758
416,2	73,57	20,795	20,795	1471,4	0,69317	69,317	50,795
416,8	72,977	20,818	20,818	1459,5	0,69395	69,395	50,818
417,4	73,213	20,849	20,849	1464,3	0,69498	69,498	50,849
418	73,369	20,881	20,881	1467,4	0,69603	69,603	50,881
418,6	73,064	20,905	20,905	1461,3	0,69683	69,683	50,905
419,2	73,664	20,943	20,943	1473,3	0,69812	69,812	50,943
419,8	73,386	20,968	20,968	1467,7	0,69893	69,893	50,968
420,4	73,259	20,996	20,996	1465,2	0,69986	69,986	50,996
421	74,061	21,037	21,037	1481,2	0,70124	70,124	51,037
421,6	73,389	21,055	21,055	1467,8	0,70183	70,183	51,055
422,2	73,581	21,088	21,088	1471,6	0,70293	70,293	51,088
422,8	73,554	21,116	21,116	1471,1	0,70388	70,388	51,116
423,4	73,419	21,143	21,143	1468,4	0,70475	70,475	51,143
424	73,831	21,18	21,18	1476,6	0,70599	70,599	51,18
424,6	73,615	21,205	21,205	1472,3	0,70683	70,683	51,205
425,1	73,576	21,235	21,235	1471,5	0,70785	70,785	51,235
425,7	74,188	21,274	21,274	1483,8	0,70915	70,915	51,274
426,3	73,676	21,292	21,292	1473,5	0,70974	70,974	51,292
426,9	73,699	21,327	21,327	1474	0,71089	71,089	51,327
427,5	73,874	21,357	21,357	1477,5	0,71189	71,189	51,357
428,1	73,504	21,381	21,381	1470,1	0,7127	71,27	51,381
428,7	74,038	21,42	21,42	1480,8	0,714	71,4	51,42
429,3	73,719	21,445	21,445	1474,4	0,71482	71,482	51,445
429,9	73,606	21,473	21,473	1472,1	0,71577	71,577	51,473
430,5	74,204	21,511	21,511	1484,1	0,71704	71,704	51,511
431,1	73,705	21,531	21,531	1474,1	0,71771	71,771	51,531
431,7	73,932	21,564	21,564	1478,6	0,71882	71,882	51,564
432,3	74,216	21,597	21,597	1484,3	0,71989	71,989	51,597
432,9	73,832	21,62	21,62	1476,6	0,72067	72,067	51,62
433,5	74,21	21,655	21,655	1484,2	0,72184	72,184	51,655
434,1	74,096	21,682	21,682	1481,9	0,72272	72,272	51,682
434,7	73,887	21,709	21,709	1477,7	0,72365	72,365	51,709
435,3	74,544	21,749	21,749	1490,9	0,72498	72,498	51,749
435,9	73,956	21,768	21,768	1479,1	0,72561	72,561	51,768
436,5	74,121	21,801	21,801	1482,4	0,72671	72,671	51,801
437,1	74,406	21,833	21,833	1488,1	0,72776	72,776	51,833
437,6	74,072	21,859	21,859	1481,4	0,72864	72,864	51,859
438,2	74,475	21,896	21,896	1489,5	0,72986	72,986	51,896
438,8	74,223	21,92	21,92	1484,5	0,73068	73,068	51,92
439,4	74,149	21,948	21,948	1483	0,73161	73,161	51,948
440	74,771	21,989	21,989	1495,4	0,73295	73,295	51,989
440,6	73,963	22,007	22,007	1479,3	0,73356	73,356	52,007
441,2	74,055	22,04	22,04	1481,1	0,73467	73,467	52,04
441,8	74,125	22,07	22,07	1482,5	0,73566	73,566	52,07
442,4	73,934	22,096	22,096	1478,7	0,73653	73,653	52,096
443	74,251	22,132	22,132	1485	0,73774	73,774	52,132
443,6	74,118	22,157	22,157	1482,4	0,73858	73,858	52,157
444,2	74,083	22,186	22,186	1481,7	0,73955	73,955	52,186
444,8	74,782	22,228	22,228	1495,6	0,74094	74,094	52,228
445,4	74,167	22,247	22,247	1483,3	0,74156	74,156	52,247
446	74,397	22,279	22,279	1487,9	0,74264	74,264	52,279
446,6	74,601	22,311	22,311	1492	0,74371	74,371	52,311
447,2	74,267	22,334	22,334	1485,3	0,74448	74,448	52,334
447,8	74,789	22,372	22,372	1495,8	0,74574	74,574	52,372
448,4	74,581	22,397	22,397	1491,6	0,74657	74,657	52,397
449	74,67	22,427	22,427	1493,4	0,74757	74,757	52,427
449,6	75,207	22,465	22,465	1504,1	0,74885	74,885	52,465
450,2	74,53	22,483	22,483	1490,6	0,74944	74,944	52,483
450,7	74,658	22,516	22,516	1493,2	0,75053	75,053	52,516
451,3	74,934	22,546	22,546	1498,7	0,75155	75,155	52,546
451,9	74,698	22,573	22,573	1494	0,75244	75,244	52,573
452,5	75,225	22,61	22,61	1504,5	0,75366	75,366	52,61
453,1	75,146	22,637	22,637	1502,9	0,75455	75,455	52,637
453,7	75,173	22,665	22,665	1503,5	0,75551	75,551	52,665
454,3	75,72	22,704	22,704	1514,4	0,7568	75,68	52,704
454,9	75,099	22,722	22,722	1502	0,75739	75,739	52,722
455,5	75,295	22,755	22,755	1505,9	0,7585	75,85	52,755
456,1	75,563	22,788	22,788	1511,3	0,75959	75,959	52,788
456,7	75,169	22,81	22,81	1503,4	0,76032	76,032	52,81
457,3	75,708	22,848	22,848	1514,2	0,76161	76,161	52,848
457,9	75,5	22,874	22,874	1510	0,76246	76,246	52,874
458,5	75,321	22,901	22,901	1506,4	0,76336	76,336	52,901
459,1	76,116	22,943	22,943	1522,3	0,76478	76,478	52,943
459,7	75,391	22,961	22,961	1507,8	0,76536	76,536	52,961
460,3	75,503	22,994	22,994	1510,1	0,76647	76,647	52,994
460,9	75,645	23,025	23,025	1512,9	0,7675	76,75	53,025
461,5	75,259	23,049	23,049	1505,2	0,7683	76,83	53,049
462,1	75,697	23,085	23,085	1513,9	0,76951	76,951	53,085
462,7	75,544	23,111	23,111	1510,9	0,77036	77,036	53,111
463,3	75,47	23,14	23,14	1509,4	0,77134	77,134	53,14
463,8	76,144	23,18	23,18	1522,9	0,77267	77,267	53,18
464,4	75,48	23,197	23,197	1509,6	0,77324	77,324	53,197
465	75,647	23,231	23,231	1512,9	0,77438	77,438	53,231
465,6	75,804	23,26	23,26	1516,1	0,77533	77,533	53,26
466,2	75,587	23,287	23,287	1511,7	0,77624	77,624	53,287
466,8	76,065	23,324	23,324	1521,3	0,77748	77,748	53,324
467,4	75,825	23,35	23,35	1516,5	0,77832	77,832	53,35
468	75,843	23,378	23,378	1516,9	0,77928	77,928	53,378
468,6	76,535	23,419	23,419	1530,7	0,78064	78,064	53,419
469,2	75,916	23,438	23,438	1518,3	0,78128	78,128	53,438
469,8	75,92	23,468	23,468	1518,4	0,78228	78,228	53,468
470,4	76,206	23,502	23,502	1524,1	0,7834	78,34	53,502
471	75,854	23,525	23,525	1517,1	0,78417	78,417	53,525
471,6	76,241	23,561	23,561	1524,8	0,78537	78,537	53,561
472,2	76,051	23,587	23,587	1521	0,78623	78,623	53,587
472,8	75,895	23,614	23,614	1517,9	0,78715	78,715	53,614
473,4	76,589	23,655	23,655	1531,8	0,78851	78,851	53,655
474	76,15	23,676	23,676	1523	0,78921	78,921	53,676
474,6	76,314	23,71	23,71	1526,3	0,79033	79,033	53,71
475,2	76,221	23,738	23,738	1524,4	0,79128	79,128	53,738
475,8	76,048	23,765	23,765	1521	0,79217	79,217	53,765
476,4	76,53	23,802	23,802	1530,6	0,7934	79,34	53,802
476,9	76,159	23,826	23,826	1523,2	0,79419	79,419	53,826
477,5	76,18	23,854	23,854	1523,6	0,79514	79,514	53,854
478,1	76,893	23,895	23,895	1537,9	0,79652	79,652	53,895
478,7	76,239	23,913	23,913	1524,8	0,79712	79,712	53,913
479,3	76,432	23,947	23,947	1528,6	0,79822	79,822	53,947
479,9	76,626	23,976	23,976	1532,5	0,79919	79,919	53,976
480,5	76,247	24,001	24,001	1524,9	0,80003	80,003	54,001
481,1	76,656	24,038	24,038	1533,1	0,80125	80,125	54,038
481,7	76,442	24,063	24,063	1528,8	0,8021	80,21	54,063
482,3	76,415	24,092	24,092	1528,3	0,80307	80,307	54,092
482,9	76,991	24,13	24,13	1539,8	0,80433	80,433	54,13
483,5	76,498	24,152	24,152	1530	0,80508	80,508	54,152
484,1	76,539	24,183	24,183	1530,8	0,80609	80,609	54,183
484,7	76,736	24,215	24,215	1534,7	0,80717	80,717	54,215
485,3	76,337	24,238	24,238	1526,7	0,80795	80,795	54,238
485,9	76,783	24,276	24,276	1535,7	0,8092	80,92	54,276
486,5	76,706	24,303	24,303	1534,1	0,81009	81,009	54,303
487,1	76,602	24,33	24,33	1532	0,81102	81,102	54,33
487,7	77,238	24,369	24,369	1544,8	0,8123	81,23	54,369
488,3	76,722	24,391	24,391	1534,4	0,81304	81,304	54,391
488,9	76,87	24,422	24,422	1537,4	0,81407	81,407	54,422
489,5	77,097	24,454	24,454	1541,9	0,81515	81,515	54,454
490	76,742	24,478	24,478	1534,8	0,81593	81,593	54,478
490,6	77,174	24,515	24,515	1543,5	0,81716	81,716	54,515
491,2	76,924	24,539	24,539	1538,5	0,81796	81,796	54,539
491,8	76,76	24,567	24,567	1535,2	0,81888	81,888	54,567
492,4	77,528	24,608	24,608	1550,6	0,82026	82,026	54,608
493	76,995	24,627	24,627	1539,9	0,82089	82,089	54,627
493,6	77,109	24,659	24,659	1542,2	0,82195	82,195	54,659
494,2	77,455	24,695	24,695	1549,1	0,82316	82,316	54,695
494,8	77,016	24,715	24,715	1540,3	0,82384	82,384	54,715
495,4	77,427	24,753	24,753	1548,5	0,82509	82,509	54,753
496	77,351	24,78	24,78	1547	0,82601	82,601	54,78
496,6	77,254	24,808	24,808	1545,1	0,82692	82,692	54,808
497,2	77,75	24,846	24,846	1555	0,82821	82,821	54,846
497,8	77,268	24,866	24,866	1545,4	0,82887	82,887	54,866
498,4	77,358	24,898	24,898	1547,2	0,82992	82,992	54,898
499	77,446	24,926	24,926	1548,9	0,83088	83,088	54,926
499,6	77,167	24,952	24,952	1543,3	0,83174	83,174	54,952
500,2	77,735	24,991	24,991	1554,7	0,83304	83,304	54,991
500,8	77,477	25,016	25,016	1549,5	0,83385	83,385	55,016
501,4	77,474	25,045	25,045	1549,5	0,83482	83,482	55,045
502	77,869	25,081	25,081	1557,4	0,83605	83,605	55,081
502,6	77,618	25,105	25,105	1552,4	0,83682	83,682	55,105
503,1	77,616	25,134	25,134	1552,3	0,8378	83,78	55,134
503,7	77,938	25,169	25,169	1558,8	0,83898	83,898	55,169
504,3	77,514	25,191	25,191	1550,3	0,83971	83,971	55,191
504,9	77,874	25,228	25,228	1557,5	0,84094	84,094	55,228
505,5	77,83	25,256	25,256	1556,6	0,84186	84,186	55,256
506,1	77,703	25,282	25,282	1554,1	0,84272	84,272	55,282
506,7	78,232	25,321	25,321	1564,6	0,84403	84,403	55,321
507,3	77,945	25,345	25,345	1558,9	0,84483	84,483	55,345
507,9	77,895	25,374	25,374	1557,9	0,8458	84,58	55,374
508,5	77,967	25,405	25,405	1559,3	0,84683	84,683	55,405
509,1	77,763	25,431	25,431	1555,3	0,84771	84,771	55,431
509,7	78,17	25,468	25,468	1563,4	0,84894	84,894	55,468
510,3	77,82	25,492	25,492	1556,4	0,84972	84,972	55,492
510,9	77,868	25,522	25,522	1557,4	0,85073	85,073	55,522
511,5	78,409	25,56	25,56	1568,2	0,85199	85,199	55,56
512,1	77,879	25,579	25,579	1557,6	0,85265	85,265	55,579
512,7	78,094	25,612	25,612	1561,9	0,85375	85,375	55,612
513,3	78,247	25,645	25,645	1564,9	0,85483	85,483	55,645
513,4		25,659	25,659		0,85531	85,531	55,659