File: Tests de traction/Fichiers source/04_12_2016/3.txt
Time (s)	Load (N)	Machine Extension (mm)	Extension (mm)	Stress (MPa)	Strain	Percentage Strain	Gauge Length (mm)
0
0,4599	0,0027915	0,00010712	0,00010712	0,05583	3,5707E-06	0,00035707	30
0,9199	1,2248	0,031383	0,031383	24,497	0,0010461	0,10461	30,031
1,38	2,4348	0,046606	0,046606	48,697	0,0015535	0,15535	30,047
1,84	5,036	0,072324	0,072324	100,72	0,0024108	0,24108	30,072
2,3	7,1781	0,092147	0,092147	143,56	0,0030716	0,30716	30,092
2,76	10,887	0,12194	0,12194	217,75	0,0040647	0,40647	30,122
3,22	12,365	0,13766	0,13766	247,29	0,0045887	0,45887	30,138
3,68	15,684	0,16819	0,16819	313,68	0,0056064	0,56064	30,168
4,139	17,348	0,18327	0,18327	346,95	0,0061089	0,61089	30,183
4,599	20,38	0,21598	0,21598	407,6	0,0071995	0,71995	30,216
5,059	21,61	0,22899	0,22899	432,2	0,0076331	0,76331	30,229
5,519	24,638	0,26283	0,26283	492,77	0,0087611	0,87611	30,263
5,979	25,699	0,27649	0,27649	513,98	0,0092163	0,92163	30,276
6,439	28,589	0,31049	0,31049	571,79	0,01035	1,035	30,31
6,899	29,323	0,32246	0,32246	586,46	0,010749	1,0749	30,322
7,359	32,128	0,35813	0,35813	642,56	0,011938	1,1938	30,358
7,819	33,039	0,36965	0,36965	660,78	0,012322	1,2322	30,37
8,279	35,224	0,39772	0,39772	704,49	0,013257	1,3257	30,398
8,739	36,253	0,41478	0,41478	725,05	0,013826	1,3826	30,415
9,199	37,889	0,44212	0,44212	757,77	0,014737	1,4737	30,442
9,659	39,311	0,46197	0,46197	786,22	0,015399	1,5399	30,462
10,12	41,131	0,48797	0,48797	822,62	0,016266	1,6266	30,488
10,58	41,853	0,50659	0,50659	837,05	0,016886	1,6886	30,507
11,04	43,946	0,53361	0,53361	878,92	0,017787	1,7787	30,534
11,5	44,957	0,55527	0,55527	899,13	0,018509	1,8509	30,555
11,96	46,07	0,57737	0,57737	921,4	0,019246	1,9246	30,577
12,42	47,307	0,60104	0,60104	946,14	0,020035	2,0035	30,601
12,88	48,565	0,62293	0,62293	971,31	0,020764	2,0764	30,623
13,34	49,523	0,64614	0,64614	990,45	0,021538	2,1538	30,646
13,8	50,828	0,66842	0,66842	1016,6	0,022281	2,2281	30,668
14,26	51,479	0,69183	0,69183	1029,6	0,023061	2,3061	30,692
14,72	52,64	0,71541	0,71541	1052,8	0,023847	2,3847	30,715
15,18	53,468	0,73922	0,73922	1069,4	0,024641	2,4641	30,739
15,64	54,399	0,76019	0,76019	1088	0,02534	2,534	30,76
16,1	55,344	0,78894	0,78894	1106,9	0,026298	2,6298	30,789
16,56	55,627	0,80421	0,80421	1112,5	0,026807	2,6807	30,804
17,02	56,46	0,8342	0,8342	1129,2	0,027807	2,7807	30,834
17,48	56,901	0,85372	0,85372	1138	0,028457	2,8457	30,854
17,94	57,77	0,88307	0,88307	1155,4	0,029436	2,9436	30,883
18,4	57,613	0,89574	0,89574	1152,3	0,029858	2,9858	30,896
18,86	58,733	0,92928	0,92928	1174,7	0,030976	3,0976	30,929
19,32	58,795	0,9433	0,9433	1175,9	0,031443	3,1443	30,943
19,78	59,778	0,97566	0,97566	1195,6	0,032522	3,2522	30,976
20,24	59,504	0,9902	0,9902	1190,1	0,033007	3,3007	30,99
20,7	60,39	1,022	1,022	1207,8	0,034068	3,4068	31,022
21,16	59,775	1,0345	1,0345	1195,5	0,034484	3,4484	31,035
21,62	60,697	1,0662	1,0662	1213,9	0,035541	3,5541	31,066
22,08	60,044	1,0821	1,0821	1200,9	0,036071	3,6071	31,082
22,54	60,581	1,1122	1,1122	1211,6	0,037072	3,7072	31,112
23	60,019	1,1274	1,1274	1200,4	0,03758	3,758	31,127
23,46	60,29	1,1552	1,1552	1205,8	0,038507	3,8507	31,155
23,92	59,553	1,174	1,174	1191,1	0,039134	3,9134	31,174
24,38	60,2	1,1991	1,1991	1204	0,039969	3,9969	31,199
24,84	59,525	1,2187	1,2187	1190,5	0,040624	4,0624	31,219
25,3	60,199	1,2444	1,2444	1204	0,041478	4,1478	31,244
25,76	59,571	1,2667	1,2667	1191,4	0,042223	4,2223	31,267
26,22	60,122	1,2911	1,2911	1202,4	0,043038	4,3038	31,291
26,68	59,432	1,3133	1,3133	1188,6	0,043778	4,3778	31,313
27,14	59,786	1,3346	1,3346	1195,7	0,044488	4,4488	31,335
27,6	59,095	1,3586	1,3586	1181,9	0,045286	4,5286	31,359
28,06	59,13	1,3812	1,3812	1182,6	0,046042	4,6042	31,381
28,52	59,621	1,4085	1,4085	1192,4	0,046951	4,6951	31,409
28,98	59,765	1,4278	1,4278	1195,3	0,047593	4,7593	31,428
29,44	59,64	1,4566	1,4566	1192,8	0,048554	4,8554	31,457
29,9	59,11	1,4718	1,4718	1182,2	0,049058	4,9058	31,472
30,36	59,826	1,5019	1,5019	1196,5	0,050064	5,0064	31,502
30,82	59,355	1,5166	1,5166	1187,1	0,050552	5,0552	31,517
31,28	60,496	1,5502	1,5502	1209,9	0,051672	5,1672	31,55
31,74	59,694	1,5633	1,5633	1193,9	0,052109	5,2109	31,563
32,2	60,851	1,5985	1,5985	1217	0,053282	5,3282	31,598
32,66	58,567	1,608	1,608	1171,3	0,053599	5,3599	31,608
33,12	59,814	1,6453	1,6453	1196,3	0,054844	5,4844	31,645
33,58	58,487	1,6541	1,6541	1169,7	0,055135	5,5135	31,654
34,04	59,947	1,6902	1,6902	1198,9	0,056339	5,6339	31,69
34,5	59,073	1,7011	1,7011	1181,5	0,056702	5,6702	31,701
34,96	60,636	1,7374	1,7374	1212,7	0,057913	5,7913	31,737
35,42	59,161	1,7454	1,7454	1183,2	0,058181	5,8181	31,745
35,88	60,556	1,7773	1,7773	1211,1	0,059243	5,9243	31,777
36,34	59,659	1,7956	1,7956	1193,2	0,059855	5,9855	31,796
36,8	59,943	1,8221	1,8221	1198,9	0,060737	6,0737	31,822
37,26	59,297	1,8408	1,8408	1185,9	0,061362	6,1362	31,841
37,72	60,016	1,8679	1,8679	1200,3	0,062263	6,2263	31,868
38,18	59,604	1,8887	1,8887	1192,1	0,062957	6,2957	31,889
38,64	59,873	1,9108	1,9108	1197,5	0,063695	6,3695	31,911
39,1	59,657	1,933	1,933	1193,1	0,064433	6,4433	31,933
39,56	60,188	1,9569	1,9569	1203,8	0,065231	6,5231	31,957
40,02	60,141	1,9808	1,9808	1202,8	0,066025	6,6025	31,981
40,47	60,207	2,0029	2,0029	1204,1	0,066763	6,6763	32,003
40,93	60,317	2,0289	2,0289	1206,3	0,067631	6,7631	32,029
41,39	60,139	2,0476	2,0476	1202,8	0,068255	6,8255	32,048
41,85	60,228	2,075	2,075	1204,6	0,069165	6,9165	32,075
42,31	59,724	2,092	2,092	1194,5	0,069732	6,9732	32,092
42,77	60,152	2,1225	2,1225	1203	0,070752	7,0752	32,123
43,23	59,685	2,1389	2,1389	1193,7	0,071296	7,1296	32,139
43,69	60,04	2,168	2,168	1200,8	0,072265	7,2265	32,168
44,15	59,216	2,1836	2,1836	1184,3	0,072785	7,2785	32,184
44,61	60,06	2,2166	2,2166	1201,2	0,073888	7,3888	32,217
45,07	58,988	2,2316	2,2316	1179,8	0,074386	7,4386	32,232
45,53	59,944	2,2624	2,2624	1198,9	0,075412	7,5412	32,262
45,99	58,911	2,2746	2,2746	1178,2	0,07582	7,582	32,275
46,45	60,205	2,3109	2,3109	1204,1	0,07703	7,703	32,311
46,91	58,828	2,321	2,321	1176,6	0,077366	7,7366	32,321
47,37	60,024	2,356	2,356	1200,5	0,078532	7,8532	32,356
47,83	58,687	2,3688	2,3688	1173,7	0,078961	7,8961	32,369
48,29	59,936	2,4034	2,4034	1198,7	0,080115	8,0115	32,403
48,75	58,693	2,4155	2,4155	1173,9	0,080518	8,0518	32,416
49,21	59,455	2,4415	2,4415	1189,1	0,081382	8,1382	32,441
49,67	59,014	2,4639	2,4639	1180,3	0,08213	8,213	32,464
50,13	59,276	2,4862	2,4862	1185,5	0,082872	8,2872	32,486
50,59	58,796	2,5086	2,5086	1175,9	0,083621	8,3621	32,509
51,05	59,461	2,5343	2,5343	1189,2	0,084478	8,4478	32,534
51,51	58,896	2,554	2,554	1177,9	0,085133	8,5133	32,554
51,97	59,428	2,5788	2,5788	1188,6	0,085959	8,5959	32,579
52,43	59,07	2,6004	2,6004	1181,4	0,08668	8,668	32,6
52,89	59,446	2,6225	2,6225	1188,9	0,087418	8,7418	32,623
53,35	59,61	2,6489	2,6489	1192,2	0,088297	8,8297	32,649
53,81	59,702	2,6703	2,6703	1194	0,089009	8,9009	32,67
54,27	59,992	2,6964	2,6964	1199,8	0,089881	8,9881	32,696
54,73	60,085	2,7166	2,7166	1201,7	0,090553	9,0553	32,717
55,19	60,342	2,7427	2,7427	1206,8	0,091423	9,1423	32,743
55,65	60,272	2,7604	2,7604	1205,4	0,092015	9,2015	32,76
56,11	60,756	2,7886	2,7886	1215,1	0,092954	9,2954	32,789
56,57	60,436	2,8064	2,8064	1208,7	0,093546	9,3546	32,806
57,03	61,032	2,8363	2,8363	1220,6	0,094544	9,4544	32,836
57,49	60,84	2,8537	2,8537	1216,8	0,095122	9,5122	32,854
57,95	61,399	2,884	2,884	1228	0,096133	9,6133	32,884
58,41	60,667	2,897	2,897	1213,3	0,096566	9,6566	32,897
58,87	61,574	2,9296	2,9296	1231,5	0,097655	9,7655	32,93
59,33	60,508	2,942	2,942	1210,2	0,098067	9,8067	32,942
59,79	61,729	2,9761	2,9761	1234,6	0,099204	9,9204	32,976
60,25	60,883	2,9897	2,9897	1217,7	0,099658	9,9658	32,99
60,71	61,904	3,0217	3,0217	1238,1	0,10072	10,072	33,022
61,17	61,069	3,0364	3,0364	1221,4	0,10121	10,121	33,036
61,63	62,183	3,0682	3,0682	1243,7	0,10227	10,227	33,068
62,09	61,213	3,0831	3,0831	1224,3	0,10277	10,277	33,083
62,55	62,101	3,1129	3,1129	1242	0,10376	10,376	33,113
63,01	61,405	3,1277	3,1277	1228,1	0,10426	10,426	33,128
63,47	61,783	3,1545	3,1545	1235,7	0,10515	10,515	33,155
63,93	61,443	3,1757	3,1757	1228,9	0,10586	10,586	33,176
64,39	61,973	3,1995	3,1995	1239,5	0,10665	10,665	33,199
64,85	61,681	3,223	3,223	1233,6	0,10743	10,743	33,223
65,31	61,86	3,2441	3,2441	1237,2	0,10814	10,814	33,244
65,77	61,608	3,2676	3,2676	1232,2	0,10892	10,892	33,268
66,23	61,976	3,2915	3,2915	1239,5	0,10972	10,972	33,291
66,69	61,864	3,3147	3,3147	1237,3	0,11049	11,049	33,315
67,15	62,191	3,3375	3,3375	1243,8	0,11125	11,125	33,338
67,61	62,065	3,361	3,361	1241,3	0,11203	11,203	33,361
68,07	62,172	3,3827	3,3827	1243,4	0,11276	11,276	33,383
68,53	62,288	3,4087	3,4087	1245,8	0,11362	11,362	33,409
68,99	62,359	3,4291	3,4291	1247,2	0,1143	11,43	33,429
69,45	62,418	3,456	3,456	1248,4	0,1152	11,52	33,456
69,91	62,133	3,4749	3,4749	1242,7	0,11583	11,583	33,475
70,37	62,585	3,5024	3,5024	1251,7	0,11675	11,675	33,502
70,83	62,106	3,5179	3,5179	1242,1	0,11726	11,726	33,518
71,29	63,013	3,5511	3,5511	1260,3	0,11837	11,837	33,551
71,75	62,197	3,5639	3,5639	1243,9	0,1188	11,88	33,564
72,21	62,603	3,5949	3,5949	1252,1	0,11983	11,983	33,595
72,67	61,914	3,6105	3,6105	1238,3	0,12035	12,035	33,611
73,13	63,154	3,6432	3,6432	1263,1	0,12144	12,144	33,643
73,59	62,297	3,6565	3,6565	1245,9	0,12188	12,188	33,656
74,05	63,128	3,6899	3,6899	1262,6	0,123	12,3	33,69
74,51	62,384	3,7033	3,7033	1247,7	0,12344	12,344	33,703
74,97	63,126	3,7349	3,7349	1262,5	0,1245	12,45	33,735
75,43	62,36	3,7495	3,7495	1247,2	0,12498	12,498	33,75
75,89	62,836	3,7767	3,7767	1256,7	0,12589	12,589	33,777
76,35	62,149	3,7944	3,7944	1243	0,12648	12,648	33,794
76,81	62,073	3,8213	3,8213	1241,5	0,12738	12,738	33,821
77,27	61,377	3,8422	3,8422	1227,5	0,12807	12,807	33,842
77,73	61,887	3,867	3,867	1237,7	0,1289	12,89	33,867
78,19	61,708	3,8897	3,8897	1234,2	0,12966	12,966	33,89
78,65	62,138	3,9125	3,9125	1242,8	0,13042	13,042	33,913
79,11	61,839	3,9346	3,9346	1236,8	0,13115	13,115	33,935
79,57	62,299	3,9591	3,9591	1246	0,13197	13,197	33,959
80,03	62,094	3,981	3,981	1241,9	0,1327	13,27	33,981
80,49	62,483	4,0038	4,0038	1249,7	0,13346	13,346	34,004
80,95	62,513	4,0276	4,0276	1250,3	0,13425	13,425	34,028
81,41	62,592	4,0501	4,0501	1251,8	0,135	13,5	34,05
81,87	62,681	4,0732	4,0732	1253,6	0,13577	13,577	34,073
82,33	62,908	4,0947	4,0947	1258,2	0,13649	13,649	34,095
82,79	62,894	4,1187	4,1187	1257,9	0,13729	13,729	34,119
83,25	63,112	4,1434	4,1434	1262,2	0,13811	13,811	34,143
83,71	63,23	4,1685	4,1685	1264,6	0,13895	13,895	34,168
84,17	62,982	4,1861	4,1861	1259,6	0,13954	13,954	34,186
84,63	63,491	4,2167	4,2167	1269,8	0,14056	14,056	34,217
85,09	62,903	4,231	4,231	1258,1	0,14103	14,103	34,231
85,55	63,612	4,2622	4,2622	1272,2	0,14207	14,207	34,262
86,01	62,952	4,2764	4,2764	1259	0,14255	14,255	34,276
86,47	63,802	4,3093	4,3093	1276	0,14364	14,364	34,309
86,93	62,899	4,3227	4,3227	1258	0,14409	14,409	34,323
87,39	64	4,3557	4,3557	1280	0,14519	14,519	34,356
87,85	63,341	4,3697	4,3697	1266,8	0,14566	14,566	34,37
88,31	64,14	4,4023	4,4023	1282,8	0,14674	14,674	34,402
88,77	63,15	4,4157	4,4157	1263	0,14719	14,719	34,416
89,23	63,822	4,446	4,446	1276,4	0,1482	14,82	34,446
89,69	63,257	4,4644	4,4644	1265,1	0,14881	14,881	34,464
90,15	63,806	4,4905	4,4905	1276,1	0,14968	14,968	34,49
90,61	63,232	4,5099	4,5099	1264,6	0,15033	15,033	34,51
91,07	63,48	4,5347	4,5347	1269,6	0,15116	15,116	34,535
91,53	62,982	4,5546	4,5546	1259,6	0,15182	15,182	34,555
91,99	63,066	4,5794	4,5794	1261,3	0,15265	15,265	34,579
92,45	62,612	4,6006	4,6006	1252,2	0,15335	15,335	34,601
92,91	62,881	4,6248	4,6248	1257,6	0,15416	15,416	34,625
93,37	62,66	4,6468	4,6468	1253,2	0,15489	15,489	34,647
93,83	62,806	4,6713	4,6713	1256,1	0,15571	15,571	34,671
94,29	62,827	4,6948	4,6948	1256,5	0,15649	15,649	34,695
94,75	63,156	4,7184	4,7184	1263,1	0,15728	15,728	34,718
95,21	63,099	4,7416	4,7416	1262	0,15805	15,805	34,742
95,67	63,176	4,762	4,762	1263,5	0,15873	15,873	34,762
96,13	63,454	4,789	4,789	1269,1	0,15963	15,963	34,789
96,59	63,245	4,807	4,807	1264,9	0,16023	16,023	34,807
97,05	63,745	4,836	4,836	1274,9	0,1612	16,12	34,836
97,51	63,619	4,8526	4,8526	1272,4	0,16175	16,175	34,853
97,97	64,295	4,8864	4,8864	1285,9	0,16288	16,288	34,886
98,43	63,357	4,8975	4,8975	1267,1	0,16325	16,325	34,898
98,89	64,329	4,93	4,93	1286,6	0,16433	16,433	34,93
99,35	63,253	4,9436	4,9436	1265,1	0,16479	16,479	34,944
99,81	64,492	4,9786	4,9786	1289,8	0,16595	16,595	34,979
100,3	63,471	4,9887	4,9887	1269,4	0,16629	16,629	34,989
100,7	64,588	5,0242	5,0242	1291,8	0,16747	16,747	35,024
101,2	63,53	5,0339	5,0339	1270,6	0,1678	16,78	35,034
101,6	64,765	5,0712	5,0712	1295,3	0,16904	16,904	35,071
102,1	63,668	5,0817	5,0817	1273,4	0,16939	16,939	35,082
102,6	64,417	5,112	5,112	1288,3	0,1704	17,04	35,112
103	63,767	5,1283	5,1283	1275,3	0,17094	17,094	35,128
103,5	64,615	5,1586	5,1586	1292,3	0,17195	17,195	35,159
103,9	63,738	5,1725	5,1725	1274,8	0,17242	17,242	35,172
104,4	64,447	5,2021	5,2021	1288,9	0,1734	17,34	35,202
104,9	63,921	5,2207	5,2207	1278,4	0,17402	17,402	35,221
105,3	64,306	5,2461	5,2461	1286,1	0,17487	17,487	35,246
105,8	64,153	5,2682	5,2682	1283,1	0,17561	17,561	35,268
106,2	64,45	5,2934	5,2934	1289	0,17645	17,645	35,293
106,7	64,26	5,3151	5,3151	1285,2	0,17717	17,717	35,315
107,2	64,466	5,3389	5,3389	1289,3	0,17796	17,796	35,339
107,6	64,09	5,3591	5,3591	1281,8	0,17864	17,864	35,359
108,1	64,311	5,3843	5,3843	1286,2	0,17948	17,948	35,384
108,5	64,39	5,4071	5,4071	1287,8	0,18024	18,024	35,407
109	64,25	5,4308	5,4308	1285	0,18103	18,103	35,431
109,5	63,809	5,4573	5,4573	1276,2	0,18191	18,191	35,457
109,9	63,322	5,4744	5,4744	1266,4	0,18248	18,248	35,474
110,4	63,527	5,5024	5,5024	1270,5	0,18341	18,341	35,502
110,8	63,136	5,52	5,52	1262,7	0,184	18,4	35,52
111,3	63,873	5,5502	5,5502	1277,5	0,18501	18,501	35,55
111,8	63,27	5,5663	5,5663	1265,4	0,18554	18,554	35,566
112,2	64,036	5,5955	5,5955	1280,7	0,18652	18,652	35,595
112,7	63,356	5,6099	5,6099	1267,1	0,187	18,7	35,61
113,1	64,596	5,6463	5,6463	1291,9	0,18821	18,821	35,646
113,6	63,625	5,655	5,655	1272,5	0,1885	18,85	35,655
114,1	64,586	5,6918	5,6918	1291,7	0,18973	18,973	35,692
114,5	63,9	5,7023	5,7023	1278	0,19008	19,008	35,702
115	65,196	5,7407	5,7407	1303,9	0,19136	19,136	35,741
115,4	63,923	5,7473	5,7473	1278,5	0,19158	19,158	35,747
115,9	64,996	5,7834	5,7834	1299,9	0,19278	19,278	35,783
116,4	64,349	5,796	5,796	1287	0,1932	19,32	35,796
116,8	65,07	5,8263	5,8263	1301,4	0,19421	19,421	35,826
117,3	64,391	5,8411	5,8411	1287,8	0,1947	19,47	35,841
117,7	64,884	5,8704	5,8704	1297,7	0,19568	19,568	35,87
118,2	64,521	5,889	5,889	1290,4	0,1963	19,63	35,889
118,7	65,002	5,9155	5,9155	1300	0,19718	19,718	35,915
119,1	64,585	5,9345	5,9345	1291,7	0,19782	19,782	35,935
119,6	65,055	5,9613	5,9613	1301,1	0,19871	19,871	35,961
120	64,946	5,9836	5,9836	1298,9	0,19945	19,945	35,984
120,5	64,975	6,0056	6,0056	1299,5	0,20019	20,019	36,006
121	64,869	6,0283	6,0283	1297,4	0,20094	20,094	36,028
121,4	65,104	6,0509	6,0509	1302,1	0,2017	20,17	36,051
121,9	65,21	6,0756	6,0756	1304,2	0,20252	20,252	36,076
122,3	64,971	6,0944	6,0944	1299,4	0,20315	20,315	36,094
122,8	65,243	6,1231	6,1231	1304,9	0,2041	20,41	36,123
123,3	65,246	6,1435	6,1435	1304,9	0,20478	20,478	36,144
123,7	65,642	6,1721	6,1721	1312,8	0,20574	20,574	36,172
124,2	64,985	6,1865	6,1865	1299,7	0,20622	20,622	36,187
124,6	65,691	6,2181	6,2181	1313,8	0,20727	20,727	36,218
125,1	65,073	6,2314	6,2314	1301,5	0,20771	20,771	36,231
125,6	65,772	6,2625	6,2625	1315,4	0,20875	20,875	36,262
126	65,231	6,2789	6,2789	1304,6	0,2093	20,93	36,279
126,5	66,17	6,3124	6,3124	1323,4	0,21041	21,041	36,312
126,9	65,239	6,3234	6,3234	1304,8	0,21078	21,078	36,323
127,4	66,123	6,3573	6,3573	1322,5	0,21191	21,191	36,357
127,9	65,165	6,3695	6,3695	1303,3	0,21232	21,232	36,37
128,3	66,166	6,4031	6,4031	1323,3	0,21344	21,344	36,403
128,8	65,266	6,4167	6,4167	1305,3	0,21389	21,389	36,417
129,2	65,853	6,4459	6,4459	1317,1	0,21486	21,486	36,446
129,7	65,213	6,4617	6,4617	1304,3	0,21539	21,539	36,462
130,2	66,143	6,4943	6,4943	1322,9	0,21648	21,648	36,494
130,6	65,307	6,5091	6,5091	1306,1	0,21697	21,697	36,509
131,1	66,016	6,537	6,537	1320,3	0,2179	21,79	36,537
131,5	65,527	6,5553	6,5553	1310,5	0,21851	21,851	36,555
132	65,757	6,5799	6,5799	1315,1	0,21933	21,933	36,58
132,5	65,612	6,6021	6,6021	1312,2	0,22007	22,007	36,602
132,9	65,941	6,6282	6,6282	1318,8	0,22094	22,094	36,628
133,4	65,778	6,6506	6,6506	1315,6	0,22169	22,169	36,651
133,8	65,949	6,6715	6,6715	1319	0,22238	22,238	36,671
134,3	65,874	6,6964	6,6964	1317,5	0,22321	22,321	36,696
134,8	65,751	6,7161	6,7161	1315	0,22387	22,387	36,716
135,2	65,884	6,7416	6,7416	1317,7	0,22472	22,472	36,742
135,7	65,919	6,7625	6,7625	1318,4	0,22542	22,542	36,763
136,1	66,134	6,7895	6,7895	1322,7	0,22632	22,632	36,79
136,6	65,984	6,8093	6,8093	1319,7	0,22698	22,698	36,809
137,1	66,332	6,8367	6,8367	1326,6	0,22789	22,789	36,837
137,5	65,929	6,854	6,854	1318,6	0,22847	22,847	36,854
138	66,327	6,8821	6,8821	1326,5	0,2294	22,94	36,882
138,4	65,953	6,8994	6,8994	1319,1	0,22998	22,998	36,899
138,9	66,456	6,9293	6,9293	1329,1	0,23098	23,098	36,929
139,4	65,961	6,945	6,945	1319,2	0,2315	23,15	36,945
139,8	66,729	6,978	6,978	1334,6	0,2326	23,26	36,978
140,3	65,951	6,9904	6,9904	1319	0,23301	23,301	36,99
140,7	66,702	7,0211	7,0211	1334	0,23404	23,404	37,021
141,2	66,038	7,0355	7,0355	1320,8	0,23452	23,452	37,035
141,7	67,033	7,0712	7,0712	1340,7	0,23571	23,571	37,071
142,1	66,15	7,0824	7,0824	1323	0,23608	23,608	37,082
142,6	66,833	7,1158	7,1158	1336,7	0,23719	23,719	37,116
143	66,16	7,1294	7,1294	1323,2	0,23765	23,765	37,129
143,5	66,63	7,1586	7,1586	1332,6	0,23862	23,862	37,159
144	65,987	7,1736	7,1736	1319,7	0,23912	23,912	37,174
144,4	66,53	7,2027	7,2027	1330,6	0,24009	24,009	37,203
144,9	66,125	7,2221	7,2221	1322,5	0,24074	24,074	37,222
145,3	66,601	7,249	7,249	1332	0,24163	24,163	37,249
145,8	66,228	7,2686	7,2686	1324,6	0,24229	24,229	37,269
146,3	66,565	7,2925	7,2925	1331,3	0,24308	24,308	37,292
146,7	66,523	7,3162	7,3162	1330,5	0,24387	24,387	37,316
147,2	66,713	7,3402	7,3402	1334,3	0,24467	24,467	37,34
147,6	66,572	7,3626	7,3626	1331,4	0,24542	24,542	37,363
148,1	66,583	7,3848	7,3848	1331,7	0,24616	24,616	37,385
148,6	66,695	7,4102	7,4102	1333,9	0,24701	24,701	37,41
149	66,728	7,4309	7,4309	1334,6	0,2477	24,77	37,431
149,5	66,806	7,4565	7,4565	1336,1	0,24855	24,855	37,457
149,9	66,608	7,4763	7,4763	1332,2	0,24921	24,921	37,476
150,4	66,801	7,5021	7,5021	1336	0,25007	25,007	37,502
150,9	66,504	7,5195	7,5195	1330,1	0,25065	25,065	37,519
151,3	67,079	7,5502	7,5502	1341,6	0,25167	25,167	37,55
151,8	66,575	7,5656	7,5656	1331,5	0,25219	25,219	37,566
152,2	67,093	7,5954	7,5954	1341,9	0,25318	25,318	37,595
152,7	66,557	7,6129	7,6129	1331,1	0,25376	25,376	37,613
153,2	67,44	7,6447	7,6447	1348,8	0,25482	25,482	37,645
153,6	66,589	7,6562	7,6562	1331,8	0,25521	25,521	37,656
154,1	67,287	7,69	7,69	1345,7	0,25633	25,633	37,69
154,5	66,63	7,7057	7,7057	1332,6	0,25686	25,686	37,706
155	67,617	7,7397	7,7397	1352,3	0,25799	25,799	37,74
155,5	66,636	7,7486	7,7486	1332,7	0,25829	25,829	37,749
155,9	67,562	7,7839	7,7839	1351,2	0,25946	25,946	37,784
156,4	66,659	7,7962	7,7962	1333,2	0,25987	25,987	37,796
156,8	67,227	7,8262	7,8262	1344,5	0,26087	26,087	37,826
157,3	66,896	7,8426	7,8426	1337,9	0,26142	26,142	37,843
157,8	67,092	7,8703	7,8703	1341,8	0,26234	26,234	37,87
158,2	66,771	7,889	7,889	1335,4	0,26297	26,297	37,889
158,7	67,296	7,9158	7,9158	1345,9	0,26386	26,386	37,916
159,1	66,996	7,936	7,936	1339,9	0,26453	26,453	37,936
159,6	67,22	7,9612	7,9612	1344,4	0,26537	26,537	37,961
160,1	67,036	7,9828	7,9828	1340,7	0,26609	26,609	37,983
160,5	67,195	8,006	8,006	1343,9	0,26687	26,687	38,006
161	67,131	8,0293	8,0293	1342,6	0,26764	26,764	38,029
161,4	67,182	8,0509	8,0509	1343,6	0,26836	26,836	38,051
161,9	67,081	8,0748	8,0748	1341,6	0,26916	26,916	38,075
162,4	67,093	8,0956	8,0956	1341,9	0,26985	26,985	38,096
162,8	67,426	8,1231	8,1231	1348,5	0,27077	27,077	38,123
163,3	67,098	8,1438	8,1438	1342	0,27146	27,146	38,144
163,7	67,29	8,1684	8,1684	1345,8	0,27228	27,228	38,168
164,2	67,003	8,1873	8,1873	1340,1	0,27291	27,291	38,187
164,7	67,354	8,2157	8,2157	1347,1	0,27386	27,386	38,216
165,1	66,935	8,2334	8,2334	1338,7	0,27445	27,445	38,233
165,6	67,528	8,264	8,264	1350,6	0,27547	27,547	38,264
166	66,952	8,2787	8,2787	1339	0,27596	27,596	38,279
166,5	67,539	8,3103	8,3103	1350,8	0,27701	27,701	38,31
167	66,908	8,3236	8,3236	1338,2	0,27745	27,745	38,324
167,4	67,843	8,3585	8,3585	1356,9	0,27862	27,862	38,359
167,9	66,84	8,3715	8,3715	1336,8	0,27905	27,905	38,371
168,3	68,005	8,4066	8,4066	1360,1	0,28022	28,022	38,407
168,8	67,052	8,417	8,417	1341	0,28057	28,057	38,417
169,3	67,85	8,4512	8,4512	1357	0,28171	28,171	38,451
169,7	66,888	8,4623	8,4623	1337,8	0,28208	28,208	38,462
170,2	67,516	8,4933	8,4933	1350,3	0,28311	28,311	38,493
170,6	66,869	8,5088	8,5088	1337,4	0,28363	28,363	38,509
171,1	67,319	8,5385	8,5385	1346,4	0,28462	28,462	38,539
171,6	66,845	8,5557	8,5557	1336,9	0,28519	28,519	38,556
172	67,188	8,5836	8,5836	1343,8	0,28612	28,612	38,584
172,5	66,594	8,6011	8,6011	1331,9	0,2867	28,67	38,601
172,9	66,858	8,6284	8,6284	1337,2	0,28761	28,761	38,628
173,4	66,355	8,6475	8,6475	1327,1	0,28825	28,825	38,648
173,9	66,394	8,6726	8,6726	1327,9	0,28909	28,909	38,673
174,3	66,292	8,6949	8,6949	1325,8	0,28983	28,983	38,695
174,8	66,53	8,72	8,72	1330,6	0,29067	29,067	38,72
175,2	66,561	8,7431	8,7431	1331,2	0,29144	29,144	38,743
175,7	66,544	8,7636	8,7636	1330,9	0,29212	29,212	38,764
176,2	66,666	8,7886	8,7886	1333,3	0,29295	29,295	38,789
176,6	66,793	8,8114	8,8114	1335,9	0,29371	29,371	38,811
177,1	66,912	8,8348	8,8348	1338,2	0,29449	29,449	38,835
177,5	66,98	8,8564	8,8564	1339,6	0,29521	29,521	38,856
178	67,28	8,8831	8,8831	1345,6	0,2961	29,61	38,883
178,5	66,949	8,9003	8,9003	1339	0,29668	29,668	38,9
178,9	67,508	8,9305	8,9305	1350,2	0,29768	29,768	38,93
179,4	66,937	8,9446	8,9446	1338,7	0,29815	29,815	38,945
179,8	67,814	8,9799	8,9799	1356,3	0,29933	29,933	38,98
180,3	67,04	8,9919	8,9919	1340,8	0,29973	29,973	38,992
180,8	67,882	9,0243	9,0243	1357,6	0,30081	30,081	39,024
181,2	67,153	9,0371	9,0371	1343,1	0,30124	30,124	39,037
181,7	68,37	9,0746	9,0746	1367,4	0,30249	30,249	39,075
182,1	67,307	9,0831	9,0831	1346,1	0,30277	30,277	39,083
182,6	67,938	9,1146	9,1146	1358,8	0,30382	30,382	39,115
183,1	67,418	9,1293	9,1293	1348,4	0,30431	30,431	39,129
183,5	68,136	9,1615	9,1615	1362,7	0,30538	30,538	39,162
184	67,57	9,1774	9,1774	1351,4	0,30591	30,591	39,177
184,4	68,023	9,2058	9,2058	1360,5	0,30686	30,686	39,206
184,9	67,465	9,2215	9,2215	1349,3	0,30738	30,738	39,222
185,4	67,782	9,2479	9,2479	1355,6	0,30826	30,826	39,248
185,8	67,492	9,2681	9,2681	1349,8	0,30894	30,894	39,268
186,3	68,035	9,2941	9,2941	1360,7	0,3098	30,98	39,294
186,7	67,799	9,3159	9,3159	1356	0,31053	31,053	39,316
187,2	68,002	9,3415	9,3415	1360	0,31138	31,138	39,342
187,7	67,788	9,3631	9,3631	1355,8	0,3121	31,21	39,363
188,1	67,87	9,3849	9,3849	1357,4	0,31283	31,283	39,385
188,6	67,822	9,4088	9,4088	1356,4	0,31363	31,363	39,409
189	67,844	9,4321	9,4321	1356,9	0,3144	31,44	39,432
189,5	68,006	9,4582	9,4582	1360,1	0,31527	31,527	39,458
190	67,723	9,4765	9,4765	1354,5	0,31588	31,588	39,476
190,4	68,027	9,5047	9,5047	1360,5	0,31682	31,682	39,505
190,9	67,776	9,5208	9,5208	1355,5	0,31736	31,736	39,521
191,3	68,248	9,5509	9,5509	1365	0,31836	31,836	39,551
191,8	67,912	9,5682	9,5682	1358,2	0,31894	31,894	39,568
192,3	68,259	9,5966	9,5966	1365,2	0,31989	31,989	39,597
192,7	67,744	9,6116	9,6116	1354,9	0,32039	32,039	39,612
193,2	68,573	9,6457	9,6457	1371,5	0,32152	32,152	39,646
193,6	67,732	9,6571	9,6571	1354,6	0,3219	32,19	39,657
194,1	68,325	9,6866	9,6866	1366,5	0,32289	32,289	39,687
194,6	67,852	9,7065	9,7065	1357	0,32355	32,355	39,707
195	68,787	9,739	9,739	1375,7	0,32463	32,463	39,739
195,5	67,907	9,7502	9,7502	1358,1	0,32501	32,501	39,75
195,9	68,999	9,7875	9,7875	1380	0,32625	32,625	39,788
196,4	67,884	9,7965	9,7965	1357,7	0,32655	32,655	39,796
196,9	68,839	9,8317	9,8317	1376,8	0,32772	32,772	39,832
197,3	68,147	9,8438	9,8438	1362,9	0,32813	32,813	39,844
197,8	68,585	9,8739	9,8739	1371,7	0,32913	32,913	39,874
198,2	68,097	9,8881	9,8881	1361,9	0,3296	32,96	39,888
198,7	68,563	9,9179	9,9179	1371,3	0,3306	33,06	39,918
199,2	68,223	9,9375	9,9375	1364,5	0,33125	33,125	39,938
199,6	68,433	9,9629	9,9629	1368,7	0,3321	33,21	39,963
200,1	68,09	9,9823	9,9823	1361,8	0,33274	33,274	39,982
200,5	68,329	10,007	10,007	1366,6	0,33358	33,358	40,007
201	68,212	10,03	10,03	1364,2	0,33433	33,433	40,03
201,5	68,416	10,052	10,052	1368,3	0,33508	33,508	40,052
201,9	68,373	10,077	10,077	1367,5	0,33589	33,589	40,077
202,4	68,456	10,099	10,099	1369,1	0,33663	33,663	40,099
202,8	68,55	10,124	10,124	1371	0,33748	33,748	40,124
203,3	68,532	10,145	10,145	1370,6	0,33818	33,818	40,145
203,8	68,765	10,172	10,172	1375,3	0,33907	33,907	40,172
204,2	68,365	10,188	10,188	1367,3	0,33961	33,961	40,188
204,7	68,683	10,217	10,217	1373,7	0,34057	34,057	40,217
205,1	68,427	10,233	10,233	1368,5	0,34111	34,111	40,233
205,6	68,831	10,263	10,263	1376,6	0,34211	34,211	40,263
206,1	68,502	10,28	10,28	1370	0,34266	34,266	40,28
206,5	69,118	10,312	10,312	1382,4	0,34372	34,372	40,312
207	68,499	10,326	10,326	1370	0,34418	34,418	40,326
207,4	69,362	10,359	10,359	1387,2	0,34529	34,529	40,359
207,9	68,417	10,37	10,37	1368,3	0,34566	34,566	40,37
208,4	69,25	10,405	10,405	1385	0,34683	34,683	40,405
208,8	68,371	10,416	10,416	1367,4	0,3472	34,72	40,416
209,3	69,301	10,448	10,448	1386	0,34827	34,827	40,448
209,7	68,554	10,466	10,466	1371,1	0,34886	34,886	40,466
210,2	69,347	10,496	10,496	1386,9	0,34986	34,986	40,496
210,7	68,627	10,511	10,511	1372,5	0,35037	35,037	40,511
211,1	69,114	10,54	10,54	1382,3	0,35133	35,133	40,54
211,6	68,685	10,557	10,557	1373,7	0,3519	35,19	40,557
212	68,971	10,582	10,582	1379,4	0,35275	35,275	40,582
212,5	68,73	10,603	10,603	1374,6	0,35344	35,344	40,603
213	68,996	10,627	10,627	1379,9	0,35424	35,424	40,627
213,4	68,724	10,649	10,649	1374,5	0,35496	35,496	40,649
213,9	69,02	10,675	10,675	1380,4	0,35583	35,583	40,675
214,3	68,816	10,696	10,696	1376,3	0,35654	35,654	40,696
214,8	68,94	10,72	10,72	1378,8	0,35735	35,735	40,72
215,3	68,878	10,743	10,743	1377,6	0,35812	35,812	40,743
215,7	68,838	10,764	10,764	1376,8	0,35881	35,881	40,764
216,2	68,927	10,789	10,789	1378,5	0,35965	35,965	40,789
216,6	68,935	10,812	10,812	1378,7	0,36041	36,041	40,812
217,1	69,245	10,837	10,837	1384,9	0,36124	36,124	40,837
217,6	69,174	10,858	10,858	1383,5	0,36192	36,192	40,858
218	69,294	10,884	10,884	1385,9	0,3628	36,28	40,884
218,5	68,863	10,902	10,902	1377,3	0,36341	36,341	40,902
218,9	69,243	10,93	10,93	1384,9	0,36433	36,433	40,93
219,4	68,71	10,945	10,945	1374,2	0,36485	36,485	40,945
219,9	69,363	10,977	10,977	1387,3	0,3659	36,59	40,977
220,3	68,779	10,994	10,994	1375,6	0,36645	36,645	40,994
220,8	69,441	11,024	11,024	1388,8	0,36746	36,746	41,024
221,2	68,74	11,037	11,037	1374,8	0,36789	36,789	41,037
221,7	69,566	11,071	11,071	1391,3	0,36903	36,903	41,071
222,2	68,899	11,085	11,085	1378	0,3695	36,95	41,085
222,6	69,67	11,118	11,118	1393,4	0,37059	37,059	41,118
223,1	69,002	11,131	11,131	1380	0,37105	37,105	41,131
223,5	69,751	11,165	11,165	1395	0,37216	37,216	41,165
224	68,943	11,178	11,178	1378,9	0,37261	37,261	41,178
224,5	69,317	11,205	11,205	1386,3	0,37349	37,349	41,205
224,9	69,075	11,225	11,225	1381,5	0,37417	37,417	41,225
225,4	69,239	11,249	11,249	1384,8	0,37498	37,498	41,249
225,8	68,91	11,268	11,268	1378,2	0,37561	37,561	41,268
226,3	69,361	11,295	11,295	1387,2	0,37651	37,651	41,295
226,8	69,252	11,317	11,317	1385	0,37723	37,723	41,317
227,2	69,58	11,343	11,343	1391,6	0,37809	37,809	41,343
227,7	69,422	11,365	11,365	1388,4	0,37882	37,882	41,365
228,1	69,552	11,388	11,388	1391	0,37959	37,959	41,388
228,6	69,609	11,411	11,411	1392,2	0,38036	38,036	41,411
229,1	69,502	11,432	11,432	1390	0,38108	38,108	41,432
229,5	69,519	11,456	11,456	1390,4	0,38186	38,186	41,456
230	69,491	11,478	11,478	1389,8	0,3826	38,26	41,478
230,4	69,535	11,503	11,503	1390,7	0,38343	38,343	41,503
230,9	69,366	11,521	11,521	1387,3	0,38405	38,405	41,521
231,4	69,74	11,55	11,55	1394,8	0,38499	38,499	41,55
231,8	69,528	11,569	11,569	1390,6	0,38563	38,563	41,569
232,3	69,777	11,596	11,596	1395,5	0,38654	38,654	41,596
232,7	69,292	11,615	11,615	1385,8	0,38718	38,718	41,615
233,2	69,917	11,644	11,644	1398,3	0,38814	38,814	41,644
233,7	69,368	11,659	11,659	1387,4	0,38863	38,863	41,659
234,1	69,936	11,691	11,691	1398,7	0,38969	38,969	41,691
234,6	69,395	11,705	11,705	1387,9	0,39018	39,018	41,705
235	70,08	11,739	11,739	1401,6	0,3913	39,13	41,739
235,5	69,313	11,75	11,75	1386,3	0,39167	39,167	41,75
236	70,297	11,786	11,786	1405,9	0,39287	39,287	41,786
236,4	69,542	11,798	11,798	1390,8	0,39327	39,327	41,798
236,9	69,909	11,825	11,825	1398,2	0,39416	39,416	41,825
237,3	69,358	11,841	11,841	1387,2	0,39471	39,471	41,841
237,8	70,082	11,873	11,873	1401,6	0,39578	39,578	41,873
238,3	69,636	11,891	11,891	1392,7	0,39635	39,635	41,891
238,7	70,09	11,919	11,919	1401,8	0,39729	39,729	41,919
239,2	69,691	11,937	11,937	1393,8	0,3979	39,79	41,937
239,6	70,071	11,964	11,964	1401,4	0,39878	39,878	41,964
240,1	69,894	11,983	11,983	1397,9	0,39945	39,945	41,983
240,5	69,995	12,009	12,009	1399,9	0,40029	40,029	42,009
241	69,905	12,029	12,029	1398,1	0,40098	40,098	42,029
241,5	70,109	12,053	12,053	1402,2	0,40176	40,176	42,053
241,9	69,924	12,077	12,077	1398,5	0,40256	40,256	42,077
242,4	70,056	12,097	12,097	1401,1	0,40324	40,324	42,097
242,8	69,985	12,121	12,121	1399,7	0,40404	40,404	42,121
243,3	70,017	12,145	12,145	1400,3	0,40482	40,482	42,145
243,8	70,019	12,169	12,169	1400,4	0,40562	40,562	42,169
244,2	70,007	12,19	12,19	1400,1	0,40634	40,634	42,19
244,7	70,11	12,216	12,216	1402,2	0,40719	40,719	42,216
245,1	69,986	12,235	12,235	1399,7	0,40784	40,784	42,235
245,6	70,273	12,263	12,263	1405,5	0,40878	40,878	42,263
246,1	70,008	12,281	12,281	1400,2	0,40937	40,937	42,281
246,5	70,64	12,313	12,313	1412,8	0,41043	41,043	42,313
247	70,041	12,326	12,326	1400,8	0,41085	41,085	42,326
247,4	70,656	12,359	12,359	1413,1	0,41195	41,195	42,359
247,9	70,056	12,372	12,372	1401,1	0,41241	41,241	42,372
248,4	70,938	12,407	12,407	1418,8	0,41357	41,357	42,407
248,8	70,033	12,416	12,416	1400,7	0,41387	41,387	42,416
249,3	71,026	12,455	12,455	1420,5	0,41515	41,515	42,455
249,7	70,072	12,463	12,463	1401,4	0,41543	41,543	42,463
250,2	70,89	12,498	12,498	1417,8	0,41662	41,662	42,498
250,7	70,272	12,511	12,511	1405,4	0,41705	41,705	42,511
251,1	70,745	12,541	12,541	1414,9	0,41802	41,802	42,541
251,6	70,393	12,559	12,559	1407,9	0,41862	41,862	42,559
252	70,758	12,585	12,585	1415,2	0,41951	41,951	42,585
252,5	70,221	12,601	12,601	1404,4	0,42003	42,003	42,601
253	70,642	12,63	12,63	1412,8	0,42101	42,101	42,63
253,4	70,313	12,65	12,65	1406,3	0,42167	42,167	42,65
253,9	70,453	12,675	12,675	1409,1	0,42248	42,248	42,675
254,3	70,34	12,696	12,696	1406,8	0,4232	42,32	42,696
254,8	70,617	12,72	12,72	1412,3	0,42402	42,402	42,72
255,3	70,514	12,743	12,743	1410,3	0,42478	42,478	42,743
255,7	70,612	12,765	12,765	1412,2	0,42552	42,552	42,765
256,2	70,615	12,789	12,789	1412,3	0,42631	42,631	42,789
256,6	70,613	12,812	12,812	1412,3	0,42707	42,707	42,812
257,1	70,787	12,838	12,838	1415,7	0,42793	42,793	42,838
257,6	70,653	12,858	12,858	1413,1	0,4286	42,86	42,858
258	70,663	12,882	12,882	1413,3	0,42941	42,941	42,882
258,5	70,59	12,903	12,903	1411,8	0,43011	43,011	42,903
258,9	70,888	12,931	12,931	1417,8	0,43104	43,104	42,931
259,4	70,466	12,947	12,947	1409,3	0,43157	43,157	42,947
259,9	71,049	12,979	12,979	1421	0,43264	43,264	42,979
260,3	70,483	12,994	12,994	1409,7	0,43314	43,314	42,994
260,8	71,196	13,026	13,026	1423,9	0,4342	43,42	43,026
261,2	70,552	13,037	13,037	1411	0,43458	43,458	43,037
261,7	71,474	13,075	13,075	1429,5	0,43583	43,583	43,075
262,2	70,566	13,084	13,084	1411,3	0,43613	43,613	43,084
262,6	71,214	13,117	13,117	1424,3	0,43723	43,723	43,117
263,1	70,603	13,132	13,132	1412,1	0,43773	43,773	43,132
263,5	71,326	13,167	13,167	1426,5	0,4389	43,89	43,167
264	70,593	13,177	13,177	1411,9	0,43923	43,923	43,177
264,5	71,289	13,209	13,209	1425,8	0,4403	44,03	43,209
264,9	70,707	13,223	13,223	1414,1	0,44077	44,077	43,223
265,4	71,09	13,252	13,252	1421,8	0,44173	44,173	43,252
265,8	70,581	13,268	13,268	1411,6	0,44227	44,227	43,268
266,3	71,141	13,296	13,296	1422,8	0,44321	44,321	43,296
266,8	70,914	13,318	13,318	1418,3	0,44394	44,394	43,318
267,2	71,119	13,342	13,342	1422,4	0,44475	44,475	43,342
267,7	70,85	13,364	13,364	1417	0,44548	44,548	43,364
268,1	70,95	13,387	13,387	1419	0,44622	44,622	43,387
268,6	70,894	13,409	13,409	1417,9	0,44697	44,697	43,409
269,1	70,996	13,433	13,433	1419,9	0,44778	44,778	43,433
269,5	71,144	13,458	13,458	1422,9	0,4486	44,86	43,458
270	70,963	13,479	13,479	1419,3	0,44929	44,929	43,479
270,4	71,162	13,504	13,504	1423,2	0,45012	45,012	43,504
270,9	70,982	13,523	13,523	1419,6	0,45076	45,076	43,523
271,4	71,269	13,551	13,551	1425,4	0,45169	45,169	43,551
271,8	71,115	13,571	13,571	1422,3	0,45235	45,235	43,571
272,3	71,328	13,597	13,597	1426,6	0,45325	45,325	43,597
272,7	71,071	13,615	13,615	1421,4	0,45384	45,384	43,615
273,2	71,542	13,646	13,646	1430,8	0,45485	45,485	43,646
273,7	71,038	13,66	13,66	1420,8	0,45535	45,535	43,66
274,1	71,558	13,691	13,691	1431,2	0,45638	45,638	43,691
274,6	71,163	13,706	13,706	1423,3	0,45685	45,685	43,706
275	71,817	13,74	13,74	1436,3	0,458	45,8	43,74
275,5	71,108	13,752	13,752	1422,2	0,45839	45,839	43,752
276	71,797	13,785	13,785	1435,9	0,45951	45,951	43,785
276,4	71,173	13,798	13,798	1423,5	0,45995	45,995	43,798
276,9	72,105	13,834	13,834	1442,1	0,46113	46,113	43,834
277,3	71,253	13,845	13,845	1425,1	0,46149	46,149	43,845
277,8	71,764	13,875	13,875	1435,3	0,4625	46,25	43,875
278,3	71,342	13,891	13,891	1426,8	0,46305	46,305	43,891
278,7	71,565	13,918	13,918	1431,3	0,46394	46,394	43,918
279,2	71,302	13,938	13,938	1426	0,46459	46,459	43,938
279,6	71,479	13,964	13,964	1429,6	0,46548	46,548	43,964
280,1	71,343	13,984	13,984	1426,9	0,46614	46,614	43,984
280,6	71,324	14,009	14,009	1426,5	0,46697	46,697	44,009
281	71,337	14,03	14,03	1426,7	0,46765	46,765	44,03
281,5	71,633	14,055	14,055	1432,7	0,46849	46,849	44,055
281,9	71,485	14,076	14,076	1429,7	0,46922	46,922	44,076
282,4	71,545	14,098	14,098	1430,9	0,46995	46,995	44,098
282,9	71,694	14,124	14,124	1433,9	0,47081	47,081	44,124
283,3	71,658	14,146	14,146	1433,2	0,47154	47,154	44,146
283,8	71,643	14,17	14,17	1432,9	0,47234	47,234	44,17
284,2	71,653	14,192	14,192	1433,1	0,47306	47,306	44,192
284,7	71,807	14,218	14,218	1436,1	0,47392	47,392	44,218
285,2	71,682	14,238	14,238	1433,6	0,4746	47,46	44,238
285,6	71,924	14,264	14,264	1438,5	0,47547	47,547	44,264
286,1	71,717	14,282	14,282	1434,3	0,47607	47,607	44,282
286,5	72,243	14,311	14,311	1444,9	0,47704	47,704	44,311
287	71,58	14,326	14,326	1431,6	0,47753	47,753	44,326
287,5	72,232	14,359	14,359	1444,6	0,47863	47,863	44,359
287,9	71,588	14,371	14,371	1431,8	0,47905	47,905	44,371
288,4	72,222	14,406	14,406	1444,4	0,48021	48,021	44,406
288,8	71,628	14,417	14,417	1432,6	0,48058	48,058	44,417
289,3	72,023	14,449	14,449	1440,5	0,48165	48,165	44,449
289,8	71,549	14,465	14,465	1431	0,48216	48,216	44,465
290,2	72,256	14,5	14,5	1445,1	0,48332	48,332	44,5
290,7	71,686	14,511	14,511	1433,7	0,48371	48,371	44,511
291,1	72,347	14,543	14,543	1446,9	0,48477	48,477	44,543
291,6	71,728	14,556	14,556	1434,6	0,48521	48,521	44,556
292,1	72,132	14,585	14,585	1442,6	0,48618	48,618	44,585
292,5	71,791	14,605	14,605	1435,8	0,48683	48,683	44,605
293	72,057	14,63	14,63	1441,1	0,48766	48,766	44,63
293,4	71,85	14,652	14,652	1437	0,4884	48,84	44,652
293,9	72,099	14,675	14,675	1442	0,48916	48,916	44,675
294,4	71,997	14,697	14,697	1439,9	0,4899	48,99	44,697
294,8	72,167	14,721	14,721	1443,3	0,4907	49,07	44,721
295,3	72,143	14,744	14,744	1442,9	0,49148	49,148	44,744
295,7	72,162	14,767	14,767	1443,2	0,49222	49,222	44,767
296,2	72,136	14,79	14,79	1442,7	0,493	49,3	44,79
296,7	72,282	14,813	14,813	1445,6	0,49378	49,378	44,813
297,1	72,318	14,836	14,836	1446,4	0,49455	49,455	44,836
297,6	72,254	14,859	14,859	1445,1	0,49528	49,528	44,859
298	72,405	14,884	14,884	1448,1	0,49612	49,612	44,884
298,5	72,285	14,904	14,904	1445,7	0,4968	49,68	44,904
299	72,457	14,93	14,93	1449,1	0,49767	49,767	44,93
299,4	72,118	14,948	14,948	1442,4	0,49827	49,827	44,948
299,9	72,43	14,976	14,976	1448,6	0,49921	49,921	44,976
300,3	72,211	14,995	14,995	1444,2	0,49983	49,983	44,995
300,8	72,647	15,025	15,025	1452,9	0,50084	50,084	45,025
301,3	72,057	15,039	15,039	1441,1	0,50131	50,131	45,039
301,7	72,717	15,073	15,073	1454,3	0,50242	50,242	45,073
302,2	72,132	15,086	15,086	1442,6	0,50286	50,286	45,086
302,6	72,69	15,117	15,117	1453,8	0,50392	50,392	45,117
303,1	72,135	15,131	15,131	1442,7	0,50435	50,435	45,131
303,6	73,026	15,167	15,167	1460,5	0,50557	50,557	45,167
304	72,266	15,178	15,178	1445,3	0,50593	50,593	45,178
304,5	72,806	15,209	15,209	1456,1	0,50696	50,696	45,209
304,9	72,336	15,225	15,225	1446,7	0,5075	50,75	45,225
305,4	72,814	15,254	15,254	1456,3	0,50848	50,848	45,254
305,9	72,361	15,271	15,271	1447,2	0,50903	50,903	45,271
306,3	72,768	15,298	15,298	1455,4	0,50992	50,992	45,298
306,8	72,415	15,316	15,316	1448,3	0,51054	51,054	45,316
307,2	72,744	15,343	15,343	1454,9	0,51142	51,142	45,343
307,7	72,617	15,364	15,364	1452,3	0,51214	51,214	45,364
308,2	72,892	15,39	15,39	1457,8	0,513	51,3	45,39
308,6	72,81	15,413	15,413	1456,2	0,51376	51,376	45,413
309,1	72,829	15,434	15,434	1456,6	0,51446	51,446	45,434
309,5	72,77	15,458	15,458	1455,4	0,51526	51,526	45,458
310	72,896	15,481	15,481	1457,9	0,51602	51,602	45,481
310,5	72,841	15,503	15,503	1456,8	0,51678	51,678	45,503
310,9	72,767	15,524	15,524	1455,3	0,51746	51,746	45,524
311,4	72,964	15,55	15,55	1459,3	0,51832	51,832	45,55
311,8	72,901	15,571	15,571	1458	0,51904	51,904	45,571
312,3	73,206	15,599	15,599	1464,1	0,51997	51,997	45,599
312,8	72,899	15,617	15,617	1458	0,52055	52,055	45,617
313,2	73,249	15,646	15,646	1465	0,52152	52,152	45,646
313,7	72,831	15,661	15,661	1456,6	0,52204	52,204	45,661
314,1	73,292	15,691	15,691	1465,8	0,52305	52,305	45,691
314,6	72,801	15,706	15,706	1456	0,52355	52,355	45,706
315,1	73,423	15,739	15,739	1468,5	0,52464	52,464	45,739
315,5	72,771	15,752	15,752	1455,4	0,52508	52,508	45,752
316	73,483	15,785	15,785	1469,7	0,52617	52,617	45,785
316,4	72,831	15,798	15,798	1456,6	0,5266	52,66	45,798
316,9	73,963	15,837	15,837	1479,3	0,52789	52,789	45,837
317,4	72,854	15,842	15,842	1457,1	0,52808	52,808	45,842
317,8	73,464	15,875	15,875	1469,3	0,52918	52,918	45,875
318,3	73,025	15,892	15,892	1460,5	0,52973	52,973	45,892
318,7	73,516	15,92	15,92	1470,3	0,53066	53,066	45,92
319,2	73,116	15,939	15,939	1462,3	0,5313	53,13	45,939
319,7	73,504	15,966	15,966	1470,1	0,53219	53,219	45,966
320,1	73,227	15,986	15,986	1464,5	0,53286	53,286	45,986
320,6	73,393	16,011	16,011	1467,9	0,53369	53,369	46,011
321	73,222	16,031	16,031	1464,4	0,53436	53,436	46,031
321,5	73,54	16,056	16,056	1470,8	0,53521	53,521	46,056
322	73,306	16,077	16,077	1466,1	0,53589	53,589	46,077
322,4	73,429	16,1	16,1	1468,6	0,53668	53,668	46,1
322,9	73,311	16,123	16,123	1466,2	0,53744	53,744	46,123
323,3	73,507	16,146	16,146	1470,1	0,53821	53,821	46,146
323,8	73,462	16,17	16,17	1469,2	0,53901	53,901	46,17
324,3	73,456	16,192	16,192	1469,1	0,53974	53,974	46,192
324,7	73,579	16,217	16,217	1471,6	0,54056	54,056	46,217
325,2	73,365	16,239	16,239	1467,3	0,54131	54,131	46,239
325,6	73,504	16,266	16,266	1470,1	0,54219	54,219	46,266
326,1	73,517	16,283	16,283	1470,3	0,54275	54,275	46,283
326,6	73,822	16,313	16,313	1476,4	0,54376	54,376	46,313
327	73,456	16,33	16,33	1469,1	0,54434	54,434	46,33
327,5	73,935	16,359	16,359	1478,7	0,54531	54,531	46,359
327,9	73,44	16,374	16,374	1468,8	0,54578	54,578	46,374
328,4	74,156	16,408	16,408	1483,1	0,54692	54,692	46,408
328,9	73,465	16,42	16,42	1469,3	0,54733	54,733	46,42
329,3	74,073	16,452	16,452	1481,5	0,54839	54,839	46,452
329,8	73,435	16,464	16,464	1468,7	0,54882	54,882	46,464
330,2	74,227	16,499	16,499	1484,5	0,54996	54,996	46,499
330,7	73,592	16,512	16,512	1471,8	0,55039	55,039	46,512
331,2	74,171	16,543	16,543	1483,4	0,55144	55,144	46,543
331,6	73,771	16,559	16,559	1475,4	0,55197	55,197	46,559
332,1	74,439	16,591	16,591	1488,8	0,55303	55,303	46,591
332,5	73,751	16,603	16,603	1475	0,55342	55,342	46,603
333	74,085	16,633	16,633	1481,7	0,55444	55,444	46,633
333,5	73,887	16,651	16,651	1477,7	0,55504	55,504	46,651
333,9	74,1	16,677	16,677	1482	0,5559	55,59	46,677
334,4	73,826	16,697	16,697	1476,5	0,55658	55,658	46,697
334,8	74,166	16,725	16,725	1483,3	0,55749	55,749	46,725
335,3	73,977	16,744	16,744	1479,5	0,55813	55,813	46,744
335,8	74,173	16,769	16,769	1483,5	0,55898	55,898	46,769
336,2	74,048	16,79	16,79	1481	0,55966	55,966	46,79
336,7	74,085	16,815	16,815	1481,7	0,5605	56,05	46,815
337,1	74,171	16,839	16,839	1483,4	0,56131	56,131	46,839
337,6	74,114	16,858	16,858	1482,3	0,56193	56,193	46,858
338,1	74,207	16,885	16,885	1484,1	0,56282	56,282	46,885
338,5	74,092	16,905	16,905	1481,8	0,56351	56,351	46,905
339	74,326	16,932	16,932	1486,5	0,56439	56,439	46,932
339,4	73,937	16,949	16,949	1478,7	0,56496	56,496	46,949
339,9	74,55	16,981	16,981	1491	0,56602	56,602	46,981
340,4	74,015	16,995	16,995	1480,3	0,5665	56,65	46,995
340,8	74,481	17,025	17,025	1489,6	0,56751	56,751	47,025
341,3	74,076	17,04	17,04	1481,5	0,56798	56,798	47,04
341,7	74,816	17,075	17,075	1496,3	0,56916	56,916	47,075
342,2	74,073	17,087	17,087	1481,5	0,56955	56,955	47,087
342,7	74,65	17,119	17,119	1493	0,57062	57,062	47,119
343,1	74,194	17,132	17,132	1483,9	0,57108	57,108	47,132
343,6	74,975	17,169	17,169	1499,5	0,57228	57,228	47,169
344	74,147	17,179	17,179	1482,9	0,57263	57,263	47,179
344,5	74,936	17,214	17,214	1498,7	0,57379	57,379	47,214
345	74,186	17,225	17,225	1483,7	0,57417	57,417	47,225
345,4	74,904	17,259	17,259	1498,1	0,57529	57,529	47,259
345,9	74,28	17,273	17,273	1485,6	0,57576	57,576	47,273
346,3	74,668	17,3	17,3	1493,4	0,57667	57,667	47,3
346,8	74,424	17,319	17,319	1488,5	0,57731	57,731	47,319
347,3	74,675	17,344	17,344	1493,5	0,57814	57,814	47,344
347,7	74,404	17,364	17,364	1488,1	0,5788	57,88	47,364
348,2	74,594	17,391	17,391	1491,9	0,5797	57,97	47,391
348,6	74,439	17,411	17,411	1488,8	0,58038	58,038	47,411
349,1	74,537	17,435	17,435	1490,7	0,58116	58,116	47,435
349,6	74,627	17,46	17,46	1492,5	0,58199	58,199	47,46
350	74,564	17,479	17,479	1491,3	0,58263	58,263	47,479
350,5	74,52	17,503	17,503	1490,4	0,58345	58,345	47,503
350,9	74,564	17,526	17,526	1491,3	0,58418	58,418	47,526
351,4	74,816	17,552	17,552	1496,3	0,58506	58,506	47,552
351,9	74,705	17,572	17,572	1494,1	0,58572	58,572	47,572
352,3	75,006	17,6	17,6	1500,1	0,58666	58,666	47,6
352,8	74,711	17,615	17,615	1494,2	0,58716	58,716	47,615
353,2	75,039	17,645	17,645	1500,8	0,58818	58,818	47,645
353,7	74,655	17,662	17,662	1493,1	0,58872	58,872	47,662
354,2	74,988	17,691	17,691	1499,8	0,58969	58,969	47,691
354,6	74,774	17,711	17,711	1495,5	0,59035	59,035	47,711
355,1	75,235	17,741	17,741	1504,7	0,59137	59,137	47,741
355,5	74,672	17,753	17,753	1493,4	0,59178	59,178	47,753
356	75,38	17,787	17,787	1507,6	0,59289	59,289	47,787
356,5	74,783	17,8	17,8	1495,7	0,59332	59,332	47,8
356,9	75,65	17,836	17,836	1513	0,59454	59,454	47,836
357,4	74,779	17,844	17,844	1495,6	0,5948	59,48	47,844
357,8	75,408	17,879	17,879	1508,2	0,59596	59,596	47,879
358,3	74,838	17,891	17,891	1496,8	0,59637	59,637	47,891
358,8	75,404	17,923	17,923	1508,1	0,59744	59,744	47,923
359,2	74,907	17,937	17,937	1498,1	0,59791	59,791	47,937
359,7	75,328	17,968	17,968	1506,6	0,59894	59,894	47,968
360,1	74,988	17,986	17,986	1499,8	0,59954	59,954	47,986
360,6	75,11	18,011	18,011	1502,2	0,60036	60,036	48,011
361,1	74,925	18,031	18,031	1498,5	0,60104	60,104	48,031
361,5	75,237	18,057	18,057	1504,7	0,60191	60,191	48,057
362	75,181	18,079	18,079	1503,6	0,60264	60,264	48,079
362,4	75,165	18,101	18,101	1503,3	0,60337	60,337	48,101
362,9	75,13	18,124	18,124	1502,6	0,60415	60,415	48,124
363,4	75,262	18,148	18,148	1505,2	0,60494	60,494	48,148
363,8	75,236	18,17	18,17	1504,7	0,60568	60,568	48,17
364,3	75,119	18,194	18,194	1502,4	0,60646	60,646	48,194
364,7	75,329	18,219	18,219	1506,6	0,60729	60,729	48,219
365,2	75,19	18,24	18,24	1503,8	0,60799	60,799	48,24
365,7	75,323	18,266	18,266	1506,5	0,60886	60,886	48,266
366,1	75,225	18,283	18,283	1504,5	0,60945	60,945	48,283
366,6	75,385	18,312	18,312	1507,7	0,61039	61,039	48,312
367	75,221	18,329	18,329	1504,4	0,61097	61,097	48,329
367,5	75,585	18,359	18,359	1511,7	0,61196	61,196	48,359
368	75,143	18,374	18,374	1502,9	0,61247	61,247	48,374
368,4	75,647	18,404	18,404	1512,9	0,61348	61,348	48,404
368,9	75,094	18,42	18,42	1501,9	0,614	61,4	48,42
369,3	75,534	18,454	18,454	1510,7	0,61514	61,514	48,454
369,8	75,17	18,464	18,464	1503,4	0,61548	61,548	48,464
370,3	75,756	18,5	18,5	1515,1	0,61667	61,667	48,5
370,7	75,124	18,513	18,513	1502,5	0,61709	61,709	48,513
371,2	75,912	18,546	18,546	1518,2	0,6182	61,82	48,546
371,6	75,333	18,56	18,56	1506,7	0,61866	61,866	48,56
372,1	75,79	18,589	18,589	1515,8	0,61964	61,964	48,589
372,6	75,428	18,606	18,606	1508,6	0,62021	62,021	48,606
373	75,775	18,634	18,634	1515,5	0,62113	62,113	48,634
373,5	75,497	18,653	18,653	1509,9	0,62175	62,175	48,653
373,9	75,659	18,677	18,677	1513,2	0,62258	62,258	48,677
374,4	75,458	18,698	18,698	1509,2	0,62325	62,325	48,698
374,9	75,745	18,724	18,724	1514,9	0,62413	62,413	48,724
375,3	75,643	18,747	18,747	1512,9	0,62489	62,489	48,747
375,8	75,745	18,77	18,77	1514,9	0,62566	62,566	48,77
376,2	75,908	18,792	18,792	1518,2	0,6264	62,64	48,792
376,7	75,858	18,814	18,814	1517,2	0,62714	62,714	48,814
377,2	75,936	18,839	18,839	1518,7	0,62795	62,795	48,839
377,6	75,923	18,861	18,861	1518,5	0,62868	62,868	48,861
378,1	75,947	18,885	18,885	1518,9	0,6295	62,95	48,885
378,5	75,871	18,905	18,905	1517,4	0,63016	63,016	48,905
379	76,054	18,932	18,932	1521,1	0,63106	63,106	48,932
379,5	75,799	18,95	18,95	1516	0,63165	63,165	48,95
379,9	76,084	18,977	18,977	1521,7	0,63258	63,258	48,977
380,4	75,977	18,999	18,999	1519,5	0,6333	63,33	48,999
380,8	76,163	19,025	19,025	1523,3	0,63417	63,417	49,025
381,3	75,825	19,04	19,04	1516,5	0,63468	63,468	49,04
381,8	76,418	19,073	19,073	1528,4	0,63578	63,578	49,073
382,2	75,799	19,085	19,085	1516	0,63618	63,618	49,085
382,7	76,388	19,119	19,119	1527,8	0,63729	63,729	49,119
383,1	75,838	19,132	19,132	1516,8	0,63775	63,775	49,132
383,6	76,579	19,167	19,167	1531,6	0,6389	63,89	49,167
384,1	75,955	19,179	19,179	1519,1	0,63929	63,929	49,179
384,5	76,515	19,211	19,211	1530,3	0,64037	64,037	49,211
385	75,986	19,225	19,225	1519,7	0,64084	64,084	49,225
385,4	76,508	19,256	19,256	1530,2	0,64188	64,188	49,256
385,9	76,051	19,273	19,273	1521	0,64242	64,242	49,273
386,4	76,415	19,3	19,3	1528,3	0,64333	64,333	49,3
386,8	76,096	19,317	19,317	1521,9	0,6439	64,39	49,317
387,3	76,38	19,343	19,343	1527,6	0,64476	64,476	49,343
387,7	76,28	19,365	19,365	1525,6	0,64552	64,552	49,365
388,2	76,573	19,391	19,391	1531,5	0,64637	64,637	49,391
388,7	76,476	19,413	19,413	1529,5	0,6471	64,71	49,413
389,1	76,435	19,434	19,434	1528,7	0,64781	64,781	49,434
389,6	76,299	19,457	19,457	1526	0,64856	64,856	49,457
390	76,475	19,481	19,481	1529,5	0,64938	64,938	49,481
390,5	76,355	19,503	19,503	1527,1	0,65011	65,011	49,503
391	76,462	19,527	19,527	1529,2	0,65089	65,089	49,527
391,4	76,37	19,549	19,549	1527,4	0,65163	65,163	49,549
391,9	76,454	19,573	19,573	1529,1	0,65243	65,243	49,573
392,3	76,535	19,598	19,598	1530,7	0,65328	65,328	49,598
392,8	76,314	19,617	19,617	1526,3	0,6539	65,39	49,617
393,3	76,706	19,645	19,645	1534,1	0,65483	65,483	49,645
393,7	76,373	19,663	19,663	1527,5	0,65542	65,542	49,663
394,2	76,686	19,692	19,692	1533,7	0,6564	65,64	49,692
394,6	76,385	19,71	19,71	1527,7	0,65701	65,701	49,71
395,1	76,917	19,741	19,741	1538,3	0,65802	65,802	49,741
395,6	76,405	19,755	19,755	1528,1	0,65851	65,851	49,755
396	74,466	19,787	19,787	1489,3	0,65956	65,956	49,787
396,5	11,298	19,8	19,8	225,96	0,65999	65,999	49,8
396,6		19,808	19,808		0,66026	66,026	49,808