File: Tests de traction/Fichiers source/04_12_2016/4.txt
Time (s)	Load (N)	Machine Extension (mm)	Extension (mm)	Stress (MPa)	Strain	Percentage Strain	Gauge Length (mm)
0
0,4658	0,0003284	0,00009663	0,00009663	0,0065679	0,000003221	0,0003221	30
0,9315	1,7435	0,030656	0,030656	34,87	0,0010219	0,10219	30,031
1,397	2,5097	0,039599	0,039599	50,193	0,00132	0,132	30,04
1,863	7,2858	0,075247	0,075247	145,72	0,0025082	0,25082	30,075
2,329	8,8393	0,085882	0,085882	176,79	0,0028627	0,28627	30,086
2,795	13,809	0,1219	0,1219	276,19	0,0040635	0,40635	30,122
3,26	15,415	0,1341	0,1341	308,3	0,0044701	0,44701	30,134
3,726	19,425	0,16883	0,16883	388,5	0,0056275	0,56275	30,169
4,192	20,802	0,18144	0,18144	416,03	0,0060479	0,60479	30,181
4,658	24,521	0,21662	0,21662	490,42	0,0072205	0,72205	30,217
5,123	25,582	0,22844	0,22844	511,63	0,0076147	0,76147	30,228
5,589	28,927	0,26265	0,26265	578,55	0,008755	0,8755	30,263
6,055	30,089	0,27606	0,27606	601,77	0,009202	0,9202	30,276
6,521	32,795	0,30622	0,30622	655,9	0,010207	1,0207	30,306
6,986	34,047	0,32252	0,32252	680,94	0,010751	1,0751	30,323
7,452	36,574	0,35222	0,35222	731,48	0,011741	1,1741	30,352
7,918	37,751	0,36974	0,36974	755,01	0,012325	1,2325	30,37
8,384	40,024	0,39695	0,39695	800,48	0,013232	1,3232	30,397
8,849	41,09	0,4156	0,4156	821,8	0,013853	1,3853	30,416
9,315	42,886	0,4426	0,4426	857,72	0,014753	1,4753	30,443
9,781	44,376	0,46166	0,46166	887,53	0,015389	1,5389	30,462
10,25	46,427	0,48972	0,48972	928,54	0,016324	1,6324	30,49
10,71	47,388	0,50936	0,50936	947,77	0,016979	1,6979	30,509
11,18	49,178	0,53509	0,53509	983,56	0,017836	1,7836	30,535
11,64	50,305	0,55693	0,55693	1006,1	0,018564	1,8564	30,557
12,11	51,605	0,58177	0,58177	1032,1	0,019392	1,9392	30,582
12,58	52,53	0,60213	0,60213	1050,6	0,020071	2,0071	30,602
13,04	54,297	0,62748	0,62748	1085,9	0,020916	2,0916	30,627
13,51	55,21	0,64993	0,64993	1104,2	0,021664	2,1664	30,65
13,97	56,564	0,67412	0,67412	1131,3	0,022471	2,2471	30,674
14,44	57,263	0,69779	0,69779	1145,3	0,02326	2,326	30,698
14,9	58,517	0,72114	0,72114	1170,3	0,024038	2,4038	30,721
15,37	59,365	0,74388	0,74388	1187,3	0,024796	2,4796	30,744
15,84	60,334	0,76546	0,76546	1206,7	0,025515	2,5515	30,765
16,3	60,883	0,79217	0,79217	1217,7	0,026406	2,6406	30,792
16,77	61,66	0,81231	0,81231	1233,2	0,027077	2,7077	30,812
17,23	62,268	0,83744	0,83744	1245,4	0,027915	2,7915	30,837
17,7	62,788	0,85918	0,85918	1255,8	0,028639	2,8639	30,859
18,16	63,252	0,88508	0,88508	1265	0,029503	2,9503	30,885
18,63	63,611	0,90375	0,90375	1272,2	0,030125	3,0125	30,904
19,1	63,741	0,93307	0,93307	1274,8	0,031102	3,1102	30,933
19,56	62,894	0,95016	0,95016	1257,9	0,031672	3,1672	30,95
20,03	63,864	0,98005	0,98005	1277,3	0,032668	3,2668	30,98
20,49	64,153	0,9975	0,9975	1283,1	0,03325	3,325	30,998
20,96	64,996	1,0276	1,0276	1299,9	0,034254	3,4254	31,028
21,42	64,935	1,0425	1,0425	1298,7	0,034749	3,4749	31,042
21,89	65,843	1,0753	1,0753	1316,9	0,035843	3,5843	31,075
22,36	65,436	1,0891	1,0891	1308,7	0,036305	3,6305	31,089
22,82	66,169	1,1191	1,1191	1323,4	0,037302	3,7302	31,119
23,29	66,147	1,1342	1,1342	1322,9	0,037806	3,7806	31,134
23,75	66,998	1,1701	1,1701	1340	0,039004	3,9004	31,17
24,22	66,358	1,1822	1,1822	1327,2	0,039407	3,9407	31,182
24,68	67,613	1,2168	1,2168	1352,3	0,040561	4,0561	31,217
25,15	66,864	1,2289	1,2289	1337,3	0,040964	4,0964	31,229
25,62	67,906	1,2635	1,2635	1358,1	0,042118	4,2118	31,264
26,08	67,454	1,275	1,275	1349,1	0,0425	4,25	31,275
26,55	67,948	1,3095	1,3095	1359	0,043649	4,3649	31,309
27,01	67,342	1,3224	1,3224	1346,8	0,04408	4,408	31,322
27,48	68,456	1,3572	1,3572	1369,1	0,045239	4,5239	31,357
27,95	67,154	1,3706	1,3706	1343,1	0,045686	4,5686	31,371
28,41	68,421	1,402	1,402	1368,4	0,046734	4,6734	31,402
28,88	67,356	1,4177	1,4177	1347,1	0,047256	4,7256	31,418
29,34	68,157	1,4449	1,4449	1363,1	0,048165	4,8165	31,445
29,81	66,538	1,4625	1,4625	1330,8	0,048749	4,8749	31,462
30,27	67,581	1,4902	1,4902	1351,6	0,049673	4,9673	31,49
30,74	66,722	1,5104	1,5104	1334,4	0,050345	5,0345	31,51
31,21	66,953	1,5338	1,5338	1339,1	0,051127	5,1127	31,534
31,67	65,988	1,5576	1,5576	1319,8	0,05192	5,192	31,558
32,14	66,34	1,5819	1,5819	1326,8	0,052731	5,2731	31,582
32,6	65,614	1,6046	1,6046	1312,3	0,053486	5,3486	31,605
33,07	66,495	1,6311	1,6311	1329,9	0,054369	5,4369	31,631
33,53	65,83	1,6516	1,6516	1316,6	0,055052	5,5052	31,652
34	65,916	1,6733	1,6733	1318,3	0,055777	5,5777	31,673
34,47	64,518	1,6981	1,6981	1290,4	0,056602	5,6602	31,698
34,93	65,239	1,7233	1,7233	1304,8	0,057442	5,7442	31,723
35,4	63,755	1,7447	1,7447	1275,1	0,058157	5,8157	31,745
35,86	64,573	1,7687	1,7687	1291,5	0,058958	5,8958	31,769
36,33	64,258	1,7908	1,7908	1285,2	0,059695	5,9695	31,791
36,79	64,697	1,8146	1,8146	1293,9	0,060488	6,0488	31,815
37,26	64,858	1,8381	1,8381	1297,2	0,061269	6,1269	31,838
37,73	65,428	1,8619	1,8619	1308,6	0,062063	6,2063	31,862
38,19	65,524	1,8853	1,8853	1310,5	0,062842	6,2842	31,885
38,66	65,67	1,9052	1,9052	1313,4	0,063506	6,3506	31,905
39,12	65,612	1,933	1,933	1312,2	0,064432	6,4432	31,933
39,59	65,663	1,9522	1,9522	1313,3	0,065075	6,5075	31,952
40,05	66,086	1,9814	1,9814	1321,7	0,066047	6,6047	31,981
40,52	65,837	1,9994	1,9994	1316,7	0,066646	6,6646	31,999
40,99	66,708	2,0299	2,0299	1334,2	0,067663	6,7663	32,03
41,45	66,169	2,0449	2,0449	1323,4	0,068162	6,8162	32,045
41,92	66,617	2,0743	2,0743	1332,3	0,069142	6,9142	32,074
42,38	66,381	2,0928	2,0928	1327,6	0,069761	6,9761	32,093
42,85	66,224	2,1241	2,1241	1324,5	0,070802	7,0802	32,124
43,31	65,385	2,1377	2,1377	1307,7	0,071255	7,1255	32,138
43,78	66,281	2,171	2,171	1325,6	0,072367	7,2367	32,171
44,25	65,072	2,1822	2,1822	1301,4	0,072741	7,2741	32,182
44,71	66,528	2,2178	2,2178	1330,6	0,073926	7,3926	32,218
45,18	65,452	2,2293	2,2293	1309	0,07431	7,431	32,229
45,64	66,793	2,2647	2,2647	1335,9	0,07549	7,549	32,265
46,11	65,772	2,2762	2,2762	1315,4	0,075875	7,5875	32,276
46,58	66,814	2,313	2,313	1336,3	0,077099	7,7099	32,313
47,04	65,412	2,3231	2,3231	1308,2	0,077436	7,7436	32,323
47,51	66,576	2,3579	2,3579	1331,5	0,078597	7,8597	32,358
47,97	65,344	2,3697	2,3697	1306,9	0,078991	7,8991	32,37
48,44	66,916	2,4061	2,4061	1338,3	0,080202	8,0202	32,406
48,9	65,438	2,4162	2,4162	1308,8	0,080541	8,0541	32,416
49,37	66,989	2,4507	2,4507	1339,8	0,081691	8,1691	32,451
49,84	65,851	2,465	2,465	1317	0,082166	8,2166	32,465
50,3	67,244	2,4957	2,4957	1344,9	0,08319	8,319	32,496
50,77	66,512	2,5126	2,5126	1330,2	0,083754	8,3754	32,513
51,23	67,339	2,5395	2,5395	1346,8	0,084651	8,4651	32,54
51,7	66,779	2,5577	2,5577	1335,6	0,085256	8,5256	32,558
52,16	67,555	2,5835	2,5835	1351,1	0,086116	8,6116	32,583
52,63	66,823	2,6046	2,6046	1336,5	0,086821	8,6821	32,605
53,1	67,58	2,6297	2,6297	1351,6	0,087657	8,7657	32,63
53,56	67,009	2,6519	2,6519	1340,2	0,088398	8,8398	32,652
54,03	67,662	2,6768	2,6768	1353,2	0,089227	8,9227	32,677
54,49	67,098	2,6968	2,6968	1342	0,089892	8,9892	32,697
54,96	67,492	2,7218	2,7218	1349,8	0,090728	9,0728	32,722
55,42	67,272	2,7448	2,7448	1345,4	0,091494	9,1494	32,745
55,89	67,772	2,7699	2,7699	1355,4	0,092331	9,2331	32,77
56,36	67,632	2,792	2,792	1352,6	0,093068	9,3068	32,792
56,82	68,036	2,8157	2,8157	1360,7	0,093857	9,3857	32,816
57,29	67,77	2,8407	2,8407	1355,4	0,09469	9,469	32,841
57,75	68,209	2,8631	2,8631	1364,2	0,095438	9,5438	32,863
58,22	67,751	2,886	2,886	1355	0,096201	9,6201	32,886
58,68	68,13	2,9087	2,9087	1362,6	0,096957	9,6957	32,909
59,15	67,829	2,9333	2,9333	1356,6	0,097776	9,7776	32,933
59,62	67,961	2,9548	2,9548	1359,2	0,098492	9,8492	32,955
60,08	67,455	2,9804	2,9804	1349,1	0,099348	9,9348	32,98
60,55	67,273	3,002	3,002	1345,5	0,10007	10,007	33,002
61,01	66,952	3,0273	3,0273	1339	0,10091	10,091	33,027
61,48	66,58	3,0465	3,0465	1331,6	0,10155	10,155	33,047
61,94	66,81	3,0753	3,0753	1336,2	0,10251	10,251	33,075
62,41	66,429	3,0931	3,0931	1328,6	0,1031	10,31	33,093
62,88	66,897	3,1217	3,1217	1337,9	0,10406	10,406	33,122
63,34	66,479	3,1392	3,1392	1329,6	0,10464	10,464	33,139
63,81	67,188	3,1706	3,1706	1343,8	0,10569	10,569	33,171
64,27	66,422	3,186	3,186	1328,4	0,1062	10,62	33,186
64,74	67,268	3,2182	3,2182	1345,4	0,10727	10,727	33,218
65,21	66,31	3,2315	3,2315	1326,2	0,10772	10,772	33,231
65,67	67,657	3,2667	3,2667	1353,1	0,10889	10,889	33,267
66,14	66,348	3,2763	3,2763	1327	0,10921	10,921	33,276
66,6	67,66	3,3128	3,3128	1353,2	0,11043	11,043	33,313
67,07	66,565	3,3236	3,3236	1331,3	0,11079	11,079	33,324
67,53	67,881	3,3621	3,3621	1357,6	0,11207	11,207	33,362
68	66,853	3,3705	3,3705	1337,1	0,11235	11,235	33,371
68,47	67,965	3,4038	3,4038	1359,3	0,11346	11,346	33,404
68,93	66,873	3,4164	3,4164	1337,5	0,11388	11,388	33,416
69,4	68,701	3,4555	3,4555	1374	0,11518	11,518	33,455
69,86	67,267	3,4648	3,4648	1345,3	0,11549	11,549	33,465
70,33	68,578	3,4986	3,4986	1371,6	0,11662	11,662	33,499
70,79	67,387	3,5113	3,5113	1347,7	0,11704	11,704	33,511
71,26	68,672	3,5459	3,5459	1373,4	0,1182	11,82	33,546
71,73	67,099	3,556	3,556	1342	0,11853	11,853	33,556
72,19	68,37	3,5884	3,5884	1367,4	0,11961	11,961	33,588
72,66	67,625	3,6063	3,6063	1352,5	0,12021	12,021	33,606
73,12	68,172	3,6344	3,6344	1363,4	0,12115	12,115	33,634
73,59	66,841	3,6525	3,6525	1336,8	0,12175	12,175	33,652
74,05	67,35	3,6795	3,6795	1347	0,12265	12,265	33,68
74,52	66,618	3,6991	3,6991	1332,4	0,1233	12,33	33,699
74,99	67,063	3,7259	3,7259	1341,3	0,1242	12,42	33,726
75,45	66,598	3,7476	3,7476	1332	0,12492	12,492	33,748
75,92	66,997	3,7708	3,7708	1339,9	0,12569	12,569	33,771
76,38	66,502	3,7954	3,7954	1330	0,12651	12,651	33,795
76,85	66,641	3,8175	3,8175	1332,8	0,12725	12,725	33,817
77,31	66,413	3,8419	3,8419	1328,3	0,12806	12,806	33,842
77,78	66,61	3,8635	3,8635	1332,2	0,12878	12,878	33,863
78,25	66,476	3,8867	3,8867	1329,5	0,12956	12,956	33,887
78,71	66,991	3,9111	3,9111	1339,8	0,13037	13,037	33,911
79,18	66,623	3,9338	3,9338	1332,5	0,13113	13,113	33,934
79,64	67,099	3,958	3,958	1342	0,13193	13,193	33,958
80,11	67,149	3,9821	3,9821	1343	0,13274	13,274	33,982
80,58	67,385	4,0016	4,0016	1347,7	0,13339	13,339	34,002
81,04	67,591	4,0293	4,0293	1351,8	0,13431	13,431	34,029
81,51	67,492	4,0495	4,0495	1349,8	0,13498	13,498	34,049
81,97	67,752	4,0745	4,0745	1355	0,13582	13,582	34,074
82,44	67,779	4,0957	4,0957	1355,6	0,13652	13,652	34,096
82,9	68,048	4,1229	4,1229	1361	0,13743	13,743	34,123
83,37	68,072	4,1436	4,1436	1361,4	0,13812	13,812	34,144
83,84	68,233	4,1703	4,1703	1364,7	0,13901	13,901	34,17
84,3	67,774	4,1878	4,1878	1355,5	0,13959	13,959	34,188
84,77	68,038	4,216	4,216	1360,8	0,14053	14,053	34,216
85,23	67,758	4,2344	4,2344	1355,2	0,14115	14,115	34,234
85,7	67,905	4,2632	4,2632	1358,1	0,14211	14,211	34,263
86,16	67,54	4,2807	4,2807	1350,8	0,14269	14,269	34,281
86,63	68,201	4,3118	4,3118	1364	0,14373	14,373	34,312
87,1	67,455	4,3244	4,3244	1349,1	0,14415	14,415	34,324
87,56	68,399	4,3605	4,3605	1368	0,14535	14,535	34,36
88,03	67,054	4,371	4,371	1341,1	0,1457	14,57	34,371
88,49	68,562	4,4083	4,4083	1371,2	0,14694	14,694	34,408
88,96	67,304	4,4199	4,4199	1346,1	0,14733	14,733	34,42
89,42	67,977	4,4516	4,4516	1359,5	0,14839	14,839	34,452
89,89	67,18	4,467	4,467	1343,6	0,1489	14,89	34,467
90,36	68,688	4,504	4,504	1373,8	0,15013	15,013	34,504
90,82	66,702	4,5105	4,5105	1334	0,15035	15,035	34,51
91,29	68,032	4,5459	4,5459	1360,6	0,15153	15,153	34,546
91,75	67,23	4,5597	4,5597	1344,6	0,15199	15,199	34,56
92,22	68,263	4,5921	4,5921	1365,3	0,15307	15,307	34,592
92,68	67,322	4,6075	4,6075	1346,4	0,15358	15,358	34,608
93,15	68,117	4,6375	4,6375	1362,3	0,15458	15,458	34,637
93,62	67,316	4,6535	4,6535	1346,3	0,15512	15,512	34,654
94,08	68,126	4,6827	4,6827	1362,5	0,15609	15,609	34,683
94,55	67,345	4,7011	4,7011	1346,9	0,1567	15,67	34,701
95,01	68,074	4,7284	4,7284	1361,5	0,15761	15,761	34,728
95,48	67,527	4,7479	4,7479	1350,5	0,15826	15,826	34,748
95,94	68,226	4,7747	4,7747	1364,5	0,15916	15,916	34,775
96,41	67,655	4,7941	4,7941	1353,1	0,1598	15,98	34,794
96,88	68,275	4,8216	4,8216	1365,5	0,16072	16,072	34,822
97,34	67,66	4,8412	4,8412	1353,2	0,16137	16,137	34,841
97,81	68,069	4,8659	4,8659	1361,4	0,1622	16,22	34,866
98,27	67,892	4,8895	4,8895	1357,8	0,16298	16,298	34,89
98,74	68,011	4,9122	4,9122	1360,2	0,16374	16,374	34,912
99,21	67,73	4,9357	4,9357	1354,6	0,16452	16,452	34,936
99,67	67,769	4,9576	4,9576	1355,4	0,16525	16,525	34,958
100,1	67,977	4,9842	4,9842	1359,5	0,16614	16,614	34,984
100,6	67,906	5,0056	5,0056	1358,1	0,16685	16,685	35,006
101,1	67,932	5,0292	5,0292	1358,6	0,16764	16,764	35,029
101,5	67,865	5,0504	5,0504	1357,3	0,16835	16,835	35,05
102	68,083	5,077	5,077	1361,7	0,16923	16,923	35,077
102,5	67,818	5,0968	5,0968	1356,4	0,16989	16,989	35,097
102,9	68,06	5,123	5,123	1361,2	0,17077	17,077	35,123
103,4	67,783	5,143	5,143	1355,7	0,17143	17,143	35,143
103,9	68,241	5,1716	5,1716	1364,8	0,17239	17,239	35,172
104,3	67,843	5,1901	5,1901	1356,9	0,173	17,3	35,19
104,8	68,264	5,2194	5,2194	1365,3	0,17398	17,398	35,219
105,3	67,551	5,235	5,235	1351	0,1745	17,45	35,235
105,7	68,167	5,2658	5,2658	1363,3	0,17553	17,553	35,266
106,2	67,757	5,283	5,283	1355,1	0,1761	17,61	35,283
106,7	68,319	5,3131	5,3131	1366,4	0,1771	17,71	35,313
107,1	67,671	5,3281	5,3281	1353,4	0,1776	17,76	35,328
107,6	68,51	5,3609	5,3609	1370,2	0,1787	17,87	35,361
108,1	67,664	5,3738	5,3738	1353,3	0,17913	17,913	35,374
108,5	68,265	5,406	5,406	1365,3	0,1802	18,02	35,406
109	67,852	5,4206	5,4206	1357	0,18069	18,069	35,421
109,5	68,717	5,4536	5,4536	1374,3	0,18179	18,179	35,454
109,9	67,899	5,4679	5,4679	1358	0,18226	18,226	35,468
110,4	68,679	5,5009	5,5009	1373,6	0,18336	18,336	35,501
110,8	68,076	5,5142	5,5142	1361,5	0,18381	18,381	35,514
111,3	69,363	5,5509	5,5509	1387,3	0,18503	18,503	35,551
111,8	67,866	5,5598	5,5598	1357,3	0,18533	18,533	35,56
112,2	69,099	5,5956	5,5956	1382	0,18652	18,652	35,596
112,7	67,965	5,6061	5,6061	1359,3	0,18687	18,687	35,606
113,2	68,863	5,6402	5,6402	1377,3	0,18801	18,801	35,64
113,6	67,836	5,655	5,655	1356,7	0,1885	18,85	35,655
114,1	68,626	5,684	5,684	1372,5	0,18947	18,947	35,684
114,6	67,908	5,7027	5,7027	1358,2	0,19009	19,009	35,703
115	68,736	5,7322	5,7322	1374,7	0,19107	19,107	35,732
115,5	67,995	5,7466	5,7466	1359,9	0,19155	19,155	35,747
116	68,739	5,7779	5,7779	1374,8	0,1926	19,26	35,778
116,4	67,65	5,7947	5,7947	1353	0,19316	19,316	35,795
116,9	68,125	5,8219	5,8219	1362,5	0,19406	19,406	35,822
117,4	67,5	5,8422	5,8422	1350	0,19474	19,474	35,842
117,8	68,132	5,8683	5,8683	1362,6	0,19561	19,561	35,868
118,3	67,825	5,8896	5,8896	1356,5	0,19632	19,632	35,89
118,8	68,225	5,9149	5,9149	1364,5	0,19716	19,716	35,915
119,2	67,989	5,9371	5,9371	1359,8	0,1979	19,79	35,937
119,7	68,296	5,9613	5,9613	1365,9	0,19871	19,871	35,961
120,2	68,015	5,9827	5,9827	1360,3	0,19942	19,942	35,983
120,6	68,23	6,0061	6,0061	1364,6	0,2002	20,02	36,006
121,1	68,358	6,0305	6,0305	1367,2	0,20102	20,102	36,031
121,6	68,406	6,0536	6,0536	1368,1	0,20179	20,179	36,054
122	68,278	6,0773	6,0773	1365,6	0,20258	20,258	36,077
122,5	68,428	6,0992	6,0992	1368,6	0,20331	20,331	36,099
123	68,697	6,1271	6,1271	1373,9	0,20424	20,424	36,127
123,4	68,299	6,1458	6,1458	1366	0,20486	20,486	36,146
123,9	68,376	6,1704	6,1704	1367,5	0,20568	20,568	36,17
124,4	68,456	6,1911	6,1911	1369,1	0,20637	20,637	36,191
124,8	68,655	6,221	6,221	1373,1	0,20737	20,737	36,221
125,3	68,19	6,2371	6,2371	1363,8	0,2079	20,79	36,237
125,8	68,689	6,2665	6,2665	1373,8	0,20888	20,888	36,266
126,2	68,346	6,2841	6,2841	1366,9	0,20947	20,947	36,284
126,7	68,921	6,3137	6,3137	1378,4	0,21046	21,046	36,314
127,2	68,242	6,33	6,33	1364,8	0,211	21,1	36,33
127,6	68,543	6,3584	6,3584	1370,9	0,21195	21,195	36,358
128,1	67,815	6,3756	6,3756	1356,3	0,21252	21,252	36,376
128,5	68,489	6,4087	6,4087	1369,8	0,21362	21,362	36,409
129	67,672	6,4225	6,4225	1353,4	0,21408	21,408	36,423
129,5	68,253	6,4538	6,4538	1365,1	0,21513	21,513	36,454
129,9	67,596	6,4701	6,4701	1351,9	0,21567	21,567	36,47
130,4	67,983	6,5015	6,5015	1359,7	0,21672	21,672	36,502
130,9	66,686	6,5152	6,5152	1333,7	0,21717	21,717	36,515
131,3	67,652	6,5464	6,5464	1353	0,21821	21,821	36,546
131,8	66,849	6,563	6,563	1337	0,21877	21,877	36,563
132,3	67,924	6,5984	6,5984	1358,5	0,21995	21,995	36,598
132,7	66,8	6,6077	6,6077	1336	0,22026	22,026	36,608
133,2	68,047	6,643	6,643	1360,9	0,22143	22,143	36,643
133,7	67,387	6,657	6,657	1347,7	0,2219	22,19	36,657
134,1	68,202	6,6871	6,6871	1364	0,2229	22,29	36,687
134,6	67,313	6,7003	6,7003	1346,3	0,22334	22,334	36,7
135,1	68,493	6,7338	6,7338	1369,9	0,22446	22,446	36,734
135,5	68,041	6,7505	6,7505	1360,8	0,22502	22,502	36,75
136	68,618	6,7775	6,7775	1372,4	0,22592	22,592	36,778
136,5	68,236	6,7958	6,7958	1364,7	0,22653	22,653	36,796
136,9	68,816	6,8237	6,8237	1376,3	0,22746	22,746	36,824
137,4	68,28	6,8419	6,8419	1365,6	0,22806	22,806	36,842
137,9	68,733	6,868	6,868	1374,7	0,22893	22,893	36,868
138,3	68,383	6,8889	6,8889	1367,7	0,22963	22,963	36,889
138,8	68,829	6,9151	6,9151	1376,6	0,2305	23,05	36,915
139,3	68,466	6,935	6,935	1369,3	0,23117	23,117	36,935
139,7	69,01	6,9624	6,9624	1380,2	0,23208	23,208	36,962
140,2	68,509	6,9822	6,9822	1370,2	0,23274	23,274	36,982
140,7	68,947	7,0077	7,0077	1378,9	0,23359	23,359	37,008
141,1	68,907	7,0305	7,0305	1378,1	0,23435	23,435	37,03
141,6	69,217	7,056	7,056	1384,3	0,2352	23,52	37,056
142,1	68,892	7,0774	7,0774	1377,8	0,23591	23,591	37,077
142,5	68,871	7,0992	7,0992	1377,4	0,23664	23,664	37,099
143	69	7,1247	7,1247	1380	0,23749	23,749	37,125
143,5	68,929	7,1467	7,1467	1378,6	0,23822	23,822	37,147
143,9	69,058	7,1715	7,1715	1381,2	0,23905	23,905	37,171
144,4	68,974	7,1922	7,1922	1379,5	0,23974	23,974	37,192
144,8	69,108	7,2184	7,2184	1382,2	0,24061	24,061	37,218
145,3	69,152	7,2412	7,2412	1383	0,24137	24,137	37,241
145,8	69,448	7,268	7,268	1389	0,24227	24,227	37,268
146,2	69,178	7,2866	7,2866	1383,6	0,24289	24,289	37,287
146,7	69,373	7,3126	7,3126	1387,5	0,24375	24,375	37,313
147,2	69,039	7,3307	7,3307	1380,8	0,24436	24,436	37,331
147,6	69,595	7,3612	7,3612	1391,9	0,24537	24,537	37,361
148,1	69,117	7,3782	7,3782	1382,3	0,24594	24,594	37,378
148,6	69,651	7,4085	7,4085	1393	0,24695	24,695	37,409
149	69,235	7,4259	7,4259	1384,7	0,24753	24,753	37,426
149,5	69,849	7,457	7,457	1397	0,24857	24,857	37,457
150	69,038	7,4702	7,4702	1380,8	0,24901	24,901	37,47
150,4	69,692	7,5017	7,5017	1393,8	0,25006	25,006	37,502
150,9	68,888	7,517	7,517	1377,8	0,25057	25,057	37,517
151,4	70,164	7,5522	7,5522	1403,3	0,25174	25,174	37,552
151,8	68,836	7,5617	7,5617	1376,7	0,25206	25,206	37,562
152,3	69,866	7,5964	7,5964	1397,3	0,25321	25,321	37,596
152,8	68,98	7,6093	7,6093	1379,6	0,25364	25,364	37,609
153,2	69,98	7,6439	7,6439	1399,6	0,2548	25,48	37,644
153,7	69,262	7,6587	7,6587	1385,2	0,25529	25,529	37,659
154,2	69,995	7,6907	7,6907	1399,9	0,25636	25,636	37,691
154,6	68,922	7,7023	7,7023	1378,4	0,25674	25,674	37,702
155,1	69,885	7,735	7,735	1397,7	0,25783	25,783	37,735
155,6	69,202	7,7502	7,7502	1384	0,25834	25,834	37,75
156	69,72	7,7795	7,7795	1394,4	0,25932	25,932	37,78
156,5	69,382	7,7989	7,7989	1387,6	0,25996	25,996	37,799
157	69,706	7,8248	7,8248	1394,1	0,26083	26,083	37,825
157,4	69,381	7,8439	7,8439	1387,6	0,26146	26,146	37,844
157,9	69,829	7,8718	7,8718	1396,6	0,26239	26,239	37,872
158,4	69,362	7,8905	7,8905	1387,2	0,26302	26,302	37,89
158,8	69,899	7,9162	7,9162	1398	0,26387	26,387	37,916
159,3	69,443	7,9377	7,9377	1388,9	0,26459	26,459	37,938
159,8	69,863	7,9652	7,9652	1397,3	0,26551	26,551	37,965
160,2	69,464	7,984	7,984	1389,3	0,26613	26,613	37,984
160,7	69,815	8,0096	8,0096	1396,3	0,26699	26,699	38,01
161,2	69,595	8,0303	8,0303	1391,9	0,26768	26,768	38,03
161,6	69,936	8,0565	8,0565	1398,7	0,26855	26,855	38,056
162,1	69,62	8,0773	8,0773	1392,4	0,26924	26,924	38,077
162,5	69,837	8,1012	8,1012	1396,7	0,27004	27,004	38,101
163	69,708	8,124	8,124	1394,2	0,2708	27,08	38,124
163,5	69,786	8,1504	8,1504	1395,7	0,27168	27,168	38,15
163,9	69,744	8,1723	8,1723	1394,9	0,27241	27,241	38,172
164,4	69,833	8,1945	8,1945	1396,7	0,27315	27,315	38,195
164,9	69,7	8,2193	8,2193	1394	0,27398	27,398	38,219
165,3	69,781	8,2415	8,2415	1395,6	0,27472	27,472	38,241
165,8	69,81	8,2671	8,2671	1396,2	0,27557	27,557	38,267
166,3	69,795	8,2881	8,2881	1395,9	0,27627	27,627	38,288
166,7	70,06	8,3154	8,3154	1401,2	0,27718	27,718	38,315
167,2	69,899	8,3339	8,3339	1398	0,2778	27,78	38,334
167,7	70,168	8,3622	8,3622	1403,4	0,27874	27,874	38,362
168,1	69,758	8,3794	8,3794	1395,2	0,27931	27,931	38,379
168,6	70,392	8,4104	8,4104	1407,8	0,28035	28,035	38,41
169,1	69,71	8,4252	8,4252	1394,2	0,28084	28,084	38,425
169,5	70,29	8,4563	8,4563	1405,8	0,28188	28,188	38,456
170	69,657	8,4711	8,4711	1393,1	0,28237	28,237	38,471
170,5	70,355	8,5035	8,5035	1407,1	0,28345	28,345	38,504
170,9	69,751	8,5192	8,5192	1395	0,28397	28,397	38,519
171,4	70,093	8,5498	8,5498	1401,9	0,28499	28,499	38,55
171,9	69,777	8,5655	8,5655	1395,5	0,28552	28,552	38,566
172,3	70,737	8,5991	8,5991	1414,7	0,28664	28,664	38,599
172,8	69,818	8,6116	8,6116	1396,4	0,28705	28,705	38,612
173,3	70,614	8,644	8,644	1412,3	0,28813	28,813	38,644
173,7	69,679	8,6564	8,6564	1393,6	0,28855	28,855	38,656
174,2	70,831	8,6924	8,6924	1416,6	0,28975	28,975	38,692
174,7	69,698	8,7032	8,7032	1394	0,29011	29,011	38,703
175,1	70,555	8,7377	8,7377	1411,1	0,29126	29,126	38,738
175,6	69,686	8,7507	8,7507	1393,7	0,29169	29,169	38,751
176,1	70,642	8,7843	8,7843	1412,8	0,29281	29,281	38,784
176,5	69,995	8,7995	8,7995	1399,9	0,29332	29,332	38,799
177	70,628	8,8302	8,8302	1412,6	0,29434	29,434	38,83
177,5	69,84	8,8439	8,8439	1396,8	0,2948	29,48	38,844
177,9	70,487	8,8745	8,8745	1409,7	0,29582	29,582	38,874
178,4	69,867	8,892	8,892	1397,3	0,2964	29,64	38,892
178,8	70,497	8,9194	8,9194	1409,9	0,29731	29,731	38,919
179,3	70,007	8,9386	8,9386	1400,1	0,29795	29,795	38,939
179,8	70,287	8,9655	8,9655	1405,7	0,29885	29,885	38,965
180,2	69,865	8,9839	8,9839	1397,3	0,29946	29,946	38,984
180,7	70,507	9,0124	9,0124	1410,1	0,30041	30,041	39,012
181,2	70,233	9,0324	9,0324	1404,7	0,30108	30,108	39,032
181,6	70,577	9,0583	9,0583	1411,5	0,30194	30,194	39,058
182,1	70,231	9,0794	9,0794	1404,6	0,30265	30,265	39,079
182,6	70,389	9,1052	9,1052	1407,8	0,30351	30,351	39,105
183	70,439	9,1282	9,1282	1408,8	0,30427	30,427	39,128
183,5	70,539	9,151	9,151	1410,8	0,30503	30,503	39,151
184	70,282	9,1728	9,1728	1405,6	0,30576	30,576	39,173
184,4	70,373	9,1947	9,1947	1407,5	0,30649	30,649	39,195
184,9	70,283	9,2191	9,2191	1405,7	0,3073	30,73	39,219
185,4	70,42	9,2428	9,2428	1408,4	0,30809	30,809	39,243
185,8	70,496	9,2671	9,2671	1409,9	0,3089	30,89	39,267
186,3	70,565	9,2912	9,2912	1411,3	0,30971	30,971	39,291
186,8	70,497	9,3152	9,3152	1409,9	0,31051	31,051	39,315
187,2	70,33	9,3351	9,3351	1406,6	0,31117	31,117	39,335
187,7	70,597	9,3626	9,3626	1411,9	0,31209	31,209	39,363
188,2	70,453	9,3834	9,3834	1409,1	0,31278	31,278	39,383
188,6	70,402	9,4069	9,4069	1408	0,31356	31,356	39,407
189,1	70,345	9,4283	9,4283	1406,9	0,31428	31,428	39,428
189,6	70,719	9,4578	9,4578	1414,4	0,31526	31,526	39,458
190	70,182	9,4731	9,4731	1403,6	0,31577	31,577	39,473
190,5	70,661	9,5048	9,5048	1413,2	0,31683	31,683	39,505
191	70,14	9,52	9,52	1402,8	0,31733	31,733	39,52
191,4	70,778	9,5505	9,5505	1415,6	0,31835	31,835	39,551
191,9	70,186	9,567	9,567	1403,7	0,3189	31,89	39,567
192,4	71,018	9,5988	9,5988	1420,4	0,31996	31,996	39,599
192,8	70,149	9,6095	9,6095	1403	0,32032	32,032	39,609
193,3	71,167	9,6467	9,6467	1423,3	0,32156	32,156	39,647
193,8	70,305	9,6583	9,6583	1406,1	0,32194	32,194	39,658
194,2	71,272	9,6947	9,6947	1425,4	0,32316	32,316	39,695
194,7	70,271	9,7038	9,7038	1405,4	0,32346	32,346	39,704
195,2	71,452	9,742	9,742	1429	0,32473	32,473	39,742
195,6	70,411	9,7508	9,7508	1408,2	0,32503	32,503	39,751
196,1	71,383	9,786	9,786	1427,7	0,3262	32,62	39,786
196,5	70,544	9,7988	9,7988	1410,9	0,32663	32,663	39,799
197	71,617	9,8344	9,8344	1432,3	0,32781	32,781	39,834
197,5	70,636	9,8465	9,8465	1412,7	0,32822	32,822	39,846
197,9	71,311	9,8781	9,8781	1426,2	0,32927	32,927	39,878
198,4	70,46	9,8921	9,8921	1409,2	0,32974	32,974	39,892
198,9	71,125	9,9235	9,9235	1422,5	0,33078	33,078	39,924
199,3	70,661	9,9414	9,9414	1413,2	0,33138	33,138	39,941
199,8	70,926	9,9679	9,9679	1418,5	0,33226	33,226	39,968
200,3	70,413	9,9862	9,9862	1408,3	0,33287	33,287	39,986
200,7	70,824	10,014	10,014	1416,5	0,3338	33,38	40,014
201,2	70,624	10,034	10,034	1412,5	0,33448	33,448	40,034
201,7	70,826	10,059	10,059	1416,5	0,33531	33,531	40,059
202,1	70,647	10,081	10,081	1412,9	0,33605	33,605	40,081
202,6	70,881	10,105	10,105	1417,6	0,33683	33,683	40,105
203,1	70,718	10,127	10,127	1414,4	0,33755	33,755	40,127
203,5	70,962	10,152	10,152	1419,2	0,33841	33,841	40,152
204	70,55	10,175	10,175	1411	0,33918	33,918	40,175
204,5	71,003	10,2	10,2	1420,1	0,33999	33,999	40,2
204,9	70,821	10,222	10,222	1416,4	0,34074	34,074	40,222
205,4	70,818	10,244	10,244	1416,4	0,34147	34,147	40,244
205,9	70,862	10,268	10,268	1417,2	0,34227	34,227	40,268
206,3	70,912	10,289	10,289	1418,2	0,34297	34,297	40,289
206,8	71,083	10,316	10,316	1421,7	0,34385	34,385	40,316
207,3	70,962	10,337	10,337	1419,2	0,34456	34,456	40,337
207,7	71,148	10,362	10,362	1423	0,3454	34,54	40,362
208,2	71,008	10,382	10,382	1420,2	0,34607	34,607	40,382
208,7	71,159	10,409	10,409	1423,2	0,34695	34,695	40,409
209,1	71,114	10,43	10,43	1422,3	0,34768	34,768	40,43
209,6	71,219	10,456	10,456	1424,4	0,34854	34,854	40,456
210,1	70,876	10,475	10,475	1417,5	0,34916	34,916	40,475
210,5	71,24	10,503	10,503	1424,8	0,35009	35,009	40,503
211	70,986	10,524	10,524	1419,7	0,35079	35,079	40,524
211,5	71,242	10,551	10,551	1424,8	0,35172	35,172	40,551
211,9	70,948	10,569	10,569	1419	0,35229	35,229	40,569
212,4	71,361	10,597	10,597	1427,2	0,35325	35,325	40,597
212,8	70,919	10,614	10,614	1418,4	0,35379	35,379	40,614
213,3	71,621	10,646	10,646	1432,4	0,35487	35,487	40,646
213,8	70,901	10,66	10,66	1418	0,35532	35,532	40,66
214,2	71,714	10,694	10,694	1434,3	0,35647	35,647	40,694
214,7	70,874	10,707	10,707	1417,5	0,3569	35,69	40,707
215,2	71,537	10,738	10,738	1430,7	0,35793	35,793	40,738
215,6	70,906	10,753	10,753	1418,1	0,35845	35,845	40,753
216,1	71,747	10,788	10,788	1434,9	0,35958	35,958	40,788
216,6	70,872	10,799	10,799	1417,4	0,35998	35,998	40,799
217	71,623	10,832	10,832	1432,5	0,36106	36,106	40,832
217,5	70,888	10,848	10,848	1417,8	0,36159	36,159	40,848
218	72,3	10,886	10,886	1446	0,36286	36,286	40,886
218,4	71,109	10,892	10,892	1422,2	0,36305	36,305	40,892
218,9	71,971	10,928	10,928	1439,4	0,36428	36,428	40,928
219,4	70,98	10,94	10,94	1419,6	0,36466	36,466	40,94
219,8	71,979	10,974	10,974	1439,6	0,36579	36,579	40,974
220,3	71,199	10,987	10,987	1424	0,36624	36,624	40,987
220,8	71,619	11,018	11,018	1432,4	0,36727	36,727	41,018
221,2	71,294	11,035	11,035	1425,9	0,36783	36,783	41,035
221,7	71,789	11,065	11,065	1435,8	0,36882	36,882	41,065
222,2	71,309	11,083	11,083	1426,2	0,36943	36,943	41,083
222,6	71,374	11,107	11,107	1427,5	0,37022	37,022	41,107
223,1	71,27	11,128	11,128	1425,4	0,37093	37,093	41,128
223,6	71,482	11,153	11,153	1429,6	0,37177	37,177	41,153
224	71,218	11,174	11,174	1424,4	0,37247	37,247	41,174
224,5	71,462	11,201	11,201	1429,2	0,37338	37,338	41,201
225	71,247	11,222	11,222	1424,9	0,37406	37,406	41,222
225,4	71,372	11,245	11,245	1427,4	0,37484	37,484	41,245
225,9	71,328	11,269	11,269	1426,6	0,37565	37,565	41,269
226,4	71,52	11,294	11,294	1430,4	0,37647	37,647	41,294
226,8	71,425	11,316	11,316	1428,5	0,37721	37,721	41,316
227,3	71,584	11,34	11,34	1431,7	0,378	37,8	41,34
227,8	71,563	11,364	11,364	1431,3	0,3788	37,88	41,364
228,2	71,592	11,386	11,386	1431,8	0,37952	37,952	41,386
228,7	71,528	11,409	11,409	1430,6	0,38031	38,031	41,409
229,1	71,438	11,43	11,43	1428,8	0,38101	38,101	41,43
229,6	71,696	11,457	11,457	1433,9	0,38191	38,191	41,457
230,1	71,471	11,477	11,477	1429,4	0,38257	38,257	41,477
230,5	71,665	11,504	11,504	1433,3	0,38348	38,348	41,504
231	71,396	11,523	11,523	1427,9	0,38409	38,409	41,523
231,5	71,724	11,551	11,551	1434,5	0,38503	38,503	41,551
231,9	71,576	11,571	11,571	1431,5	0,38571	38,571	41,571
232,4	71,929	11,599	11,599	1438,6	0,38664	38,664	41,599
232,9	71,439	11,617	11,617	1428,8	0,38722	38,722	41,617
233,3	71,946	11,647	11,647	1438,9	0,38823	38,823	41,647
233,8	71,469	11,663	11,663	1429,4	0,38878	38,878	41,663
234,3	71,856	11,692	11,692	1437,1	0,38974	38,974	41,692
234,7	71,433	11,71	11,71	1428,7	0,39033	39,033	41,71
235,2	71,923	11,74	11,74	1438,5	0,39133	39,133	41,74
235,7	71,475	11,756	11,756	1429,5	0,39188	39,188	41,756
236,1	72,185	11,79	11,79	1443,7	0,39298	39,298	41,79
236,6	71,415	11,802	11,802	1428,3	0,39339	39,339	41,802
237,1	72,294	11,837	11,837	1445,9	0,39455	39,455	41,837
237,5	71,306	11,846	11,846	1426,1	0,39488	39,488	41,846
238	72,452	11,885	11,885	1449	0,39615	39,615	41,885
238,5	71,475	11,894	11,894	1429,5	0,39648	39,648	41,894
238,9	72,676	11,933	11,933	1453,5	0,39778	39,778	41,933
239,4	71,515	11,94	11,94	1430,3	0,398	39,8	41,94
239,9	72,396	11,976	11,976	1447,9	0,39921	39,921	41,976
240,3	71,579	11,987	11,987	1431,6	0,39957	39,957	41,987
240,8	72,296	12,021	12,021	1445,9	0,40069	40,069	42,021
241,3	71,671	12,036	12,036	1433,4	0,40119	40,119	42,036
241,7	72,293	12,067	12,067	1445,9	0,40223	40,223	42,067
242,2	71,736	12,083	12,083	1434,7	0,40277	40,277	42,083
242,7	72,234	12,112	12,112	1444,7	0,40373	40,373	42,112
243,1	71,526	12,127	12,127	1430,5	0,40422	40,422	42,127
243,6	72,092	12,159	12,159	1441,8	0,4053	40,53	42,159
244,1	71,742	12,177	12,177	1434,8	0,4059	40,59	42,177
244,5	71,972	12,202	12,202	1439,4	0,40675	40,675	42,202
245	71,651	12,223	12,223	1433	0,40742	40,742	42,223
245,5	71,83	12,246	12,246	1436,6	0,4082	40,82	42,246
245,9	71,71	12,27	12,27	1434,2	0,40902	40,902	42,27
246,4	71,793	12,294	12,294	1435,9	0,40979	40,979	42,294
246,8	71,846	12,318	12,318	1436,9	0,41059	41,059	42,318
247,3	71,908	12,34	12,34	1438,2	0,41134	41,134	42,34
247,8	71,892	12,364	12,364	1437,8	0,41214	41,214	42,364
248,2	71,937	12,387	12,387	1438,7	0,41289	41,289	42,387
248,7	71,987	12,412	12,412	1439,7	0,41372	41,372	42,412
249,2	71,953	12,433	12,433	1439,1	0,41444	41,444	42,433
249,6	71,975	12,458	12,458	1439,5	0,41525	41,525	42,458
250,1	71,933	12,48	12,48	1438,7	0,416	41,6	42,48
250,6	72,052	12,504	12,504	1441	0,41682	41,682	42,504
251	72,149	12,527	12,527	1443	0,41756	41,756	42,527
251,5	72,298	12,553	12,553	1446	0,41842	41,842	42,553
252	72,099	12,572	12,572	1442	0,41905	41,905	42,572
252,4	72,339	12,6	12,6	1446,8	0,41999	41,999	42,6
252,9	72,048	12,618	12,618	1441	0,42061	42,061	42,618
253,4	72,323	12,647	12,647	1446,5	0,42155	42,155	42,647
253,8	71,898	12,663	12,663	1438	0,42211	42,211	42,663
254,3	72,378	12,693	12,693	1447,6	0,42309	42,309	42,693
254,8	72,043	12,711	12,711	1440,9	0,42371	42,371	42,711
255,2	72,414	12,74	12,74	1448,3	0,42467	42,467	42,74
255,7	72,128	12,756	12,756	1442,6	0,42521	42,521	42,756
256,2	72,683	12,788	12,788	1453,7	0,42627	42,627	42,788
256,6	72,16	12,803	12,803	1443,2	0,42677	42,677	42,803
257,1	72,794	12,836	12,836	1455,9	0,42786	42,786	42,836
257,6	72,141	12,85	12,85	1442,8	0,42832	42,832	42,85
258	72,825	12,883	12,883	1456,5	0,42942	42,942	42,883
258,5	72,077	12,895	12,895	1441,5	0,42982	42,982	42,895
259	72,864	12,93	12,93	1457,3	0,43101	43,101	42,93
259,4	72,234	12,944	12,944	1444,7	0,43146	43,146	42,944
259,9	73,002	12,978	12,978	1460	0,43259	43,259	42,978
260,4	72,143	12,989	12,989	1442,9	0,43296	43,296	42,989
260,8	72,999	13,023	13,023	1460	0,4341	43,41	43,023
261,3	72,206	13,036	13,036	1444,1	0,43454	43,454	43,036
261,8	73,234	13,072	13,072	1464,7	0,43574	43,574	43,072
262,2	72,309	13,083	13,083	1446,2	0,43611	43,611	43,083
262,7	72,89	13,114	13,114	1457,8	0,43713	43,713	43,114
263,1	72,402	13,13	13,13	1448	0,43766	43,766	43,13
263,6	72,862	13,16	13,16	1457,2	0,43867	43,867	43,16
264,1	72,27	13,175	13,175	1445,4	0,43917	43,917	43,175
264,5	72,818	13,205	13,205	1456,4	0,44018	44,018	43,205
265	72,352	13,223	13,223	1447	0,44078	44,078	43,223
265,5	72,672	13,25	13,25	1453,4	0,44166	44,166	43,25
265,9	72,37	13,27	13,27	1447,4	0,44234	44,234	43,27
266,4	72,601	13,296	13,296	1452	0,4432	44,32	43,296
266,9	72,536	13,319	13,319	1450,7	0,44397	44,397	43,319
267,3	72,693	13,343	13,343	1453,9	0,44478	44,478	43,343
267,8	72,459	13,365	13,365	1449,2	0,4455	44,55	43,365
268,3	72,427	13,386	13,386	1448,5	0,44621	44,621	43,386
268,7	72,468	13,411	13,411	1449,4	0,44704	44,704	43,411
269,2	72,499	13,435	13,435	1450	0,44784	44,784	43,435
269,7	72,508	13,46	13,46	1450,2	0,44865	44,865	43,46
270,1	72,539	13,482	13,482	1450,8	0,44941	44,941	43,482
270,6	72,446	13,505	13,505	1448,9	0,45016	45,016	43,505
271,1	72,474	13,528	13,528	1449,5	0,45092	45,092	43,528
271,5	72,67	13,553	13,553	1453,4	0,45175	45,175	43,553
272	72,629	13,574	13,574	1452,6	0,45246	45,246	43,574
272,5	72,744	13,6	13,6	1454,9	0,45334	45,334	43,6
272,9	72,554	13,62	13,62	1451,1	0,45399	45,399	43,62
273,4	72,897	13,649	13,649	1457,9	0,45496	45,496	43,649
273,9	72,507	13,666	13,666	1450,1	0,45555	45,555	43,666
274,3	72,818	13,694	13,694	1456,4	0,45647	45,647	43,694
274,8	72,501	13,712	13,712	1450	0,45706	45,706	43,712
275,3	73,081	13,744	13,744	1461,6	0,45815	45,815	43,744
275,7	72,54	13,758	13,758	1450,8	0,45861	45,861	43,758
276,2	73,177	13,79	13,79	1463,5	0,45965	45,965	43,79
276,7	72,532	13,804	13,804	1450,6	0,46015	46,015	43,804
277,1	73,088	13,834	13,834	1461,8	0,46115	46,115	43,834
277,6	72,659	13,852	13,852	1453,2	0,46174	46,174	43,852
278,1	72,971	13,881	13,881	1459,4	0,46272	46,272	43,881
278,5	72,74	13,896	13,896	1454,8	0,4632	46,32	43,896
279	73,278	13,93	13,93	1465,6	0,46434	46,434	43,93
279,5	72,502	13,943	13,943	1450	0,46476	46,476	43,943
279,9	73,179	13,977	13,977	1463,6	0,4659	46,59	43,977
280,4	72,546	13,989	13,989	1450,9	0,4663	46,63	43,989
280,8	73,345	14,026	14,026	1466,9	0,46752	46,752	44,026
281,3	72,707	14,037	14,037	1454,1	0,46791	46,791	44,037
281,8	73,553	14,072	14,072	1471,1	0,46908	46,908	44,072
282,2	72,788	14,085	14,085	1455,8	0,46949	46,949	44,085
282,7	73,52	14,117	14,117	1470,4	0,47057	47,057	44,117
283,2	72,678	14,129	14,129	1453,6	0,47096	47,096	44,129
283,6	73,36	14,161	14,161	1467,2	0,47203	47,203	44,161
284,1	72,875	14,179	14,179	1457,5	0,47262	47,262	44,179
284,6	73,141	14,205	14,205	1462,8	0,47351	47,351	44,205
285	72,832	14,225	14,225	1456,6	0,47417	47,417	44,225
285,5	73,122	14,252	14,252	1462,4	0,47506	47,506	44,252
286	72,852	14,272	14,272	1457	0,47572	47,572	44,272
286,4	73,069	14,296	14,296	1461,4	0,47655	47,655	44,296
286,9	72,813	14,317	14,317	1456,3	0,47723	47,723	44,317
287,4	73,37	14,346	14,346	1467,4	0,47822	47,822	44,346
287,8	73,013	14,365	14,365	1460,3	0,47884	47,884	44,365
288,3	73,069	14,391	14,391	1461,4	0,47969	47,969	44,391
288,8	72,879	14,411	14,411	1457,6	0,48038	48,038	44,411
289,2	73,24	14,439	14,439	1464,8	0,48129	48,129	44,439
289,7	73,149	14,461	14,461	1463	0,48205	48,205	44,461
290,2	73,235	14,485	14,485	1464,7	0,48283	48,283	44,485
290,6	73,113	14,507	14,507	1462,3	0,48358	48,358	44,507
291,1	73,275	14,531	14,531	1465,5	0,48437	48,437	44,531
291,6	73,179	14,553	14,553	1463,6	0,48509	48,509	44,553
292	73,185	14,576	14,576	1463,7	0,48587	48,587	44,576
292,5	73,306	14,601	14,601	1466,1	0,48671	48,671	44,601
293	73,255	14,623	14,623	1465,1	0,48742	48,742	44,623
293,4	73,357	14,649	14,649	1467,1	0,48829	48,829	44,649
293,9	73,126	14,667	14,667	1462,5	0,4889	48,89	44,667
294,4	73,44	14,695	14,695	1468,8	0,48984	48,984	44,695
294,8	73,191	14,716	14,716	1463,8	0,49052	49,052	44,716
295,3	73,415	14,742	14,742	1468,3	0,49141	49,141	44,742
295,8	73,31	14,76	14,76	1466,2	0,49201	49,201	44,76
296,2	73,742	14,791	14,791	1474,8	0,49304	49,304	44,791
296,7	73,164	14,807	14,807	1463,3	0,49357	49,357	44,807
297,1	73,684	14,836	14,836	1473,7	0,49453	49,453	44,836
297,6	73,338	14,854	14,854	1466,8	0,49512	49,512	44,854
298,1	73,787	14,884	14,884	1475,7	0,49614	49,614	44,884
298,5	73,28	14,9	14,9	1465,6	0,49665	49,665	44,9
299	73,783	14,929	14,929	1475,7	0,49764	49,764	44,929
299,5	73,225	14,944	14,944	1464,5	0,49813	49,813	44,944
299,9	74,095	14,979	14,979	1481,9	0,49928	49,928	44,979
300,4	73,307	14,991	14,991	1466,1	0,49971	49,971	44,991
300,9	74,074	15,025	15,025	1481,5	0,50082	50,082	45,025
301,3	73,57	15,04	15,04	1471,4	0,50132	50,132	45,04
301,8	74,115	15,072	15,072	1482,3	0,50239	50,239	45,072
302,3	73,453	15,085	15,085	1469,1	0,50282	50,282	45,085
302,7	73,955	15,121	15,121	1479,1	0,50404	50,404	45,121
303,2	73,478	15,132	15,132	1469,6	0,50439	50,439	45,132
303,7	73,998	15,162	15,162	1480	0,50541	50,541	45,162
304,1	73,525	15,179	15,179	1470,5	0,50597	50,597	45,179
304,6	74,092	15,21	15,21	1481,8	0,50701	50,701	45,21
305,1	73,564	15,226	15,226	1471,3	0,50754	50,754	45,226
305,5	74,084	15,255	15,255	1481,7	0,5085	50,85	45,255
306	73,719	15,274	15,274	1474,4	0,50914	50,914	45,274
306,5	74,065	15,299	15,299	1481,3	0,50996	50,996	45,299
306,9	73,622	15,318	15,318	1472,4	0,51061	51,061	45,318
307,4	73,896	15,344	15,344	1477,9	0,51147	51,147	45,344
307,9	73,772	15,366	15,366	1475,4	0,51221	51,221	45,366
308,3	74,155	15,394	15,394	1483,1	0,51314	51,314	45,394
308,8	73,87	15,413	15,413	1477,4	0,51376	51,376	45,413
309,3	74,068	15,439	15,439	1481,4	0,51462	51,462	45,439
309,7	73,893	15,46	15,46	1477,9	0,51534	51,534	45,46
310,2	74,166	15,484	15,484	1483,3	0,51614	51,614	45,484
310,7	73,999	15,507	15,507	1480	0,5169	51,69	45,507
311,1	74,068	15,531	15,531	1481,4	0,51769	51,769	45,531
311,6	74,089	15,553	15,553	1481,8	0,51843	51,843	45,553
312,1	74,239	15,579	15,579	1484,8	0,51929	51,929	45,579
312,5	74,18	15,603	15,603	1483,6	0,52009	52,009	45,603
313	74,092	15,624	15,624	1481,8	0,52079	52,079	45,624
313,5	74,08	15,648	15,648	1481,6	0,5216	52,16	45,648
313,9	74,2	15,672	15,672	1484	0,52241	52,241	45,672
314,4	74,187	15,696	15,696	1483,7	0,52318	52,318	45,696
314,8	74,095	15,717	15,717	1481,9	0,52388	52,388	45,717
315,3	74,247	15,743	15,743	1484,9	0,52478	52,478	45,743
315,8	73,998	15,763	15,763	1480	0,52544	52,544	45,763
316,2	74,307	15,79	15,79	1486,1	0,52633	52,633	45,79
316,7	73,892	15,809	15,809	1477,8	0,52696	52,696	45,809
317,2	74,413	15,838	15,838	1488,3	0,52792	52,792	45,838
317,6	73,951	15,855	15,855	1479	0,5285	52,85	45,855
318,1	74,307	15,884	15,884	1486,1	0,52947	52,947	45,884
318,6	73,847	15,9	15,9	1476,9	0,52999	52,999	45,9
319	74,414	15,932	15,932	1488,3	0,53108	53,108	45,932
319,5	73,846	15,946	15,946	1476,9	0,53154	53,154	45,946
320	74,457	15,979	15,979	1489,1	0,53263	53,263	45,979
320,4	73,986	15,994	15,994	1479,7	0,53315	53,315	45,994
320,9	74,705	16,027	16,027	1494,1	0,53424	53,424	46,027
321,4	73,914	16,039	16,039	1478,3	0,53462	53,462	46,039
321,8	74,766	16,074	16,074	1495,3	0,53581	53,581	46,074
322,3	73,96	16,085	16,085	1479,2	0,53616	53,616	46,085
322,8	74,898	16,121	16,121	1498	0,53738	53,738	46,121
323,2	74,083	16,133	16,133	1481,7	0,53778	53,778	46,133
323,7	74,765	16,167	16,167	1495,3	0,53889	53,889	46,167
324,2	74,232	16,181	16,181	1484,6	0,53938	53,938	46,181
324,6	74,934	16,215	16,215	1498,7	0,54051	54,051	46,215
325,1	74,073	16,226	16,226	1481,5	0,54085	54,085	46,226
325,6	74,632	16,257	16,257	1492,6	0,5419	54,19	46,257
326	74,227	16,274	16,274	1484,5	0,54247	54,247	46,274
326,5	74,736	16,305	16,305	1494,7	0,54349	54,349	46,305
327	74,269	16,321	16,321	1485,4	0,54404	54,404	46,321
327,4	74,66	16,348	16,348	1493,2	0,54495	54,495	46,348
327,9	74,35	16,369	16,369	1487	0,54562	54,562	46,369
328,4	74,618	16,394	16,394	1492,4	0,54645	54,645	46,394
328,8	74,351	16,412	16,412	1487	0,54706	54,706	46,412
329,3	74,63	16,441	16,441	1492,6	0,54805	54,805	46,441
329,8	74,629	16,464	16,464	1492,6	0,54879	54,879	46,464
330,2	74,719	16,487	16,487	1494,4	0,54957	54,957	46,487
330,7	74,494	16,505	16,505	1489,9	0,55017	55,017	46,505
331,1	74,674	16,533	16,533	1493,5	0,5511	55,11	46,533
331,6	74,698	16,555	16,555	1494	0,55182	55,182	46,555
332,1	74,759	16,579	16,579	1495,2	0,55263	55,263	46,579
332,5	74,709	16,599	16,599	1494,2	0,55332	55,332	46,599
333	74,915	16,625	16,625	1498,3	0,55418	55,418	46,625
333,5	74,832	16,649	16,649	1496,6	0,55495	55,495	46,649
333,9	74,895	16,672	16,672	1497,9	0,55572	55,572	46,672
334,4	74,835	16,695	16,695	1496,7	0,55649	55,649	46,695
334,9	74,991	16,72	16,72	1499,8	0,55732	55,732	46,72
335,3	74,844	16,741	16,741	1496,9	0,55805	55,805	46,741
335,8	75,078	16,764	16,764	1501,6	0,55881	55,881	46,764
336,3	75,138	16,791	16,791	1502,8	0,55969	55,969	46,791
336,7	74,913	16,81	16,81	1498,3	0,56034	56,034	46,81
337,2	75,114	16,837	16,837	1502,3	0,56123	56,123	46,837
337,7	75,076	16,858	16,858	1501,5	0,56195	56,195	46,858
338,1	75,219	16,885	16,885	1504,4	0,56283	56,283	46,885
338,6	74,905	16,902	16,902	1498,1	0,56341	56,341	46,902
339,1	75,332	16,932	16,932	1506,6	0,56441	56,441	46,932
339,5	74,856	16,95	16,95	1497,1	0,565	56,5	46,95
340	75,421	16,981	16,981	1508,4	0,56602	56,602	46,981
340,5	74,914	16,995	16,995	1498,3	0,56651	56,651	46,995
340,9	75,402	17,026	17,026	1508	0,56755	56,755	47,026
341,4	74,964	17,042	17,042	1499,3	0,56805	56,805	47,042
341,9	75,783	17,077	17,077	1515,7	0,56923	56,923	47,077
342,3	75,036	17,087	17,087	1500,7	0,56955	56,955	47,087
342,8	75,517	17,118	17,118	1510,3	0,57059	57,059	47,118
343,3	75,13	17,135	17,135	1502,6	0,57118	57,118	47,135
343,7	76,031	17,172	17,172	1520,6	0,5724	57,24	47,172
344,2	74,946	17,178	17,178	1498,9	0,57261	57,261	47,178
344,7	75,792	17,216	17,216	1515,8	0,57385	57,385	47,216
345,1	75,062	17,227	17,227	1501,2	0,57424	57,424	47,227
345,6	75,808	17,262	17,262	1516,2	0,57542	57,542	47,262
346,1	75,146	17,275	17,275	1502,9	0,57585	57,585	47,275
346,5	75,744	17,307	17,307	1514,9	0,5769	57,69	47,307
347	75,1	17,321	17,321	1502	0,57737	57,737	47,321
347,5	75,764	17,353	17,353	1515,3	0,57843	57,843	47,353
347,9	75,262	17,369	17,369	1505,2	0,57898	57,898	47,369
348,4	75,512	17,4	17,4	1510,2	0,57999	57,999	47,4
348,8	75,196	17,415	17,415	1503,9	0,58049	58,049	47,415
349,3	75,603	17,444	17,444	1512,1	0,58146	58,146	47,444
349,8	75,253	17,462	17,462	1505,1	0,58206	58,206	47,462
350,2	75,516	17,489	17,489	1510,3	0,58296	58,296	47,489
350,7	75,353	17,51	17,51	1507,1	0,58368	58,368	47,51
351,2	75,424	17,533	17,533	1508,5	0,58445	58,445	47,533
351,6	75,444	17,558	17,558	1508,9	0,58526	58,526	47,558
352,1	75,528	17,581	17,581	1510,6	0,58602	58,602	47,581
352,6	75,439	17,603	17,603	1508,8	0,58676	58,676	47,603
353	75,73	17,629	17,629	1514,6	0,58762	58,762	47,629
353,5	75,7	17,652	17,652	1514	0,5884	58,84	47,652
354	75,796	17,675	17,675	1515,9	0,58915	58,915	47,675
354,4	75,677	17,698	17,698	1513,5	0,58995	58,995	47,698
354,9	75,704	17,72	17,72	1514,1	0,59068	59,068	47,72
355,4	75,698	17,743	17,743	1514	0,59144	59,144	47,743
355,8	75,677	17,765	17,765	1513,5	0,59218	59,218	47,765
356,3	75,826	17,79	17,79	1516,5	0,59301	59,301	47,79
356,8	75,701	17,812	17,812	1514	0,59374	59,374	47,812
357,2	75,807	17,836	17,836	1516,1	0,59454	59,454	47,836
357,7	75,745	17,86	17,86	1514,9	0,59534	59,534	47,86
358,2	76,008	17,885	17,885	1520,2	0,59618	59,618	47,885
358,6	75,734	17,904	17,904	1514,7	0,59681	59,681	47,904
359,1	75,914	17,931	17,931	1518,3	0,59768	59,768	47,931
359,6	75,785	17,951	17,951	1515,7	0,59836	59,836	47,951
360	76,033	17,98	17,98	1520,7	0,59932	59,932	47,98
360,5	75,739	17,998	17,998	1514,8	0,59992	59,992	47,998
361	76,224	18,029	18,029	1524,5	0,60096	60,096	48,029
361,4	75,74	18,043	18,043	1514,8	0,60144	60,144	48,043
361,9	76,303	18,075	18,075	1526,1	0,6025	60,25	48,075
362,4	75,739	18,089	18,089	1514,8	0,60296	60,296	48,089
362,8	76,465	18,123	18,123	1529,3	0,6041	60,41	48,123
363,3	75,776	18,135	18,135	1515,5	0,60449	60,449	48,135
363,8	76,443	18,169	18,169	1528,9	0,60562	60,562	48,169
364,2	75,853	18,182	18,182	1517,1	0,60607	60,607	48,182
364,7	76,665	18,218	18,218	1533,3	0,60728	60,728	48,218
365,1	75,805	18,229	18,229	1516,1	0,60762	60,762	48,229
365,6	76,406	18,26	18,26	1528,1	0,60868	60,868	48,26
366,1	75,826	18,275	18,275	1516,5	0,60915	60,915	48,275
366,5	76,754	18,311	18,311	1535,1	0,61036	61,036	48,311
367	76,028	18,323	18,323	1520,6	0,61077	61,077	48,323
367,5	76,822	18,358	18,358	1536,4	0,61193	61,193	48,358
367,9	75,998	18,368	18,368	1520	0,61226	61,226	48,368
368,4	76,955	18,406	18,406	1539,1	0,61352	61,352	48,406
368,9	76,192	18,417	18,417	1523,8	0,61389	61,389	48,417
369,3	76,58	18,448	18,448	1531,6	0,61493	61,493	48,448
369,8	76,109	18,462	18,462	1522,2	0,61541	61,541	48,462
370,3	76,535	18,493	18,493	1530,7	0,61643	61,643	48,493
370,7	76,135	18,509	18,509	1522,7	0,61698	61,698	48,509
371,2	76,577	18,539	18,539	1531,5	0,61797	61,797	48,539
371,7	76,213	18,557	18,557	1524,3	0,61856	61,856	48,557
372,1	76,469	18,583	18,583	1529,4	0,61943	61,943	48,583
372,6	76,302	18,604	18,604	1526	0,62014	62,014	48,604
373,1	76,597	18,63	18,63	1531,9	0,62101	62,101	48,63
373,5	76,398	18,652	18,652	1528	0,62173	62,173	48,652
374	76,464	18,675	18,675	1529,3	0,62249	62,249	48,675
374,5	76,436	18,697	18,697	1528,7	0,62325	62,325	48,697
374,9	76,569	18,722	18,722	1531,4	0,62406	62,406	48,722
375,4	76,604	18,746	18,746	1532,1	0,62486	62,486	48,746
375,9	76,66	18,769	18,769	1533,2	0,62562	62,562	48,769
376,3	76,548	18,792	18,792	1531	0,62639	62,639	48,792
376,8	76,66	18,815	18,815	1533,2	0,62717	62,717	48,815
377,3	76,697	18,839	18,839	1533,9	0,62798	62,798	48,839
377,7	76,65	18,861	18,861	1533	0,62869	62,869	48,861
378,2	76,725	18,885	18,885	1534,5	0,62949	62,949	48,885
378,7	76,553	18,907	18,907	1531,1	0,63024	63,024	48,907
379,1	76,771	18,933	18,933	1535,4	0,6311	63,11	48,933
379,6	76,521	18,952	18,952	1530,4	0,63172	63,172	48,952
380,1	76,644	18,979	18,979	1532,9	0,63263	63,263	48,979
380,5	76,584	19	19	1531,7	0,63332	63,332	49
381	76,914	19,028	19,028	1538,3	0,63425	63,425	49,028
381,5	76,572	19,046	19,046	1531,4	0,63486	63,486	49,046
381,9	76,956	19,074	19,074	1539,1	0,63579	63,579	49,074
382,4	76,617	19,092	19,092	1532,3	0,6364	63,64	49,092
382,8	77,107	19,119	19,119	1542,1	0,63729	63,729	49,119
383,3	76,8	19,139	19,139	1536	0,63797	63,797	49,139
383,8	77,065	19,168	19,168	1541,3	0,63893	63,893	49,168
384,2	76,679	19,185	19,185	1533,6	0,63949	63,949	49,185
384,7	77,225	19,217	19,217	1544,5	0,64058	64,058	49,217
385,2	76,692	19,232	19,232	1533,8	0,64106	64,106	49,232
385,6	77,402	19,266	19,266	1548	0,64218	64,218	49,266
386,1	76,589	19,275	19,275	1531,8	0,64252	64,252	49,275
386,6	77,334	19,311	19,311	1546,7	0,6437	64,37	49,311
387	76,675	19,323	19,323	1533,5	0,64409	64,409	49,323
387,5	77,698	19,36	19,36	1554	0,64535	64,535	49,36
388	76,796	19,371	19,371	1535,9	0,64569	64,569	49,371
388,4	77,396	19,402	19,402	1547,9	0,64672	64,672	49,402
388,9	76,976	19,417	19,417	1539,5	0,64724	64,724	49,417
389,4	77,5	19,449	19,449	1550	0,6483	64,83	49,449
389,8	77,022	19,463	19,463	1540,4	0,64878	64,878	49,463
390,3	77,595	19,495	19,495	1551,9	0,64984	64,984	49,495
390,8	77,079	19,51	19,51	1541,6	0,65034	65,034	49,51
391,2	77,38	19,539	19,539	1547,6	0,65131	65,131	49,539
391,7	77,063	19,556	19,556	1541,3	0,65187	65,187	49,556
392,2	77,452	19,585	19,585	1549	0,65284	65,284	49,585
392,6	77,24	19,606	19,606	1544,8	0,65353	65,353	49,606
393,1	77,396	19,631	19,631	1547,9	0,65437	65,437	49,631
393,6	77,303	19,653	19,653	1546,1	0,6551	65,51	49,653
394	77,532	19,679	19,679	1550,6	0,65597	65,597	49,679
394,5	77,345	19,699	19,699	1546,9	0,65665	65,665	49,699
395	77,395	19,725	19,725	1547,9	0,65749	65,749	49,725
395,4	77,385	19,747	19,747	1547,7	0,65824	65,824	49,747
395,9	77,449	19,77	19,77	1549	0,65899	65,899	49,77
396,4	77,363	19,793	19,793	1547,3	0,65977	65,977	49,793
396,8	77,427	19,815	19,815	1548,5	0,66049	66,049	49,815
397,3	77,539	19,841	19,841	1550,8	0,66138	66,138	49,841
397,8	77,514	19,863	19,863	1550,3	0,66209	66,209	49,863
398,2	77,618	19,887	19,887	1552,4	0,6629	66,29	49,887
398,7	77,611	19,909	19,909	1552,2	0,66364	66,364	49,909
399,1	77,649	19,934	19,934	1553	0,66447	66,447	49,934
399,6	77,639	19,956	19,956	1552,8	0,6652	66,52	49,956
400,1	77,725	19,982	19,982	1554,5	0,66605	66,605	49,982
400,5	75,786	20,001	20,001	1515,7	0,66671	66,671	50,001
401	72,179	20,027	20,027	1443,6	0,66757	66,757	50,027
401,5	-0,34637	20,05	20,05	-6,9274	0,66835	66,835	50,05
401,6	-0,3651			-7,3019