File: Tests de traction/Fichiers source/04_12_2016/5.txt
Time (s)	Load (N)	Machine Extension (mm)	Extension (mm)	Stress (MPa)	Strain	Percentage Strain	Gauge Length (mm)
0
0,3589	-0,0088431	0,000067421	0,000067421	-0,17686	2,2474E-06	0,00022474	30
0,7177	-0,0031043	0,0021968	0,0021968	-0,062085	0,000073226	0,0073226	30,002
1,077	1,1495	0,032576	0,032576	22,99	0,0010859	0,10859	30,033
1,435	1,6454	0,040732	0,040732	32,907	0,0013577	0,13577	30,041
1,794	6,1792	0,074969	0,074969	123,58	0,002499	0,2499	30,075
2,153	7,1619	0,080744	0,080744	143,24	0,0026915	0,26915	30,081
2,512	10,329	0,097691	0,097691	206,58	0,0032564	0,32564	30,098
2,871	14,536	0,123	0,123	290,71	0,0040999	0,40999	30,123
3,23	15,978	0,13203	0,13203	319,55	0,0044009	0,44009	30,132
3,589	19,292	0,15411	0,15411	385,85	0,0051369	0,51369	30,154
3,948	21,541	0,17235	0,17235	430,82	0,0057449	0,57449	30,172
4,306	23,249	0,18497	0,18497	464,98	0,0061655	0,61655	30,185
4,665	27,439	0,21783	0,21783	548,78	0,0072609	0,72609	30,218
5,024	28,317	0,22554	0,22554	566,35	0,007518	0,7518	30,226
5,383	30,065	0,2432	0,2432	601,29	0,0081068	0,81068	30,243
5,742	32,242	0,26506	0,26506	644,84	0,0088352	0,88352	30,265
6,101	33,7	0,2783	0,2783	674	0,0092767	0,92767	30,278
6,46	35,799	0,29778	0,29778	715,98	0,009926	0,9926	30,298
6,818	37,219	0,31526	0,31526	744,37	0,010509	1,0509	30,315
7,177	38,81	0,33062	0,33062	776,2	0,011021	1,1021	30,331
7,536	41,673	0,36084	0,36084	833,46	0,012028	1,2028	30,361
7,895	41,876	0,36779	0,36779	837,51	0,01226	1,226	30,368
8,254	43,948	0,38632	0,38632	878,96	0,012877	1,2877	30,386
8,613	45,91	0,41295	0,41295	918,21	0,013765	1,3765	30,413
8,972	46,201	0,41902	0,41902	924,01	0,013967	1,3967	30,419
9,33	47,776	0,44302	0,44302	955,53	0,014767	1,4767	30,443
9,689	48,881	0,45904	0,45904	977,62	0,015301	1,5301	30,459
10,05	50,177	0,47315	0,47315	1003,5	0,015772	1,5772	30,473
10,41	52,495	0,5042	0,5042	1049,9	0,016807	1,6807	30,504
10,77	52,954	0,51333	0,51333	1059,1	0,017111	1,7111	30,513
11,12	54,096	0,5292	0,5292	1081,9	0,01764	1,764	30,529
11,48	55,482	0,55026	0,55026	1109,6	0,018342	1,8342	30,55
11,84	56,191	0,56136	0,56136	1123,8	0,018712	1,8712	30,561
12,2	57,61	0,58621	0,58621	1152,2	0,01954	1,954	30,586
12,56	58,353	0,60383	0,60383	1167,1	0,020128	2,0128	30,604
12,92	59,268	0,61833	0,61833	1185,4	0,020611	2,0611	30,618
13,28	61,027	0,64552	0,64552	1220,5	0,021517	2,1517	30,646
13,64	61,018	0,6546	0,6546	1220,4	0,02182	2,182	30,655
14	62,445	0,6727	0,6727	1248,9	0,022423	2,2423	30,673
14,35	63,247	0,69573	0,69573	1264,9	0,023191	2,3191	30,696
14,71	63,614	0,7067	0,7067	1272,3	0,023557	2,3557	30,707
15,07	64,855	0,73114	0,73114	1297,1	0,024371	2,4371	30,731
15,43	65,253	0,74674	0,74674	1305,1	0,024891	2,4891	30,747
15,79	65,883	0,76218	0,76218	1317,7	0,025406	2,5406	30,762
16,15	66,708	0,78924	0,78924	1334,2	0,026308	2,6308	30,789
16,51	66,146	0,79807	0,79807	1322,9	0,026602	2,6602	30,798
16,87	67,03	0,81682	0,81682	1340,6	0,027227	2,7227	30,817
17,23	67,593	0,8378	0,8378	1351,9	0,027927	2,7927	30,838
17,58	67,991	0,84964	0,84964	1359,8	0,028321	2,8321	30,85
17,94	68,954	0,87515	0,87515	1379,1	0,029172	2,9172	30,875
18,3	68,986	0,88942	0,88942	1379,7	0,029647	2,9647	30,889
18,66	68,97	0,90637	0,90637	1379,4	0,030212	3,0212	30,906
19,02	70,017	0,93328	0,93328	1400,3	0,031109	3,1109	30,933
19,38	69,496	0,94174	0,94174	1389,9	0,031391	3,1391	30,942
19,74	69,741	0,9582	0,9582	1394,8	0,03194	3,194	30,958
20,1	70,162	0,98072	0,98072	1403,2	0,032691	3,2691	30,981
20,46	70,171	0,99449	0,99449	1403,4	0,03315	3,315	30,994
20,81	70,701	1,0194	1,0194	1414	0,033979	3,3979	31,019
21,17	69,906	1,0332	1,0332	1398,1	0,03444	3,444	31,033
21,53	70,659	1,0495	1,0495	1413,2	0,034985	3,4985	31,05
21,89	71,037	1,0756	1,0756	1420,7	0,035855	3,5855	31,076
22,25	70,174	1,0843	1,0843	1403,5	0,036144	3,6144	31,084
22,61	70,958	1,1063	1,1063	1419,2	0,036877	3,6877	31,106
22,97	70,572	1,1256	1,1256	1411,4	0,03752	3,752	31,126
23,33	70,633	1,1383	1,1383	1412,7	0,037942	3,7942	31,138
23,69	72,188	1,1674	1,1674	1443,8	0,038914	3,8914	31,167
24,04	70,639	1,1754	1,1754	1412,8	0,039179	3,9179	31,175
24,4	71,3	1,1936	1,1936	1426	0,039787	3,9787	31,194
24,76	71,257	1,218	1,218	1425,1	0,040601	4,0601	31,218
25,12	68,891	1,2275	1,2275	1377,8	0,040917	4,0917	31,228
25,48	68,962	1,2488	1,2488	1379,2	0,041627	4,1627	31,249
25,84	68,116	1,2674	1,2674	1362,3	0,042247	4,2247	31,267
26,2	67,642	1,2814	1,2814	1352,8	0,042713	4,2713	31,281
26,56	69,683	1,3089	1,3089	1393,7	0,043631	4,3631	31,309
26,91	69,139	1,3197	1,3197	1382,8	0,043991	4,3991	31,32
27,27	69,48	1,3373	1,3373	1389,6	0,044577	4,4577	31,337
27,63	70,471	1,3612	1,3612	1409,4	0,045374	4,5374	31,361
27,99	69,767	1,371	1,371	1395,3	0,0457	4,57	31,371
28,35	70,895	1,3936	1,3936	1417,9	0,046454	4,6454	31,394
28,71	70,166	1,4119	1,4119	1403,3	0,047062	4,7062	31,412
29,07	69,503	1,4245	1,4245	1390,1	0,047482	4,7482	31,424
29,43	69,556	1,4545	1,4545	1391,1	0,048484	4,8484	31,455
29,79	67,61	1,4625	1,4625	1352,2	0,048751	4,8751	31,463
30,14	68,297	1,4808	1,4808	1365,9	0,04936	4,936	31,481
30,5	69,264	1,5048	1,5048	1385,3	0,05016	5,016	31,505
30,86	68,735	1,5136	1,5136	1374,7	0,050452	5,0452	31,514
31,22	69,568	1,5364	1,5364	1391,4	0,051213	5,1213	31,536
31,58	69,325	1,5544	1,5544	1386,5	0,051814	5,1814	31,554
31,94	69,964	1,5679	1,5679	1399,3	0,052264	5,2264	31,568
32,3	70,898	1,598	1,598	1418	0,053268	5,3268	31,598
32,66	69,918	1,6051	1,6051	1398,4	0,053505	5,3505	31,605
33,02	70,486	1,6252	1,6252	1409,7	0,054174	5,4174	31,625
33,37	70,346	1,6482	1,6482	1406,9	0,054941	5,4941	31,648
33,73	69,897	1,6581	1,6581	1397,9	0,05527	5,527	31,658
34,09	70,828	1,682	1,682	1416,6	0,056067	5,6067	31,682
34,45	70,303	1,6995	1,6995	1406,1	0,056649	5,6649	31,699
34,81	70,31	1,7127	1,7127	1406,2	0,057091	5,7091	31,713
35,17	71,656	1,7423	1,7423	1433,1	0,058078	5,8078	31,742
35,53	69,33	1,7485	1,7485	1386,6	0,058284	5,8284	31,749
35,89	70,142	1,7692	1,7692	1402,8	0,058974	5,8974	31,769
36,25	69,706	1,7915	1,7915	1394,1	0,059715	5,9715	31,791
36,6	68,703	1,8021	1,8021	1374,1	0,06007	6,007	31,802
36,96	69,688	1,8237	1,8237	1393,8	0,060789	6,0789	31,824
37,32	69,13	1,8387	1,8387	1382,6	0,061291	6,1291	31,839
37,68	69,689	1,8583	1,8583	1393,8	0,061942	6,1942	31,858
38,04	70,317	1,8832	1,8832	1406,3	0,062773	6,2773	31,883
38,4	69,587	1,8936	1,8936	1391,7	0,063119	6,3119	31,894
38,76	70,328	1,9126	1,9126	1406,6	0,063755	6,3755	31,913
39,12	70,079	1,9333	1,9333	1401,6	0,064445	6,4445	31,933
39,48	69,329	1,9448	1,9448	1386,6	0,064826	6,4826	31,945
39,83	70,587	1,9689	1,9689	1411,7	0,065631	6,5631	31,969
40,19	69,868	1,9837	1,9837	1397,4	0,066123	6,6123	31,984
40,55	69,988	2,0006	2,0006	1399,8	0,066688	6,6688	32,001
40,91	70,744	2,0255	2,0255	1414,9	0,067517	6,7517	32,026
41,27	69,758	2,0377	2,0377	1395,2	0,067924	6,7924	32,038
41,63	69,896	2,056	2,056	1397,9	0,068533	6,8533	32,056
41,99	69,718	2,0786	2,0786	1394,4	0,069288	6,9288	32,079
42,35	68,778	2,0894	2,0894	1375,6	0,069645	6,9645	32,089
42,7	70,097	2,111	2,111	1401,9	0,070365	7,0365	32,111
43,06	69,43	2,1288	2,1288	1388,6	0,070961	7,0961	32,129
43,42	69,891	2,1454	2,1454	1397,8	0,071515	7,1515	32,145
43,78	71,047	2,1729	2,1729	1420,9	0,07243	7,243	32,173
44,14	69,368	2,1776	2,1776	1387,4	0,072587	7,2587	32,178
44,5	70,763	2,2008	2,2008	1415,3	0,073361	7,3361	32,201
44,86	70,58	2,2207	2,2207	1411,6	0,074023	7,4023	32,221
45,22	70,54	2,2312	2,2312	1410,8	0,074373	7,4373	32,231
45,58	71,502	2,2574	2,2574	1430	0,075247	7,5247	32,257
45,93	70,877	2,2715	2,2715	1417,5	0,075717	7,5717	32,272
46,29	71,002	2,2875	2,2875	1420	0,076249	7,6249	32,287
46,65	71,916	2,3139	2,3139	1438,3	0,077129	7,7129	32,314
47,01	70,669	2,3213	2,3213	1413,4	0,077376	7,7376	32,321
47,37	71,76	2,3429	2,3429	1435,2	0,078098	7,8098	32,343
47,73	71,285	2,3633	2,3633	1425,7	0,078778	7,8778	32,363
48,09	70,867	2,3755	2,3755	1417,3	0,079182	7,9182	32,375
48,45	72,712	2,4072	2,4072	1454,2	0,080239	8,0239	32,407
48,81	70,624	2,413	2,413	1412,5	0,080434	8,0434	32,413
49,16	71,347	2,4321	2,4321	1426,9	0,081069	8,1069	32,432
49,52	71,835	2,4554	2,4554	1436,7	0,081845	8,1845	32,455
49,88	71,145	2,4669	2,4669	1422,9	0,082232	8,2232	32,467
50,24	71,959	2,4885	2,4885	1439,2	0,08295	8,295	32,488
50,6	71,225	2,5054	2,5054	1424,5	0,083513	8,3513	32,505
50,96	69,404	2,5212	2,5212	1388,1	0,084042	8,4042	32,521
51,32	69,925	2,5461	2,5461	1398,5	0,084871	8,4871	32,546
51,68	68,474	2,5567	2,5567	1369,5	0,085224	8,5224	32,557
52,04	69,2	2,5739	2,5739	1384	0,085798	8,5798	32,574
52,39	70,332	2,6011	2,6011	1406,6	0,086705	8,6705	32,601
52,75	69,19	2,6108	2,6108	1383,8	0,087026	8,7026	32,611
53,11	70,273	2,6321	2,6321	1405,5	0,087737	8,7737	32,632
53,47	69,66	2,6488	2,6488	1393,2	0,088294	8,8294	32,649
53,83	70,111	2,6637	2,6637	1402,2	0,08879	8,879	32,664
54,19	71,487	2,6918	2,6918	1429,7	0,089726	8,9726	32,692
54,55	70,425	2,7023	2,7023	1408,5	0,090076	9,0076	32,702
54,91	70,174	2,7174	2,7174	1403,5	0,090579	9,0579	32,717
55,27	70,683	2,7419	2,7419	1413,7	0,091397	9,1397	32,742
55,62	69,764	2,7526	2,7526	1395,3	0,091752	9,1752	32,753
55,98	70,847	2,7762	2,7762	1416,9	0,092541	9,2541	32,776
56,34	70,393	2,7937	2,7937	1407,9	0,093124	9,3124	32,794
56,7	70,156	2,8069	2,8069	1403,1	0,093562	9,3562	32,807
57,06	71,628	2,8362	2,8362	1432,6	0,09454	9,454	32,836
57,42	69,937	2,8427	2,8427	1398,7	0,094755	9,4755	32,843
57,78	70,65	2,8631	2,8631	1413	0,095437	9,5437	32,863
58,14	71,06	2,8863	2,8863	1421,2	0,09621	9,621	32,886
58,49	70,294	2,8968	2,8968	1405,9	0,096559	9,6559	32,897
58,85	70,913	2,9181	2,9181	1418,3	0,097271	9,7271	32,918
59,21	70,306	2,9353	2,9353	1406,1	0,097844	9,7844	32,935
59,57	70,18	2,9498	2,9498	1403,6	0,098325	9,8325	32,95
59,93	71,316	2,9777	2,9777	1426,3	0,099255	9,9255	32,978
60,29	70,35	2,9881	2,9881	1407	0,099604	9,9604	32,988
60,65	70,726	3,007	3,007	1414,5	0,10023	10,023	33,007
61,01	70,585	3,0269	3,0269	1411,7	0,1009	10,09	33,027
61,37	70,111	3,0409	3,0409	1402,2	0,10136	10,136	33,041
61,72	71,05	3,0643	3,0643	1421	0,10214	10,214	33,064
62,08	70,259	3,0803	3,0803	1405,2	0,10268	10,268	33,08
62,44	69,983	3,0939	3,0939	1399,7	0,10313	10,313	33,094
62,8	70,854	3,1201	3,1201	1417,1	0,104	10,4	33,12
63,16	69,655	3,1291	3,1291	1393,1	0,1043	10,43	33,129
63,52	70,058	3,1488	3,1488	1401,2	0,10496	10,496	33,149
63,88	70,419	3,1722	3,1722	1408,4	0,10574	10,574	33,172
64,24	69,269	3,1818	3,1818	1385,4	0,10606	10,606	33,182
64,6	70,668	3,2057	3,2057	1413,4	0,10686	10,686	33,206
64,95	69,964	3,2224	3,2224	1399,3	0,10741	10,741	33,222
65,31	69,974	3,2384	3,2384	1399,5	0,10795	10,795	33,238
65,67	71,222	3,2668	3,2668	1424,4	0,10889	10,889	33,267
66,03	69,851	3,2733	3,2733	1397	0,10911	10,911	33,273
66,39	70,338	3,2926	3,2926	1406,8	0,10975	10,975	33,293
66,75	70,541	3,3141	3,3141	1410,8	0,11047	11,047	33,314
67,11	69,956	3,3251	3,3251	1399,1	0,11084	11,084	33,325
67,47	71,115	3,3511	3,3511	1422,3	0,1117	11,17	33,351
67,83	70,24	3,3659	3,3659	1404,8	0,1122	11,22	33,366
68,18	70,354	3,3823	3,3823	1407,1	0,11274	11,274	33,382
68,54	71,152	3,4081	3,4081	1423	0,1136	11,36	33,408
68,9	70,029	3,417	3,417	1400,6	0,1139	11,39	33,417
69,26	70,736	3,4385	3,4385	1414,7	0,11462	11,462	33,438
69,62	70,368	3,4583	3,4583	1407,4	0,11528	11,528	33,458
69,98	69,708	3,4698	3,4698	1394,2	0,11566	11,566	33,47
70,34	70,83	3,4973	3,4973	1416,6	0,11658	11,658	33,497
70,7	69,7	3,5086	3,5086	1394	0,11695	11,695	33,509
71,06	69,645	3,5253	3,5253	1392,9	0,11751	11,751	33,525
71,41	69,854	3,5515	3,5515	1397,1	0,11838	11,838	33,551
71,77	68,199	3,5605	3,5605	1364	0,11868	11,868	33,56
72,13	68,884	3,5816	3,5816	1377,7	0,11939	11,939	33,582
72,49	68,808	3,5995	3,5995	1376,2	0,11998	11,998	33,599
72,85	68,829	3,6148	3,6148	1376,6	0,12049	12,049	33,615
73,21	70,075	3,642	3,642	1401,5	0,1214	12,14	33,642
73,57	68,931	3,6509	3,6509	1378,6	0,1217	12,17	33,651
73,93	69,252	3,6694	3,6694	1385	0,12231	12,231	33,669
74,29	69,926	3,6931	3,6931	1398,5	0,1231	12,31	33,693
74,64	68,982	3,7026	3,7026	1379,6	0,12342	12,342	33,703
75	69,882	3,725	3,725	1397,6	0,12417	12,417	33,725
75,36	69,944	3,7464	3,7464	1398,9	0,12488	12,488	33,746
75,72	69,459	3,7588	3,7588	1389,2	0,12529	12,529	33,759
76,08	70,881	3,7853	3,7853	1417,6	0,12618	12,618	33,785
76,44	70,043	3,7972	3,7972	1400,9	0,12657	12,657	33,797
76,8	69,838	3,8116	3,8116	1396,8	0,12705	12,705	33,812
77,16	71,238	3,8397	3,8397	1424,8	0,12799	12,799	33,84
77,51	69,488	3,845	3,845	1389,8	0,12817	12,817	33,845
77,87	70,626	3,8693	3,8693	1412,5	0,12898	12,898	33,869
78,23	70,492	3,8871	3,8871	1409,8	0,12957	12,957	33,887
78,59	69,981	3,8994	3,8994	1399,6	0,12998	12,998	33,899
78,95	71,823	3,9333	3,9333	1436,5	0,13111	13,111	33,933
79,31	70,029	3,939	3,939	1400,6	0,1313	13,13	33,939
79,67	70,179	3,9562	3,9562	1403,6	0,13187	13,187	33,956
80,03	70,686	3,9819	3,9819	1413,7	0,13273	13,273	33,982
80,39	70,202	3,9912	3,9912	1404	0,13304	13,304	33,991
80,74	70,958	4,0128	4,0128	1419,2	0,13376	13,376	34,013
81,1	70,501	4,0306	4,0306	1410	0,13435	13,435	34,031
81,46	70,335	4,0441	4,0441	1406,7	0,1348	13,48	34,044
81,82	71,851	4,075	4,075	1437	0,13583	13,583	34,075
82,18	70,231	4,0807	4,0807	1404,6	0,13602	13,602	34,081
82,54	70,774	4,1004	4,1004	1415,5	0,13668	13,668	34,1
82,9	71,041	4,1229	4,1229	1420,8	0,13743	13,743	34,123
83,26	70,517	4,1344	4,1344	1410,3	0,13781	13,781	34,134
83,62	71,028	4,1556	4,1556	1420,6	0,13852	13,852	34,156
83,97	70,853	4,1755	4,1755	1417,1	0,13918	13,918	34,176
84,33	70,615	4,1901	4,1901	1412,3	0,13967	13,967	34,19
84,69	71,416	4,2166	4,2166	1428,3	0,14055	14,055	34,217
85,05	70,683	4,2266	4,2266	1413,7	0,14089	14,089	34,227
85,41	70,946	4,2438	4,2438	1418,9	0,14146	14,146	34,244
85,77	70,991	4,2658	4,2658	1419,8	0,14219	14,219	34,266
86,13	70,322	4,2767	4,2767	1406,4	0,14256	14,256	34,277
86,49	71,072	4,3002	4,3002	1421,4	0,14334	14,334	34,3
86,85	70,723	4,3183	4,3183	1414,5	0,14394	14,394	34,318
87,2	70,39	4,3335	4,3335	1407,8	0,14445	14,445	34,334
87,56	71,518	4,3613	4,3613	1430,4	0,14538	14,538	34,361
87,92	70,404	4,3684	4,3684	1408,1	0,14561	14,561	34,368
88,28	70,8	4,3881	4,3881	1416	0,14627	14,627	34,388
88,64	71,189	4,4115	4,4115	1423,8	0,14705	14,705	34,412
89	70,349	4,4211	4,4211	1407	0,14737	14,737	34,421
89,36	71,152	4,4461	4,4461	1423	0,1482	14,82	34,446
89,72	70,713	4,4605	4,4605	1414,3	0,14868	14,868	34,46
90,08	70,655	4,4758	4,4758	1413,1	0,14919	14,919	34,476
90,43	71,742	4,5054	4,5054	1434,8	0,15018	15,018	34,505
90,79	70,343	4,5129	4,5129	1406,9	0,15043	15,043	34,513
91,15	70,642	4,532	4,532	1412,8	0,15107	15,107	34,532
91,51	70,822	4,5528	4,5528	1416,4	0,15176	15,176	34,553
91,87	70,201	4,5632	4,5632	1404	0,15211	15,211	34,563
92,23	71,453	4,5923	4,5923	1429,1	0,15308	15,308	34,592
92,59	70,167	4,6014	4,6014	1403,3	0,15338	15,338	34,601
92,95	70,357	4,6202	4,6202	1407,1	0,15401	15,401	34,62
93,3	71,271	4,6476	4,6476	1425,4	0,15492	15,492	34,648
93,66	70,014	4,6558	4,6558	1400,3	0,15519	15,519	34,656
94,02	70,195	4,6753	4,6753	1403,9	0,15584	15,584	34,675
94,38	69,92	4,694	4,694	1398,4	0,15647	15,647	34,694
94,74	69,662	4,7074	4,7074	1393,2	0,15691	15,691	34,707
95,1	70,486	4,7348	4,7348	1409,7	0,15783	15,783	34,735
95,46	69,507	4,7474	4,7474	1390,1	0,15825	15,825	34,747
95,82	69,683	4,763	4,763	1393,7	0,15877	15,877	34,763
96,18	70,162	4,7902	4,7902	1403,2	0,15967	15,967	34,79
96,53	69,148	4,7988	4,7988	1383	0,15996	15,996	34,799
96,89	69,249	4,8193	4,8193	1385	0,16064	16,064	34,819
97,25	68,587	4,8393	4,8393	1371,7	0,16131	16,131	34,839
97,61	67,812	4,8516	4,8516	1356,2	0,16172	16,172	34,852
97,97	68,621	4,8779	4,8779	1372,4	0,1626	16,26	34,878
98,33	67,927	4,8912	4,8912	1358,5	0,16304	16,304	34,891
98,69	67,838	4,9071	4,9071	1356,8	0,16357	16,357	34,907
99,05	68,745	4,9337	4,9337	1374,9	0,16446	16,446	34,934
99,41	67,815	4,9416	4,9416	1356,3	0,16472	16,472	34,942
99,76	68,3	4,9608	4,9608	1366	0,16536	16,536	34,961
100,1	68,544	4,9834	4,9834	1370,9	0,16611	16,611	34,983
100,5	68,228	4,9959	4,9959	1364,6	0,16653	16,653	34,996
100,8	69,176	5,0207	5,0207	1383,5	0,16736	16,736	35,021
101,2	68,894	5,0356	5,0356	1377,9	0,16785	16,785	35,036
101,6	68,868	5,0523	5,0523	1377,4	0,16841	16,841	35,052
101,9	69,7	5,0785	5,0785	1394	0,16928	16,928	35,078
102,3	68,436	5,0862	5,0862	1368,7	0,16954	16,954	35,086
102,6	68,91	5,1087	5,1087	1378,2	0,17029	17,029	35,109
103	68,627	5,1265	5,1265	1372,5	0,17088	17,088	35,126
103,4	68,285	5,1405	5,1405	1365,7	0,17135	17,135	35,141
103,7	69,517	5,1677	5,1677	1390,3	0,17226	17,226	35,168
104,1	68,062	5,1759	5,1759	1361,2	0,17253	17,253	35,176
104,4	68,391	5,195	5,195	1367,8	0,17317	17,317	35,195
104,8	69,008	5,2192	5,2192	1380,2	0,17397	17,397	35,219
105,1	68,088	5,2278	5,2278	1361,8	0,17426	17,426	35,228
105,5	68,978	5,2508	5,2508	1379,6	0,17503	17,503	35,251
105,9	68,732	5,2674	5,2674	1374,6	0,17558	17,558	35,267
106,2	68,648	5,2847	5,2847	1373	0,17616	17,616	35,285
106,6	69,605	5,3108	5,3108	1392,1	0,17703	17,703	35,311
106,9	68,759	5,3198	5,3198	1375,2	0,17733	17,733	35,32
107,3	69,17	5,3395	5,3395	1383,4	0,17798	17,798	35,34
107,7	69,417	5,3611	5,3611	1388,3	0,1787	17,87	35,361
108	68,71	5,3717	5,3717	1374,2	0,17906	17,906	35,372
108,4	69,703	5,3968	5,3968	1394,1	0,17989	17,989	35,397
108,7	69,356	5,4131	5,4131	1387,1	0,18044	18,044	35,413
109,1	69,085	5,4271	5,4271	1381,7	0,1809	18,09	35,427
109,5	70,286	5,4559	5,4559	1405,7	0,18186	18,186	35,456
109,8	69,262	5,4645	5,4645	1385,2	0,18215	18,215	35,464
110,2	69,416	5,482	5,482	1388,3	0,18273	18,273	35,482
110,5	69,839	5,5036	5,5036	1396,8	0,18345	18,345	35,504
110,9	69,08	5,5139	5,5139	1381,6	0,1838	18,38	35,514
111,2	69,748	5,5364	5,5364	1395	0,18455	18,455	35,536
111,6	69,717	5,5565	5,5565	1394,3	0,18522	18,522	35,556
112	69,481	5,5702	5,5702	1389,6	0,18567	18,567	35,57
112,3	70,321	5,5977	5,5977	1406,4	0,18659	18,659	35,598
112,7	69,672	5,6077	5,6077	1393,4	0,18692	18,692	35,608
113	69,964	5,6254	5,6254	1399,3	0,18751	18,751	35,625
113,4	70,563	5,6513	5,6513	1411,3	0,18838	18,838	35,651
113,8	69,188	5,6563	5,6563	1383,8	0,18854	18,854	35,656
114,1	70,339	5,6829	5,6829	1406,8	0,18943	18,943	35,683
114,5	69,676	5,6973	5,6973	1393,5	0,18991	18,991	35,697
114,8	69,967	5,7161	5,7161	1399,3	0,19054	19,054	35,716
115,2	70,906	5,7444	5,7444	1418,1	0,19148	19,148	35,744
115,6	69,521	5,7485	5,7485	1390,4	0,19162	19,162	35,748
115,9	69,99	5,7697	5,7697	1399,8	0,19232	19,232	35,77
116,3	70,211	5,791	5,791	1404,2	0,19303	19,303	35,791
116,6	69,613	5,8016	5,8016	1392,3	0,19339	19,339	35,802
117	70,842	5,8323	5,8323	1416,8	0,19441	19,441	35,832
117,3	69,773	5,8439	5,8439	1395,5	0,1948	19,48	35,844
117,7	69,979	5,8591	5,8591	1399,6	0,1953	19,53	35,859
118,1	70,217	5,8809	5,8809	1404,3	0,19603	19,603	35,881
118,4	69,739	5,8952	5,8952	1394,8	0,19651	19,651	35,895
118,8	70,114	5,9139	5,9139	1402,3	0,19713	19,713	35,914
119,1	70,019	5,9337	5,9337	1400,4	0,19779	19,779	35,934
119,5	69,691	5,9453	5,9453	1393,8	0,19818	19,818	35,945
119,9	70,361	5,9715	5,9715	1407,2	0,19905	19,905	35,971
120,2	69,935	5,9847	5,9847	1398,7	0,19949	19,949	35,985
120,6	70,003	6,0027	6,0027	1400,1	0,20009	20,009	36,003
120,9	70,582	6,0276	6,0276	1411,6	0,20092	20,092	36,028
121,3	69,628	6,0371	6,0371	1392,6	0,20124	20,124	36,037
121,7	70,018	6,0583	6,0583	1400,4	0,20194	20,194	36,058
122	69,714	6,0781	6,0781	1394,3	0,2026	20,26	36,078
122,4	68,944	6,0889	6,0889	1378,9	0,20296	20,296	36,089
122,7	70,034	6,1163	6,1163	1400,7	0,20388	20,388	36,116
123,1	69,348	6,1284	6,1284	1387	0,20428	20,428	36,128
123,4	69,665	6,1474	6,1474	1393,3	0,20491	20,491	36,147
123,8	69,801	6,1691	6,1691	1396	0,20564	20,564	36,169
124,2	69,269	6,1802	6,1802	1385,4	0,20601	20,601	36,18
124,5	69,916	6,2023	6,2023	1398,3	0,20674	20,674	36,202
124,9	69,674	6,2209	6,2209	1393,5	0,20736	20,736	36,221
125,2	69,232	6,2336	6,2336	1384,6	0,20779	20,779	36,234
125,6	70,09	6,2595	6,2595	1401,8	0,20865	20,865	36,26
126	69,482	6,2725	6,2725	1389,6	0,20908	20,908	36,272
126,3	69,505	6,2881	6,2881	1390,1	0,2096	20,96	36,288
126,7	70,301	6,3144	6,3144	1406	0,21048	21,048	36,314
127	69,287	6,3219	6,3219	1385,7	0,21073	21,073	36,322
127,4	69,976	6,3456	6,3456	1399,5	0,21152	21,152	36,346
127,8	69,741	6,3627	6,3627	1394,8	0,21209	21,209	36,363
128,1	69,389	6,376	6,376	1387,8	0,21253	21,253	36,376
128,5	70,682	6,4078	6,4078	1413,6	0,21359	21,359	36,408
128,8	69,78	6,4158	6,4158	1395,6	0,21386	21,386	36,416
129,2	69,966	6,4341	6,4341	1399,3	0,21447	21,447	36,434
129,6	69,919	6,4533	6,4533	1398,4	0,21511	21,511	36,453
129,9	69,585	6,4674	6,4674	1391,7	0,21558	21,558	36,467
130,3	70,089	6,4894	6,4894	1401,8	0,21631	21,631	36,489
130,6	69,705	6,5057	6,5057	1394,1	0,21686	21,686	36,506
131	69,661	6,5199	6,5199	1393,2	0,21733	21,733	36,52
131,3	70,268	6,5469	6,5469	1405,4	0,21823	21,823	36,547
131,7	69,652	6,5579	6,5579	1393	0,2186	21,86	36,558
132,1	69,987	6,5777	6,5777	1399,7	0,21926	21,926	36,578
132,4	70,396	6,6007	6,6007	1407,9	0,22002	22,002	36,601
132,8	69,635	6,6116	6,6116	1392,7	0,22039	22,039	36,612
133,1	70,164	6,6331	6,6331	1403,3	0,2211	22,11	36,633
133,5	69,93	6,6501	6,6501	1398,6	0,22167	22,167	36,65
133,9	69,589	6,6641	6,6641	1391,8	0,22214	22,214	36,664
134,2	70,896	6,6944	6,6944	1417,9	0,22315	22,315	36,694
134,6	69,457	6,7002	6,7002	1389,1	0,22334	22,334	36,7
134,9	70,171	6,72	6,72	1403,4	0,224	22,4	36,72
135,3	70,494	6,743	6,743	1409,9	0,22477	22,477	36,743
135,7	69,848	6,7525	6,7525	1397	0,22508	22,508	36,753
136	70,38	6,7764	6,7764	1407,6	0,22588	22,588	36,776
136,4	70,284	6,794	6,794	1405,7	0,22647	22,647	36,794
136,7	69,897	6,8085	6,8085	1397,9	0,22695	22,695	36,808
137,1	70,881	6,836	6,836	1417,6	0,22787	22,787	36,836
137,4	69,994	6,8448	6,8448	1399,9	0,22816	22,816	36,845
137,8	70,254	6,8642	6,8642	1405,1	0,22881	22,881	36,864
138,2	70,595	6,8873	6,8873	1411,9	0,22958	22,958	36,887
138,5	69,779	6,8958	6,8958	1395,6	0,22986	22,986	36,896
138,9	70,71	6,9224	6,9224	1414,2	0,23075	23,075	36,922
139,2	70,075	6,9359	6,9359	1401,5	0,2312	23,12	36,936
139,6	69,969	6,9523	6,9523	1399,4	0,23174	23,174	36,952
140	70,974	6,9799	6,9799	1419,5	0,23266	23,266	36,98
140,3	69,887	6,9869	6,9869	1397,7	0,2329	23,29	36,987
140,7	70,279	7,0075	7,0075	1405,6	0,23358	23,358	37,008
141	70,22	7,0273	7,0273	1404,4	0,23424	23,424	37,027
141,4	69,912	7,0398	7,0398	1398,2	0,23466	23,466	37,04
141,8	70,636	7,07	7,07	1412,7	0,23567	23,567	37,07
142,1	69,855	7,0787	7,0787	1397,1	0,23596	23,596	37,079
142,5	69,974	7,0969	7,0969	1399,5	0,23656	23,656	37,097
142,8	70,584	7,1218	7,1218	1411,7	0,23739	23,739	37,122
143,2	69,862	7,1324	7,1324	1397,2	0,23775	23,775	37,132
143,5	70,168	7,1522	7,1522	1403,4	0,23841	23,841	37,152
143,9	70,226	7,173	7,173	1404,5	0,2391	23,91	37,173
144,3	69,613	7,1835	7,1835	1392,3	0,23945	23,945	37,183
144,6	70,548	7,2103	7,2103	1411	0,24034	24,034	37,21
145	69,855	7,223	7,223	1397,1	0,24077	24,077	37,223
145,3	70,048	7,2408	7,2408	1401	0,24136	24,136	37,241
145,7	70,729	7,2666	7,2666	1414,6	0,24222	24,222	37,267
146,1	69,887	7,2758	7,2758	1397,7	0,24253	24,253	37,276
146,4	70,343	7,2969	7,2969	1406,9	0,24323	24,323	37,297
146,8	70,125	7,314	7,314	1402,5	0,2438	24,38	37,314
147,1	69,714	7,3266	7,3266	1394,3	0,24422	24,422	37,327
147,5	70,848	7,3553	7,3553	1417	0,24518	24,518	37,355
147,9	70,052	7,3676	7,3676	1401	0,24559	24,559	37,368
148,2	70,117	7,383	7,383	1402,3	0,2461	24,61	37,383
148,6	70,755	7,4093	7,4093	1415,1	0,24698	24,698	37,409
148,9	69,978	7,4188	7,4188	1399,6	0,24729	24,729	37,419
149,3	70,254	7,4387	7,4387	1405,1	0,24796	24,796	37,439
149,6	70,176	7,4581	7,4581	1403,5	0,2486	24,86	37,458
150	69,889	7,4709	7,4709	1397,8	0,24903	24,903	37,471
150,4	70,905	7,4984	7,4984	1418,1	0,24995	24,995	37,498
150,7	70,047	7,5109	7,5109	1400,9	0,25036	25,036	37,511
151,1	70,085	7,5272	7,5272	1401,7	0,25091	25,091	37,527
151,4	70,691	7,5511	7,5511	1413,8	0,2517	25,17	37,551
151,8	69,907	7,5601	7,5601	1398,1	0,252	25,2	37,56
152,2	70,481	7,5824	7,5824	1409,6	0,25275	25,275	37,582
152,5	70,314	7,6014	7,6014	1406,3	0,25338	25,338	37,601
152,9	70,038	7,614	7,614	1400,8	0,2538	25,38	37,614
153,2	70,902	7,6437	7,6437	1418	0,25479	25,479	37,644
153,6	70,245	7,6528	7,6528	1404,9	0,25509	25,509	37,653
154	70,163	7,6716	7,6716	1403,3	0,25572	25,572	37,672
154,3	70,598	7,6944	7,6944	1412	0,25648	25,648	37,694
154,7	69,893	7,7057	7,7057	1397,9	0,25686	25,686	37,706
155	70,338	7,7278	7,7278	1406,8	0,25759	25,759	37,728
155,4	70,183	7,7442	7,7442	1403,7	0,25814	25,814	37,744
155,7	70,026	7,7586	7,7586	1400,5	0,25862	25,862	37,759
156,1	71,104	7,7872	7,7872	1422,1	0,25957	25,957	37,787
156,5	70,178	7,7972	7,7972	1403,6	0,25991	25,991	37,797
156,8	70,198	7,8142	7,8142	1404	0,26047	26,047	37,814
157,2	70,811	7,8391	7,8391	1416,2	0,2613	26,13	37,839
157,5	70,132	7,8499	7,8499	1402,6	0,26166	26,166	37,85
157,9	70,572	7,8713	7,8713	1411,4	0,26238	26,238	37,871
158,3	70,432	7,8889	7,8889	1408,6	0,26296	26,296	37,889
158,6	70,092	7,902	7,902	1401,8	0,2634	26,34	37,902
159	71,258	7,933	7,933	1425,2	0,26443	26,443	37,933
159,3	70,244	7,941	7,941	1404,9	0,2647	26,47	37,941
159,7	70,315	7,9587	7,9587	1406,3	0,26529	26,529	37,959
160,1	70,608	7,9812	7,9812	1412,2	0,26604	26,604	37,981
160,4	70,039	7,9926	7,9926	1400,8	0,26642	26,642	37,993
160,8	70,705	8,0162	8,0162	1414,1	0,26721	26,721	38,016
161,1	70,208	8,03	8,03	1404,2	0,26767	26,767	38,03
161,5	70,221	8,0458	8,0458	1404,4	0,26819	26,819	38,046
161,8	71,084	8,073	8,073	1421,7	0,2691	26,91	38,073
162,2	70,252	8,0821	8,0821	1405	0,2694	26,94	38,082
162,6	70,322	8,1024	8,1024	1406,4	0,27008	27,008	38,102
162,9	70,596	8,1223	8,1223	1411,9	0,27074	27,074	38,122
163,3	70,202	8,1358	8,1358	1404	0,27119	27,119	38,136
163,6	70,689	8,1589	8,1589	1413,8	0,27196	27,196	38,159
164	70,279	8,1737	8,1737	1405,6	0,27246	27,246	38,174
164,4	70,017	8,1906	8,1906	1400,3	0,27302	27,302	38,191
164,7	70,872	8,2172	8,2172	1417,4	0,27391	27,391	38,217
165,1	69,908	8,2253	8,2253	1398,2	0,27418	27,418	38,225
165,4	70,37	8,2474	8,2474	1407,4	0,27491	27,491	38,247
165,8	70,526	8,2685	8,2685	1410,5	0,27562	27,562	38,268
166,2	70,022	8,2799	8,2799	1400,4	0,276	27,6	38,28
166,5	70,405	8,3013	8,3013	1408,1	0,27671	27,671	38,301
166,9	70,367	8,319	8,319	1407,3	0,2773	27,73	38,319
167,2	70,347	8,3349	8,3349	1406,9	0,27783	27,783	38,335
167,6	71,038	8,3616	8,3616	1420,8	0,27872	27,872	38,362
167,9	70,119	8,3706	8,3706	1402,4	0,27902	27,902	38,371
168,3	70,55	8,391	8,391	1411	0,2797	27,97	38,391
168,7	70,626	8,4114	8,4114	1412,5	0,28038	28,038	38,411
169	69,963	8,4212	8,4212	1399,3	0,28071	28,071	38,421
169,4	70,767	8,4477	8,4477	1415,3	0,28159	28,159	38,448
169,7	70,371	8,4624	8,4624	1407,4	0,28208	28,208	38,462
170,1	70,182	8,4773	8,4773	1403,6	0,28258	28,258	38,477
170,5	71,032	8,505	8,505	1420,6	0,2835	28,35	38,505
170,8	70,003	8,5117	8,5117	1400,1	0,28372	28,372	38,512
171,2	70,647	8,5352	8,5352	1412,9	0,28451	28,451	38,535
171,5	70,479	8,5529	8,5529	1409,6	0,2851	28,51	38,553
171,9	70,236	8,5665	8,5665	1404,7	0,28555	28,555	38,567
172,3	71,378	8,596	8,596	1427,6	0,28653	28,653	38,596
172,6	70,283	8,6036	8,6036	1405,7	0,28679	28,679	38,604
173	70,344	8,6209	8,6209	1406,9	0,28736	28,736	38,621
173,3	70,985	8,6469	8,6469	1419,7	0,28823	28,823	38,647
173,7	70,26	8,6563	8,6563	1405,2	0,28854	28,854	38,656
174	70,552	8,6782	8,6782	1411	0,28927	28,927	38,678
174,4	70,595	8,6977	8,6977	1411,9	0,28992	28,992	38,698
174,8	70,208	8,7104	8,7104	1404,2	0,29035	29,035	38,71
175,1	70,801	8,7351	8,7351	1416	0,29117	29,117	38,735
175,5	70,494	8,7482	8,7482	1409,9	0,29161	29,161	38,748
175,8	70,589	8,767	8,767	1411,8	0,29223	29,223	38,767
176,2	70,82	8,7893	8,7893	1416,4	0,29298	29,298	38,789
176,6	70,123	8,7998	8,7998	1402,5	0,29333	29,333	38,8
176,9	70,763	8,8234	8,8234	1415,3	0,29411	29,411	38,823
177,3	70,502	8,8397	8,8397	1410	0,29466	29,466	38,84
177,6	70,18	8,8529	8,8529	1403,6	0,2951	29,51	38,853
178	70,939	8,8796	8,8796	1418,8	0,29599	29,599	38,88
178,4	70,436	8,8925	8,8925	1408,7	0,29642	29,642	38,893
178,7	70,521	8,9095	8,9095	1410,4	0,29698	29,698	38,909
179,1	70,991	8,9343	8,9343	1419,8	0,29781	29,781	38,934
179,4	70,199	8,944	8,944	1404	0,29813	29,813	38,944
179,8	70,612	8,962	8,962	1412,2	0,29873	29,873	38,962
180,2	70,476	8,9833	8,9833	1409,5	0,29944	29,944	38,983
180,5	70,262	8,9974	8,9974	1405,2	0,29991	29,991	38,997
180,9	70,948	9,0228	9,0228	1419	0,30076	30,076	39,023
181,2	70,576	9,0359	9,0359	1411,5	0,3012	30,12	39,036
181,6	70,577	9,053	9,053	1411,5	0,30177	30,177	39,053
181,9	70,959	9,0765	9,0765	1419,2	0,30255	30,255	39,077
182,3	70,367	9,0854	9,0854	1407,3	0,30285	30,285	39,085
182,7	70,865	9,1099	9,1099	1417,3	0,30366	30,366	39,11
183	70,645	9,1272	9,1272	1412,9	0,30424	30,424	39,127
183,4	70,426	9,1418	9,1418	1408,5	0,30473	30,473	39,142
183,7	71,356	9,171	9,171	1427,1	0,3057	30,57	39,171
184,1	70,222	9,1762	9,1762	1404,4	0,30587	30,587	39,176
184,5	70,359	9,1969	9,1969	1407,2	0,30656	30,656	39,197
184,8	70,812	9,2194	9,2194	1416,2	0,30731	30,731	39,219
185,2	70,158	9,2289	9,2289	1403,2	0,30763	30,763	39,229
185,5	70,605	9,2526	9,2526	1412,1	0,30842	30,842	39,253
185,9	70,463	9,2693	9,2693	1409,3	0,30898	30,898	39,269
186,3	70,361	9,2857	9,2857	1407,2	0,30952	30,952	39,286
186,6	71,118	9,3121	9,3121	1422,4	0,3104	31,04	39,312
187	70,259	9,3204	9,3204	1405,2	0,31068	31,068	39,32
187,3	70,693	9,3422	9,3422	1413,9	0,31141	31,141	39,342
187,7	70,835	9,363	9,363	1416,7	0,3121	31,21	39,363
188	70,127	9,3726	9,3726	1402,5	0,31242	31,242	39,373
188,4	70,835	9,3975	9,3975	1416,7	0,31325	31,325	39,398
188,8	70,289	9,4124	9,4124	1405,8	0,31375	31,375	39,412
189,1	70,18	9,4272	9,4272	1403,6	0,31424	31,424	39,427
189,5	71,021	9,4562	9,4562	1420,4	0,31521	31,521	39,456
189,8	70,137	9,4654	9,4654	1402,7	0,31551	31,551	39,465
190,2	70,517	9,483	9,483	1410,3	0,3161	31,61	39,483
190,6	70,697	9,5068	9,5068	1413,9	0,31689	31,689	39,507
190,9	70,056	9,5168	9,5168	1401,1	0,31723	31,723	39,517
191,3	70,634	9,5416	9,5416	1412,7	0,31805	31,805	39,542
191,6	70,342	9,5565	9,5565	1406,8	0,31855	31,855	39,556
192	70,283	9,5718	9,5718	1405,7	0,31906	31,906	39,572
192,4	71,122	9,6011	9,6011	1422,4	0,32004	32,004	39,601
192,7	70,176	9,6073	9,6073	1403,5	0,32024	32,024	39,607
193,1	70,594	9,6286	9,6286	1411,9	0,32095	32,095	39,629
193,4	70,677	9,6499	9,6499	1413,5	0,32166	32,166	39,65
193,8	70,186	9,661	9,661	1403,7	0,32203	32,203	39,661
194,1	70,86	9,6859	9,6859	1417,2	0,32286	32,286	39,686
194,5	70,455	9,7	9,7	1409,1	0,32333	32,333	39,7
194,9	70,513	9,7174	9,7174	1410,3	0,32391	32,391	39,717
195,2	71,23	9,7441	9,7441	1424,6	0,3248	32,48	39,744
195,6	70,229	9,7497	9,7497	1404,6	0,32499	32,499	39,75
195,9	70,651	9,7719	9,7719	1413	0,32573	32,573	39,772
196,3	70,615	9,7915	9,7915	1412,3	0,32638	32,638	39,792
196,7	70,187	9,802	9,802	1403,7	0,32673	32,673	39,802
197	71,703	9,8367	9,8367	1434,1	0,32789	32,789	39,837
197,4	70,51	9,8425	9,8425	1410,2	0,32808	32,808	39,842
197,7	70,766	9,8621	9,8621	1415,3	0,32874	32,874	39,862
198,1	71,084	9,8843	9,8843	1421,7	0,32948	32,948	39,884
198,5	70,318	9,8939	9,8939	1406,4	0,3298	32,98	39,894
198,8	70,842	9,9166	9,9166	1416,8	0,33055	33,055	39,917
199,2	70,749	9,9356	9,9356	1415	0,33119	33,119	39,936
199,5	70,332	9,9474	9,9474	1406,6	0,33158	33,158	39,947
199,9	71,024	9,9763	9,9763	1420,5	0,33254	33,254	39,976
200,2	70,515	9,986	9,986	1410,3	0,33287	33,287	39,986
200,6	70,656	10,005	10,005	1413,1	0,33348	33,348	40,005
201	71,16	10,029	10,029	1423,2	0,33429	33,429	40,029
201,3	70,322	10,039	10,039	1406,4	0,33462	33,462	40,039
201,7	70,979	10,058	10,058	1419,6	0,33528	33,528	40,058
202	70,924	10,078	10,078	1418,5	0,33595	33,595	40,078
202,4	70,549	10,091	10,091	1411	0,33636	33,636	40,091
202,8	71,375	10,119	10,119	1427,5	0,3373	33,73	40,119
203,1	70,706	10,131	10,131	1414,1	0,33769	33,769	40,131
203,5	70,791	10,148	10,148	1415,8	0,33827	33,827	40,148
203,8	71,323	10,173	10,173	1426,5	0,33909	33,909	40,173
204,2	70,438	10,18	10,18	1408,8	0,33934	33,934	40,18
204,6	71,018	10,204	10,204	1420,4	0,34014	34,014	40,204
204,9	70,87	10,221	10,221	1417,4	0,34071	34,071	40,221
205,3	70,632	10,236	10,236	1412,6	0,34119	34,119	40,236
205,6	71,167	10,261	10,261	1423,3	0,34202	34,202	40,261
206	70,799	10,274	10,274	1416	0,34245	34,245	40,274
206,3	70,923	10,291	10,291	1418,5	0,34304	34,304	40,291
206,7	71,326	10,315	10,315	1426,5	0,34384	34,384	40,315
207,1	70,679	10,325	10,325	1413,6	0,34418	34,418	40,325
207,4	71,158	10,345	10,345	1423,2	0,34484	34,484	40,345
207,8	70,877	10,364	10,364	1417,5	0,34545	34,545	40,364
208,1	70,647	10,38	10,38	1412,9	0,34599	34,599	40,38
208,5	71,355	10,409	10,409	1427,1	0,34698	34,698	40,409
208,9	70,889	10,415	10,415	1417,8	0,34718	34,718	40,415
209,2	70,993	10,436	10,436	1419,9	0,34785	34,785	40,436
209,6	70,985	10,455	10,455	1419,7	0,34851	34,851	40,455
209,9	70,542	10,468	10,468	1410,8	0,34893	34,893	40,468
210,3	71,095	10,492	10,492	1421,9	0,34974	34,974	40,492
210,7	70,763	10,508	10,508	1415,3	0,35025	35,025	40,508
211	70,823	10,524	10,524	1416,5	0,35081	35,081	40,524
211,4	71,292	10,55	10,55	1425,8	0,35168	35,168	40,55
211,7	70,688	10,561	10,561	1413,8	0,35202	35,202	40,561
212,1	70,842	10,58	10,58	1416,8	0,35265	35,265	40,58
212,4	71,049	10,602	10,602	1421	0,3534	35,34	40,602
212,8	70,419	10,612	10,612	1408,4	0,35374	35,374	40,612
213,2	71,007	10,633	10,633	1420,1	0,35445	35,445	40,633
213,5	70,732	10,651	10,651	1414,6	0,35504	35,504	40,651
213,9	70,508	10,665	10,665	1410,2	0,35551	35,551	40,665
214,2	71,499	10,696	10,696	1430	0,35653	35,653	40,696
214,6	70,585	10,703	10,703	1411,7	0,35678	35,678	40,703
215	70,732	10,722	10,722	1414,6	0,35741	35,741	40,722
215,3	71,003	10,745	10,745	1420,1	0,35816	35,816	40,745
215,7	70,368	10,755	10,755	1407,4	0,35849	35,849	40,755
216	71,085	10,78	10,78	1421,7	0,35933	35,933	40,78
216,4	70,632	10,793	10,793	1412,6	0,35977	35,977	40,793
216,8	70,94	10,813	10,813	1418,8	0,36042	36,042	40,813
217,1	71,47	10,837	10,837	1429,4	0,36125	36,125	40,837
217,5	70,719	10,847	10,847	1414,4	0,36156	36,156	40,847
217,8	71,068	10,865	10,865	1421,4	0,36217	36,217	40,865
218,2	71,059	10,886	10,886	1421,2	0,36285	36,285	40,886
218,5	70,557	10,897	10,897	1411,1	0,36324	36,324	40,897
218,9	71,263	10,925	10,925	1425,3	0,36415	36,415	40,925
219,3	70,593	10,936	10,936	1411,9	0,36453	36,453	40,936
219,6	70,702	10,954	10,954	1414	0,36514	36,514	40,954
220	71,449	10,982	10,982	1429	0,36606	36,606	40,982
220,3	70,504	10,988	10,988	1410,1	0,36625	36,625	40,988
220,7	70,916	11,011	11,011	1418,3	0,36704	36,704	41,011
221,1	70,877	11,029	11,029	1417,5	0,36765	36,765	41,029
221,4	70,487	11,042	11,042	1409,7	0,36806	36,806	41,042
221,8	71,443	11,071	11,071	1428,9	0,36902	36,902	41,071
222,1	70,703	11,082	11,082	1414,1	0,36939	36,939	41,082
222,5	70,702	11,097	11,097	1414	0,36991	36,991	41,097
222,9	71,125	11,122	11,122	1422,5	0,37072	37,072	41,122
223,2	70,659	11,134	11,134	1413,2	0,37113	37,113	41,134
223,6	70,647	11,151	11,151	1412,9	0,37171	37,171	41,151
223,9	70,89	11,174	11,174	1417,8	0,37248	37,248	41,174
224,3	70,347	11,184	11,184	1406,9	0,3728	37,28	41,184
224,6	71,199	11,214	11,214	1424	0,37379	37,379	41,214
225	70,431	11,223	11,223	1408,6	0,37411	37,411	41,223
225,4	70,655	11,242	11,242	1413,1	0,37474	37,474	41,242
225,7	71,26	11,265	11,265	1425,2	0,37548	37,548	41,265
226,1	70,596	11,275	11,275	1411,9	0,37583	37,583	41,275
226,4	70,877	11,297	11,297	1417,5	0,37658	37,658	41,297
226,8	70,707	11,315	11,315	1414,1	0,37716	37,716	41,315
227,2	70,393	11,327	11,327	1407,9	0,37757	37,757	41,327
227,5	71,634	11,361	11,361	1432,7	0,37869	37,869	41,361
227,9	70,517	11,365	11,365	1410,3	0,37885	37,885	41,365
228,2	70,729	11,385	11,385	1414,6	0,37951	37,951	41,385
228,6	71,234	11,409	11,409	1424,7	0,38031	38,031	41,409
229	70,675	11,419	11,419	1413,5	0,38065	38,065	41,419
229,3	70,923	11,44	11,44	1418,5	0,38134	38,134	41,44
229,7	70,949	11,46	11,46	1419	0,38201	38,201	41,46
230	70,584	11,472	11,472	1411,7	0,38242	38,242	41,472
230,4	71,478	11,503	11,503	1429,6	0,38344	38,344	41,503
230,8	70,541	11,509	11,509	1410,8	0,38365	38,365	41,509
231,1	70,808	11,528	11,528	1416,2	0,38426	38,426	41,528
231,5	71,266	11,553	11,553	1425,3	0,3851	38,51	41,553
231,8	70,718	11,564	11,564	1414,4	0,38548	38,548	41,564
232,2	70,967	11,584	11,584	1419,3	0,38615	38,615	41,584
232,5	70,767	11,601	11,601	1415,3	0,3867	38,67	41,601
232,9	70,684	11,617	11,617	1413,7	0,38723	38,723	41,617
233,3	71,56	11,647	11,647	1431,2	0,38825	38,825	41,647
233,6	70,581	11,654	11,654	1411,6	0,38846	38,846	41,654
234	70,842	11,673	11,673	1416,8	0,38909	38,909	41,673
234,3	70,994	11,694	11,694	1419,9	0,38981	38,981	41,694
234,7	70,755	11,708	11,708	1415,1	0,39028	39,028	41,708
235,1	71,002	11,729	11,729	1420	0,39096	39,096	41,729
235,4	70,917	11,747	11,747	1418,3	0,39158	39,158	41,747
235,8	70,667	11,762	11,762	1413,3	0,39206	39,206	41,762
236,1	71,481	11,79	11,79	1429,6	0,39301	39,301	41,79
236,5	70,716	11,798	11,798	1414,3	0,39327	39,327	41,798
236,9	70,804	11,817	11,817	1416,1	0,3939	39,39	41,817
237,2	71,188	11,839	11,839	1423,8	0,39464	39,464	41,839
237,6	70,626	11,849	11,849	1412,5	0,39496	39,496	41,849
237,9	71,239	11,873	11,873	1424,8	0,39576	39,576	41,873
238,3	70,846	11,889	11,889	1416,9	0,3963	39,63	41,889
238,6	70,844	11,905	11,905	1416,9	0,39685	39,685	41,905
239	71,626	11,934	11,934	1432,5	0,3978	39,78	41,934
239,4	70,743	11,941	11,941	1414,9	0,39802	39,802	41,941
239,7	70,949	11,959	11,959	1419	0,39865	39,865	41,959
240,1	71,088	11,982	11,982	1421,8	0,39939	39,939	41,982
240,4	70,677	11,994	11,994	1413,5	0,39979	39,979	41,994
240,8	71,4	12,018	12,018	1428	0,40061	40,061	42,018
241,2	70,829	12,032	12,032	1416,6	0,40106	40,106	42,032
241,5	70,809	12,049	12,049	1416,2	0,40163	40,163	42,049
241,9	71,398	12,075	12,075	1428	0,40249	40,249	42,075
242,2	70,572	12,083	12,083	1411,4	0,40277	40,277	42,083
242,6	70,964	12,104	12,104	1419,3	0,40345	40,345	42,104
243	71,12	12,125	12,125	1422,4	0,40418	40,418	42,125
243,3	70,654	12,136	12,136	1413,1	0,40455	40,455	42,136
243,7	71,085	12,163	12,163	1421,7	0,40543	40,543	42,163
244	70,746	12,175	12,175	1414,9	0,40583	40,583	42,175
244,4	70,692	12,194	12,194	1413,8	0,40647	40,647	42,194
244,7	71,256	12,218	12,218	1425,1	0,40728	40,728	42,218
245,1	70,648	12,228	12,228	1413	0,40761	40,761	42,228
245,5	70,788	12,246	12,246	1415,8	0,40821	40,821	42,246
245,8	70,926	12,267	12,267	1418,5	0,40891	40,891	42,267
246,2	70,616	12,28	12,28	1412,3	0,40934	40,934	42,28
246,5	71,28	12,307	12,307	1425,6	0,41023	41,023	42,307
246,9	70,781	12,318	12,318	1415,6	0,41062	41,062	42,318
247,3	70,793	12,336	12,336	1415,9	0,4112	41,12	42,336
247,6	71,25	12,361	12,361	1425	0,41202	41,202	42,361
248	70,783	12,37	12,37	1415,7	0,41234	41,234	42,37
248,3	70,917	12,391	12,391	1418,3	0,41304	41,304	42,391
248,7	70,998	12,411	12,411	1420	0,41371	41,371	42,411
249,1	70,61	12,423	12,423	1412,2	0,41411	41,411	42,423
249,4	71,168	12,448	12,448	1423,4	0,41495	41,495	42,448
249,8	70,937	12,464	12,464	1418,7	0,41546	41,546	42,464
250,1	70,854	12,48	12,48	1417,1	0,41599	41,599	42,48
250,5	71,138	12,503	12,503	1422,8	0,41678	41,678	42,503
250,8	70,698	12,514	12,514	1414	0,41714	41,714	42,514
251,2	71,127	12,535	12,535	1422,5	0,41782	41,782	42,535
251,6	71,117	12,556	12,556	1422,3	0,41853	41,853	42,556
251,9	70,866	12,568	12,568	1417,3	0,41895	41,895	42,568
252,3	71,906	12,6	12,6	1438,1	0,42	42	42,6
252,6	70,8	12,604	12,604	1416	0,42015	42,015	42,604
253	70,974	12,623	12,623	1419,5	0,42078	42,078	42,623
253,4	71,319	12,646	12,646	1426,4	0,42155	42,155	42,646
253,7	70,713	12,656	12,656	1414,3	0,42188	42,188	42,656
254,1	71,28	12,679	12,679	1425,6	0,42263	42,263	42,679
254,4	70,978	12,697	12,697	1419,6	0,42324	42,324	42,697
254,8	70,884	12,712	12,712	1417,7	0,42373	42,373	42,712
255,2	71,654	12,739	12,739	1433,1	0,42463	42,463	42,739
255,5	71,041	12,75	12,75	1420,8	0,42501	42,501	42,75
255,9	71,1	12,768	12,768	1422	0,42559	42,559	42,768
256,2	71,423	12,791	12,791	1428,5	0,42635	42,635	42,791
256,6	70,885	12,802	12,802	1417,7	0,42673	42,673	42,802
256,9	71,358	12,822	12,822	1427,2	0,42739	42,739	42,822
257,3	71,099	12,84	12,84	1422	0,428	42,8	42,84
257,7	70,971	12,856	12,856	1419,4	0,42854	42,854	42,856
258	71,654	12,883	12,883	1433,1	0,42945	42,945	42,883
258,4	70,909	12,893	12,893	1418,2	0,42975	42,975	42,893
258,7	71,163	12,912	12,912	1423,3	0,43039	43,039	42,912
259,1	71,473	12,936	12,936	1429,5	0,4312	43,12	42,936
259,5	70,905	12,946	12,946	1418,1	0,43154	43,154	42,946
259,8	71,156	12,967	12,967	1423,1	0,43224	43,224	42,967
260,2	71,081	12,984	12,984	1421,6	0,4328	43,28	42,984
260,5	70,937	12,999	12,999	1418,7	0,43329	43,329	42,999
260,9	71,73	13,027	13,027	1434,6	0,43422	43,422	43,027
261,3	71,006	13,036	13,036	1420,1	0,43452	43,452	43,036
261,6	71,27	13,055	13,055	1425,4	0,43518	43,518	43,055
262	71,609	13,078	13,078	1432,2	0,43592	43,592	43,078
262,3	70,896	13,086	13,086	1417,9	0,4362	43,62	43,086
262,7	71,471	13,112	13,112	1429,4	0,43705	43,705	43,112
263	71,256	13,128	13,128	1425,1	0,43761	43,761	43,128
263,4	71,297	13,145	13,145	1425,9	0,43817	43,817	43,145
263,8	71,783	13,17	13,17	1435,7	0,43902	43,902	43,17
264,1	71,003	13,178	13,178	1420,1	0,43925	43,925	43,178
264,5	71,318	13,199	13,199	1426,4	0,43998	43,998	43,199
264,8	71,345	13,218	13,218	1426,9	0,44061	44,061	43,218
265,2	70,92	13,23	13,23	1418,4	0,44099	44,099	43,23
265,6	71,902	13,26	13,26	1438	0,44199	44,199	43,26
265,9	71,169	13,269	13,269	1423,4	0,4423	44,23	43,269
266,3	71,247	13,287	13,287	1424,9	0,44289	44,289	43,287
266,6	71,715	13,312	13,312	1434,3	0,44373	44,373	43,312
267	71,101	13,322	13,322	1422	0,44406	44,406	43,322
267,4	71,42	13,344	13,344	1428,4	0,44479	44,479	43,344
267,7	71,352	13,362	13,362	1427	0,44539	44,539	43,362
268,1	71,1	13,374	13,374	1422	0,4458	44,58	43,374
268,4	71,581	13,401	13,401	1431,6	0,44671	44,671	43,401
268,8	71,245	13,414	13,414	1424,9	0,44713	44,713	43,414
269,1	71,105	13,43	13,43	1422,1	0,44766	44,766	43,43
269,5	71,684	13,455	13,455	1433,7	0,44851	44,851	43,455
269,9	71,123	13,465	13,465	1422,5	0,44883	44,883	43,465
270,2	71,297	13,488	13,488	1425,9	0,44958	44,958	43,488
270,6	71,52	13,507	13,507	1430,4	0,45022	45,022	43,507
270,9	71,041	13,516	13,516	1420,8	0,45054	45,054	43,516
271,3	71,735	13,545	13,545	1434,7	0,45148	45,148	43,545
271,7	71,277	13,557	13,557	1425,5	0,45191	45,191	43,557
272	71,269	13,573	13,573	1425,4	0,45243	45,243	43,573
272,4	71,894	13,6	13,6	1437,9	0,45334	45,334	43,6
272,7	71,174	13,609	13,609	1423,5	0,45362	45,362	43,609
273,1	71,607	13,632	13,632	1432,1	0,45438	45,438	43,632
273,5	71,546	13,65	13,65	1430,9	0,455	45,5	43,65
273,8	71,124	13,661	13,661	1422,5	0,45538	45,538	43,661
274,2	71,802	13,689	13,689	1436	0,4563	45,63	43,689
274,5	71,442	13,702	13,702	1428,8	0,45673	45,673	43,702
274,9	71,314	13,717	13,717	1426,3	0,45725	45,725	43,717
275,2	71,97	13,744	13,744	1439,4	0,45815	45,815	43,744
275,6	71,184	13,75	13,75	1423,7	0,45834	45,834	43,75
276	71,615	13,773	13,773	1432,3	0,45911	45,911	43,773
276,3	71,47	13,791	13,791	1429,4	0,45971	45,971	43,791
276,7	71,238	13,805	13,805	1424,8	0,46016	46,016	43,805
277	72,269	13,837	13,837	1445,4	0,46122	46,122	43,837
277,4	71,399	13,843	13,843	1428	0,46143	46,143	43,843
277,8	71,664	13,864	13,864	1433,3	0,46212	46,212	43,864
278,1	71,804	13,885	13,885	1436,1	0,46283	46,283	43,885
278,5	71,277	13,895	13,895	1425,5	0,46318	46,318	43,895
278,8	71,624	13,918	13,918	1432,5	0,46393	46,393	43,918
279,2	71,423	13,934	13,934	1428,5	0,46447	46,447	43,934
279,6	71,483	13,952	13,952	1429,7	0,46505	46,505	43,952
279,9	71,799	13,975	13,975	1436	0,46585	46,585	43,975
280,3	71,337	13,987	13,987	1426,7	0,46623	46,623	43,987
280,6	71,48	14,006	14,006	1429,6	0,46686	46,686	44,006
281	71,663	14,028	14,028	1433,3	0,46758	46,758	44,028
281,3	71,393	14,041	14,041	1427,9	0,46802	46,802	44,041
281,7	71,803	14,062	14,062	1436,1	0,46872	46,872	44,062
282,1	71,675	14,078	14,078	1433,5	0,46926	46,926	44,078
282,4	71,338	14,093	14,093	1426,8	0,46976	46,976	44,093
282,8	72,232	14,123	14,123	1444,6	0,47076	47,076	44,123
283,1	71,54	14,13	14,13	1430,8	0,471	47,1	44,13
283,5	71,678	14,148	14,148	1433,6	0,47159	47,159	44,148
283,9	71,681	14,17	14,17	1433,6	0,47233	47,233	44,17
284,2	71,411	14,18	14,18	1428,2	0,47268	47,268	44,18
284,6	71,802	14,206	14,206	1436	0,47352	47,352	44,206
284,9	71,603	14,221	14,221	1432,1	0,47402	47,402	44,221
285,3	71,453	14,238	14,238	1429,1	0,47459	47,459	44,238
285,7	71,844	14,262	14,262	1436,9	0,47538	47,538	44,262
286	71,392	14,273	14,273	1427,8	0,47577	47,577	44,273
286,4	71,754	14,293	14,293	1435,1	0,47645	47,645	44,293
286,7	71,859	14,315	14,315	1437,2	0,47717	47,717	44,315
287,1	71,321	14,326	14,326	1426,4	0,47753	47,753	44,326
287,5	71,925	14,351	14,351	1438,5	0,47836	47,836	44,351
287,8	71,584	14,365	14,365	1431,7	0,47882	47,882	44,365
288,2	71,673	14,38	14,38	1433,5	0,47935	47,935	44,38
288,5	72,345	14,408	14,408	1446,9	0,48028	48,028	44,408
288,9	71,581	14,419	14,419	1431,6	0,48062	48,062	44,419
289,2	71,804	14,437	14,437	1436,1	0,48123	48,123	44,437
289,6	71,888	14,457	14,457	1437,8	0,48191	48,191	44,457
290	71,538	14,47	14,47	1430,8	0,48235	48,235	44,47
290,3	71,819	14,493	14,493	1436,4	0,4831	48,31	44,493
290,7	71,578	14,508	14,508	1431,6	0,48359	48,359	44,508
291	71,661	14,526	14,526	1433,2	0,4842	48,42	44,526
291,4	72,081	14,55	14,55	1441,6	0,485	48,5	44,55
291,8	71,458	14,559	14,559	1429,2	0,48531	48,531	44,559
292,1	71,863	14,582	14,582	1437,3	0,48605	48,605	44,582
292,5	71,909	14,602	14,602	1438,2	0,48672	48,672	44,602
292,8	71,395	14,612	14,612	1427,9	0,48706	48,706	44,612
293,2	72,027	14,637	14,637	1440,5	0,48791	48,791	44,637
293,6	71,642	14,652	14,652	1432,8	0,48839	48,839	44,652
293,9	71,729	14,668	14,668	1434,6	0,48894	48,894	44,668
294,3	72,304	14,696	14,696	1446,1	0,48988	48,988	44,696
294,6	71,607	14,704	14,704	1432,1	0,49013	49,013	44,704
295	71,832	14,725	14,725	1436,6	0,49084	49,084	44,725
295,3	71,909	14,745	14,745	1438,2	0,4915	49,15	44,745
295,7	71,394	14,755	14,755	1427,9	0,49184	49,184	44,755
296,1	72,325	14,785	14,785	1446,5	0,49283	49,283	44,785
296,4	71,604	14,795	14,795	1432,1	0,49316	49,316	44,795
296,8	71,607	14,811	14,811	1432,1	0,49371	49,371	44,811
297,1	72,115	14,834	14,834	1442,3	0,49448	49,448	44,834
297,5	71,521	14,845	14,845	1430,4	0,49485	49,485	44,845
297,9	71,873	14,868	14,868	1437,5	0,4956	49,56	44,868
298,2	71,974	14,888	14,888	1439,5	0,49627	49,627	44,888
298,6	71,596	14,899	14,899	1431,9	0,49663	49,663	44,899
298,9	72,422	14,93	14,93	1448,4	0,49767	49,767	44,93
299,3	71,597	14,938	14,938	1431,9	0,49793	49,793	44,938
299,7	71,651	14,955	14,955	1433	0,49851	49,851	44,955
300	72,182	14,981	14,981	1443,6	0,49937	49,937	44,981
300,4	71,596	14,99	14,99	1431,9	0,49967	49,967	44,99
300,7	71,904	15,012	15,012	1438,1	0,50042	50,042	45,012
301,1	71,744	15,029	15,029	1434,9	0,50097	50,097	45,029
301,4	71,474	15,046	15,046	1429,5	0,50152	50,152	45,046
301,8	72,119	15,071	15,071	1442,4	0,50237	50,237	45,071
302,2	71,53	15,081	15,081	1430,6	0,5027	50,27	45,081
302,5	71,729	15,101	15,101	1434,6	0,50338	50,338	45,101
302,9	71,848	15,121	15,121	1437	0,50405	50,405	45,121
303,2	71,368	15,133	15,133	1427,4	0,50442	50,442	45,133
303,6	71,648	15,154	15,154	1433	0,50515	50,515	45,154
304	71,7	15,175	15,175	1434	0,50582	50,582	45,175
304,3	71,394	15,188	15,188	1427,9	0,50627	50,627	45,188
304,7	71,944	15,213	15,213	1438,9	0,50711	50,711	45,213
305	71,423	15,227	15,227	1428,5	0,50755	50,755	45,227
305,4	71,486	15,244	15,244	1429,7	0,50812	50,812	45,244
305,8	71,856	15,268	15,268	1437,1	0,50893	50,893	45,268
306,1	71,204	15,277	15,277	1424,1	0,50922	50,922	45,277
306,5	71,363	15,3	15,3	1427,3	0,51001	51,001	45,3
306,8	71,275	15,317	15,317	1425,5	0,51058	51,058	45,317
307,2	70,901	15,331	15,331	1418	0,51103	51,103	45,331
307,5	71,833	15,365	15,365	1436,7	0,51217	51,217	45,365
307,9	70,323	15,366	15,366	1406,5	0,51221	51,221	45,366
308,3	70,194	15,387	15,387	1403,9	0,51291	51,291	45,387
308,6	69,531	15,409	15,409	1390,6	0,51362	51,362	45,409
309	68,062	15,419	15,419	1361,2	0,51396	51,396	45,419
309,3	-0,23222	15,449	15,449	-4,6443	0,51496	51,496	45,449
309,4		15,458	15,458		0,51528	51,528	45,458