File: Tests de traction/Fichiers source/04_12_2016/6.txt
Time (s)	Load (N)	Machine Extension (mm)	Extension (mm)	Stress (MPa)	Strain	Percentage Strain	Gauge Length (mm)
0
0,5235	0,0044177	0,00012063	0,00012063	0,088354	4,0208E-06	0,00040208	30
1,047	0,67535	0,032831	0,032831	13,507	0,0010944	0,10944	30,033
1,571	2,4681	0,053701	0,053701	49,363	0,00179	0,179	30,054
2,094	7,0274	0,079282	0,079282	140,55	0,0026427	0,26427	30,079
2,618	13,101	0,11095	0,11095	262,02	0,0036983	0,36983	30,111
3,141	17,464	0,13196	0,13196	349,27	0,0043986	0,43986	30,132
3,665	23,793	0,16979	0,16979	475,86	0,0056598	0,56598	30,17
4,188	26,086	0,18378	0,18378	521,71	0,006126	0,6126	30,184
4,712	30,969	0,21915	0,21915	619,37	0,007305	0,7305	30,219
5,235	33,006	0,23595	0,23595	660,12	0,0078651	0,78651	30,236
5,759	36,724	0,26714	0,26714	734,49	0,0089046	0,89046	30,267
6,283	39,629	0,29125	0,29125	792,58	0,0097082	0,97082	30,291
6,806	42,39	0,31716	0,31716	847,79	0,010572	1,0572	30,317
7,33	45,148	0,34446	0,34446	902,97	0,011482	1,1482	30,344
7,853	47,138	0,36816	0,36816	942,75	0,012272	1,2272	30,368
8,377	50,494	0,3951	0,3951	1009,9	0,01317	1,317	30,395
8,9	51,765	0,4187	0,4187	1035,3	0,013957	1,3957	30,419
9,424	54,952	0,45415	0,45415	1099	0,015138	1,5138	30,454
9,947	56,325	0,47264	0,47264	1126,5	0,015755	1,5755	30,473
10,47	58,863	0,5046	0,5046	1177,3	0,01682	1,682	30,505
10,99	60,785	0,52428	0,52428	1215,7	0,017476	1,7476	30,524
11,52	62,595	0,55299	0,55299	1251,9	0,018433	1,8433	30,553
12,04	63,9	0,57874	0,57874	1278	0,019291	1,9291	30,579
12,57	65,44	0,60268	0,60268	1308,8	0,020089	2,0089	30,603
13,09	67,951	0,63469	0,63469	1359	0,021156	2,1156	30,635
13,61	68,983	0,65625	0,65625	1379,7	0,021875	2,1875	30,656
14,14	71,322	0,69157	0,69157	1426,4	0,023052	2,3052	30,692
14,66	71,739	0,7076	0,7076	1434,8	0,023587	2,3587	30,708
15,18	73,385	0,74125	0,74125	1467,7	0,024708	2,4708	30,741
15,71	74,413	0,7602	0,7602	1488,3	0,02534	2,534	30,76
16,23	75,513	0,79048	0,79048	1510,3	0,026349	2,6349	30,79
16,75	76,964	0,81272	0,81272	1539,3	0,027091	2,7091	30,813
17,28	77,363	0,84037	0,84037	1547,3	0,028012	2,8012	30,84
17,8	78,7	0,86579	0,86579	1574	0,02886	2,886	30,866
18,32	79,391	0,89373	0,89373	1587,8	0,029791	2,9791	30,894
18,85	80,557	0,9228	0,9228	1611,1	0,03076	3,076	30,923
19,37	80,396	0,94379	0,94379	1607,9	0,03146	3,146	30,944
19,89	81,399	0,98126	0,98126	1628	0,032709	3,2709	30,981
20,42	80,227	0,99274	0,99274	1604,5	0,033091	3,3091	30,993
20,94	81,224	1,0288	1,0288	1624,5	0,034292	3,4292	31,029
21,47	81,312	1,0475	1,0475	1626,2	0,034916	3,4916	31,047
21,99	80,96	1,0781	1,0781	1619,2	0,035936	3,5936	31,078
22,51	81,442	1,1011	1,1011	1628,8	0,036704	3,6704	31,101
23,04	80,669	1,1278	1,1278	1613,4	0,037594	3,7594	31,128
23,56	80,241	1,1568	1,1568	1604,8	0,038559	3,8559	31,157
24,08	78,945	1,1796	1,1796	1578,9	0,039319	3,9319	31,18
24,61	80,776	1,214	1,214	1615,5	0,040467	4,0467	31,214
25,13	79,233	1,2308	1,2308	1584,7	0,041027	4,1027	31,231
25,65	79,787	1,2646	1,2646	1595,7	0,042155	4,2155	31,265
26,18	78,748	1,2846	1,2846	1575	0,04282	4,282	31,285
26,7	78,486	1,3132	1,3132	1569,7	0,043774	4,3774	31,313
27,22	78,179	1,3386	1,3386	1563,6	0,044621	4,4621	31,339
27,75	77,576	1,365	1,365	1551,5	0,045499	4,5499	31,365
28,27	77,421	1,3912	1,3912	1548,4	0,046372	4,6372	31,391
28,8	76,061	1,4167	1,4167	1521,2	0,047224	4,7224	31,417
29,32	76,885	1,4456	1,4456	1537,7	0,048188	4,8188	31,446
29,84	75,652	1,4672	1,4672	1513	0,048906	4,8906	31,467
30,37	77,508	1,5026	1,5026	1550,2	0,050086	5,0086	31,503
30,89	76,905	1,5175	1,5175	1538,1	0,050584	5,0584	31,518
31,41	78,33	1,552	1,552	1566,6	0,051735	5,1735	31,552
31,94	77,956	1,5714	1,5714	1559,1	0,052381	5,2381	31,571
32,46	77,825	1,6019	1,6019	1556,5	0,053397	5,3397	31,602
32,98	78,598	1,6261	1,6261	1572	0,054202	5,4202	31,626
33,51	78,264	1,652	1,652	1565,3	0,055068	5,5068	31,652
34,03	77,94	1,681	1,681	1558,8	0,056033	5,6033	31,681
34,55	76,313	1,7015	1,7015	1526,3	0,056716	5,6716	31,701
35,08	76,884	1,7377	1,7377	1537,7	0,057924	5,7924	31,738
35,6	74,448	1,7523	1,7523	1489	0,05841	5,841	31,752
36,12	76,501	1,7882	1,7882	1530	0,059606	5,9606	31,788
36,65	75,486	1,8051	1,8051	1509,7	0,060171	6,0171	31,805
37,17	76,412	1,8384	1,8384	1528,2	0,06128	6,128	31,838
37,7	76,763	1,8618	1,8618	1535,3	0,062061	6,2061	31,862
38,22	76,435	1,8888	1,8888	1528,7	0,062959	6,2959	31,889
38,74	77,103	1,9154	1,9154	1542,1	0,063848	6,3848	31,915
39,27	75,682	1,9385	1,9385	1513,6	0,064617	6,4617	31,938
39,79	76,554	1,9706	1,9706	1531,1	0,065685	6,5685	31,971
40,31	73,196	1,9899	1,9899	1463,9	0,066332	6,6332	31,99
40,84	74,52	2,0275	2,0275	1490,4	0,067584	6,7584	32,028
41,36	72,872	2,0411	2,0411	1457,4	0,068036	6,8036	32,041
41,88	74,565	2,0781	2,0781	1491,3	0,069269	6,9269	32,078
42,41	73,59	2,0955	2,0955	1471,8	0,069851	6,9851	32,096
42,93	74,25	2,125	2,125	1485	0,070833	7,0833	32,125
43,45	74,609	2,1484	2,1484	1492,2	0,071614	7,1614	32,148
43,98	74,494	2,1753	2,1753	1489,9	0,072512	7,2512	32,175
44,5	75,452	2,204	2,204	1509	0,073467	7,3467	32,204
45,03	74,351	2,2272	2,2272	1487	0,074239	7,4239	32,227
45,55	75,664	2,2587	2,2587	1513,3	0,075289	7,5289	32,259
46,07	73,96	2,2792	2,2792	1479,2	0,075973	7,5973	32,279
46,6	75,577	2,3156	2,3156	1511,5	0,077187	7,7187	32,316
47,12	72,784	2,3294	2,3294	1455,7	0,077646	7,7646	32,329
47,64	72,423	2,3622	2,3622	1448,5	0,07874	7,874	32,362
48,17	71,565	2,3829	2,3829	1431,3	0,079431	7,9431	32,383
48,69	71,268	2,4112	2,4112	1425,4	0,080374	8,0374	32,411
49,21	72,099	2,4379	2,4379	1442	0,081262	8,1262	32,438
49,74	72,087	2,4637	2,4637	1441,7	0,082124	8,2124	32,464
50,26	73,425	2,4945	2,4945	1468,5	0,083149	8,3149	32,494
50,78	72,476	2,516	2,516	1449,5	0,083866	8,3866	32,516
51,31	74,009	2,5486	2,5486	1480,2	0,084954	8,4954	32,549
51,83	72,699	2,567	2,567	1454	0,085567	8,5567	32,567
52,35	74,002	2,599	2,599	1480	0,086632	8,6632	32,599
52,88	73,586	2,6192	2,6192	1471,7	0,087307	8,7307	32,619
53,4	73,883	2,6491	2,6491	1477,7	0,088303	8,8303	32,649
53,93	73,941	2,6727	2,6727	1478,8	0,089091	8,9091	32,673
54,45	73,646	2,6989	2,6989	1472,9	0,089964	8,9964	32,699
54,97	74,269	2,7259	2,7259	1485,4	0,090864	9,0864	32,726
55,5	73,883	2,7507	2,7507	1477,7	0,091689	9,1689	32,751
56,02	75,753	2,7857	2,7857	1515,1	0,092857	9,2857	32,786
56,54	74,108	2,8023	2,8023	1482,2	0,09341	9,341	32,802
57,07	75,466	2,8367	2,8367	1509,3	0,094556	9,4556	32,837
57,59	74,152	2,8535	2,8535	1483	0,095115	9,5115	32,853
58,11	75,012	2,8868	2,8868	1500,2	0,096225	9,6225	32,887
58,64	74,559	2,9072	2,9072	1491,2	0,096905	9,6905	32,907
59,16	74,303	2,9347	2,9347	1486,1	0,097824	9,7824	32,935
59,68	74,824	2,9605	2,9605	1496,5	0,098683	9,8683	32,961
60,21	74,235	2,9852	2,9852	1484,7	0,099507	9,9507	32,985
60,73	75,689	3,0173	3,0173	1513,8	0,10058	10,058	33,017
61,26	74,544	3,0382	3,0382	1490,9	0,10127	10,127	33,038
61,78	76,123	3,074	3,074	1522,5	0,10247	10,247	33,074
62,3	74,408	3,0895	3,0895	1488,2	0,10298	10,298	33,089
62,83	75,341	3,1227	3,1227	1506,8	0,10409	10,409	33,123
63,35	74,547	3,1424	3,1424	1490,9	0,10475	10,475	33,142
63,87	74,91	3,1735	3,1735	1498,2	0,10578	10,578	33,173
64,4	75,096	3,1971	3,1971	1501,9	0,10657	10,657	33,197
64,92	74,791	3,2235	3,2235	1495,8	0,10745	10,745	33,224
65,44	75,013	3,2491	3,2491	1500,3	0,1083	10,83	33,249
65,97	74,585	3,2738	3,2738	1491,7	0,10913	10,913	33,274
66,49	75,676	3,3058	3,3058	1513,5	0,11019	11,019	33,306
67,01	74,274	3,3246	3,3246	1485,5	0,11082	11,082	33,325
67,54	75,961	3,3612	3,3612	1519,2	0,11204	11,204	33,361
68,06	74,28	3,3759	3,3759	1485,6	0,11253	11,253	33,376
68,58	75,244	3,408	3,408	1504,9	0,1136	11,36	33,408
69,11	74,759	3,4312	3,4312	1495,2	0,11437	11,437	33,431
69,63	74,834	3,4599	3,4599	1496,7	0,11533	11,533	33,46
70,16	75,274	3,4853	3,4853	1505,5	0,11618	11,618	33,485
70,68	74,48	3,5102	3,5102	1489,6	0,11701	11,701	33,51
71,2	75,62	3,5411	3,5411	1512,4	0,11804	11,804	33,541
71,73	74,343	3,5591	3,5591	1486,9	0,11864	11,864	33,559
72,25	75,954	3,5967	3,5967	1519,1	0,11989	11,989	33,597
72,77	74,027	3,6094	3,6094	1480,5	0,12031	12,031	33,609
73,3	75,34	3,6472	3,6472	1506,8	0,12157	12,157	33,647
73,82	74,877	3,6657	3,6657	1497,5	0,12219	12,219	33,666
74,34	74,683	3,6944	3,6944	1493,7	0,12315	12,315	33,694
74,87	74,911	3,7205	3,7205	1498,2	0,12402	12,402	33,72
75,39	74,581	3,7472	3,7472	1491,6	0,12491	12,491	33,747
75,91	75,093	3,7725	3,7725	1501,9	0,12575	12,575	33,773
76,44	74,422	3,7985	3,7985	1488,4	0,12662	12,662	33,799
76,96	75,789	3,8313	3,8313	1515,8	0,12771	12,771	33,831
77,49	74,358	3,8486	3,8486	1487,2	0,12829	12,829	33,849
78,01	75,444	3,8843	3,8843	1508,9	0,12948	12,948	33,884
78,53	74,312	3,8996	3,8996	1486,2	0,12999	12,999	33,9
79,06	75,638	3,9376	3,9376	1512,8	0,13125	13,125	33,938
79,58	74,396	3,9558	3,9558	1487,9	0,13186	13,186	33,956
80,1	74,029	3,983	3,983	1480,6	0,13277	13,277	33,983
80,63	73,63	4,0084	4,0084	1472,6	0,13361	13,361	34,008
81,15	72,831	4,0352	4,0352	1456,6	0,13451	13,451	34,035
81,67	73,544	4,0647	4,0647	1470,9	0,13549	13,549	34,065
82,2	72,598	4,0839	4,0839	1452	0,13613	13,613	34,084
82,72	74,166	4,1203	4,1203	1483,3	0,13734	13,734	34,12
83,24	73,084	4,1376	4,1376	1461,7	0,13792	13,792	34,138
83,77	74,121	4,1718	4,1718	1482,4	0,13906	13,906	34,172
84,29	72,799	4,1909	4,1909	1456	0,1397	13,97	34,191
84,81	72,333	4,2196	4,2196	1446,7	0,14065	14,065	34,22
85,34	72,44	4,245	4,245	1448,8	0,1415	14,15	34,245
85,86	72,175	4,2706	4,2706	1443,5	0,14235	14,235	34,271
86,39	72,913	4,2966	4,2966	1458,3	0,14322	14,322	34,297
86,91	72,641	4,3217	4,3217	1452,8	0,14406	14,406	34,322
87,43	73,81	4,3527	4,3527	1476,2	0,14509	14,509	34,353
87,96	72,74	4,3712	4,3712	1454,8	0,14571	14,571	34,371
88,48	74,522	4,409	4,409	1490,4	0,14697	14,697	34,409
89	72,964	4,4241	4,4241	1459,3	0,14747	14,747	34,424
89,53	74,103	4,4584	4,4584	1482,1	0,14861	14,861	34,458
90,05	73,341	4,4777	4,4777	1466,8	0,14926	14,926	34,478
90,57	73,952	4,5095	4,5095	1479	0,15032	15,032	34,509
91,1	73,958	4,5325	4,5325	1479,2	0,15108	15,108	34,533
91,62	73,601	4,5564	4,5564	1472	0,15188	15,188	34,556
92,14	74,26	4,5865	4,5865	1485,2	0,15288	15,288	34,587
92,67	73,294	4,6062	4,6062	1465,9	0,15354	15,354	34,606
93,19	74,721	4,6438	4,6438	1494,4	0,15479	15,479	34,644
93,72	73,607	4,6599	4,6599	1472,1	0,15533	15,533	34,66
94,24	74,6	4,6946	4,6946	1492	0,15649	15,649	34,695
94,76	73,954	4,7132	4,7132	1479,1	0,15711	15,711	34,713
95,29	74,157	4,7435	4,7435	1483,1	0,15812	15,812	34,744
95,81	74,012	4,7673	4,7673	1480,2	0,15891	15,891	34,767
96,33	73,943	4,7949	4,7949	1478,9	0,15983	15,983	34,795
96,86	74,486	4,8221	4,8221	1489,7	0,16074	16,074	34,822
97,38	73,784	4,845	4,845	1475,7	0,1615	16,15	34,845
97,9	74,658	4,876	4,876	1493,2	0,16253	16,253	34,876
98,43	73,625	4,8963	4,8963	1472,5	0,16321	16,321	34,896
98,95	75,004	4,9315	4,9315	1500,1	0,16438	16,438	34,932
99,47	73,394	4,9468	4,9468	1467,9	0,16489	16,489	34,947
100	74,641	4,9813	4,9813	1492,8	0,16604	16,604	34,981
100,5	73,919	5,0022	5,0022	1478,4	0,16674	16,674	35,002
101	74,039	5,0304	5,0304	1480,8	0,16768	16,768	35,03
101,6	74,103	5,0552	5,0552	1482,1	0,16851	16,851	35,055
102,1	73,572	5,0819	5,0819	1471,4	0,1694	16,94	35,082
102,6	74,095	5,1077	5,1077	1481,9	0,17026	17,026	35,108
103,1	73,151	5,1307	5,1307	1463	0,17102	17,102	35,131
103,7	75,227	5,1733	5,1733	1504,5	0,17244	17,244	35,173
104,2	73,068	5,1816	5,1816	1461,4	0,17272	17,272	35,182
104,7	74,31	5,218	5,218	1486,2	0,17393	17,393	35,218
105,2	73,406	5,2351	5,2351	1468,1	0,1745	17,45	35,235
105,8	73,751	5,2651	5,2651	1475	0,1755	17,55	35,265
106,3	73,934	5,2897	5,2897	1478,7	0,17632	17,632	35,29
106,8	73,801	5,3171	5,3171	1476	0,17724	17,724	35,317
107,3	74,297	5,3445	5,3445	1485,9	0,17815	17,815	35,345
107,9	73,597	5,3674	5,3674	1471,9	0,17891	17,891	35,367
108,4	74,633	5,401	5,401	1492,7	0,18003	18,003	35,401
108,9	73,305	5,417	5,417	1466,1	0,18057	18,057	35,417
109,4	74,904	5,4561	5,4561	1498,1	0,18187	18,187	35,456
109,9	73,501	5,4709	5,4709	1470	0,18236	18,236	35,471
110,5	74,452	5,5041	5,5041	1489	0,18347	18,347	35,504
111	73,938	5,5253	5,5253	1478,8	0,18418	18,418	35,525
111,5	74,303	5,5548	5,5548	1486,1	0,18516	18,516	35,555
112	74,321	5,5792	5,5792	1486,4	0,18597	18,597	35,579
112,6	73,883	5,6032	5,6032	1477,7	0,18677	18,677	35,603
113,1	74,203	5,6308	5,6308	1484,1	0,18769	18,769	35,631
113,6	73,586	5,654	5,654	1471,7	0,18847	18,847	35,654
114,1	74,863	5,6897	5,6897	1497,3	0,18966	18,966	35,69
114,7	73,627	5,7065	5,7065	1472,5	0,19022	19,022	35,707
115,2	74,917	5,7423	5,7423	1498,3	0,19141	19,141	35,742
115,7	73,98	5,7596	5,7596	1479,6	0,19199	19,199	35,76
116,2	74,517	5,7909	5,7909	1490,3	0,19303	19,303	35,791
116,8	74,225	5,8136	5,8136	1484,5	0,19379	19,379	35,814
117,3	73,906	5,8404	5,8404	1478,1	0,19468	19,468	35,84
117,8	74,363	5,8688	5,8688	1487,3	0,19563	19,563	35,869
118,3	74,202	5,8931	5,8931	1484	0,19644	19,644	35,893
118,8	74,984	5,9242	5,9242	1499,7	0,19747	19,747	35,924
119,4	73,985	5,9435	5,9435	1479,7	0,19812	19,812	35,944
119,9	74,95	5,9763	5,9763	1499	0,19921	19,921	35,976
120,4	73,944	5,9955	5,9955	1478,9	0,19985	19,985	35,996
120,9	74,76	6,0289	6,0289	1495,2	0,20096	20,096	36,029
121,5	74,245	6,0482	6,0482	1484,9	0,20161	20,161	36,048
122	74,523	6,079	6,079	1490,5	0,20263	20,263	36,079
122,5	74,359	6,1022	6,1022	1487,2	0,20341	20,341	36,102
123	74,235	6,1291	6,1291	1484,7	0,2043	20,43	36,129
123,6	74,53	6,1564	6,1564	1490,6	0,20521	20,521	36,156
124,1	74,191	6,1809	6,1809	1483,8	0,20603	20,603	36,181
124,6	75,168	6,2136	6,2136	1503,4	0,20712	20,712	36,214
125,1	73,794	6,2308	6,2308	1475,9	0,20769	20,769	36,231
125,7	74,487	6,2636	6,2636	1489,7	0,20879	20,879	36,264
126,2	74,454	6,2855	6,2855	1489,1	0,20952	20,952	36,285
126,7	74,764	6,3165	6,3165	1495,3	0,21055	21,055	36,317
127,2	74,205	6,3378	6,3378	1484,1	0,21126	21,126	36,338
127,7	74,093	6,3639	6,3639	1481,9	0,21213	21,213	36,364
128,3	74,365	6,3906	6,3906	1487,3	0,21302	21,302	36,391
128,8	73,881	6,416	6,416	1477,6	0,21387	21,387	36,416
129,3	74,611	6,4461	6,4461	1492,2	0,21487	21,487	36,446
129,8	73,789	6,4648	6,4648	1475,8	0,21549	21,549	36,465
130,4	74,978	6,5048	6,5048	1499,6	0,21683	21,683	36,505
130,9	73,469	6,5181	6,5181	1469,4	0,21727	21,727	36,518
131,4	74,328	6,5509	6,5509	1486,6	0,21836	21,836	36,551
131,9	74,035	6,5733	6,5733	1480,7	0,21911	21,911	36,573
132,5	74,086	6,6018	6,6018	1481,7	0,22006	22,006	36,602
133	74,103	6,6262	6,6262	1482,1	0,22087	22,087	36,626
133,5	73,952	6,6526	6,6526	1479	0,22175	22,175	36,653
134	74,033	6,6786	6,6786	1480,7	0,22262	22,262	36,679
134,6	73,35	6,7003	6,7003	1467	0,22334	22,334	36,7
135,1	74,698	6,7372	6,7372	1494	0,22457	22,457	36,737
135,6	73,641	6,7521	6,7521	1472,8	0,22507	22,507	36,752
136,1	74,972	6,7906	6,7906	1499,4	0,22635	22,635	36,791
136,6	73,818	6,8062	6,8062	1476,4	0,22687	22,687	36,806
137,2	74,349	6,8394	6,8394	1487	0,22798	22,798	36,839
137,7	74,061	6,8604	6,8604	1481,2	0,22868	22,868	36,86
138,2	73,867	6,8878	6,8878	1477,3	0,22959	22,959	36,888
138,7	74,535	6,9141	6,9141	1490,7	0,23047	23,047	36,914
139,3	74,042	6,939	6,939	1480,8	0,2313	23,13	36,939
139,8	75,063	6,9727	6,9727	1501,3	0,23242	23,242	36,973
140,3	74,025	6,9894	6,9894	1480,5	0,23298	23,298	36,989
140,8	74,781	7,0252	7,0252	1495,6	0,23417	23,417	37,025
141,4	73,949	7,0428	7,0428	1479	0,23476	23,476	37,043
141,9	74,65	7,0748	7,0748	1493	0,23583	23,583	37,075
142,4	74,163	7,0957	7,0957	1483,3	0,23652	23,652	37,096
142,9	74,235	7,1242	7,1242	1484,7	0,23747	23,747	37,124
143,5	74,455	7,15	7,15	1489,1	0,23833	23,833	37,15
144	74,334	7,1768	7,1768	1486,7	0,23923	23,923	37,177
144,5	74,411	7,2023	7,2023	1488,2	0,24008	24,008	37,202
145	74,057	7,2271	7,2271	1481,1	0,2409	24,09	37,227
145,5	74,936	7,2592	7,2592	1498,7	0,24197	24,197	37,259
146,1	73,931	7,2769	7,2769	1478,6	0,24256	24,256	37,277
146,6	74,95	7,3115	7,3115	1499	0,24372	24,372	37,311
147,1	73,974	7,3285	7,3285	1479,5	0,24428	24,428	37,328
147,6	74,828	7,3639	7,3639	1496,6	0,24546	24,546	37,364
148,2	74,258	7,3831	7,3831	1485,2	0,2461	24,61	37,383
148,7	74,259	7,4122	7,4122	1485,2	0,24707	24,707	37,412
149,2	74,516	7,4387	7,4387	1490,3	0,24796	24,796	37,439
149,7	74,04	7,4623	7,4623	1480,8	0,24874	24,874	37,462
150,3	74,645	7,4925	7,4925	1492,9	0,24975	24,975	37,493
150,8	74,026	7,5131	7,5131	1480,5	0,25044	25,044	37,513
151,3	75,267	7,5506	7,5506	1505,3	0,25169	25,169	37,551
151,8	74,072	7,5642	7,5642	1481,4	0,25214	25,214	37,564
152,4	74,788	7,599	7,599	1495,8	0,2533	25,33	37,599
152,9	74,159	7,6188	7,6188	1483,2	0,25396	25,396	37,619
153,4	74,324	7,648	7,648	1486,5	0,25493	25,493	37,648
153,9	74,27	7,6732	7,6732	1485,4	0,25577	25,577	37,673
154,4	74,095	7,6991	7,6991	1481,9	0,25664	25,664	37,699
155	74,353	7,7272	7,7272	1487,1	0,25757	25,757	37,727
155,5	74,005	7,7509	7,7509	1480,1	0,25836	25,836	37,751
156	74,94	7,7836	7,7836	1498,8	0,25945	25,945	37,784
156,5	73,997	7,8002	7,8002	1479,9	0,26001	26,001	37,8
157,1	75,084	7,8376	7,8376	1501,7	0,26125	26,125	37,838
157,6	74,061	7,8536	7,8536	1481,2	0,26179	26,179	37,854
158,1	74,478	7,8851	7,8851	1489,6	0,26284	26,284	37,885
158,6	74,386	7,9088	7,9088	1487,7	0,26363	26,363	37,909
159,2	74,224	7,936	7,936	1484,5	0,26453	26,453	37,936
159,7	74,201	7,9602	7,9602	1484	0,26534	26,534	37,96
160,2	73,915	7,9879	7,9879	1478,3	0,26626	26,626	37,988
160,7	74,703	8,0155	8,0155	1494,1	0,26718	26,718	38,015
161,3	73,904	8,0365	8,0365	1478,1	0,26788	26,788	38,036
161,8	75,22	8,0738	8,0738	1504,4	0,26913	26,913	38,074
162,3	73,848	8,0877	8,0877	1477	0,26959	26,959	38,088
162,8	74,854	8,123	8,123	1497,1	0,27077	27,077	38,123
163,3	74,244	8,1443	8,1443	1484,9	0,27148	27,148	38,144
163,9	74,423	8,1717	8,1717	1488,5	0,27239	27,239	38,172
164,4	74,463	8,1961	8,1961	1489,3	0,2732	27,32	38,196
164,9	74,186	8,2223	8,2223	1483,7	0,27408	27,408	38,222
165,4	74,554	8,2515	8,2515	1491,1	0,27505	27,505	38,252
166	74,026	8,273	8,273	1480,5	0,27577	27,577	38,273
166,5	74,945	8,3069	8,3069	1498,9	0,2769	27,69	38,307
167	73,972	8,3242	8,3242	1479,4	0,27747	27,747	38,324
167,5	75,132	8,3611	8,3611	1502,6	0,2787	27,87	38,361
168,1	73,9	8,3767	8,3767	1478	0,27922	27,922	38,377
168,6	74,916	8,4116	8,4116	1498,3	0,28039	28,039	38,412
169,1	74,259	8,4308	8,4308	1485,2	0,28103	28,103	38,431
169,6	74,46	8,4602	8,4602	1489,2	0,28201	28,201	38,46
170,2	74,531	8,4861	8,4861	1490,6	0,28287	28,287	38,486
170,7	74,246	8,5099	8,5099	1484,9	0,28366	28,366	38,51
171,2	74,944	8,5391	8,5391	1498,9	0,28464	28,464	38,539
171,7	74,217	8,5609	8,5609	1484,3	0,28536	28,536	38,561
172,2	75,662	8,5998	8,5998	1513,2	0,28666	28,666	38,6
172,8	74,17	8,6103	8,6103	1483,4	0,28701	28,701	38,61
173,3	75,191	8,6481	8,6481	1503,8	0,28827	28,827	38,648
173,8	74,254	8,6644	8,6644	1485,1	0,28881	28,881	38,664
174,3	74,383	8,6931	8,6931	1487,7	0,28977	28,977	38,693
174,9	74,423	8,7195	8,7195	1488,5	0,29065	29,065	38,72
175,4	74,354	8,7465	8,7465	1487,1	0,29155	29,155	38,747
175,9	74,842	8,7753	8,7753	1496,8	0,29251	29,251	38,775
176,4	74,401	8,7982	8,7982	1488	0,29327	29,327	38,798
177	75,104	8,8297	8,8297	1502,1	0,29432	29,432	38,83
177,5	74,3	8,8478	8,8478	1486	0,29493	29,493	38,848
178	75,308	8,8845	8,8845	1506,2	0,29615	29,615	38,885
178,5	74,312	8,9006	8,9006	1486,2	0,29669	29,669	38,901
179,1	74,941	8,9337	8,9337	1498,8	0,29779	29,779	38,934
179,6	74,547	8,9544	8,9544	1490,9	0,29848	29,848	38,954
180,1	74,656	8,9843	8,9843	1493,1	0,29948	29,948	38,984
180,6	74,742	9,0089	9,0089	1494,8	0,3003	30,03	39,009
181,1	74,434	9,0343	9,0343	1488,7	0,30114	30,114	39,034
181,7	75,093	9,0631	9,0631	1501,9	0,3021	30,21	39,063
182,2	74,494	9,0848	9,0848	1489,9	0,30283	30,283	39,085
182,7	75,462	9,1198	9,1198	1509,2	0,30399	30,399	39,12
183,2	74,434	9,136	9,136	1488,7	0,30453	30,453	39,136
183,8	75,372	9,1716	9,1716	1507,4	0,30572	30,572	39,172
184,3	74,48	9,1888	9,1888	1489,6	0,30629	30,629	39,189
184,8	74,717	9,2191	9,2191	1494,3	0,3073	30,73	39,219
185,3	74,569	9,2429	9,2429	1491,4	0,3081	30,81	39,243
185,9	74,542	9,2702	9,2702	1490,8	0,30901	30,901	39,27
186,4	75,052	9,2985	9,2985	1501	0,30995	30,995	39,299
186,9	74,473	9,32	9,32	1489,5	0,31067	31,067	39,32
187,4	75,43	9,3549	9,3549	1508,6	0,31183	31,183	39,355
188	74,347	9,3716	9,3716	1486,9	0,31239	31,239	39,372
188,5	75,251	9,4072	9,4072	1505	0,31357	31,357	39,407
189	74,348	9,4238	9,4238	1487	0,31413	31,413	39,424
189,5	74,962	9,4572	9,4572	1499,2	0,31524	31,524	39,457
190	74,618	9,4781	9,4781	1492,4	0,31594	31,594	39,478
190,6	74,743	9,5069	9,5069	1494,9	0,3169	31,69	39,507
191,1	74,741	9,5312	9,5312	1494,8	0,31771	31,771	39,531
191,6	74,9	9,56	9,56	1498	0,31867	31,867	39,56
192,1	74,938	9,5867	9,5867	1498,8	0,31956	31,956	39,587
192,7	74,468	9,6082	9,6082	1489,4	0,32027	32,027	39,608
193,2	75,975	9,6475	9,6475	1519,5	0,32158	32,158	39,648
193,7	74,511	9,6593	9,6593	1490,2	0,32198	32,198	39,659
194,2	75,363	9,6945	9,6945	1507,3	0,32315	32,315	39,695
194,8	74,625	9,7131	9,7131	1492,5	0,32377	32,377	39,713
195,3	74,915	9,7422	9,7422	1498,3	0,32474	32,474	39,742
195,8	74,943	9,7664	9,7664	1498,9	0,32555	32,555	39,766
196,3	74,923	9,7938	9,7938	1498,5	0,32646	32,646	39,794
196,9	75,182	9,8192	9,8192	1503,6	0,32731	32,731	39,819
197,4	74,811	9,8446	9,8446	1496,2	0,32815	32,815	39,845
197,9	75,56	9,8779	9,8779	1511,2	0,32926	32,926	39,878
198,4	74,641	9,8947	9,8947	1492,8	0,32982	32,982	39,895
198,9	75,711	9,9324	9,9324	1514,2	0,33108	33,108	39,932
199,5	74,557	9,9465	9,9465	1491,1	0,33155	33,155	39,947
200	74,919	9,9772	9,9772	1498,4	0,33257	33,257	39,977
200,5	74,781	10,001	10,001	1495,6	0,33337	33,337	40,001
201	74,965	10,031	10,031	1499,3	0,33435	33,435	40,031
201,6	75,116	10,055	10,055	1502,3	0,33515	33,515	40,055
202,1	74,854	10,082	10,082	1497,1	0,33606	33,606	40,082
202,6	75,248	10,107	10,107	1505	0,33691	33,691	40,107
203,1	74,71	10,132	10,132	1494,2	0,33773	33,773	40,132
203,7	75,531	10,165	10,165	1510,6	0,33884	33,884	40,165
204,2	74,687	10,183	10,183	1493,7	0,33944	33,944	40,183
204,7	75,659	10,22	10,22	1513,2	0,34066	34,066	40,22
205,2	74,79	10,236	10,236	1495,8	0,34121	34,121	40,236
205,8	75,29	10,268	10,268	1505,8	0,34228	34,228	40,268
206,3	74,926	10,289	10,289	1498,5	0,34298	34,298	40,289
206,8	75,032	10,316	10,316	1500,6	0,34388	34,388	40,316
207,3	75,204	10,344	10,344	1504,1	0,3448	34,48	40,344
207,8	74,848	10,367	10,367	1497	0,34555	34,555	40,367
208,4	76,221	10,407	10,407	1524,4	0,34689	34,689	40,407
208,9	74,759	10,417	10,417	1495,2	0,34725	34,725	40,417
209,4	75,74	10,455	10,455	1514,8	0,34851	34,851	40,455
209,9	74,735	10,471	10,471	1494,7	0,34903	34,903	40,471
210,5	75,321	10,505	10,505	1506,4	0,35017	35,017	40,505
211	75,174	10,525	10,525	1503,5	0,35082	35,082	40,525
211,5	75,08	10,555	10,555	1501,6	0,35182	35,182	40,555
212	75,061	10,577	10,577	1501,2	0,35258	35,258	40,577
212,6	75,143	10,606	10,606	1502,9	0,35352	35,352	40,606
213,1	75,592	10,631	10,631	1511,8	0,35436	35,436	40,631
213,6	74,908	10,655	10,655	1498,2	0,35516	35,516	40,655
214,1	75,873	10,69	10,69	1517,5	0,35632	35,632	40,69
214,7	74,805	10,706	10,706	1496,1	0,35687	35,687	40,706
215,2	75,737	10,741	10,741	1514,7	0,35804	35,804	40,741
215,7	75,039	10,759	10,759	1500,8	0,35865	35,865	40,759
216,2	75,523	10,791	10,791	1510,5	0,35971	35,971	40,791
216,7	75,415	10,815	10,815	1508,3	0,36049	36,049	40,815
217,3	75,302	10,84	10,84	1506	0,36135	36,135	40,84
217,8	75,442	10,867	10,867	1508,8	0,36223	36,223	40,867
218,3	75,079	10,891	10,891	1501,6	0,36304	36,304	40,891
218,8	75,926	10,926	10,926	1518,5	0,36419	36,419	40,926
219,4	74,967	10,942	10,942	1499,3	0,36473	36,473	40,942
219,9	75,739	10,976	10,976	1514,8	0,36588	36,588	40,976
220,4	75,079	10,995	10,995	1501,6	0,3665	36,65	40,995
220,9	75,711	11,028	11,028	1514,2	0,3676	36,76	41,028
221,5	75,433	11,049	11,049	1508,7	0,3683	36,83	41,049
222	75,499	11,077	11,077	1510	0,36925	36,925	41,077
222,5	75,686	11,104	11,104	1513,7	0,37012	37,012	41,104
223	75,53	11,129	11,129	1510,6	0,37098	37,098	41,129
223,6	75,83	11,157	11,157	1516,6	0,37189	37,189	41,157
224,1	75,497	11,18	11,18	1509,9	0,37267	37,267	41,18
224,6	76,047	11,212	11,212	1520,9	0,37374	37,374	41,212
225,1	75,328	11,23	11,23	1506,6	0,37434	37,434	41,23
225,6	76,238	11,266	11,266	1524,8	0,37553	37,553	41,266
226,2	75,506	11,283	11,283	1510,1	0,37609	37,609	41,283
226,7	75,925	11,314	11,314	1518,5	0,37713	37,713	41,314
227,2	75,975	11,339	11,339	1519,5	0,37795	37,795	41,339
227,7	75,757	11,364	11,364	1515,1	0,37881	37,881	41,364
228,3	76,034	11,389	11,389	1520,7	0,37964	37,964	41,389
228,8	75,751	11,417	11,417	1515	0,38056	38,056	41,417
229,3	76,391	11,445	11,445	1527,8	0,38151	38,151	41,445
229,8	75,594	11,465	11,465	1511,9	0,38218	38,218	41,465
230,4	76,424	11,502	11,502	1528,5	0,3834	38,34	41,502
230,9	75,681	11,517	11,517	1513,6	0,38392	38,392	41,517
231,4	76,434	11,553	11,553	1528,7	0,38509	38,509	41,553
231,9	75,881	11,573	11,573	1517,6	0,38576	38,576	41,573
232,5	76,11	11,602	11,602	1522,2	0,38672	38,672	41,602
233	76,05	11,626	11,626	1521	0,38754	38,754	41,626
233,5	75,939	11,653	11,653	1518,8	0,38842	38,842	41,653
234	76,206	11,68	11,68	1524,1	0,38933	38,933	41,68
234,5	75,731	11,701	11,701	1514,6	0,39004	39,004	41,701
235,1	76,503	11,736	11,736	1530,1	0,3912	39,12	41,736
235,6	75,479	11,753	11,753	1509,6	0,39177	39,177	41,753
236,1	76,601	11,79	11,79	1532	0,39301	39,301	41,79
236,6	75,706	11,806	11,806	1514,1	0,39352	39,352	41,806
237,2	76,528	11,841	11,841	1530,6	0,39471	39,471	41,841
237,7	76,158	11,86	11,86	1523,2	0,39535	39,535	41,86
238,2	76,167	11,89	11,89	1523,3	0,39632	39,632	41,89
238,7	76,363	11,916	11,916	1527,3	0,39719	39,719	41,916
239,3	75,772	11,937	11,937	1515,4	0,39791	39,791	41,937
239,8	76,444	11,97	11,97	1528,9	0,399	39,9	41,97
240,3	75,645	11,988	11,988	1512,9	0,39961	39,961	41,988
240,8	76,885	12,027	12,027	1537,7	0,40091	40,091	42,027
241,4	75,822	12,042	12,042	1516,4	0,40139	40,139	42,042
241,9	76,42	12,075	12,075	1528,4	0,4025	40,25	42,075
242,4	75,843	12,094	12,094	1516,9	0,40314	40,314	42,094
242,9	76,157	12,125	12,125	1523,1	0,40417	40,417	42,125
243,4	76,185	12,15	12,15	1523,7	0,40501	40,501	42,15
244	76,04	12,176	12,176	1520,8	0,40586	40,586	42,176
244,5	76,299	12,204	12,204	1526	0,40679	40,679	42,204
245	75,859	12,227	12,227	1517,2	0,40755	40,755	42,227
245,5	77,111	12,264	12,264	1542,2	0,40881	40,881	42,264
246,1	75,716	12,276	12,276	1514,3	0,40921	40,921	42,276
246,6	76,733	12,313	12,313	1534,7	0,41042	41,042	42,313
247,1	76,099	12,328	12,328	1522	0,41095	41,095	42,328
247,6	76,596	12,363	12,363	1531,9	0,4121	41,21	42,363
248,2	76,271	12,385	12,385	1525,4	0,41282	41,282	42,385
248,7	76,435	12,413	12,413	1528,7	0,41377	41,377	42,413
249,2	76,257	12,437	12,437	1525,1	0,41458	41,458	42,437
249,7	76,196	12,462	12,462	1523,9	0,41539	41,539	42,462
250,3	76,746	12,493	12,493	1534,9	0,41644	41,644	42,493
250,8	76,044	12,513	12,513	1520,9	0,41709	41,709	42,513
251,3	77,241	12,551	12,551	1544,8	0,41837	41,837	42,551
251,8	76,23	12,565	12,565	1524,6	0,41885	41,885	42,565
252,3	76,997	12,6	12,6	1539,9	0,42001	42,001	42,6
252,9	76,427	12,62	12,62	1528,5	0,42066	42,066	42,62
253,4	76,463	12,648	12,648	1529,3	0,42159	42,159	42,648
253,9	76,323	12,671	12,671	1526,5	0,42238	42,238	42,671
254,4	76,287	12,699	12,699	1525,7	0,4233	42,33	42,699
255	76,719	12,728	12,728	1534,4	0,42428	42,428	42,728
255,5	76,402	12,752	12,752	1528	0,42506	42,506	42,752
256	77,173	12,786	12,786	1543,5	0,42619	42,619	42,786
256,5	76,156	12,801	12,801	1523,1	0,42668	42,668	42,801
257,1	76,883	12,835	12,835	1537,7	0,42784	42,784	42,835
257,6	76,216	12,854	12,854	1524,3	0,42848	42,848	42,854
258,1	76,539	12,885	12,885	1530,8	0,4295	42,95	42,885
258,6	76,428	12,909	12,909	1528,6	0,4303	43,03	42,909
259,2	76,365	12,936	12,936	1527,3	0,43121	43,121	42,936
259,7	76,419	12,96	12,96	1528,4	0,43199	43,199	42,96
260,2	76,27	12,986	12,986	1525,4	0,43287	43,287	42,986
260,7	76,603	13,015	13,015	1532,1	0,43384	43,384	43,015
261,3	76,191	13,037	13,037	1523,8	0,43456	43,456	43,037
261,8	77,161	13,073	13,073	1543,2	0,43578	43,578	43,073
262,3	76,25	13,088	13,088	1525	0,43627	43,627	43,088
262,8	76,655	13,124	13,124	1533,1	0,43746	43,746	43,124
263,3	76,569	13,143	13,143	1531,4	0,43811	43,811	43,143
263,9	76,733	13,174	13,174	1534,7	0,43913	43,913	43,174
264,4	76,503	13,197	13,197	1530,1	0,43989	43,989	43,197
264,9	76,352	13,222	13,222	1527	0,44074	44,074	43,222
265,4	76,746	13,248	13,248	1534,9	0,44161	44,161	43,248
266	76,347	13,273	13,273	1526,9	0,44242	44,242	43,273
266,5	76,971	13,306	13,306	1539,4	0,44354	44,354	43,306
267	76,318	13,325	13,325	1526,4	0,44417	44,417	43,325
267,5	76,959	13,359	13,359	1539,2	0,44531	44,531	43,359
268,1	76,252	13,377	13,377	1525	0,44591	44,591	43,377
268,6	76,704	13,409	13,409	1534,1	0,44697	44,697	43,409
269,1	76,402	13,431	13,431	1528	0,44771	44,771	43,431
269,6	76,489	13,459	13,459	1529,8	0,44863	44,863	43,459
270,2	76,551	13,485	13,485	1531	0,4495	44,95	43,485
270,7	76,366	13,509	13,509	1527,3	0,45031	45,031	43,509
271,2	76,86	13,539	13,539	1537,2	0,45131	45,131	43,539
271,7	76,479	13,562	13,562	1529,6	0,45207	45,207	43,562
272,2	77,452	13,594	13,594	1549	0,45314	45,314	43,594
272,8	76,445	13,613	13,613	1528,9	0,45375	45,375	43,613
273,3	77,237	13,648	13,648	1544,7	0,45494	45,494	43,648
273,8	76,638	13,667	13,667	1532,8	0,45556	45,556	43,667
274,3	76,935	13,697	13,697	1538,7	0,45657	45,657	43,697
274,9	76,761	13,719	13,719	1535,2	0,45732	45,732	43,719
275,4	76,53	13,744	13,744	1530,6	0,45813	45,813	43,744
275,9	76,842	13,773	13,773	1536,8	0,45911	45,911	43,773
276,4	76,538	13,796	13,796	1530,8	0,45988	45,988	43,796
277	77,676	13,835	13,835	1553,5	0,46118	46,118	43,835
277,5	76,358	13,848	13,848	1527,2	0,46161	46,161	43,848
278	77,266	13,884	13,884	1545,3	0,46282	46,282	43,884
278,5	76,401	13,9	13,9	1528	0,46333	46,333	43,9
279,1	76,827	13,933	13,933	1536,5	0,46443	46,443	43,933
279,6	76,681	13,956	13,956	1533,6	0,4652	46,52	43,956
280,1	76,543	13,982	13,982	1530,9	0,46607	46,607	43,982
280,6	76,739	14,009	14,009	1534,8	0,46696	46,696	44,009
281,1	76,573	14,035	14,035	1531,5	0,46782	46,782	44,035
281,7	77,011	14,061	14,061	1540,2	0,4687	46,87	44,061
282,2	76,583	14,085	14,085	1531,7	0,4695	46,95	44,085
282,7	77,514	14,122	14,122	1550,3	0,47074	47,074	44,122
283,2	76,542	14,136	14,136	1530,8	0,4712	47,12	44,136
283,8	77,247	14,169	14,169	1544,9	0,47231	47,231	44,169
284,3	76,493	14,189	14,189	1529,9	0,47295	47,295	44,189
284,8	76,865	14,22	14,22	1537,3	0,47402	47,402	44,22
285,3	76,758	14,243	14,243	1535,2	0,47475	47,475	44,243
285,9	76,715	14,27	14,27	1534,3	0,47568	47,568	44,27
286,4	76,447	14,298	14,298	1528,9	0,47659	47,659	44,298
286,9	76,242	14,32	14,32	1524,8	0,47732	47,732	44,32
287,4	77,238	14,358	14,358	1544,8	0,4786	47,86	44,358
288	76,203	14,372	14,372	1524,1	0,47905	47,905	44,372
288,5	77,035	14,409	14,409	1540,7	0,4803	48,03	44,409
289	76,088	14,424	14,424	1521,8	0,48079	48,079	44,424
289,5	76,147	14,457	14,457	1522,9	0,48189	48,189	44,457
290	75,622	14,478	14,478	1512,4	0,48261	48,261	44,478
290,6	75,567	14,505	14,505	1511,3	0,48352	48,352	44,505
291,1	75,682	14,533	14,533	1513,6	0,48443	48,443	44,533
291,6	75,589	14,558	14,558	1511,8	0,48527	48,527	44,558
292,1	76,021	14,587	14,587	1520,4	0,48623	48,623	44,587
292,7	75,798	14,61	14,61	1516	0,48699	48,699	44,61
293,2	76,511	14,643	14,643	1530,2	0,48812	48,812	44,643
293,7	75,831	14,659	14,659	1516,6	0,48863	48,863	44,659
294,2	76,777	14,698	14,698	1535,5	0,48994	48,994	44,698
294,8	75,822	14,712	14,712	1516,4	0,4904	49,04	44,712
295,3	76,179	14,743	14,743	1523,6	0,49143	49,143	44,743
295,8	76,226	14,768	14,768	1524,5	0,49226	49,226	44,768
296,3	76,197	14,794	14,794	1523,9	0,49312	49,312	44,794
296,9	76,374	14,821	14,821	1527,5	0,49403	49,403	44,821
297,4	76,052	14,845	14,845	1521	0,49483	49,483	44,845
297,9	76,721	14,877	14,877	1534,4	0,49591	49,591	44,877
298,4	76,151	14,895	14,895	1523	0,49649	49,649	44,895
298,9	76,982	14,932	14,932	1539,6	0,49772	49,772	44,932
299,5	76,073	14,946	14,946	1521,5	0,49819	49,819	44,946
300	76,63	14,979	14,979	1532,6	0,4993	49,93	44,979
300,5	76,456	15,002	15,002	1529,1	0,50006	50,006	45,002
301	76,517	15,03	15,03	1530,3	0,501	50,1	45,03
301,6	76,534	15,055	15,055	1530,7	0,50184	50,184	45,055
302,1	76,342	15,08	15,08	1526,8	0,50268	50,268	45,08
302,6	76,958	15,111	15,111	1539,2	0,5037	50,37	45,111
303,1	76,407	15,132	15,132	1528,1	0,50439	50,439	45,132
303,7	76,964	15,164	15,164	1539,3	0,50547	50,547	45,164
304,2	76,237	15,184	15,184	1524,7	0,50614	50,614	45,184
304,7	77,071	15,218	15,218	1541,4	0,50728	50,728	45,218
305,2	76,317	15,236	15,236	1526,3	0,50785	50,785	45,236
305,8	76,96	15,269	15,269	1539,2	0,50896	50,896	45,269
306,3	76,5	15,291	15,291	1530	0,50969	50,969	45,291
306,8	76,676	15,317	15,317	1533,5	0,51057	51,057	45,317
307,3	76,843	15,344	15,344	1536,9	0,51147	51,147	45,344
307,8	76,433	15,366	15,366	1528,7	0,5122	51,22	45,366
308,4	77,058	15,399	15,399	1541,2	0,5133	51,33	45,399
308,9	76,511	15,418	15,418	1530,2	0,51394	51,394	45,418
309,4	77,439	15,456	15,456	1548,8	0,51519	51,519	45,456
309,9	76,527	15,47	15,47	1530,5	0,51567	51,567	45,47
310,5	77,102	15,505	15,505	1542	0,51682	51,682	45,505
311	76,657	15,524	15,524	1533,1	0,51748	51,748	45,524
311,5	76,568	15,553	15,553	1531,4	0,51843	51,843	45,553
312	76,284	15,579	15,579	1525,7	0,51929	51,929	45,579
312,6	76,202	15,604	15,604	1524	0,52013	52,013	45,604
313,1	76,374	15,633	15,633	1527,5	0,52111	52,111	45,633
313,6	76,11	15,656	15,656	1522,2	0,52186	52,186	45,656
314,1	76,726	15,691	15,691	1534,5	0,52302	52,302	45,691
314,7	76,216	15,705	15,705	1524,3	0,5235	52,35	45,705
315,2	76,725	15,74	15,74	1534,5	0,52468	52,468	45,74
315,7	76,289	15,759	15,759	1525,8	0,52528	52,528	45,759
316,2	76,81	15,792	15,792	1536,2	0,5264	52,64	45,792
316,7	76,551	15,813	15,813	1531	0,5271	52,71	45,813
317,3	76,685	15,842	15,842	1533,7	0,52805	52,805	45,842
317,8	76,695	15,866	15,866	1533,9	0,52887	52,887	45,866
318,3	76,477	15,891	15,891	1529,5	0,52969	52,969	45,891
318,8	77,178	15,925	15,925	1543,6	0,53083	53,083	45,925
319,4	76,635	15,943	15,943	1532,7	0,53144	53,144	45,943
319,9	77,193	15,978	15,978	1543,9	0,53259	53,259	45,978
320,4	76,464	15,994	15,994	1529,3	0,53312	53,312	45,994
320,9	77,17	16,029	16,029	1543,4	0,53428	53,428	46,029
321,5	76,797	16,049	16,049	1535,9	0,53497	53,497	46,049
322	76,775	16,076	16,076	1535,5	0,53585	53,585	46,076
322,5	76,91	16,101	16,101	1538,2	0,53671	53,671	46,101
323	76,661	16,126	16,126	1533,2	0,53754	53,754	46,126
323,6	77,016	16,156	16,156	1540,3	0,53852	53,852	46,156
324,1	76,726	16,179	16,179	1534,5	0,53931	53,931	46,179
324,6	77,398	16,215	16,215	1548	0,54049	54,049	46,215
325,1	76,542	16,231	16,231	1530,8	0,54102	54,102	46,231
325,6	77,053	16,262	16,262	1541,1	0,54206	54,206	46,262
326,2	76,485	16,283	16,283	1529,7	0,54276	54,276	46,283
326,7	76,875	16,314	16,314	1537,5	0,54381	54,381	46,314
327,2	76,631	16,338	16,338	1532,6	0,5446	54,46	46,338
327,7	76,632	16,364	16,364	1532,6	0,54548	54,548	46,364
328,3	76,586	16,39	16,39	1531,7	0,54634	54,634	46,39
328,8	76,449	16,415	16,415	1529	0,54717	54,717	46,415
329,3	76,79	16,446	16,446	1535,8	0,54819	54,819	46,446
329,8	76,274	16,465	16,465	1525,5	0,54884	54,884	46,465
330,4	77,224	16,504	16,504	1544,5	0,55015	55,015	46,504
330,9	76,121	16,518	16,518	1522,4	0,55061	55,061	46,518
331,4	76,706	16,552	16,552	1534,1	0,55174	55,174	46,552
331,9	76,672	16,574	16,574	1533,4	0,55248	55,248	46,574
332,5	76,769	16,603	16,603	1535,4	0,55343	55,343	46,603
333	76,598	16,625	16,625	1532	0,55416	55,416	46,625
333,5	76,475	16,65	16,65	1529,5	0,55499	55,499	46,65
334	76,745	16,68	16,68	1534,9	0,556	55,6	46,68
334,5	76,456	16,702	16,702	1529,1	0,55672	55,672	46,702
335,1	77,137	16,737	16,737	1542,7	0,55789	55,789	46,737
335,6	76,507	16,754	16,754	1530,1	0,55848	55,848	46,754
336,1	76,913	16,788	16,788	1538,3	0,55961	55,961	46,788
336,6	76,689	16,806	16,806	1533,8	0,56021	56,021	46,806
337,2	76,897	16,838	16,838	1537,9	0,56127	56,127	46,838
337,7	76,74	16,861	16,861	1534,8	0,56204	56,204	46,861
338,2	76,693	16,888	16,888	1533,9	0,56293	56,293	46,888
338,7	76,861	16,915	16,915	1537,2	0,56384	56,384	46,915
339,3	76,403	16,938	16,938	1528,1	0,56461	56,461	46,938
339,8	76,646	16,965	16,965	1532,9	0,56549	56,549	46,965
340,3	76,206	16,987	16,987	1524,1	0,56624	56,624	46,987
340,8	77,209	17,026	17,026	1544,2	0,56753	56,753	47,026
341,4	76,362	17,041	17,041	1527,2	0,56804	56,804	47,041
341,9	77,247	17,078	17,078	1544,9	0,56928	56,928	47,078
342,4	76,617	17,096	17,096	1532,3	0,56988	56,988	47,096
342,9	76,763	17,125	17,125	1535,3	0,57085	57,085	47,125
343,4	76,576	17,148	17,148	1531,5	0,57159	57,159	47,148
344	76,554	17,174	17,174	1531,1	0,57246	57,246	47,174
344,5	76,888	17,204	17,204	1537,8	0,57346	57,346	47,204
345	76,466	17,226	17,226	1529,3	0,57419	57,419	47,226
345,5	77,437	17,26	17,26	1548,7	0,57533	57,533	47,26
346,1	76,474	17,277	17,277	1529,5	0,57591	57,591	47,277
346,6	77,318	17,313	17,313	1546,4	0,57708	57,708	47,313
347,1	76,562	17,329	17,329	1531,2	0,57763	57,763	47,329
347,6	76,961	17,361	17,361	1539,2	0,5787	57,87	47,361
348,2	76,678	17,384	17,384	1533,6	0,57945	57,945	47,384
348,7	76,682	17,411	17,411	1533,6	0,58038	58,038	47,411
349,2	76,772	17,437	17,437	1535,4	0,58125	58,125	47,437
349,7	76,61	17,463	17,463	1532,2	0,58209	58,209	47,463
350,3	76,949	17,493	17,493	1539	0,58309	58,309	47,493
350,8	76,63	17,514	17,514	1532,6	0,58381	58,381	47,514
351,3	77,534	17,551	17,551	1550,7	0,58504	58,504	47,551
351,8	76,591	17,567	17,567	1531,8	0,58555	58,555	47,567
352,3	77,367	17,601	17,601	1547,3	0,58671	58,671	47,601
352,9	76,715	17,618	17,618	1534,3	0,58726	58,726	47,618
353,4	77,037	17,648	17,648	1540,7	0,58827	58,827	47,648
353,9	76,899	17,674	17,674	1538	0,58912	58,912	47,674
354,4	76,956	17,7	17,7	1539,1	0,59001	59,001	47,7
355	77,099	17,726	17,726	1542	0,59088	59,088	47,726
355,5	76,804	17,75	17,75	1536,1	0,59165	59,165	47,75
356	77,566	17,785	17,785	1551,3	0,59285	59,285	47,785
356,5	76,711	17,8	17,8	1534,2	0,59333	59,333	47,8
357,1	77,57	17,836	17,836	1551,4	0,59455	59,455	47,836
357,6	76,967	17,855	17,855	1539,3	0,59515	59,515	47,855
358,1	77,321	17,886	17,886	1546,4	0,59618	59,618	47,886
358,6	77,113	17,908	17,908	1542,3	0,59694	59,694	47,908
359,2	77,035	17,935	17,935	1540,7	0,59783	59,783	47,935
359,7	77,165	17,962	17,962	1543,3	0,59873	59,873	47,962
360,2	76,887	17,985	17,985	1537,7	0,59951	59,951	47,985
360,7	76,978	18,014	18,014	1539,6	0,60047	60,047	48,014
361,2	76,768	18,037	18,037	1535,4	0,60123	60,123	48,037
361,8	77,633	18,074	18,074	1552,7	0,60245	60,245	48,074
362,3	76,892	18,09	18,09	1537,8	0,60299	60,299	48,09
362,8	77,576	18,125	18,125	1551,5	0,60418	60,418	48,125
363,3	77	18,143	18,143	1540	0,60476	60,476	48,143
363,9	77,12	18,173	18,173	1542,4	0,60576	60,576	48,173
364,4	77,024	18,196	18,196	1540,5	0,60653	60,653	48,196
364,9	76,858	18,223	18,223	1537,2	0,60744	60,744	48,223
365,4	77,088	18,25	18,25	1541,8	0,60832	60,832	48,25
366	76,974	18,274	18,274	1539,5	0,60914	60,914	48,274
366,5	77,711	18,31	18,31	1554,2	0,61032	61,032	48,31
367	76,802	18,324	18,324	1536	0,6108	61,08	48,324
367,5	77,6	18,361	18,361	1552	0,61204	61,204	48,361
368,1	76,755	18,377	18,377	1535,1	0,61255	61,255	48,377
368,6	77,222	18,409	18,409	1544,4	0,61364	61,364	48,409
369,1	76,965	18,43	18,43	1539,3	0,61435	61,435	48,43
369,6	76,995	18,458	18,458	1539,9	0,61525	61,525	48,458
370,1	77,014	18,484	18,484	1540,3	0,61612	61,612	48,484
370,7	76,879	18,511	18,511	1537,6	0,61705	61,705	48,511
371,2	77,254	18,54	18,54	1545,1	0,61801	61,801	48,54
371,7	76,814	18,559	18,559	1536,3	0,61862	61,862	48,559
372,2	77,521	18,596	18,596	1550,4	0,61986	61,986	48,596
372,8	76,76	18,614	18,614	1535,2	0,62046	62,046	48,614
373,3	77,356	18,647	18,647	1547,1	0,62156	62,156	48,647
373,8	76,819	18,666	18,666	1536,4	0,62219	62,219	48,666
374,3	77,249	18,698	18,698	1545	0,62328	62,328	48,698
374,9	77,011	18,722	18,722	1540,2	0,62406	62,406	48,722
375,4	77,009	18,747	18,747	1540,2	0,62489	62,489	48,747
375,9	77,22	18,774	18,774	1544,4	0,62581	62,581	48,774
376,4	76,908	18,797	18,797	1538,2	0,62657	62,657	48,797
377	77,365	18,829	18,829	1547,3	0,62762	62,762	48,829
377,5	76,755	18,848	18,848	1535,1	0,62827	62,827	48,848
378	77,775	18,887	18,887	1555,5	0,62956	62,956	48,887
378,5	76,741	18,899	18,899	1534,8	0,62997	62,997	48,899
379	77,212	18,933	18,933	1544,2	0,6311	63,11	48,933
379,6	76,802	18,953	18,953	1536	0,63177	63,177	48,953
380,1	76,813	18,982	18,982	1536,3	0,63273	63,273	48,982
380,6	76,85	19,008	19,008	1537	0,63361	63,361	49,008
381,1	76,878	19,035	19,035	1537,6	0,63448	63,448	49,035
381,7	77,173	19,065	19,065	1543,5	0,63548	63,548	49,065
382,2	76,753	19,083	19,083	1535,1	0,63612	63,612	49,083
382,7	77,412	19,121	19,121	1548,2	0,63736	63,736	49,121
383,2	76,582	19,135	19,135	1531,6	0,63783	63,783	49,135
383,8	77,129	19,169	19,169	1542,6	0,63898	63,898	49,169
384,3	76,654	19,188	19,188	1533,1	0,63961	63,961	49,188
384,8	77,08	19,22	19,22	1541,6	0,64067	64,067	49,22
385,3	76,667	19,243	19,243	1533,3	0,64142	64,142	49,243
385,9	76,817	19,27	19,27	1536,3	0,64234	64,234	49,27
386,4	76,748	19,296	19,296	1535	0,64321	64,321	49,296
386,9	76,657	19,32	19,32	1533,1	0,64401	64,401	49,32
387,4	77,124	19,352	19,352	1542,5	0,64505	64,505	49,352
387,9	76,576	19,37	19,37	1531,5	0,64568	64,568	49,37
388,5	77,353	19,407	19,407	1547,1	0,64689	64,689	49,407
389	76,811	19,425	19,425	1536,2	0,64749	64,749	49,425
389,5	77,336	19,458	19,458	1546,7	0,6486	64,86	49,458
390	76,96	19,478	19,478	1539,2	0,64928	64,928	49,478
390,6	77,013	19,505	19,505	1540,3	0,65015	65,015	49,505
391,1	77,035	19,531	19,531	1540,7	0,65103	65,103	49,531
391,6	77,026	19,559	19,559	1540,5	0,65196	65,196	49,559
392,1	77,331	19,587	19,587	1546,6	0,6529	65,29	49,587
392,7	76,978	19,607	19,607	1539,6	0,65357	65,357	49,607
393,2	77,697	19,645	19,645	1553,9	0,65482	65,482	49,645
393,7	76,789	19,659	19,659	1535,8	0,65529	65,529	49,659
394,2	77,458	19,695	19,695	1549,2	0,65649	65,649	49,695
394,8	76,998	19,713	19,713	1540	0,65711	65,711	49,713
395,3	77,33	19,745	19,745	1546,6	0,65817	65,817	49,745
395,8	76,995	19,766	19,766	1539,9	0,65885	65,885	49,766
396,3	77,048	19,792	19,792	1541	0,65975	65,975	49,792
396,8	77,307	19,82	19,82	1546,1	0,66066	66,066	49,82
397,4	76,955	19,841	19,841	1539,1	0,66138	66,138	49,841
397,9	77,567	19,876	19,876	1551,3	0,66253	66,253	49,876
398,4	77,039	19,894	19,894	1540,8	0,66314	66,314	49,894
398,9	77,867	19,932	19,932	1557,3	0,66441	66,441	49,932
399,5	77,055	19,948	19,948	1541,1	0,66493	66,493	49,948
400	77,584	19,98	19,98	1551,7	0,66601	66,601	49,98
400,5	77,21	20	20	1544,2	0,66668	66,668	50
401	77,518	20,031	20,031	1550,4	0,6677	66,77	50,031
401,6	77,35	20,053	20,053	1547	0,66844	66,844	50,053
402,1	77,301	20,079	20,079	1546	0,66931	66,931	50,079
402,6	77,724	20,11	20,11	1554,5	0,67033	67,033	50,11
403,1	77,309	20,131	20,131	1546,2	0,67103	67,103	50,131
403,7	77,923	20,166	20,166	1558,5	0,67221	67,221	50,166
404,2	77,419	20,185	20,185	1548,4	0,67282	67,282	50,185
404,7	77,855	20,218	20,218	1557,1	0,67393	67,393	50,218
405,2	77,236	20,236	20,236	1544,7	0,67453	67,453	50,236
405,7	77,451	20,267	20,267	1549	0,67557	67,557	50,267
406,3	77,273	20,289	20,289	1545,5	0,6763	67,63	50,289
406,8	77,226	20,318	20,318	1544,5	0,67728	67,728	50,318
407,3	77,266	20,344	20,344	1545,3	0,67815	67,815	50,344
407,8	76,898	20,369	20,369	1538	0,67897	67,897	50,369
408,4	77,027	20,395	20,395	1540,5	0,67985	67,985	50,395
408,9	76,561	20,419	20,419	1531,2	0,68064	68,064	50,419
409,4	77,286	20,455	20,455	1545,7	0,68182	68,182	50,455
409,9	76,637	20,47	20,47	1532,7	0,68233	68,233	50,47
410,5	77,49	20,507	20,507	1549,8	0,68356	68,356	50,507
411	77,145	20,525	20,525	1542,9	0,68418	68,418	50,525
411,5	77,43	20,555	20,555	1548,6	0,68516	68,516	50,555
412	77,43	20,578	20,578	1548,6	0,68595	68,595	50,578
412,6	77,379	20,604	20,604	1547,6	0,68679	68,679	50,604
413,1	77,478	20,632	20,632	1549,6	0,68773	68,773	50,632
413,6	77,362	20,654	20,654	1547,2	0,68847	68,847	50,654
414,1	78,019	20,69	20,69	1560,4	0,68967	68,967	50,69
414,6	77,372	20,707	20,707	1547,4	0,69023	69,023	50,707
415,2	77,875	20,739	20,739	1557,5	0,69128	69,128	50,739
415,7	77,351	20,759	20,759	1547	0,69196	69,196	50,759
416,2	77,863	20,792	20,792	1557,3	0,69305	69,305	50,792
416,7	77,745	20,815	20,815	1554,9	0,69382	69,382	50,815
417,3	77,694	20,841	20,841	1553,9	0,6947	69,47	50,841
417,8	77,829	20,868	20,868	1556,6	0,69561	69,561	50,868
418,3	77,623	20,892	20,892	1552,5	0,6964	69,64	50,892
418,8	78,003	20,923	20,923	1560,1	0,69742	69,742	50,923
419,4	77,504	20,942	20,942	1550,1	0,69808	69,808	50,942
419,9	78,322	20,979	20,979	1566,4	0,6993	69,93	50,979
420,4	77,713	20,993	20,993	1554,3	0,69978	69,978	50,993
420,9	78,016	21,027	21,027	1560,3	0,7009	70,09	51,027
421,5	77,79	21,048	21,048	1555,8	0,70158	70,158	51,048
422	78,004	21,078	21,078	1560,1	0,7026	70,26	51,078
422,5	77,855	21,103	21,103	1557,1	0,70343	70,343	51,103
423	77,701	21,13	21,13	1554	0,70432	70,432	51,13
423,5	78,035	21,155	21,155	1560,7	0,70516	70,516	51,155
424,1	77,742	21,179	21,179	1554,8	0,70597	70,597	51,179
424,6	78,422	21,215	21,215	1568,4	0,70718	70,718	51,215
425,1	77,599	21,23	21,23	1552	0,70765	70,765	51,23
425,6	78,348	21,266	21,266	1567	0,70886	70,886	51,266
426,2	77,642	21,283	21,283	1552,8	0,70945	70,945	51,283
426,7	77,922	21,313	21,313	1558,4	0,71045	71,045	51,313
427,2	77,8	21,337	21,337	1556	0,71123	71,123	51,337
427,7	77,898	21,364	21,364	1558	0,71215	71,215	51,364
428,3	77,995	21,392	21,392	1559,9	0,71308	71,308	51,392
428,8	77,75	21,415	21,415	1555	0,71382	71,382	51,415
429,3	78,087	21,445	21,445	1561,7	0,71485	71,485	51,445
429,8	77,686	21,467	21,467	1553,7	0,71556	71,556	51,467
430,4	78,507	21,504	21,504	1570,1	0,71679	71,679	51,504
430,9	77,541	21,515	21,515	1550,8	0,71718	71,718	51,515
431,4	78,197	21,552	21,552	1563,9	0,71841	71,841	51,552
431,9	78,061	21,574	21,574	1561,2	0,71912	71,912	51,574
432,5	78,197	21,602	21,602	1563,9	0,72007	72,007	51,602
433	78,138	21,627	21,627	1562,8	0,72088	72,088	51,627
433,5	77,851	21,649	21,649	1557	0,72165	72,165	51,649
434	78,103	21,68	21,68	1562,1	0,72265	72,265	51,68
434,5	77,745	21,701	21,701	1554,9	0,72338	72,338	51,701
435,1	78,413	21,737	21,737	1568,3	0,72457	72,457	51,737
435,6	77,708	21,753	21,753	1554,2	0,72511	72,511	51,753
436,1	78,318	21,788	21,788	1566,4	0,72627	72,627	51,788
436,6	77,793	21,806	21,806	1555,9	0,72688	72,688	51,806
437,2	78,198	21,838	21,838	1564	0,72794	72,794	51,838
437,7	78,003	21,861	21,861	1560,1	0,72871	72,871	51,861
438,2	77,921	21,887	21,887	1558,4	0,72956	72,956	51,887
438,7	78,163	21,913	21,913	1563,3	0,73044	73,044	51,913
439,3	77,963	21,94	21,94	1559,3	0,73135	73,135	51,94
439,8	78,247	21,97	21,97	1564,9	0,73234	73,234	51,97
440,3	77,872	21,989	21,989	1557,4	0,73296	73,296	51,989
440,8	78,589	22,025	22,025	1571,8	0,73417	73,417	52,025
441,4	77,836	22,039	22,039	1556,7	0,73464	73,464	52,039
441,9	78,557	22,076	22,076	1571,1	0,73587	73,587	52,076
442,4	78,137	22,096	22,096	1562,7	0,73652	73,652	52,096
442,9	78,355	22,125	22,125	1567,1	0,7375	73,75	52,125
443,4	78,342	22,149	22,149	1566,8	0,73831	73,831	52,149
444	78,258	22,174	22,174	1565,2	0,73915	73,915	52,174
444,5	78,526	22,203	22,203	1570,5	0,7401	74,01	52,203
445	78,288	22,226	22,226	1565,8	0,74087	74,087	52,226
445,5	78,998	22,263	22,263	1580	0,7421	74,21	52,263
446,1	78,317	22,277	22,277	1566,3	0,74258	74,258	52,277
446,6	79,137	22,314	22,314	1582,7	0,74379	74,379	52,314
447,1	78,425	22,329	22,329	1568,5	0,7443	74,43	52,329
447,6	78,846	22,363	22,363	1576,9	0,74542	74,542	52,363
448,2	77,595	22,384	22,384	1551,9	0,74615	74,615	52,384
448,7	76,86	22,41	22,41	1537,2	0,74702	74,702	52,41
449,2	76,398	22,437	22,437	1528	0,74791	74,791	52,437
449,7	75,573	22,463	22,463	1511,5	0,74877	74,877	52,463
450,3	75,15	22,494	22,494	1503	0,74979	74,979	52,494
450,8	73,86	22,515	22,515	1477,2	0,75048	75,048	52,515
451,3	71,645	22,55	22,55	1432,9	0,75167	75,167	52,55
451,4	-0,049102			-0,98204