File: Tests de traction/Fichiers source/04_12_2016/7.txt
Time (s)	Load (N)	Machine Extension (mm)	Extension (mm)	Stress (MPa)	Strain	Percentage Strain	Gauge Length (mm)
0
0,5658	0,026042	0,0033873	0,0033873	0,52084	0,00011291	0,011291	30,003
1,132	8,4452	0,044431	0,044431	168,9	0,001481	0,1481	30,044
1,697	11,704	0,061582	0,061582	234,08	0,0020527	0,20527	30,062
2,263	17,904	0,093355	0,093355	358,08	0,0031118	0,31118	30,093
2,829	22,546	0,12167	0,12167	450,92	0,0040557	0,40557	30,122
3,395	26,942	0,1494	0,1494	538,85	0,0049799	0,49799	30,149
3,961	31,824	0,18568	0,18568	636,47	0,0061893	0,61893	30,186
4,527	34,326	0,20057	0,20057	686,52	0,0066857	0,66857	30,201
5,092	38,721	0,23704	0,23704	774,42	0,0079012	0,79012	30,237
5,658	41,868	0,26126	0,26126	837,36	0,0087088	0,87088	30,261
6,224	44,547	0,29034	0,29034	890,94	0,0096779	0,96779	30,29
6,79	48,462	0,32366	0,32366	969,24	0,010789	1,0789	30,324
7,356	50,452	0,34411	0,34411	1009	0,01147	1,147	30,344
7,921	53,866	0,37961	0,37961	1077,3	0,012654	1,2654	30,38
8,487	55,949	0,40332	0,40332	1119	0,013444	1,3444	30,403
9,053	58,495	0,43344	0,43344	1169,9	0,014448	1,4448	30,433
9,619	61,606	0,46706	0,46706	1232,1	0,015569	1,5569	30,467
10,18	62,55	0,48692	0,48692	1251	0,016231	1,6231	30,487
10,75	64,897	0,52115	0,52115	1297,9	0,017372	1,7372	30,521
11,32	66,784	0,54468	0,54468	1335,7	0,018156	1,8156	30,545
11,88	68,476	0,57433	0,57433	1369,5	0,019144	1,9144	30,574
12,45	70,598	0,60777	0,60777	1412	0,020259	2,0259	30,608
13,01	71,726	0,63008	0,63008	1434,5	0,021003	2,1003	30,63
13,58	72,944	0,66384	0,66384	1458,9	0,022128	2,2128	30,664
14,15	74,173	0,68739	0,68739	1483,5	0,022913	2,2913	30,687
14,71	75,716	0,71678	0,71678	1514,3	0,023893	2,3893	30,717
15,28	77,586	0,74539	0,74539	1551,7	0,024846	2,4846	30,745
15,84	77,979	0,76886	0,76886	1559,6	0,025629	2,5629	30,769
16,41	79,311	0,80581	0,80581	1586,2	0,02686	2,686	30,806
16,97	79,943	0,82802	0,82802	1598,9	0,027601	2,7601	30,828
17,54	80,684	0,85903	0,85903	1613,7	0,028634	2,8634	30,859
18,11	82,295	0,88601	0,88601	1645,9	0,029534	2,9534	30,886
18,67	82,362	0,91078	0,91078	1647,2	0,030359	3,0359	30,911
19,24	83,318	0,94794	0,94794	1666,4	0,031598	3,1598	30,948
19,8	83,842	0,96762	0,96762	1676,8	0,032254	3,2254	30,968
20,37	83,815	0,99872	0,99872	1676,3	0,033291	3,3291	30,999
20,94	85,202	1,0272	1,0272	1704	0,034241	3,4241	31,027
21,5	84,995	1,0523	1,0523	1699,9	0,035075	3,5075	31,052
22,07	85,466	1,0925	1,0925	1709,3	0,036417	3,6417	31,093
22,63	85,493	1,1104	1,1104	1709,9	0,037015	3,7015	31,11
23,2	85,135	1,1414	1,1414	1702,7	0,038046	3,8046	31,141
23,76	85,835	1,1683	1,1683	1716,7	0,038943	3,8943	31,168
24,33	85,116	1,1945	1,1945	1702,3	0,039818	3,9818	31,195
24,9	85,564	1,23	1,23	1711,3	0,041	4,1	31,23
25,46	83,687	1,2484	1,2484	1673,7	0,041614	4,1614	31,248
26,03	83,541	1,2832	1,2832	1670,8	0,042772	4,2772	31,283
26,59	83,178	1,3096	1,3096	1663,6	0,043652	4,3652	31,31
27,16	78,418	1,3373	1,3373	1568,4	0,044577	4,4577	31,337
27,72	78,692	1,372	1,372	1573,8	0,045733	4,5733	31,372
28,29	75,856	1,3914	1,3914	1517,1	0,046381	4,6381	31,391
28,86	75,638	1,4258	1,4258	1512,8	0,047528	4,7528	31,426
29,42	76,11	1,4529	1,4529	1522,2	0,04843	4,843	31,453
29,99	75,366	1,4775	1,4775	1507,3	0,04925	4,925	31,478
30,55	78,475	1,5149	1,5149	1569,5	0,050496	5,0496	31,515
31,12	76,387	1,5325	1,5325	1527,7	0,051084	5,1084	31,533
31,69	77,438	1,5683	1,5683	1548,8	0,052277	5,2277	31,568
32,25	77,641	1,5934	1,5934	1552,8	0,053112	5,3112	31,593
32,82	77,216	1,6202	1,6202	1544,3	0,054008	5,4008	31,62
33,38	79,147	1,6527	1,6527	1582,9	0,055091	5,5091	31,653
33,95	76,821	1,6753	1,6753	1536,4	0,055844	5,5844	31,675
34,51	78,635	1,7099	1,7099	1572,7	0,056998	5,6998	31,71
35,08	78,383	1,7328	1,7328	1567,7	0,057761	5,7761	31,733
35,65	78,067	1,7635	1,7635	1561,3	0,058785	5,8785	31,764
36,21	78,958	1,7928	1,7928	1579,2	0,059761	5,9761	31,793
36,78	77,53	1,8172	1,8172	1550,6	0,060574	6,0574	31,817
37,34	79,502	1,8544	1,8544	1590	0,061813	6,1813	31,854
37,91	77,976	1,8737	1,8737	1559,5	0,062456	6,2456	31,874
38,48	78,345	1,9068	1,9068	1566,9	0,063561	6,3561	31,907
39,04	78,993	1,9333	1,9333	1579,9	0,064444	6,4444	31,933
39,61	77,79	1,9599	1,9599	1555,8	0,06533	6,533	31,96
40,17	79,658	1,9946	1,9946	1593,2	0,066486	6,6486	31,995
40,74	78,343	2,0145	2,0145	1566,9	0,067149	6,7149	32,014
41,3	78,156	2,0465	2,0465	1563,1	0,068216	6,8216	32,046
41,87	78,697	2,0756	2,0756	1573,9	0,069186	6,9186	32,076
42,44	77,785	2,0998	2,0998	1555,7	0,069995	6,9995	32,1
43	80,147	2,1407	2,1407	1602,9	0,071357	7,1357	32,141
43,57	77,874	2,1548	2,1548	1557,5	0,071828	7,1828	32,155
44,13	77,969	2,1876	2,1876	1559,4	0,072922	7,2922	32,188
44,7	78,91	2,2168	2,2168	1578,2	0,073892	7,3892	32,217
45,27	78,103	2,2427	2,2427	1562,1	0,074758	7,4758	32,243
45,83	79,182	2,2768	2,2768	1583,6	0,075893	7,5893	32,277
46,4	77,48	2,2966	2,2966	1549,6	0,076552	7,6552	32,297
46,96	78,244	2,3313	2,3313	1564,9	0,077708	7,7708	32,331
47,53	78,312	2,3572	2,3572	1566,2	0,078573	7,8573	32,357
48,09	76,449	2,3849	2,3849	1529	0,079497	7,9497	32,385
48,66	76,388	2,4174	2,4174	1527,8	0,080581	8,0581	32,417
49,23	75,326	2,4393	2,4393	1506,5	0,081311	8,1311	32,439
49,79	76,97	2,4735	2,4735	1539,4	0,082449	8,2449	32,473
50,36	76,76	2,4982	2,4982	1535,2	0,083274	8,3274	32,498
50,92	75,512	2,5262	2,5262	1510,2	0,084206	8,4206	32,526
51,49	76,333	2,5563	2,5563	1526,7	0,085212	8,5212	32,556
52,06	74,58	2,5792	2,5792	1491,6	0,085973	8,5973	32,579
52,62	76,585	2,6159	2,6159	1531,7	0,087197	8,7197	32,616
53,19	75,929	2,638	2,638	1518,6	0,087934	8,7934	32,638
53,75	75,774	2,6671	2,6671	1515,5	0,088904	8,8904	32,667
54,32	77,045	2,6974	2,6974	1540,9	0,089914	8,9914	32,697
54,88	75,77	2,7191	2,7191	1515,4	0,090638	9,0638	32,719
55,45	77,424	2,7574	2,7574	1548,5	0,091914	9,1914	32,757
56,02	76,819	2,7789	2,7789	1536,4	0,092631	9,2631	32,779
56,58	76,758	2,8094	2,8094	1535,2	0,093646	9,3646	32,809
57,15	77,771	2,8398	2,8398	1555,4	0,094659	9,4659	32,84
57,71	76,508	2,8622	2,8622	1530,2	0,095406	9,5406	32,862
58,28	77,735	2,9003	2,9003	1554,7	0,096677	9,6677	32,9
58,84	76,516	2,9196	2,9196	1530,3	0,09732	9,732	32,92
59,41	76,249	2,953	2,953	1525	0,098434	9,8434	32,953
59,98	76,909	2,9792	2,9792	1538,2	0,099306	9,9306	32,979
60,54	76,059	3,005	3,005	1521,2	0,10017	10,017	33,005
61,11	77,484	3,0457	3,0457	1549,7	0,10152	10,152	33,046
61,67	75,333	3,0602	3,0602	1506,7	0,10201	10,201	33,06
62,24	76,239	3,0941	3,0941	1524,8	0,10314	10,314	33,094
62,81	76,536	3,122	3,122	1530,7	0,10407	10,407	33,122
63,37	75,798	3,1475	3,1475	1516	0,10492	10,492	33,148
63,94	77,881	3,1858	3,1858	1557,6	0,10619	10,619	33,186
64,5	75,509	3,201	3,201	1510,2	0,1067	10,67	33,201
65,07	76,154	3,2359	3,2359	1523,1	0,10786	10,786	33,236
65,63	75,931	3,2617	3,2617	1518,6	0,10872	10,872	33,262
66,2	75,758	3,2886	3,2886	1515,2	0,10962	10,962	33,289
66,77	76,854	3,3249	3,3249	1537,1	0,11083	11,083	33,325
67,33	75,001	3,3434	3,3434	1500	0,11145	11,145	33,343
67,9	75,873	3,3786	3,3786	1517,5	0,11262	11,262	33,379
68,46	75,96	3,4045	3,4045	1519,2	0,11348	11,348	33,405
69,03	75,573	3,4319	3,4319	1511,5	0,1144	11,44	33,432
69,6	76,577	3,4631	3,4631	1531,5	0,11544	11,544	33,463
70,16	74,759	3,4837	3,4837	1495,2	0,11612	11,612	33,484
70,73	76,134	3,5225	3,5225	1522,7	0,11742	11,742	33,523
71,29	75,767	3,5428	3,5428	1515,3	0,11809	11,809	33,543
71,86	76,308	3,5751	3,5751	1526,2	0,11917	11,917	33,575
72,42	76,894	3,6052	3,6052	1537,9	0,12017	12,017	33,605
72,99	75,78	3,6272	3,6272	1515,6	0,12091	12,091	33,627
73,56	77,155	3,6652	3,6652	1543,1	0,12217	12,217	33,665
74,12	75,992	3,6845	3,6845	1519,8	0,12282	12,282	33,684
74,69	75,957	3,7143	3,7143	1519,1	0,12381	12,381	33,714
75,25	76,684	3,7446	3,7446	1533,7	0,12482	12,482	33,745
75,82	75,409	3,7671	3,7671	1508,2	0,12557	12,557	33,767
76,39	77,135	3,8062	3,8062	1542,7	0,12687	12,687	33,806
76,95	75,845	3,8254	3,8254	1516,9	0,12751	12,751	33,825
77,52	76,157	3,8575	3,8575	1523,1	0,12858	12,858	33,858
78,08	76,681	3,8866	3,8866	1533,6	0,12955	12,955	33,887
78,65	76,114	3,9124	3,9124	1522,3	0,13041	13,041	33,912
79,21	76,961	3,9477	3,9477	1539,2	0,13159	13,159	33,948
79,78	75,961	3,9673	3,9673	1519,2	0,13224	13,224	33,967
80,35	76,451	4,0006	4,0006	1529	0,13335	13,335	34,001
80,91	76,457	4,0261	4,0261	1529,1	0,1342	13,42	34,026
81,48	75,96	4,0539	4,0539	1519,2	0,13513	13,513	34,054
82,04	77,242	4,0894	4,0894	1544,8	0,13631	13,631	34,089
82,61	75,704	4,1071	4,1071	1514,1	0,1369	13,69	34,107
83,17	76,297	4,1418	4,1418	1525,9	0,13806	13,806	34,142
83,74	76,279	4,1661	4,1661	1525,6	0,13887	13,887	34,166
84,31	75,682	4,194	4,194	1513,6	0,1398	13,98	34,194
84,87	77,357	4,231	4,231	1547,1	0,14103	14,103	34,231
85,44	75,633	4,2472	4,2472	1512,7	0,14157	14,157	34,247
86	76,642	4,2843	4,2843	1532,8	0,14281	14,281	34,284
86,57	76,408	4,3086	4,3086	1528,2	0,14362	14,362	34,309
87,14	75,84	4,3351	4,3351	1516,8	0,1445	14,45	34,335
87,7	77,12	4,3714	4,3714	1542,4	0,14571	14,571	34,371
88,27	75,721	4,3887	4,3887	1514,4	0,14629	14,629	34,389
88,83	76,375	4,4249	4,4249	1527,5	0,1475	14,75	34,425
89,4	76,032	4,4496	4,4496	1520,6	0,14832	14,832	34,45
89,96	76,15	4,4773	4,4773	1523	0,14924	14,924	34,477
90,53	76,772	4,5091	4,5091	1535,4	0,1503	15,03	34,509
91,1	75,647	4,5333	4,5333	1512,9	0,15111	15,111	34,533
91,66	76,797	4,5692	4,5692	1535,9	0,15231	15,231	34,569
92,23	76,258	4,5924	4,5924	1525,2	0,15308	15,308	34,592
92,79	76,397	4,6223	4,6223	1527,9	0,15408	15,408	34,622
93,36	76,367	4,6504	4,6504	1527,3	0,15501	15,501	34,65
93,93	75,778	4,6735	4,6735	1515,6	0,15578	15,578	34,674
94,49	76,898	4,7115	4,7115	1538	0,15705	15,705	34,712
95,06	75,572	4,7309	4,7309	1511,4	0,1577	15,77	34,731
95,62	75,741	4,762	4,762	1514,8	0,15873	15,873	34,762
96,19	76,103	4,7927	4,7927	1522,1	0,15976	15,976	34,793
96,75	75,532	4,8169	4,8169	1510,6	0,16056	16,056	34,817
97,32	76,692	4,8533	4,8533	1533,8	0,16178	16,178	34,853
97,89	75,534	4,8724	4,8724	1510,7	0,16241	16,241	34,872
98,45	75,368	4,9033	4,9033	1507,4	0,16344	16,344	34,903
99,02	75,458	4,9315	4,9315	1509,2	0,16438	16,438	34,932
99,58	74,43	4,9568	4,9568	1488,6	0,16523	16,523	34,957
100,1	75,869	4,9927	4,9927	1517,4	0,16642	16,642	34,993
100,7	74,692	5,0125	5,0125	1493,8	0,16708	16,708	35,012
101,3	74,88	5,0437	5,0437	1497,6	0,16812	16,812	35,044
101,8	75,841	5,0749	5,0749	1516,8	0,16916	16,916	35,075
102,4	75,244	5,1005	5,1005	1504,9	0,17002	17,002	35,101
103	76,717	5,1344	5,1344	1534,3	0,17115	17,115	35,134
103,5	75,274	5,1541	5,1541	1505,5	0,1718	17,18	35,154
104,1	75,773	5,1888	5,1888	1515,5	0,17296	17,296	35,189
104,7	75,872	5,2138	5,2138	1517,4	0,17379	17,379	35,214
105,2	75,37	5,2414	5,2414	1507,4	0,17471	17,471	35,241
105,8	76,584	5,2743	5,2743	1531,7	0,17581	17,581	35,274
106,4	75,445	5,2956	5,2956	1508,9	0,17652	17,652	35,296
106,9	76,422	5,331	5,331	1528,4	0,1777	17,77	35,331
107,5	76,123	5,3562	5,3562	1522,5	0,17854	17,854	35,356
108,1	75,311	5,3819	5,3819	1506,2	0,1794	17,94	35,382
108,6	76,594	5,4161	5,4161	1531,9	0,18054	18,054	35,416
109,2	75,335	5,4357	5,4357	1506,7	0,18119	18,119	35,436
109,8	76,425	5,4745	5,4745	1528,5	0,18248	18,248	35,475
110,3	75,896	5,496	5,496	1517,9	0,1832	18,32	35,496
110,9	75,258	5,5229	5,5229	1505,2	0,1841	18,41	35,523
111,5	76,655	5,5593	5,5593	1533,1	0,18531	18,531	35,559
112	75,184	5,5804	5,5804	1503,7	0,18601	18,601	35,58
112,6	75,7	5,6152	5,6152	1514	0,18717	18,717	35,615
113,2	74,512	5,6372	5,6372	1490,2	0,18791	18,791	35,637
113,7	74,483	5,6675	5,6675	1489,7	0,18892	18,892	35,667
114,3	74,445	5,6974	5,6974	1488,9	0,18991	18,991	35,697
114,9	73,561	5,7198	5,7198	1471,2	0,19066	19,066	35,72
115,4	74,784	5,7574	5,7574	1495,7	0,19191	19,191	35,757
116	74,005	5,7781	5,7781	1480,1	0,1926	19,26	35,778
116,6	74,043	5,8089	5,8089	1480,9	0,19363	19,363	35,809
117,1	74,306	5,8366	5,8366	1486,1	0,19455	19,455	35,837
117,7	74,167	5,8619	5,8619	1483,3	0,1954	19,54	35,862
118,3	75,389	5,9	5,9	1507,8	0,19667	19,667	35,9
118,8	74,321	5,9184	5,9184	1486,4	0,19728	19,728	35,918
119,4	74,74	5,9504	5,9504	1494,8	0,19835	19,835	35,95
120	74,807	5,9789	5,9789	1496,1	0,1993	19,93	35,979
120,5	74,409	6,0039	6,0039	1488,2	0,20013	20,013	36,004
121,1	76,027	6,042	6,042	1520,5	0,2014	20,14	36,042
121,7	74,561	6,0587	6,0587	1491,2	0,20196	20,196	36,059
122,2	75,049	6,0929	6,0929	1501	0,2031	20,31	36,093
122,8	75,198	6,1188	6,1188	1504	0,20396	20,396	36,119
123,3	74,973	6,1474	6,1474	1499,5	0,20491	20,491	36,147
123,9	75,997	6,1832	6,1832	1519,9	0,20611	20,611	36,183
124,5	74,874	6,2027	6,2027	1497,5	0,20676	20,676	36,203
125	75,377	6,2359	6,2359	1507,5	0,20786	20,786	36,236
125,6	75,451	6,2617	6,2617	1509	0,20872	20,872	36,262
126,2	74,923	6,2885	6,2885	1498,5	0,20962	20,962	36,289
126,7	75,739	6,3204	6,3204	1514,8	0,21068	21,068	36,32
127,3	74,54	6,3425	6,3425	1490,8	0,21142	21,142	36,342
127,9	75,602	6,3788	6,3788	1512	0,21263	21,263	36,379
128,4	75,037	6,4013	6,4013	1500,7	0,21338	21,338	36,401
129	74,742	6,4295	6,4295	1494,8	0,21432	21,432	36,429
129,6	75,462	6,4627	6,4627	1509,2	0,21542	21,542	36,463
130,1	74,605	6,4835	6,4835	1492,1	0,21612	21,612	36,483
130,7	75,685	6,5215	6,5215	1513,7	0,21738	21,738	36,521
131,3	74,877	6,5432	6,5432	1497,5	0,21811	21,811	36,543
131,8	74,394	6,5741	6,5741	1487,9	0,21914	21,914	36,574
132,4	74,647	6,604	6,604	1492,9	0,22013	22,013	36,604
133	73,987	6,6253	6,6253	1479,7	0,22084	22,084	36,625
133,5	75,186	6,6623	6,6623	1503,7	0,22208	22,208	36,662
134,1	74,388	6,6825	6,6825	1487,8	0,22275	22,275	36,683
134,7	74,468	6,7126	6,7126	1489,4	0,22375	22,375	36,713
135,2	75,05	6,7424	6,7424	1501	0,22475	22,475	36,742
135,8	74,581	6,7675	6,7675	1491,6	0,22558	22,558	36,768
136,4	75,534	6,8056	6,8056	1510,7	0,22685	22,685	36,806
136,9	74,7	6,8272	6,8272	1494	0,22757	22,757	36,827
137,5	74,541	6,8557	6,8557	1490,8	0,22852	22,852	36,856
138,1	74,33	6,8838	6,8838	1486,6	0,22946	22,946	36,884
138,6	73,959	6,9094	6,9094	1479,2	0,23031	23,031	36,909
139,2	75,046	6,9474	6,9474	1500,9	0,23158	23,158	36,947
139,8	73,91	6,9646	6,9646	1478,2	0,23215	23,215	36,965
140,3	74,568	6,9993	6,9993	1491,4	0,23331	23,331	36,999
140,9	74,313	7,0254	7,0254	1486,3	0,23418	23,418	37,025
141,5	73,906	7,052	7,052	1478,1	0,23507	23,507	37,052
142	75,2	7,0915	7,0915	1504	0,23638	23,638	37,092
142,6	72,876	7,1042	7,1042	1457,5	0,23681	23,681	37,104
143,2	73,281	7,1401	7,1401	1465,6	0,238	23,8	37,14
143,7	73,274	7,1663	7,1663	1465,5	0,23888	23,888	37,166
144,3	72,778	7,1916	7,1916	1455,6	0,23972	23,972	37,192
144,8	75,039	7,236	7,236	1500,8	0,2412	24,12	37,236
145,4	72,964	7,2459	7,2459	1459,3	0,24153	24,153	37,246
146	73,753	7,2816	7,2816	1475,1	0,24272	24,272	37,282
146,5	73,642	7,3067	7,3067	1472,8	0,24356	24,356	37,307
147,1	73,597	7,3344	7,3344	1471,9	0,24448	24,448	37,334
147,7	74,348	7,3669	7,3669	1487	0,24556	24,556	37,367
148,2	73,511	7,389	7,389	1470,2	0,2463	24,63	37,389
148,8	74,44	7,425	7,425	1488,8	0,2475	24,75	37,425
149,4	74,112	7,4491	7,4491	1482,2	0,2483	24,83	37,449
149,9	73,984	7,4779	7,4779	1479,7	0,24926	24,926	37,478
150,5	74,247	7,5066	7,5066	1484,9	0,25022	25,022	37,507
151,1	73,629	7,5302	7,5302	1472,6	0,25101	25,101	37,53
151,6	74,812	7,5684	7,5684	1496,2	0,25228	25,228	37,568
152,2	74,153	7,5899	7,5899	1483,1	0,253	25,3	37,59
152,8	74,059	7,6197	7,6197	1481,2	0,25399	25,399	37,62
153,3	74,277	7,6477	7,6477	1485,5	0,25492	25,492	37,648
153,9	73,593	7,6731	7,6731	1471,9	0,25577	25,577	37,673
154,5	74,498	7,7097	7,7097	1490	0,25699	25,699	37,71
155	73,984	7,7306	7,7306	1479,7	0,25769	25,769	37,731
155,6	74,045	7,7602	7,7602	1480,9	0,25867	25,867	37,76
156,2	74,25	7,7875	7,7875	1485	0,25958	25,958	37,788
156,7	73,723	7,8138	7,8138	1474,5	0,26046	26,046	37,814
157,3	75,069	7,8539	7,8539	1501,4	0,2618	26,18	37,854
157,9	73,642	7,8701	7,8701	1472,8	0,26234	26,234	37,87
158,4	73,821	7,9019	7,9019	1476,4	0,2634	26,34	37,902
159	74,1	7,9312	7,9312	1482	0,26437	26,437	37,931
159,6	73,502	7,9572	7,9572	1470	0,26524	26,524	37,957
160,1	74,415	7,9932	7,9932	1488,3	0,26644	26,644	37,993
160,7	73,423	8,0117	8,0117	1468,5	0,26706	26,706	38,012
161,3	74,022	8,0462	8,0462	1480,4	0,26821	26,821	38,046
161,8	73,82	8,072	8,072	1476,4	0,26907	26,907	38,072
162,4	73,506	8,0991	8,0991	1470,1	0,26997	26,997	38,099
163	74,129	8,1307	8,1307	1482,6	0,27102	27,102	38,131
163,5	73,124	8,1524	8,1524	1462,5	0,27175	27,175	38,152
164,1	74,158	8,1898	8,1898	1483,2	0,27299	27,299	38,19
164,7	73,389	8,2118	8,2118	1467,8	0,27373	27,373	38,212
165,2	73,372	8,2412	8,2412	1467,4	0,27471	27,471	38,241
165,8	74,151	8,2722	8,2722	1483	0,27574	27,574	38,272
166,3	73,323	8,2955	8,2955	1466,5	0,27652	27,652	38,295
166,9	74,07	8,3305	8,3305	1481,4	0,27768	27,768	38,33
167,5	73,641	8,3527	8,3527	1472,8	0,27842	27,842	38,353
168	73,345	8,3824	8,3824	1466,9	0,27941	27,941	38,382
168,6	73,84	8,4135	8,4135	1476,8	0,28045	28,045	38,414
169,2	72,906	8,4354	8,4354	1458,1	0,28118	28,118	38,435
169,7	73,851	8,473	8,473	1477	0,28243	28,243	38,473
170,3	73,192	8,494	8,494	1463,8	0,28313	28,313	38,494
170,9	73,104	8,5237	8,5237	1462,1	0,28412	28,412	38,524
171,4	73,585	8,5547	8,5547	1471,7	0,28516	28,516	38,555
172	72,669	8,5775	8,5775	1453,4	0,28592	28,592	38,578
172,6	73,696	8,6158	8,6158	1473,9	0,28719	28,719	38,616
173,1	72,634	8,6345	8,6345	1452,7	0,28782	28,782	38,634
173,7	72,818	8,6664	8,6664	1456,4	0,28888	28,888	38,666
174,3	72,79	8,6941	8,6941	1455,8	0,2898	28,98	38,694
174,8	72,746	8,7209	8,7209	1454,9	0,2907	29,07	38,721
175,4	73,372	8,7558	8,7558	1467,4	0,29186	29,186	38,756
176	72,621	8,7754	8,7754	1452,4	0,29251	29,251	38,775
176,5	73,179	8,8086	8,8086	1463,6	0,29362	29,362	38,809
177,1	73,244	8,8366	8,8366	1464,9	0,29455	29,455	38,837
177,7	72,713	8,8608	8,8608	1454,3	0,29536	29,536	38,861
178,2	73,985	8,9007	8,9007	1479,7	0,29669	29,669	38,901
178,8	72,509	8,9172	8,9172	1450,2	0,29724	29,724	38,917
179,4	72,923	8,9495	8,9495	1458,5	0,29832	29,832	38,95
179,9	72,937	8,9757	8,9757	1458,7	0,29919	29,919	38,976
180,5	72,864	9,0035	9,0035	1457,3	0,30012	30,012	39,004
181,1	73,718	9,0394	9,0394	1474,4	0,30131	30,131	39,039
181,6	72,427	9,0574	9,0574	1448,5	0,30191	30,191	39,057
182,2	73,321	9,0935	9,0935	1466,4	0,30312	30,312	39,093
182,8	73,028	9,119	9,119	1460,6	0,30397	30,397	39,119
183,3	72,829	9,146	9,146	1456,6	0,30487	30,487	39,146
183,9	73,406	9,1792	9,1792	1468,1	0,30597	30,597	39,179
184,5	72,608	9,2012	9,2012	1452,2	0,30671	30,671	39,201
185	73,279	9,2347	9,2347	1465,6	0,30782	30,782	39,235
185,6	72,965	9,2585	9,2585	1459,3	0,30862	30,862	39,259
186,2	73,233	9,2886	9,2886	1464,7	0,30962	30,962	39,289
186,7	73,291	9,3205	9,3205	1465,8	0,31068	31,068	39,32
187,3	72,815	9,3423	9,3423	1456,3	0,31141	31,141	39,342
187,9	73,805	9,379	9,379	1476,1	0,31263	31,263	39,379
188,4	72,914	9,3992	9,3992	1458,3	0,31331	31,331	39,399
189	72,979	9,4301	9,4301	1459,6	0,31434	31,434	39,43
189,5	73,48	9,4611	9,4611	1469,6	0,31537	31,537	39,461
190,1	72,681	9,4826	9,4826	1453,6	0,31609	31,609	39,483
190,7	73,692	9,5192	9,5192	1473,8	0,31731	31,731	39,519
191,2	72,906	9,5411	9,5411	1458,1	0,31804	31,804	39,541
191,8	72,952	9,571	9,571	1459	0,31903	31,903	39,571
192,4	73,327	9,6016	9,6016	1466,5	0,32005	32,005	39,602
192,9	72,912	9,6244	9,6244	1458,2	0,32081	32,081	39,624
193,5	73,621	9,662	9,662	1472,4	0,32207	32,207	39,662
194,1	72,675	9,6821	9,6821	1453,5	0,32274	32,274	39,682
194,6	72,829	9,7136	9,7136	1456,6	0,32379	32,379	39,714
195,2	72,893	9,7425	9,7425	1457,9	0,32475	32,475	39,743
195,8	72,439	9,7674	9,7674	1448,8	0,32558	32,558	39,767
196,3	73,478	9,8042	9,8042	1469,6	0,32681	32,681	39,804
196,9	72,239	9,8214	9,8214	1444,8	0,32738	32,738	39,821
197,5	72,713	9,8547	9,8547	1454,3	0,32849	32,849	39,855
198	72,846	9,8819	9,8819	1456,9	0,3294	32,94	39,882
198,6	72,628	9,9105	9,9105	1452,6	0,33035	33,035	39,911
199,2	73,926	9,9492	9,9492	1478,5	0,33164	33,164	39,949
199,7	72,754	9,963	9,963	1455,1	0,3321	33,21	39,963
200,3	72,999	9,9977	9,9977	1460	0,33326	33,326	39,998
200,9	72,966	10,023	10,023	1459,3	0,33411	33,411	40,023
201,4	72,599	10,049	10,049	1452	0,33498	33,498	40,049
202	73,535	10,087	10,087	1470,7	0,33624	33,624	40,087
202,6	72,363	10,106	10,106	1447,3	0,33687	33,687	40,106
203,1	72,995	10,14	10,14	1459,9	0,33801	33,801	40,14
203,7	72,711	10,166	10,166	1454,2	0,33886	33,886	40,166
204,3	72,725	10,195	10,195	1454,5	0,33983	33,983	40,195
204,8	72,901	10,224	10,224	1458	0,3408	34,08	40,224
205,4	72,193	10,246	10,246	1443,9	0,34154	34,154	40,246
206	72,999	10,283	10,283	1460	0,34276	34,276	40,283
206,5	72,619	10,306	10,306	1452,4	0,34354	34,354	40,306
207,1	72,661	10,335	10,335	1453,2	0,34449	34,449	40,335
207,7	72,915	10,363	10,363	1458,3	0,34544	34,544	40,363
208,2	72,36	10,388	10,388	1447,2	0,34627	34,627	40,388
208,8	73,375	10,425	10,425	1467,5	0,3475	34,75	40,425
209,4	72,914	10,448	10,448	1458,3	0,34825	34,825	40,448
209,9	73,086	10,479	10,479	1461,7	0,34929	34,929	40,479
210,5	73,253	10,506	10,506	1465,1	0,3502	35,02	40,506
211	72,919	10,531	10,531	1458,4	0,35102	35,102	40,531
211,6	73,616	10,566	10,566	1472,3	0,35221	35,221	40,566
212,2	72,92	10,587	10,587	1458,4	0,35291	35,291	40,587
212,7	72,927	10,617	10,617	1458,5	0,35391	35,391	40,617
213,3	73,229	10,647	10,647	1464,6	0,35489	35,489	40,647
213,9	72,763	10,671	10,671	1455,3	0,35572	35,572	40,671
214,4	73,699	10,71	10,71	1474	0,357	35,7	40,71
215	72,746	10,729	10,729	1454,9	0,35762	35,762	40,729
215,6	73,054	10,76	10,76	1461,1	0,35866	35,866	40,76
216,1	73,094	10,788	10,788	1461,9	0,35959	35,959	40,788
216,7	72,635	10,813	10,813	1452,7	0,36044	36,044	40,813
217,3	73,485	10,85	10,85	1469,7	0,36165	36,165	40,85
217,8	72,776	10,869	10,869	1455,5	0,36231	36,231	40,869
218,4	73,212	10,903	10,903	1464,2	0,36345	36,345	40,903
219	73,209	10,929	10,929	1464,2	0,36431	36,431	40,929
219,5	72,889	10,956	10,956	1457,8	0,36521	36,521	40,956
220,1	73,953	10,994	10,994	1479,1	0,36646	36,646	40,994
220,7	72,708	11,011	11,011	1454,2	0,36703	36,703	41,011
221,2	73,493	11,046	11,046	1469,9	0,3682	36,82	41,046
221,8	73,225	11,069	11,069	1464,5	0,36897	36,897	41,069
222,4	73,153	11,098	11,098	1463,1	0,36994	36,994	41,098
222,9	73,528	11,129	11,129	1470,6	0,37098	37,098	41,129
223,5	72,765	11,15	11,15	1455,3	0,37167	37,167	41,15
224,1	73,79	11,189	11,189	1475,8	0,37297	37,297	41,189
224,6	73,157	11,212	11,212	1463,1	0,37374	37,374	41,212
225,2	73,1	11,239	11,239	1462	0,37463	37,463	41,239
225,8	73,842	11,273	11,273	1476,8	0,37577	37,577	41,273
226,3	72,887	11,292	11,292	1457,7	0,37641	37,641	41,292
226,9	73,667	11,329	11,329	1473,3	0,37764	37,764	41,329
227,5	73,281	11,351	11,351	1465,6	0,37836	37,836	41,351
228	73,167	11,381	11,381	1463,3	0,37938	37,938	41,381
228,6	73,509	11,412	11,412	1470,2	0,3804	38,04	41,412
229,2	73,053	11,435	11,435	1461,1	0,38118	38,118	41,435
229,7	73,868	11,474	11,474	1477,4	0,38246	38,246	41,474
230,3	73,169	11,492	11,492	1463,4	0,38307	38,307	41,492
230,9	73,306	11,525	11,525	1466,1	0,38416	38,416	41,525
231,4	73,507	11,552	11,552	1470,1	0,38508	38,508	41,552
232	73,216	11,579	11,579	1464,3	0,38596	38,596	41,579
232,6	73,871	11,614	11,614	1477,4	0,38713	38,713	41,614
233,1	73,039	11,632	11,632	1460,8	0,38774	38,774	41,632
233,7	73,326	11,665	11,665	1466,5	0,38885	38,885	41,665
234,2	73,327	11,695	11,695	1466,5	0,38985	38,985	41,695
234,8	73,195	11,718	11,718	1463,9	0,39061	39,061	41,718
235,4	74,131	11,758	11,758	1482,6	0,39192	39,192	41,758
235,9	73,033	11,775	11,775	1460,7	0,3925	39,25	41,775
236,5	73,182	11,806	11,806	1463,6	0,39355	39,355	41,806
237,1	73,268	11,835	11,835	1465,4	0,3945	39,45	41,835
237,6	73,149	11,862	11,862	1463	0,3954	39,54	41,862
238,2	73,715	11,896	11,896	1474,3	0,39653	39,653	41,896
238,8	72,813	11,916	11,916	1456,3	0,39719	39,719	41,916
239,3	73,567	11,951	11,951	1471,3	0,39837	39,837	41,951
239,9	73,211	11,973	11,973	1464,2	0,39911	39,911	41,973
240,5	73,02	12,002	12,002	1460,4	0,40006	40,006	42,002
241	73,771	12,037	12,037	1475,4	0,40122	40,122	42,037
241,6	73,077	12,055	12,055	1461,5	0,40184	40,184	42,055
242,2	73,568	12,093	12,093	1471,4	0,40309	40,309	42,093
242,7	73,233	12,118	12,118	1464,7	0,40392	40,392	42,118
243,3	73,055	12,144	12,144	1461,1	0,4048	40,48	42,144
243,9	73,48	12,175	12,175	1469,6	0,40585	40,585	42,175
244,4	72,988	12,199	12,199	1459,8	0,40663	40,663	42,199
245	73,796	12,235	12,235	1475,9	0,40785	40,785	42,235
245,6	73,16	12,258	12,258	1463,2	0,40859	40,859	42,258
246,1	73,309	12,288	12,288	1466,2	0,4096	40,96	42,288
246,7	73,539	12,317	12,317	1470,8	0,41057	41,057	42,317
247,3	73,061	12,34	12,34	1461,2	0,41132	41,132	42,34
247,8	73,676	12,375	12,375	1473,5	0,41251	41,251	42,375
248,4	73,158	12,398	12,398	1463,2	0,41325	41,325	42,398
249	73,152	12,427	12,427	1463	0,41423	41,423	42,427
249,5	73,66	12,46	12,46	1473,2	0,41532	41,532	42,46
250,1	73,204	12,481	12,481	1464,1	0,41604	41,604	42,481
250,7	73,798	12,519	12,519	1476	0,41728	41,728	42,519
251,2	73,262	12,54	12,54	1465,2	0,41799	41,799	42,54
251,8	73,387	12,57	12,57	1467,7	0,41901	41,901	42,57
252,4	73,518	12,598	12,598	1470,4	0,41994	41,994	42,598
252,9	73,106	12,624	12,624	1462,1	0,42078	42,078	42,624
253,5	74,289	12,664	12,664	1485,8	0,42212	42,212	42,664
254,1	73,2	12,679	12,679	1464	0,42262	42,262	42,679
254,6	73,625	12,713	12,713	1472,5	0,42377	42,377	42,713
255,2	73,671	12,741	12,741	1473,4	0,42469	42,469	42,741
255,7	73,324	12,767	12,767	1466,5	0,42555	42,555	42,767
256,3	74,33	12,804	12,804	1486,6	0,42679	42,679	42,804
256,9	73,193	12,82	12,82	1463,9	0,42734	42,734	42,82
257,4	73,783	12,856	12,856	1475,7	0,42853	42,853	42,856
258	73,666	12,881	12,881	1473,3	0,42938	42,938	42,881
258,6	73,421	12,908	12,908	1468,4	0,43027	43,027	42,908
259,1	74,24	12,944	12,944	1484,8	0,43147	43,147	42,944
259,7	73,254	12,962	12,962	1465,1	0,43206	43,206	42,962
260,3	73,875	12,997	12,997	1477,5	0,43322	43,322	42,997
260,8	73,782	13,023	13,023	1475,6	0,43411	43,411	43,023
261,4	73,423	13,049	13,049	1468,5	0,43497	43,497	43,049
262	74,093	13,084	13,084	1481,9	0,43615	43,615	43,084
262,5	73,22	13,105	13,105	1464,4	0,43683	43,683	43,105
263,1	73,853	13,139	13,139	1477,1	0,43797	43,797	43,139
263,7	73,577	13,164	13,164	1471,5	0,43879	43,879	43,164
264,2	73,63	13,194	13,194	1472,6	0,43978	43,978	43,194
264,8	73,917	13,224	13,224	1478,3	0,44079	44,079	43,224
265,4	73,372	13,244	13,244	1467,4	0,44147	44,147	43,244
265,9	74,264	13,284	13,284	1485,3	0,44278	44,278	43,284
266,5	73,584	13,303	13,303	1471,7	0,44344	44,344	43,303
267,1	73,741	13,335	13,335	1474,8	0,44449	44,449	43,335
267,6	73,754	13,362	13,362	1475,1	0,44541	44,541	43,362
268,2	73,496	13,387	13,387	1469,9	0,44624	44,624	43,387
268,8	74,072	13,422	13,422	1481,4	0,44741	44,741	43,422
269,3	73,656	13,445	13,445	1473,1	0,44818	44,818	43,445
269,9	73,717	13,476	13,476	1474,3	0,4492	44,92	43,476
270,5	73,973	13,505	13,505	1479,5	0,45016	45,016	43,505
271	73,52	13,528	13,528	1470,4	0,45092	45,092	43,528
271,6	74,477	13,566	13,566	1489,5	0,4522	45,22	43,566
272,2	73,669	13,586	13,586	1473,4	0,45287	45,287	43,586
272,7	73,775	13,617	13,617	1475,5	0,4539	45,39	43,617
273,3	73,882	13,646	13,646	1477,6	0,45486	45,486	43,646
273,9	73,518	13,672	13,672	1470,4	0,45573	45,573	43,672
274,4	73,905	13,707	13,707	1478,1	0,45689	45,689	43,707
275	73,568	13,728	13,728	1471,4	0,4576	45,76	43,728
275,6	73,736	13,759	13,759	1474,7	0,45863	45,863	43,759
276,1	73,776	13,785	13,785	1475,5	0,45951	45,951	43,785
276,7	73,587	13,813	13,813	1471,7	0,46043	46,043	43,813
277,2	74,483	13,85	13,85	1489,7	0,46167	46,167	43,85
277,8	73,463	13,868	13,868	1469,3	0,46226	46,226	43,868
278,4	74,038	13,903	13,903	1480,8	0,46345	46,345	43,903
278,9	73,836	13,928	13,928	1476,7	0,46425	46,425	43,928
279,5	73,665	13,956	13,956	1473,3	0,46521	46,521	43,956
280,1	73,966	13,987	13,987	1479,3	0,46625	46,625	43,987
280,6	73,475	14,009	14,009	1469,5	0,46698	46,698	44,009
281,2	74,298	14,046	14,046	1486	0,46821	46,821	44,046
281,8	73,729	14,068	14,068	1474,6	0,46893	46,893	44,068
282,3	73,607	14,096	14,096	1472,1	0,46985	46,985	44,096
282,9	74,358	14,133	14,133	1487,2	0,47109	47,109	44,133
283,5	73,499	14,152	14,152	1470	0,47172	47,172	44,152
284	73,986	14,186	14,186	1479,7	0,47286	47,286	44,186
284,6	73,574	14,209	14,209	1471,5	0,47365	47,365	44,209
285,2	73,63	14,24	14,24	1472,6	0,47466	47,466	44,24
285,7	73,9	14,27	14,27	1478	0,47567	47,567	44,27
286,3	73,278	14,292	14,292	1465,6	0,47638	47,638	44,292
286,9	74,052	14,328	14,328	1481	0,47761	47,761	44,328
287,4	73,456	14,349	14,349	1469,1	0,47831	47,831	44,349
288	73,634	14,38	14,38	1472,7	0,47935	47,935	44,38
288,6	73,884	14,411	14,411	1477,7	0,48035	48,035	44,411
289,1	73,626	14,437	14,437	1472,5	0,48123	48,123	44,437
289,7	74,174	14,471	14,471	1483,5	0,48238	48,238	44,471
290,3	73,423	14,491	14,491	1468,5	0,48302	48,302	44,491
290,8	73,626	14,521	14,521	1472,5	0,48404	48,404	44,521
291,4	73,769	14,55	14,55	1475,4	0,48501	48,501	44,55
292	73,573	14,577	14,577	1471,5	0,48589	48,589	44,577
292,5	74,588	14,616	14,616	1491,8	0,4872	48,72	44,616
293,1	73,52	14,632	14,632	1470,4	0,48773	48,773	44,632
293,7	73,692	14,664	14,664	1473,8	0,48879	48,879	44,664
294,2	73,731	14,692	14,692	1474,6	0,48972	48,972	44,692
294,8	73,48	14,72	14,72	1469,6	0,49065	49,065	44,72
295,4	74,032	14,753	14,753	1480,6	0,49178	49,178	44,753
295,9	73,298	14,774	14,774	1466	0,49245	49,245	44,774
296,5	73,484	14,808	14,808	1469,7	0,49362	49,362	44,808
297,1	73,538	14,833	14,833	1470,8	0,49445	49,445	44,833
297,6	73,598	14,86	14,86	1472	0,49534	49,534	44,86
298,2	74,049	14,894	14,894	1481	0,49647	49,647	44,894
298,8	73,421	14,915	14,915	1468,4	0,49717	49,717	44,915
299,3	74,129	14,951	14,951	1482,6	0,49837	49,837	44,951
299,9	73,592	14,972	14,972	1471,8	0,49905	49,905	44,972
300,4	73,782	15,004	15,004	1475,6	0,50013	50,013	45,004
301	73,998	15,034	15,034	1480	0,50114	50,114	45,034
301,6	73,446	15,057	15,057	1468,9	0,50188	50,188	45,057
302,1	74,365	15,095	15,095	1487,3	0,50317	50,317	45,095
302,7	73,524	15,115	15,115	1470,5	0,50384	50,384	45,115
303,3	73,613	15,144	15,144	1472,3	0,50479	50,479	45,144
303,8	73,933	15,176	15,176	1478,7	0,50586	50,586	45,176
304,4	73,283	15,198	15,198	1465,7	0,50659	50,659	45,198
305	73,986	15,234	15,234	1479,7	0,50781	50,781	45,234
305,5	73,419	15,255	15,255	1468,4	0,5085	50,85	45,255
306,1	73,461	15,284	15,284	1469,2	0,50945	50,945	45,284
306,7	73,938	15,315	15,315	1478,8	0,51051	51,051	45,315
307,2	73,565	15,341	15,341	1471,3	0,51137	51,137	45,341
307,8	74,118	15,379	15,379	1482,4	0,51264	51,264	45,379
308,4	73,563	15,398	15,398	1471,3	0,51327	51,327	45,398
308,9	73,726	15,428	15,428	1474,5	0,51427	51,427	45,428
309,5	73,928	15,457	15,457	1478,6	0,51524	51,524	45,457
310,1	73,726	15,484	15,484	1474,5	0,51612	51,612	45,484
310,6	74,714	15,523	15,523	1494,3	0,51744	51,744	45,523
311,2	73,479	15,536	15,536	1469,6	0,51788	51,788	45,536
311,8	73,904	15,571	15,571	1478,1	0,51903	51,903	45,571
312,3	74,017	15,597	15,597	1480,3	0,51991	51,991	45,597
312,9	73,905	15,625	15,625	1478,1	0,52084	52,084	45,625
313,5	74,506	15,661	15,661	1490,1	0,52202	52,202	45,661
314	73,724	15,682	15,682	1474,5	0,52273	52,273	45,682
314,6	74,042	15,713	15,713	1480,8	0,52376	52,376	45,713
315,2	73,98	15,738	15,738	1479,6	0,52459	52,459	45,738
315,7	73,778	15,766	15,766	1475,6	0,52552	52,552	45,766
316,3	74,805	15,804	15,804	1496,1	0,52679	52,679	45,804
316,9	73,626	15,819	15,819	1472,5	0,5273	52,73	45,819
317,4	74,182	15,853	15,853	1483,6	0,52843	52,843	45,853
318	73,983	15,879	15,879	1479,7	0,5293	52,93	45,879
318,6	73,839	15,907	15,907	1476,8	0,53022	53,022	45,907
319,1	74,291	15,94	15,94	1485,8	0,53135	53,135	45,94
319,7	73,686	15,962	15,962	1473,7	0,53206	53,206	45,962
320,3	74,129	15,996	15,996	1482,6	0,53321	53,321	45,996
320,8	73,968	16,021	16,021	1479,4	0,53405	53,405	46,021
321,4	74,124	16,051	16,051	1482,5	0,53505	53,505	46,051
321,9	74,193	16,08	16,08	1483,9	0,53599	53,599	46,08
322,5	73,696	16,103	16,103	1473,9	0,53675	53,675	46,103
323,1	74,635	16,142	16,142	1492,7	0,53806	53,806	46,142
323,6	73,772	16,161	16,161	1475,4	0,5387	53,87	46,161
324,2	73,836	16,191	16,191	1476,7	0,53971	53,971	46,191
324,8	74,082	16,22	16,22	1481,6	0,54065	54,065	46,22
325,3	73,799	16,245	16,245	1476	0,54151	54,151	46,245
325,9	74,35	16,278	16,278	1487	0,5426	54,26	46,278
326,5	73,983	16,302	16,302	1479,7	0,54341	54,341	46,302
327	74,039	16,333	16,333	1480,8	0,54442	54,442	46,333
327,6	74,369	16,363	16,363	1487,4	0,54542	54,542	46,363
328,2	73,868	16,386	16,386	1477,4	0,54621	54,621	46,386
328,7	74,589	16,423	16,423	1491,8	0,54742	54,742	46,423
329,3	74,074	16,444	16,444	1481,5	0,54814	54,814	46,444
329,9	74,038	16,475	16,475	1480,8	0,54916	54,916	46,475
330,4	74,125	16,502	16,502	1482,5	0,55008	55,008	46,502
331	73,921	16,528	16,528	1478,4	0,55092	55,092	46,528
331,6	74,663	16,567	16,567	1493,3	0,55222	55,222	46,567
332,1	74,035	16,586	16,586	1480,7	0,55285	55,285	46,586
332,7	74,246	16,617	16,617	1484,9	0,55391	55,391	46,617
333,3	74,061	16,644	16,644	1481,2	0,55479	55,479	46,644
333,8	73,944	16,672	16,672	1478,9	0,55572	55,572	46,672
334,4	74,599	16,706	16,706	1492	0,55687	55,687	46,706
335	73,679	16,722	16,722	1473,6	0,5574	55,74	46,722
335,5	74,478	16,76	16,76	1489,6	0,55867	55,867	46,76
336,1	74,317	16,785	16,785	1486,3	0,55949	55,949	46,785
336,7	74,157	16,812	16,812	1483,1	0,5604	56,04	46,812
337,2	74,746	16,847	16,847	1494,9	0,56156	56,156	46,847
337,8	74,148	16,868	16,868	1483	0,56228	56,228	46,868
338,4	74,61	16,901	16,901	1492,2	0,56338	56,338	46,901
338,9	74,207	16,926	16,926	1484,1	0,5642	56,42	46,926
339,5	74,016	16,952	16,952	1480,3	0,56505	56,505	46,952
340,1	74,883	16,991	16,991	1497,7	0,56636	56,636	46,991
340,6	74,272	17,008	17,008	1485,4	0,56693	56,693	47,008
341,2	74,705	17,045	17,045	1494,1	0,56815	56,815	47,045
341,8	74,281	17,067	17,067	1485,6	0,5689	56,89	47,067
342,3	74,289	17,096	17,096	1485,8	0,56987	56,987	47,096
342,9	74,573	17,127	17,127	1491,5	0,57089	57,089	47,127
343,5	73,918	17,148	17,148	1478,4	0,5716	57,16	47,148
344	74,679	17,186	17,186	1493,6	0,57288	57,288	47,186
344,6	74,187	17,208	17,208	1483,7	0,57358	57,358	47,208
345,1	74,284	17,238	17,238	1485,7	0,57461	57,461	47,238
345,7	74,515	17,268	17,268	1490,3	0,57558	57,558	47,268
346,3	74,361	17,294	17,294	1487,2	0,57647	57,647	47,294
346,8	74,896	17,329	17,329	1497,9	0,57764	57,764	47,329
347,4	74,192	17,347	17,347	1483,8	0,57825	57,825	47,347
348	74,507	17,379	17,379	1490,1	0,57931	57,931	47,379
348,5	74,633	17,409	17,409	1492,7	0,5803	58,03	47,409
349,1	74,244	17,434	17,434	1484,9	0,58112	58,112	47,434
349,7	75,214	17,474	17,474	1504,3	0,58248	58,248	47,474
350,2	74,261	17,489	17,489	1485,2	0,58298	58,298	47,489
350,8	74,598	17,524	17,524	1492	0,58412	58,412	47,524
351,4	74,488	17,549	17,549	1489,8	0,58496	58,496	47,549
351,9	74,414	17,575	17,575	1488,3	0,58584	58,584	47,575
352,5	75,105	17,613	17,613	1502,1	0,58711	58,711	47,613
353,1	74,128	17,629	17,629	1482,6	0,58762	58,762	47,629
353,6	74,589	17,664	17,664	1491,8	0,58878	58,878	47,664
354,2	74,492	17,691	17,691	1489,8	0,58972	58,972	47,691
354,8	74,398	17,719	17,719	1488	0,59063	59,063	47,719
355,3	74,776	17,751	17,751	1495,5	0,5917	59,17	47,751
355,9	74,279	17,772	17,772	1485,6	0,59241	59,241	47,772
356,5	74,808	17,807	17,807	1496,2	0,59358	59,358	47,807
357	74,453	17,83	17,83	1489,1	0,59433	59,433	47,83
357,6	74,792	17,863	17,863	1495,8	0,59542	59,542	47,863
358,2	74,995	17,889	17,889	1499,9	0,59631	59,631	47,889
358,7	74,371	17,913	17,913	1487,4	0,59708	59,708	47,913
359,3	75,053	17,95	17,95	1501,1	0,59834	59,834	47,95
359,9	74,555	17,972	17,972	1491,1	0,59908	59,908	47,972
360,4	74,607	18,001	18,001	1492,1	0,60003	60,003	48,001
361	74,935	18,032	18,032	1498,7	0,60106	60,106	48,032
361,6	74,499	18,055	18,055	1490	0,60184	60,184	48,055
362,1	75,282	18,092	18,092	1505,6	0,60308	60,308	48,092
362,7	74,644	18,112	18,112	1492,9	0,60374	60,374	48,112
363,3	74,747	18,143	18,143	1494,9	0,60475	60,475	48,143
363,8	74,906	18,171	18,171	1498,1	0,6057	60,57	48,171
364,4	74,684	18,199	18,199	1493,7	0,60662	60,662	48,199
365	75,214	18,235	18,235	1504,3	0,60783	60,783	48,235
365,5	74,616	18,254	18,254	1492,3	0,60848	60,848	48,254
366,1	74,633	18,287	18,287	1492,7	0,60955	60,955	48,287
366,6	74,765	18,314	18,314	1495,3	0,61048	61,048	48,314
367,2	74,59	18,339	18,339	1491,8	0,61131	61,131	48,339
367,8	75,246	18,377	18,377	1504,9	0,61257	61,257	48,377
368,3	74,369	18,394	18,394	1487,4	0,61312	61,312	48,394
368,9	74,636	18,427	18,427	1492,7	0,61424	61,424	48,427
369,5	74,731	18,456	18,456	1494,6	0,6152	61,52	48,456
370	74,543	18,48	18,48	1490,9	0,61601	61,601	48,48
370,6	75,407	18,521	18,521	1508,1	0,61738	61,738	48,521
371,2	74,231	18,535	18,535	1484,6	0,61785	61,785	48,535
371,7	74,736	18,569	18,569	1494,7	0,61898	61,898	48,569
372,3	74,449	18,596	18,596	1489	0,61986	61,986	48,596
372,9	74,368	18,622	18,622	1487,4	0,62074	62,074	48,622
373,4	75,272	18,662	18,662	1505,4	0,62205	62,205	48,662
374	74,254	18,677	18,677	1485,1	0,62258	62,258	48,677
374,6	74,705	18,712	18,712	1494,1	0,62372	62,372	48,712
375,1	74,655	18,737	18,737	1493,1	0,62458	62,458	48,737
375,7	74,425	18,765	18,765	1488,5	0,62549	62,549	48,765
376,3	74,981	18,8	18,8	1499,6	0,62666	62,666	48,8
376,8	74,137	18,818	18,818	1482,7	0,62727	62,727	48,818
377,4	74,584	18,852	18,852	1491,7	0,6284	62,84	48,852
378	74,447	18,879	18,879	1488,9	0,6293	62,93	48,879
378,5	74,53	18,908	18,908	1490,6	0,63027	63,027	48,908
379,1	74,441	18,934	18,934	1488,8	0,63113	63,113	48,934
379,7	74,21	18,96	18,96	1484,2	0,63201	63,201	48,96
380,2	74,889	18,997	18,997	1497,8	0,63324	63,324	48,997
380,8	74,449	19,018	19,018	1489	0,63394	63,394	49,018
381,4	74,504	19,048	19,048	1490,1	0,63495	63,495	49,048
381,9	74,92	19,079	19,079	1498,4	0,63598	63,598	49,079
382,5	74,573	19,1	19,1	1491,5	0,63668	63,668	49,1
383,1	75,142	19,138	19,138	1502,8	0,63794	63,794	49,138
383,6	74,743	19,161	19,161	1494,9	0,63869	63,869	49,161
384,2	74,822	19,19	19,19	1496,4	0,63968	63,968	49,19
384,8	75	19,221	19,221	1500	0,6407	64,07	49,221
385,3	74,768	19,245	19,245	1495,4	0,64148	64,148	49,245
385,9	75,434	19,281	19,281	1508,7	0,64271	64,271	49,281
386,5	74,867	19,301	19,301	1497,3	0,64338	64,338	49,301
387	75,099	19,333	19,333	1502	0,64442	64,442	49,333
387,6	74,939	19,358	19,358	1498,8	0,64526	64,526	49,358
388,1	74,99	19,388	19,388	1499,8	0,64626	64,626	49,388
388,7	75,533	19,425	19,425	1510,7	0,64749	64,749	49,425
389,3	74,906	19,441	19,441	1498,1	0,64804	64,804	49,441
389,8	75,277	19,476	19,476	1505,5	0,6492	64,92	49,476
390,4	75,148	19,5	19,5	1503	0,65	65	49,5
391	75,079	19,528	19,528	1501,6	0,65093	65,093	49,528
391,5	75,718	19,565	19,565	1514,4	0,65218	65,218	49,565
392,1	75,118	19,584	19,584	1502,4	0,65281	65,281	49,584
392,7	75,479	19,617	19,617	1509,6	0,65391	65,391	49,617
393,2	75,335	19,643	19,643	1506,7	0,65476	65,476	49,643
393,8	75,215	19,671	19,671	1504,3	0,65569	65,569	49,671
394,4	75,46	19,703	19,703	1509,2	0,65676	65,676	49,703
394,9	74,911	19,724	19,724	1498,2	0,65747	65,747	49,724
395,5	75,521	19,76	19,76	1510,4	0,65867	65,867	49,76
396,1	75,225	19,783	19,783	1504,5	0,65944	65,944	49,783
396,6	75,104	19,81	19,81	1502,1	0,66034	66,034	49,81
397,2	75,764	19,847	19,847	1515,3	0,66157	66,157	49,847
397,8	75,068	19,866	19,866	1501,4	0,66218	66,218	49,866
398,3	75,464	19,898	19,898	1509,3	0,66328	66,328	49,898
398,9	75,177	19,925	19,925	1503,5	0,66416	66,416	49,925
399,5	75,061	19,952	19,952	1501,2	0,66508	66,508	49,952
400	75,379	19,984	19,984	1507,6	0,66615	66,615	49,984
400,6	74,864	20,006	20,006	1497,3	0,66687	66,687	50,006
401,2	75,649	20,045	20,045	1513	0,66817	66,817	50,045
401,7	75,04	20,066	20,066	1500,8	0,66887	66,887	50,066
402,3	75,1	20,095	20,095	1502	0,66983	66,983	50,095
402,9	75,076	20,122	20,122	1501,5	0,67073	67,073	50,122
403,4	75,011	20,15	20,15	1500,2	0,67166	67,166	50,15
404	75,718	20,186	20,186	1514,4	0,67286	67,286	50,186
404,6	75,017	20,205	20,205	1500,3	0,67351	67,351	50,205
405,1	75,215	20,237	20,237	1504,3	0,67456	67,456	50,237
405,7	75,429	20,265	20,265	1508,6	0,67551	67,551	50,265
406,3	75,114	20,29	20,29	1502,3	0,67635	67,635	50,29
406,8	75,896	20,331	20,331	1517,9	0,67769	67,769	50,331
407,4	75,033	20,347	20,347	1500,7	0,67824	67,824	50,347
408	75,353	20,379	20,379	1507,1	0,67931	67,931	50,379
408,5	75,293	20,406	20,406	1505,9	0,68021	68,021	50,406
409,1	75,124	20,433	20,433	1502,5	0,68111	68,111	50,433
409,7	75,66	20,47	20,47	1513,2	0,68234	68,234	50,47
410,2	74,917	20,485	20,485	1498,3	0,68284	68,284	50,485
410,8	75,216	20,52	20,52	1504,3	0,68402	68,402	50,52
411,3	75,175	20,548	20,548	1503,5	0,68494	68,494	50,548
411,9	75,067	20,576	20,576	1501,3	0,68586	68,586	50,576
412,5	75,532	20,61	20,61	1510,6	0,68699	68,699	50,61
413	74,756	20,627	20,627	1495,1	0,68758	68,758	50,627
413,6	75,424	20,665	20,665	1508,5	0,68884	68,884	50,665
414,2	74,94	20,688	20,688	1498,8	0,6896	68,96	50,688
414,7	75,03	20,718	20,718	1500,6	0,69059	69,059	50,718
415,3	75,332	20,748	20,748	1506,6	0,69161	69,161	50,748
415,9	74,865	20,771	20,771	1497,3	0,69237	69,237	50,771
416,4	75,506	20,806	20,806	1510,1	0,69352	69,352	50,806
417	75,117	20,829	20,829	1502,3	0,69432	69,432	50,829
417,6	75,162	20,859	20,859	1503,2	0,69531	69,531	50,859
418,1	75,295	20,888	20,888	1505,9	0,69628	69,628	50,888
418,7	74,905	20,911	20,911	1498,1	0,69703	69,703	50,911
419,3	75,513	20,949	20,949	1510,3	0,69829	69,829	50,949
419,8	74,975	20,971	20,971	1499,5	0,69902	69,902	50,971
420,4	75,037	21	21	1500,7	0,69999	69,999	51
421	75,444	21,032	21,032	1508,9	0,70108	70,108	51,032
421,5	74,948	21,054	21,054	1499	0,70181	70,181	51,054
422,1	75,546	21,091	21,091	1510,9	0,70304	70,304	51,091
422,7	75,002	21,111	21,111	1500	0,70371	70,371	51,111
423,2	75,077	21,143	21,143	1501,5	0,70476	70,476	51,143
423,8	75,141	21,17	21,17	1502,8	0,70567	70,567	51,17
424,4	74,912	21,196	21,196	1498,2	0,70655	70,655	51,196
424,9	75,621	21,234	21,234	1512,4	0,70782	70,782	51,234
425,5	74,978	21,252	21,252	1499,6	0,70839	70,839	51,252
426,1	75,346	21,285	21,285	1506,9	0,70951	70,951	51,285
426,6	75,38	21,314	21,314	1507,6	0,71047	71,047	51,314
427,2	75,036	21,337	21,337	1500,7	0,71123	71,123	51,337
427,8	75,998	21,378	21,378	1520	0,7126	71,26	51,378
428,3	75,007	21,394	21,394	1500,1	0,71312	71,312	51,394
428,9	75,446	21,427	21,427	1508,9	0,71423	71,423	51,427
429,5	75,529	21,455	21,455	1510,6	0,71516	71,516	51,455
430	75,211	21,479	21,479	1504,2	0,71598	71,598	51,479
430,6	76,067	21,517	21,517	1521,3	0,71722	71,722	51,517
431,2	75,072	21,534	21,534	1501,4	0,71781	71,781	51,534
431,7	75,594	21,568	21,568	1511,9	0,71895	71,895	51,568
432,3	75,451	21,595	21,595	1509	0,71984	71,984	51,595
432,8	75,444	21,623	21,623	1508,9	0,72077	72,077	51,623
433,4	75,897	21,658	21,658	1517,9	0,72192	72,192	51,658
434	75,3	21,677	21,677	1506	0,72258	72,258	51,677
434,5	75,644	21,712	21,712	1512,9	0,72373	72,373	51,712
435,1	75,428	21,735	21,735	1508,6	0,72451	72,451	51,735
435,7	75,494	21,765	21,765	1509,9	0,72549	72,549	51,765
436,2	75,768	21,796	21,796	1515,4	0,72653	72,653	51,796
436,8	75,327	21,818	21,818	1506,5	0,72728	72,728	51,818
437,4	75,944	21,853	21,853	1518,9	0,72844	72,844	51,853
437,9	75,457	21,875	21,875	1509,1	0,72918	72,918	51,875
438,5	75,602	21,906	21,906	1512	0,73018	73,018	51,906
439,1	75,885	21,937	21,937	1517,7	0,73124	73,124	51,937
439,6	75,48	21,96	21,96	1509,6	0,73199	73,199	51,96
440,2	75,967	21,996	21,996	1519,3	0,73319	73,319	51,996
440,8	75,823	22,019	22,019	1516,5	0,73396	73,396	52,019
441,3	75,744	22,046	22,046	1514,9	0,73488	73,488	52,046
441,9	75,956	22,076	22,076	1519,1	0,73587	73,587	52,076
442,5	75,688	22,1	22,1	1513,8	0,73667	73,667	52,1
443	76,451	22,14	22,14	1529	0,73799	73,799	52,14
443,6	75,803	22,159	22,159	1516,1	0,73863	73,863	52,159
444,2	75,911	22,189	22,189	1518,2	0,73964	73,964	52,189
444,7	76,069	22,219	22,219	1521,4	0,74063	74,063	52,219
445,3	75,793	22,245	22,245	1515,9	0,74148	74,148	52,245
445,9	76,212	22,279	22,279	1524,2	0,74264	74,264	52,279
446,4	75,799	22,298	22,298	1516	0,74328	74,328	52,298
447	76,189	22,334	22,334	1523,8	0,74446	74,446	52,334
447,6	76,073	22,359	22,359	1521,5	0,7453	74,53	52,359
448,1	75,911	22,387	22,387	1518,2	0,74623	74,623	52,387
448,7	76,526	22,422	22,422	1530,5	0,74741	74,741	52,422
449,3	75,79	22,441	22,441	1515,8	0,74803	74,803	52,441
449,8	76,166	22,475	22,475	1523,3	0,74915	74,915	52,475
450,4	76,134	22,501	22,501	1522,7	0,75003	75,003	52,501
451	75,933	22,526	22,526	1518,7	0,75088	75,088	52,526
451,5	76,419	22,562	22,562	1528,4	0,75207	75,207	52,562
452,1	75,894	22,581	22,581	1517,9	0,75269	75,269	52,581
452,7	76,416	22,617	22,617	1528,3	0,7539	75,39	52,617
453,2	76,108	22,64	22,64	1522,2	0,75466	75,466	52,64
453,8	76,073	22,668	22,668	1521,5	0,75561	75,561	52,668
454,4	76,654	22,704	22,704	1533,1	0,75679	75,679	52,704
454,9	75,879	22,723	22,723	1517,6	0,75744	75,744	52,723
455,5	76,49	22,759	22,759	1529,8	0,75862	75,862	52,759
456	76,335	22,783	22,783	1526,7	0,75943	75,943	52,783
456,6	76,306	22,81	22,81	1526,1	0,76035	76,035	52,81
457,2	76,592	22,842	22,842	1531,8	0,76141	76,141	52,842
457,7	76,067	22,863	22,863	1521,3	0,7621	76,21	52,863
458,3	76,816	22,901	22,901	1536,3	0,76338	76,338	52,901
458,9	76,27	22,92	22,92	1525,4	0,764	76,4	52,92
459,4	76,492	22,954	22,954	1529,8	0,76512	76,512	52,954
460	76,654	22,98	22,98	1533,1	0,76601	76,601	52,98
460,6	76,413	23,008	23,008	1528,3	0,76694	76,694	53,008
461,1	77,032	23,044	23,044	1540,6	0,76812	76,812	53,044
461,7	76,503	23,062	23,062	1530,1	0,76874	76,874	53,062
462,3	76,776	23,094	23,094	1535,5	0,76981	76,981	53,094
462,8	76,941	23,123	23,123	1538,8	0,77078	77,078	53,123
463,4	76,735	23,149	23,149	1534,7	0,77164	77,164	53,149
464	77,312	23,186	23,186	1546,2	0,77286	77,286	53,186
464,5	76,67	23,204	23,204	1533,4	0,77345	77,345	53,204
465,1	76,956	23,238	23,238	1539,1	0,77458	77,458	53,238
465,7	76,992	23,263	23,263	1539,8	0,77545	77,545	53,263
466,2	76,944	23,29	23,29	1538,9	0,77634	77,634	53,29
466,8	77,604	23,329	23,329	1552,1	0,77765	77,765	53,329
467,4	76,878	23,345	23,345	1537,6	0,77818	77,818	53,345
467,9	77,104	23,378	23,378	1542,1	0,77927	77,927	53,378
468,5	76,978	23,405	23,405	1539,6	0,78015	78,015	53,405
469,1	76,784	23,43	23,43	1535,7	0,78101	78,101	53,43
469,6	77,213	23,466	23,466	1544,3	0,78219	78,219	53,466
470,2	76,808	23,487	23,487	1536,2	0,78291	78,291	53,487
470,8	77,358	23,522	23,522	1547,2	0,78407	78,407	53,522
471,3	77,091	23,546	23,546	1541,8	0,78487	78,487	53,546
471,9	77,289	23,577	23,577	1545,8	0,7859	78,59	53,577
472,5	77,453	23,607	23,607	1549,1	0,78689	78,689	53,607
473	76,999	23,628	23,628	1540	0,78759	78,759	53,628
473,6	77,59	23,665	23,665	1551,8	0,78884	78,884	53,665
474,2	77,179	23,687	23,687	1543,6	0,78955	78,955	53,687
474,7	77,122	23,717	23,717	1542,4	0,79058	79,058	53,717
475,3	77,338	23,745	23,745	1546,8	0,79149	79,149	53,745
475,9	76,958	23,768	23,768	1539,2	0,79227	79,227	53,768
476,4	77,583	23,806	23,806	1551,7	0,79353	79,353	53,806
477	77,204	23,828	23,828	1544,1	0,79427	79,427	53,828
477,5	77,357	23,858	23,858	1547,1	0,79526	79,526	53,858
478,1	77,47	23,887	23,887	1549,4	0,79624	79,624	53,887
478,7	77,235	23,911	23,911	1544,7	0,79704	79,704	53,911
479,2	77,743	23,948	23,948	1554,9	0,79827	79,827	53,948
479,8	77,307	23,97	23,97	1546,1	0,79899	79,899	53,97
480,4	77,479	24,001	24,001	1549,6	0,80002	80,002	54,001
480,9	77,483	24,029	24,029	1549,7	0,80095	80,095	54,029
481,5	77,323	24,055	24,055	1546,5	0,80182	80,182	54,055
482,1	77,969	24,092	24,092	1559,4	0,80308	80,308	54,092
482,6	77,296	24,109	24,109	1545,9	0,80364	80,364	54,109
483,2	77,479	24,141	24,141	1549,6	0,80469	80,469	54,141
483,8	77,502	24,169	24,169	1550	0,80562	80,562	54,169
484,3	77,294	24,196	24,196	1545,9	0,80652	80,652	54,196
484,9	78,232	24,235	24,235	1564,6	0,80785	80,785	54,235
485,5	77,35	24,25	24,25	1547	0,80833	80,833	54,25
486	77,893	24,286	24,286	1557,9	0,80952	80,952	54,286
486,6	77,855	24,312	24,312	1557,1	0,81038	81,038	54,312
487,2	77,665	24,337	24,337	1553,3	0,81122	81,122	54,337
487,7	78,389	24,376	24,376	1567,8	0,81254	81,254	54,376
487,9	-6,0253			-120,51