File: Tests de traction/Fichiers source/04_12_2016/8 (ou 9).txt
Time (s)	Load (N)	Machine Extension (mm)	Extension (mm)	Stress (MPa)	Strain	Percentage Strain	Gauge Length (mm)
0
0,3963	0,0019716	0,00011781	0,00011781	0,039431	3,9269E-06	0,00039269	30
0,7925	0,64528	0,013636	0,013636	12,906	0,00045453	0,045453	30,014
1,189	4,5518	0,046519	0,046519	91,035	0,0015506	0,15506	30,047
1,585	6,0889	0,054928	0,054928	121,78	0,0018309	0,18309	30,055
1,981	10,895	0,077241	0,077241	217,89	0,0025747	0,25747	30,077
2,378	14,657	0,093627	0,093627	293,14	0,0031209	0,31209	30,094
2,774	19,13	0,11517	0,11517	382,61	0,003839	0,3839	30,115
3,17	24,854	0,14184	0,14184	497,08	0,0047281	0,47281	30,142
3,566	27,376	0,15517	0,15517	547,52	0,0051725	0,51725	30,155
3,963	32,618	0,18175	0,18175	652,36	0,0060582	0,60582	30,182
4,359	34,742	0,19678	0,19678	694,83	0,0065594	0,65594	30,197
4,755	38,241	0,21687	0,21687	764,81	0,0072291	0,72291	30,217
5,151	41,713	0,23833	0,23833	834,26	0,0079445	0,79445	30,238
5,548	43,896	0,25266	0,25266	877,91	0,0084219	0,84219	30,253
5,944	47,743	0,27982	0,27982	954,86	0,0093275	0,93275	30,28
6,34	49,588	0,29434	0,29434	991,75	0,0098114	0,98114	30,294
6,736	53,081	0,31482	0,31482	1061,6	0,010494	1,0494	30,315
7,133	54,834	0,33408	0,33408	1096,7	0,011136	1,1136	30,334
7,529	57,069	0,35467	0,35467	1141,4	0,011822	1,1822	30,355
7,925	59,447	0,37906	0,37906	1188,9	0,012635	1,2635	30,379
8,321	60,827	0,39046	0,39046	1216,5	0,013015	1,3015	30,39
8,718	64,263	0,42374	0,42374	1285,3	0,014125	1,4125	30,424
9,114	65,04	0,43555	0,43555	1300,8	0,014518	1,4518	30,436
9,51	67,063	0,45345	0,45345	1341,3	0,015115	1,5115	30,453
9,906	68,197	0,47452	0,47452	1363,9	0,015817	1,5817	30,475
10,3	70,079	0,49141	0,49141	1401,6	0,01638	1,638	30,491
10,7	72,512	0,52063	0,52063	1450,2	0,017354	1,7354	30,521
11,1	73,445	0,53277	0,53277	1468,9	0,017759	1,7759	30,533
11,49	75,354	0,55496	0,55496	1507,1	0,018499	1,8499	30,555
11,89	76,155	0,57224	0,57224	1523,1	0,019075	1,9075	30,572
12,28	78,225	0,59016	0,59016	1564,5	0,019672	1,9672	30,59
12,68	79,325	0,61463	0,61463	1586,5	0,020488	2,0488	30,615
13,08	80,599	0,63211	0,63211	1612	0,02107	2,107	30,632
13,47	82,028	0,65704	0,65704	1640,6	0,021901	2,1901	30,657
13,87	82,611	0,67034	0,67034	1652,2	0,022345	2,2345	30,67
14,27	84,229	0,6922	0,6922	1684,6	0,023073	2,3073	30,692
14,66	84,874	0,71441	0,71441	1697,5	0,023814	2,3814	30,714
15,06	86,483	0,73016	0,73016	1729,7	0,024339	2,4339	30,73
15,45	87,87	0,75735	0,75735	1757,4	0,025245	2,5245	30,757
15,85	87,955	0,76924	0,76924	1759,1	0,025641	2,5641	30,769
16,25	89,684	0,79271	0,79271	1793,7	0,026424	2,6424	30,793
16,64	89,733	0,81229	0,81229	1794,7	0,027076	2,7076	30,812
17,04	90,846	0,82808	0,82808	1816,9	0,027603	2,7603	30,828
17,44	91,805	0,85457	0,85457	1836,1	0,028486	2,8486	30,855
17,83	92,463	0,86612	0,86612	1849,3	0,028871	2,8871	30,866
18,23	94,073	0,89604	0,89604	1881,5	0,029868	2,9868	30,896
18,62	93,333	0,90804	0,90804	1866,7	0,030268	3,0268	30,908
19,02	94,807	0,93062	0,93062	1896,1	0,031021	3,1021	30,931
19,42	94,674	0,95116	0,95116	1893,5	0,031705	3,1705	30,951
19,81	95,418	0,96478	0,96478	1908,4	0,032159	3,2159	30,965
20,21	96,333	0,99497	0,99497	1926,7	0,033166	3,3166	30,995
20,61	95,975	1,0075	1,0075	1919,5	0,033584	3,3584	31,008
21	97,105	1,0314	1,0314	1942,1	0,034382	3,4382	31,031
21,4	96,136	1,0478	1,0478	1922,7	0,034925	3,4925	31,048
21,79	96,529	1,0663	1,0663	1930,6	0,035545	3,5545	31,066
22,19	96,861	1,0923	1,0923	1937,2	0,03641	3,641	31,092
22,59	96,585	1,1066	1,1066	1931,7	0,036888	3,6888	31,107
22,98	96,717	1,1307	1,1307	1934,3	0,03769	3,769	31,131
23,38	96,181	1,1473	1,1473	1923,6	0,038245	3,8245	31,147
23,78	95,661	1,1656	1,1656	1913,2	0,038854	3,8854	31,166
24,17	94,051	1,1885	1,1885	1881	0,039618	3,9618	31,189
24,57	93,031	1,2055	1,2055	1860,6	0,040183	4,0183	31,205
24,96	88,03	1,235	1,235	1760,6	0,041165	4,1165	31,235
25,36	84,816	1,2458	1,2458	1696,3	0,041526	4,1526	31,246
25,76	85,638	1,2652	1,2652	1712,8	0,042174	4,2174	31,265
26,15	85,547	1,2856	1,2856	1710,9	0,042852	4,2852	31,286
26,55	87,069	1,3042	1,3042	1741,4	0,043474	4,3474	31,304
26,95	88,364	1,3297	1,3297	1767,3	0,044323	4,4323	31,33
27,34	86,623	1,3406	1,3406	1732,5	0,044687	4,4687	31,341
27,74	88,002	1,3695	1,3695	1760	0,04565	4,565	31,369
28,13	83,135	1,3866	1,3866	1662,7	0,046222	4,6222	31,387
28,53	84,601	1,4047	1,4047	1692	0,046824	4,6824	31,405
28,93	84,859	1,4275	1,4275	1697,2	0,047584	4,7584	31,428
29,32	85,345	1,4411	1,4411	1706,9	0,048038	4,8038	31,441
29,72	87,485	1,472	1,472	1749,7	0,049067	4,9067	31,472
30,12	85,154	1,4816	1,4816	1703,1	0,049388	4,9388	31,482
30,51	87,145	1,5058	1,5058	1742,9	0,050192	5,0192	31,506
30,91	85,478	1,5212	1,5212	1709,6	0,050708	5,0708	31,521
31,3	86,576	1,5413	1,5413	1731,5	0,051376	5,1376	31,541
31,7	87,093	1,5685	1,5685	1741,9	0,052285	5,2285	31,569
32,1	85,972	1,5831	1,5831	1719,4	0,052771	5,2771	31,583
32,49	87,055	1,6075	1,6075	1741,1	0,053585	5,3585	31,608
32,89	86,207	1,6224	1,6224	1724,1	0,054079	5,4079	31,622
33,29	85,892	1,6438	1,6438	1717,8	0,054792	5,4792	31,644
33,68	85,77	1,6653	1,6653	1715,4	0,055509	5,5509	31,665
34,08	85,321	1,6818	1,6818	1706,4	0,056059	5,6059	31,682
34,47	86,834	1,709	1,709	1736,7	0,056967	5,6967	31,709
34,87	85,21	1,7196	1,7196	1704,2	0,057319	5,7319	31,72
35,27	85,459	1,7434	1,7434	1709,2	0,058113	5,8113	31,743
35,66	85,162	1,7635	1,7635	1703,2	0,058783	5,8783	31,764
36,06	85,012	1,7786	1,7786	1700,2	0,059286	5,9286	31,779
36,46	86,103	1,8082	1,8082	1722,1	0,060273	6,0273	31,808
36,85	84,527	1,8194	1,8194	1690,5	0,060648	6,0648	31,819
37,25	85,677	1,8449	1,8449	1713,5	0,061495	6,1495	31,845
37,64	84,676	1,8595	1,8595	1693,5	0,061984	6,1984	31,86
38,04	84,568	1,8824	1,8824	1691,4	0,062747	6,2747	31,882
38,44	84,175	1,9036	1,9036	1683,5	0,063453	6,3453	31,904
38,83	82,71	1,9154	1,9154	1654,2	0,063845	6,3845	31,915
39,23	84,905	1,9472	1,9472	1698,1	0,064905	6,4905	31,947
39,63	83,318	1,9592	1,9592	1666,4	0,065306	6,5306	31,959
40,02	83,571	1,9811	1,9811	1671,4	0,066038	6,6038	31,981
40,42	82,819	2,0002	2,0002	1656,4	0,066672	6,6672	32
40,81	83,11	2,0182	2,0182	1662,2	0,067274	6,7274	32,018
41,21	83,724	2,0446	2,0446	1674,5	0,068155	6,8155	32,045
41,61	81,731	2,0557	2,0557	1634,6	0,068522	6,8522	32,056
42	83,9	2,0828	2,0828	1678	0,069426	6,9426	32,083
42,4	81,821	2,0976	2,0976	1636,4	0,069919	6,9919	32,098
42,8	82,428	2,1171	2,1171	1648,6	0,07057	7,057	32,117
43,19	82,008	2,1389	2,1389	1640,2	0,071298	7,1298	32,139
43,59	81,694	2,1545	2,1545	1633,9	0,071817	7,1817	32,154
43,98	83,656	2,1855	2,1855	1673,1	0,07285	7,285	32,185
44,38	81,531	2,1963	2,1963	1630,6	0,07321	7,321	32,196
44,78	82,194	2,2179	2,2179	1643,9	0,073929	7,3929	32,218
45,17	81,304	2,2368	2,2368	1626,1	0,074561	7,4561	32,237
45,57	81,934	2,2564	2,2564	1638,7	0,075213	7,5213	32,256
45,97	82,571	2,2811	2,2811	1651,4	0,076036	7,6036	32,281
46,36	80,406	2,292	2,292	1608,1	0,0764	7,64	32,292
46,76	82,696	2,3174	2,3174	1653,9	0,077248	7,7248	32,317
47,15	81,708	2,3373	2,3373	1634,2	0,077911	7,7911	32,337
47,55	81,452	2,3541	2,3541	1629	0,078471	7,8471	32,354
47,95	82,357	2,3801	2,3801	1647,1	0,079337	7,9337	32,38
48,34	80,753	2,391	2,391	1615,1	0,0797	7,97	32,391
48,74	83,027	2,4221	2,4221	1660,5	0,080737	8,0737	32,422
49,14	80,706	2,4338	2,4338	1614,1	0,081125	8,1125	32,434
49,53	82,16	2,4578	2,4578	1643,2	0,081926	8,1926	32,458
49,93	81,734	2,4777	2,4777	1634,7	0,08259	8,259	32,478
50,32	81,035	2,4924	2,4924	1620,7	0,083081	8,3081	32,492
50,72	82,798	2,5219	2,5219	1656	0,084064	8,4064	32,522
51,12	81,064	2,5325	2,5325	1621,3	0,084417	8,4417	32,533
51,51	82,278	2,557	2,557	1645,6	0,085234	8,5234	32,557
51,91	81,251	2,5753	2,5753	1625	0,085842	8,5842	32,575
52,31	81,685	2,5941	2,5941	1633,7	0,086471	8,6471	32,594
52,7	81,833	2,6185	2,6185	1636,7	0,087282	8,7282	32,618
53,1	80,422	2,6299	2,6299	1608,4	0,087664	8,7664	32,63
53,49	83,042	2,6625	2,6625	1660,8	0,08875	8,875	32,663
53,89	80,079	2,6696	2,6696	1601,6	0,088987	8,8987	32,67
54,29	81,329	2,6928	2,6928	1626,6	0,089761	8,9761	32,693
54,68	80,451	2,7129	2,7129	1609	0,090429	9,0429	32,713
55,08	80,924	2,7317	2,7317	1618,5	0,091057	9,1057	32,732
55,48	81,283	2,7566	2,7566	1625,7	0,091886	9,1886	32,757
55,87	80,228	2,7678	2,7678	1604,6	0,09226	9,226	32,768
56,27	82,016	2,795	2,795	1640,3	0,093165	9,3165	32,795
56,66	80,509	2,8108	2,8108	1610,2	0,093695	9,3695	32,811
57,06	80,79	2,8321	2,8321	1615,8	0,094404	9,4404	32,832
57,46	80,403	2,8547	2,8547	1608,1	0,095158	9,5158	32,855
57,85	80,133	2,8681	2,8681	1602,7	0,095604	9,5604	32,868
58,25	81,491	2,896	2,896	1629,8	0,096533	9,6533	32,896
58,65	79,804	2,9097	2,9097	1596,1	0,096991	9,6991	32,91
59,04	80,564	2,9304	2,9304	1611,3	0,097679	9,7679	32,93
59,44	80,276	2,9523	2,9523	1605,5	0,098411	9,8411	32,952
59,83	79,633	2,9684	2,9684	1592,7	0,098946	9,8946	32,968
60,23	81,739	2,9975	2,9975	1634,8	0,099918	9,9918	32,998
60,63	79,732	3,0061	3,0061	1594,6	0,1002	10,02	33,006
61,02	81,005	3,0319	3,0319	1620,1	0,10106	10,106	33,032
61,42	79,878	3,049	3,049	1597,6	0,10163	10,163	33,049
61,82	80,339	3,0688	3,0688	1606,8	0,10229	10,229	33,069
62,21	81,205	3,0956	3,0956	1624,1	0,10319	10,319	33,096
62,61	79,439	3,105	3,105	1588,8	0,1035	10,35	33,105
63	81,305	3,1348	3,1348	1626,1	0,10449	10,449	33,135
63,4	80,142	3,1479	3,1479	1602,8	0,10493	10,493	33,148
63,8	80,14	3,1673	3,1673	1602,8	0,10558	10,558	33,167
64,19	80,151	3,1902	3,1902	1603	0,10634	10,634	33,19
64,59	79,71	3,2051	3,2051	1594,2	0,10684	10,684	33,205
64,99	81,416	3,235	3,235	1628,3	0,10783	10,783	33,235
65,38	79,789	3,2454	3,2454	1595,8	0,10818	10,818	33,245
65,78	80,931	3,2695	3,2695	1618,6	0,10898	10,898	33,27
66,17	79,945	3,2873	3,2873	1598,9	0,10958	10,958	33,287
66,57	79,993	3,306	3,306	1599,9	0,1102	11,02	33,306
66,97	80,56	3,3312	3,3312	1611,2	0,11104	11,104	33,331
67,36	79,515	3,3439	3,3439	1590,3	0,11146	11,146	33,344
67,76	81,135	3,3717	3,3717	1622,7	0,11239	11,239	33,372
68,16	79,36	3,3854	3,3854	1587,2	0,11285	11,285	33,385
68,55	80,549	3,4081	3,4081	1611	0,1136	11,36	33,408
68,95	80,087	3,4286	3,4286	1601,7	0,11429	11,429	33,429
69,35	79,598	3,4429	3,4429	1592	0,11476	11,476	33,443
69,74	80,852	3,4696	3,4696	1617	0,11565	11,565	33,47
70,14	79,008	3,4847	3,4847	1580,2	0,11616	11,616	33,485
70,53	80,062	3,506	3,506	1601,2	0,11687	11,687	33,506
70,93	79,138	3,5233	3,5233	1582,8	0,11744	11,744	33,523
71,33	79,55	3,5424	3,5424	1591	0,11808	11,808	33,542
71,72	80,384	3,5678	3,5678	1607,7	0,11893	11,893	33,568
72,12	79,535	3,582	3,582	1590,7	0,1194	11,94	33,582
72,52	80,741	3,608	3,608	1614,8	0,12027	12,027	33,608
72,91	79,545	3,6229	3,6229	1590,9	0,12076	12,076	33,623
73,31	80,378	3,6449	3,6449	1607,6	0,1215	12,15	33,645
73,7	79,917	3,6653	3,6653	1598,3	0,12218	12,218	33,665
74,1	79,59	3,6801	3,6801	1591,8	0,12267	12,267	33,68
74,5	80,417	3,7095	3,7095	1608,3	0,12365	12,365	33,71
74,89	78,884	3,7213	3,7213	1577,7	0,12404	12,404	33,721
75,29	80,37	3,7454	3,7454	1607,4	0,12485	12,485	33,745
75,69	79,347	3,7626	3,7626	1586,9	0,12542	12,542	33,763
76,08	79,597	3,7802	3,7802	1591,9	0,12601	12,601	33,78
76,48	80,552	3,8073	3,8073	1611	0,12691	12,691	33,807
76,87	79,133	3,8186	3,8186	1582,7	0,12729	12,729	33,819
77,27	81,482	3,8516	3,8516	1629,6	0,12839	12,839	33,852
77,67	79,459	3,8614	3,8614	1589,2	0,12871	12,871	33,861
78,06	79,925	3,8828	3,8828	1598,5	0,12943	12,943	33,883
78,46	79,346	3,9017	3,9017	1586,9	0,13006	13,006	33,902
78,86	78,98	3,9178	3,9178	1579,6	0,13059	13,059	33,918
79,25	80,726	3,9483	3,9483	1614,5	0,13161	13,161	33,948
79,65	79,225	3,9595	3,9595	1584,5	0,13198	13,198	33,96
80,04	79,73	3,9816	3,9816	1594,6	0,13272	13,272	33,982
80,44	79,283	4,002	4,002	1585,7	0,1334	13,34	34,002
80,84	79,606	4,0206	4,0206	1592,1	0,13402	13,402	34,021
81,23	80,107	4,0444	4,0444	1602,1	0,13481	13,481	34,044
81,63	78,288	4,0548	4,0548	1565,8	0,13516	13,516	34,055
82,03	80,245	4,0842	4,0842	1604,9	0,13614	13,614	34,084
82,42	79,219	4,1001	4,1001	1584,4	0,13667	13,667	34,1
82,82	79,298	4,1189	4,1189	1586	0,1373	13,73	34,119
83,21	79,688	4,1422	4,1422	1593,8	0,13807	13,807	34,142
83,61	78,842	4,1571	4,1571	1576,8	0,13857	13,857	34,157
84,01	81,236	4,1882	4,1882	1624,7	0,13961	13,961	34,188
84,4	78,717	4,1955	4,1955	1574,3	0,13985	13,985	34,195
84,8	80,046	4,2208	4,2208	1600,9	0,14069	14,069	34,221
85,2	79,098	4,2382	4,2382	1582	0,14127	14,127	34,238
85,59	79,231	4,2578	4,2578	1584,6	0,14193	14,193	34,258
85,99	79,781	4,2825	4,2825	1595,6	0,14275	14,275	34,282
86,38	78,228	4,2945	4,2945	1564,6	0,14315	14,315	34,294
86,78	80,327	4,3246	4,3246	1606,5	0,14415	14,415	34,325
87,18	78,651	4,3358	4,3358	1573	0,14453	14,453	34,336
87,57	79,679	4,3584	4,3584	1593,6	0,14528	14,528	34,358
87,97	79,427	4,3801	4,3801	1588,5	0,146	14,6	34,38
88,37	78,528	4,3935	4,3935	1570,6	0,14645	14,645	34,393
88,76	80,347	4,423	4,423	1606,9	0,14743	14,743	34,423
89,16	79,012	4,4341	4,4341	1580,2	0,1478	14,78	34,434
89,55	79,548	4,4581	4,4581	1591	0,1486	14,86	34,458
89,95	79,392	4,478	4,478	1587,8	0,14927	14,927	34,478
90,35	79,371	4,4953	4,4953	1587,4	0,14984	14,984	34,495
90,74	79,965	4,52	4,52	1599,3	0,15067	15,067	34,52
91,14	79,082	4,534	4,534	1581,6	0,15113	15,113	34,534
91,54	79,922	4,5577	4,5577	1598,4	0,15192	15,192	34,558
91,93	79,118	4,5737	4,5737	1582,4	0,15246	15,246	34,574
92,33	79,543	4,5955	4,5955	1590,9	0,15318	15,318	34,596
92,72	79,484	4,617	4,617	1589,7	0,1539	15,39	34,617
93,12	79,025	4,6316	4,6316	1580,5	0,15439	15,439	34,632
93,52	80,893	4,6641	4,6641	1617,9	0,15547	15,547	34,664
93,91	78,923	4,6729	4,6729	1578,5	0,15576	15,576	34,673
94,31	79,201	4,6947	4,6947	1584	0,15649	15,649	34,695
94,71	79,19	4,715	4,715	1583,8	0,15717	15,717	34,715
95,1	78,974	4,7315	4,7315	1579,5	0,15772	15,772	34,731
95,5	79,985	4,7584	4,7584	1599,7	0,15861	15,861	34,758
95,89	78,485	4,7693	4,7693	1569,7	0,15898	15,898	34,769
96,29	79,978	4,7939	4,7939	1599,6	0,1598	15,98	34,794
96,69	79,155	4,8125	4,8125	1583,1	0,16042	16,042	34,812
97,08	78,864	4,8322	4,8322	1577,3	0,16107	16,107	34,832
97,48	79,55	4,857	4,857	1591	0,1619	16,19	34,857
97,88	78,476	4,8694	4,8694	1569,5	0,16231	16,231	34,869
98,27	80,832	4,9029	4,9029	1616,6	0,16343	16,343	34,903
98,67	78,36	4,9094	4,9094	1567,2	0,16365	16,365	34,909
99,06	79,428	4,9332	4,9332	1588,6	0,16444	16,444	34,933
99,46	78,729	4,9523	4,9523	1574,6	0,16508	16,508	34,952
99,86	78,69	4,9684	4,9684	1573,8	0,16561	16,561	34,968
100,3	79,782	4,9963	4,9963	1595,6	0,16654	16,654	34,996
100,6	78,496	5,0079	5,0079	1569,9	0,16693	16,693	35,008
101	79,451	5,033	5,033	1589	0,16777	16,777	35,033
101,4	78,501	5,051	5,051	1570	0,16837	16,837	35,051
101,8	79,115	5,0723	5,0723	1582,3	0,16908	16,908	35,072
102,2	79,134	5,094	5,094	1582,7	0,1698	16,98	35,094
102,6	78,086	5,1067	5,1067	1561,7	0,17022	17,022	35,107
103	79,34	5,1339	5,1339	1586,8	0,17113	17,113	35,134
103,4	78,457	5,1469	5,1469	1569,1	0,17156	17,156	35,147
103,8	79,052	5,1705	5,1705	1581	0,17235	17,235	35,171
104,2	78,577	5,191	5,191	1571,5	0,17303	17,303	35,191
104,6	78,268	5,2064	5,2064	1565,4	0,17355	17,355	35,206
105	79,895	5,237	5,237	1597,9	0,17457	17,457	35,237
105,4	78,38	5,2467	5,2467	1567,6	0,17489	17,489	35,247
105,8	79,288	5,2705	5,2705	1585,8	0,17568	17,568	35,271
106,2	78,896	5,2901	5,2901	1577,9	0,17634	17,634	35,29
106,6	78,69	5,3069	5,3069	1573,8	0,1769	17,69	35,307
107	78,658	5,3303	5,3303	1573,2	0,17768	17,768	35,33
107,4	78,235	5,3421	5,3421	1564,7	0,17807	17,807	35,342
107,8	80,199	5,377	5,377	1604	0,17923	17,923	35,377
108,2	77,968	5,3842	5,3842	1559,4	0,17947	17,947	35,384
108,6	79,027	5,409	5,409	1580,5	0,1803	18,03	35,409
109	78,67	5,428	5,428	1573,4	0,18093	18,093	35,428
109,4	78,506	5,4458	5,4458	1570,1	0,18153	18,153	35,446
109,8	79,761	5,4745	5,4745	1595,2	0,18248	18,248	35,475
110,2	77,866	5,4825	5,4825	1557,3	0,18275	18,275	35,482
110,6	79,151	5,5078	5,5078	1583	0,18359	18,359	35,508
111	77,987	5,525	5,525	1559,7	0,18417	18,417	35,525
111,3	78,42	5,5453	5,5453	1568,4	0,18484	18,484	35,545
111,7	78,604	5,568	5,568	1572,1	0,1856	18,56	35,568
112,1	77,885	5,5826	5,5826	1557,7	0,18609	18,609	35,583
112,5	79,605	5,6135	5,6135	1592,1	0,18712	18,712	35,614
112,9	78,072	5,6243	5,6243	1561,4	0,18748	18,748	35,624
113,3	79,05	5,6473	5,6473	1581	0,18824	18,824	35,647
113,7	77,974	5,6665	5,6665	1559,5	0,18888	18,888	35,667
114,1	78,247	5,6827	5,6827	1564,9	0,18942	18,942	35,683
114,5	78,708	5,7085	5,7085	1574,2	0,19028	19,028	35,708
114,9	78,22	5,7222	5,7222	1564,4	0,19074	19,074	35,722
115,3	78,554	5,7461	5,7461	1571,1	0,19154	19,154	35,746
115,7	78,503	5,7625	5,7625	1570,1	0,19208	19,208	35,762
116,1	78,714	5,7815	5,7815	1574,3	0,19272	19,272	35,782
116,5	79,378	5,8088	5,8088	1587,6	0,19363	19,363	35,809
116,9	78,375	5,8204	5,8204	1567,5	0,19401	19,401	35,82
117,3	79,761	5,8497	5,8497	1595,2	0,19499	19,499	35,85
117,7	78,266	5,8631	5,8631	1565,3	0,19544	19,544	35,863
118,1	78,474	5,8822	5,8822	1569,5	0,19607	19,607	35,882
118,5	78,791	5,9036	5,9036	1575,8	0,19679	19,679	35,904
118,9	78,131	5,9189	5,9189	1562,6	0,1973	19,73	35,919
119,3	79,881	5,9507	5,9507	1597,6	0,19836	19,836	35,951
119,7	78,357	5,9597	5,9597	1567,1	0,19866	19,866	35,96
120,1	79,056	5,9827	5,9827	1581,1	0,19942	19,942	35,983
120,5	78,854	6,0029	6,0029	1577,1	0,2001	20,01	36,003
120,9	78,532	6,0191	6,0191	1570,6	0,20064	20,064	36,019
121,3	79,366	6,0456	6,0456	1587,3	0,20152	20,152	36,046
121,7	78,217	6,0572	6,0572	1564,3	0,20191	20,191	36,057
122	80,432	6,089	6,089	1608,6	0,20297	20,297	36,089
122,4	78,081	6,0972	6,0972	1561,6	0,20324	20,324	36,097
122,8	78,875	6,121	6,121	1577,5	0,20403	20,403	36,121
123,2	78,783	6,1408	6,1408	1575,7	0,20469	20,469	36,141
123,6	78,591	6,1571	6,1571	1571,8	0,20524	20,524	36,157
124	79,401	6,1859	6,1859	1588	0,2062	20,62	36,186
124,4	78,374	6,198	6,198	1567,5	0,2066	20,66	36,198
124,8	79,157	6,2214	6,2214	1583,1	0,20738	20,738	36,221
125,2	78,422	6,2382	6,2382	1568,4	0,20794	20,794	36,238
125,6	78,57	6,2587	6,2587	1571,4	0,20862	20,862	36,259
126	79,236	6,2822	6,2822	1584,7	0,20941	20,941	36,282
126,4	78,099	6,2967	6,2967	1562	0,20989	20,989	36,297
126,8	79,435	6,3229	6,3229	1588,7	0,21076	21,076	36,323
127,2	78,4	6,3373	6,3373	1568	0,21124	21,124	36,337
127,6	78,827	6,3592	6,3592	1576,5	0,21197	21,197	36,359
128	78,893	6,3808	6,3808	1577,9	0,21269	21,269	36,381
128,4	77,955	6,3948	6,3948	1559,1	0,21316	21,316	36,395
128,8	79,507	6,4238	6,4238	1590,1	0,21413	21,413	36,424
129,2	78,402	6,4364	6,4364	1568	0,21455	21,455	36,436
129,6	79,067	6,4582	6,4582	1581,3	0,21527	21,527	36,458
130	78,824	6,4792	6,4792	1576,5	0,21597	21,597	36,479
130,4	78,549	6,4948	6,4948	1571	0,21649	21,649	36,495
130,8	79,416	6,5219	6,5219	1588,3	0,2174	21,74	36,522
131,2	78,379	6,5336	6,5336	1567,6	0,21779	21,779	36,534
131,6	79,625	6,5622	6,5622	1592,5	0,21874	21,874	36,562
132	78,412	6,5751	6,5751	1568,2	0,21917	21,917	36,575
132,3	78,908	6,5964	6,5964	1578,2	0,21988	21,988	36,596
132,7	79,034	6,6192	6,6192	1580,7	0,22064	22,064	36,619
133,1	78,353	6,6329	6,6329	1567,1	0,2211	22,11	36,633
133,5	79,923	6,6632	6,6632	1598,5	0,22211	22,211	36,663
133,9	78,142	6,6724	6,6724	1562,8	0,22241	22,241	36,672
134,3	79,169	6,697	6,697	1583,4	0,22323	22,323	36,697
134,7	78,609	6,7152	6,7152	1572,2	0,22384	22,384	36,715
135,1	78,764	6,7349	6,7349	1575,3	0,2245	22,45	36,735
135,5	79,347	6,7589	6,7589	1586,9	0,2253	22,53	36,759
135,9	78,277	6,7703	6,7703	1565,5	0,22568	22,568	36,77
136,3	79,577	6,7987	6,7987	1591,5	0,22662	22,662	36,799
136,7	78,437	6,8129	6,8129	1568,7	0,2271	22,71	36,813
137,1	78,868	6,8345	6,8345	1577,4	0,22782	22,782	36,834
137,5	78,971	6,8562	6,8562	1579,4	0,22854	22,854	36,856
137,9	78,317	6,8707	6,8707	1566,3	0,22902	22,902	36,871
138,3	79,499	6,9	6,9	1590	0,23	23	36,9
138,7	78,109	6,9111	6,9111	1562,2	0,23037	23,037	36,911
139,1	78,785	6,9343	6,9343	1575,7	0,23114	23,114	36,934
139,5	78,235	6,9529	6,9529	1564,7	0,23176	23,176	36,953
139,9	78,438	6,9712	6,9712	1568,8	0,23237	23,237	36,971
140,3	79,312	6,9979	6,9979	1586,2	0,23326	23,326	36,998
140,7	78,33	7,0085	7,0085	1566,6	0,23362	23,362	37,008
141,1	78,909	7,0363	7,0363	1578,2	0,23454	23,454	37,036
141,5	78,277	7,0509	7,0509	1565,5	0,23503	23,503	37,051
141,9	78,323	7,0697	7,0697	1566,5	0,23566	23,566	37,07
142,3	78,825	7,0953	7,0953	1576,5	0,23651	23,651	37,095
142,7	77,927	7,1062	7,1062	1558,5	0,23687	23,687	37,106
143	79,585	7,1392	7,1392	1591,7	0,23797	23,797	37,139
143,4	78,135	7,1493	7,1493	1562,7	0,23831	23,831	37,149
143,8	78,686	7,1714	7,1714	1573,7	0,23905	23,905	37,171
144,2	78,28	7,1913	7,1913	1565,6	0,23971	23,971	37,191
144,6	78,046	7,2077	7,2077	1560,9	0,24026	24,026	37,208
145	79,002	7,2357	7,2357	1580	0,24119	24,119	37,236
145,4	77,737	7,2463	7,2463	1554,7	0,24154	24,154	37,246
145,8	79,076	7,2756	7,2756	1581,5	0,24252	24,252	37,276
146,2	77,705	7,2862	7,2862	1554,1	0,24287	24,287	37,286
146,6	78,209	7,3082	7,3082	1564,2	0,24361	24,361	37,308
147	78,443	7,3318	7,3318	1568,9	0,24439	24,439	37,332
147,4	77,645	7,3448	7,3448	1552,9	0,24483	24,483	37,345
147,8	79,168	7,3756	7,3756	1583,4	0,24585	24,585	37,376
148,2	77,989	7,3875	7,3875	1559,8	0,24625	24,625	37,388
148,6	78,356	7,4102	7,4102	1567,1	0,24701	24,701	37,41
149	78,126	7,4292	7,4292	1562,5	0,24764	24,764	37,429
149,4	77,931	7,4456	7,4456	1558,6	0,24819	24,819	37,446
149,8	78,887	7,4736	7,4736	1577,7	0,24912	24,912	37,474
150,2	77,747	7,4857	7,4857	1554,9	0,24952	24,952	37,486
150,6	78,777	7,5082	7,5082	1575,5	0,25027	25,027	37,508
151	78,044	7,5268	7,5268	1560,9	0,25089	25,089	37,527
151,4	78,126	7,5451	7,5451	1562,5	0,2515	25,15	37,545
151,8	78,699	7,5713	7,5713	1574	0,25238	25,238	37,571
152,2	77,738	7,5825	7,5825	1554,8	0,25275	25,275	37,583
152,6	79,233	7,614	7,614	1584,7	0,2538	25,38	37,614
153	77,884	7,6247	7,6247	1557,7	0,25416	25,416	37,625
153,4	78,519	7,6471	7,6471	1570,4	0,2549	25,49	37,647
153,7	78,029	7,6659	7,6659	1560,6	0,25553	25,553	37,666
154,1	77,863	7,6841	7,6841	1557,3	0,25614	25,614	37,684
154,5	78,737	7,7113	7,7113	1574,7	0,25704	25,704	37,711
154,9	77,624	7,7226	7,7226	1552,5	0,25742	25,742	37,723
155,3	78,101	7,7466	7,7466	1562	0,25822	25,822	37,747
155,7	77,228	7,7635	7,7635	1544,6	0,25878	25,878	37,763
156,1	77,632	7,7845	7,7845	1552,6	0,25948	25,948	37,785
156,5	78,107	7,8083	7,8083	1562,1	0,26028	26,028	37,808
156,9	77,398	7,8209	7,8209	1548	0,2607	26,07	37,821
157,3	79,396	7,8552	7,8552	1587,9	0,26184	26,184	37,855
157,7	77,516	7,8615	7,8615	1550,3	0,26205	26,205	37,862
158,1	77,975	7,8848	7,8848	1559,5	0,26283	26,283	37,885
158,5	77,797	7,9035	7,9035	1555,9	0,26345	26,345	37,904
158,9	77,474	7,9203	7,9203	1549,5	0,26401	26,401	37,92
159,3	78,853	7,9509	7,9509	1577,1	0,26503	26,503	37,951
159,7	77,498	7,9608	7,9608	1550	0,26536	26,536	37,961
160,1	78,417	7,9881	7,9881	1568,3	0,26627	26,627	37,988
160,5	77,823	8,0013	8,0013	1556,5	0,26671	26,671	38,001
160,9	78,154	8,0234	8,0234	1563,1	0,26745	26,745	38,023
161,3	78,186	8,0445	8,0445	1563,7	0,26815	26,815	38,044
161,7	77,605	8,0614	8,0614	1552,1	0,26871	26,871	38,061
162,1	79,133	8,0884	8,0884	1582,7	0,26961	26,961	38,088
162,5	77,597	8,0998	8,0998	1551,9	0,26999	26,999	38,1
162,9	78,154	8,1217	8,1217	1563,1	0,27072	27,072	38,122
163,3	78,383	8,1455	8,1455	1567,7	0,27152	27,152	38,145
163,7	77,732	8,1598	8,1598	1554,6	0,27199	27,199	38,16
164,1	78,793	8,1876	8,1876	1575,9	0,27292	27,292	38,188
164,4	77,569	8,198	8,198	1551,4	0,27327	27,327	38,198
164,8	78,239	8,2219	8,2219	1564,8	0,27406	27,406	38,222
165,2	77,677	8,2384	8,2384	1553,5	0,27461	27,461	38,238
165,6	78,244	8,2608	8,2608	1564,9	0,27536	27,536	38,261
166	78,705	8,2849	8,2849	1574,1	0,27616	27,616	38,285
166,4	77,99	8,2964	8,2964	1559,8	0,27655	27,655	38,296
166,8	79,488	8,3292	8,3292	1589,8	0,27764	27,764	38,329
167,2	77,845	8,3379	8,3379	1556,9	0,27793	27,793	38,338
167,6	78,513	8,3607	8,3607	1570,3	0,27869	27,869	38,361
168	78,162	8,3811	8,3811	1563,2	0,27937	27,937	38,381
168,4	77,91	8,3962	8,3962	1558,2	0,27987	27,987	38,396
168,8	79,101	8,4261	8,4261	1582	0,28087	28,087	38,426
169,2	77,777	8,4352	8,4352	1555,5	0,28117	28,117	38,435
169,6	78,576	8,4608	8,4608	1571,5	0,28203	28,203	38,461
170	78,067	8,4779	8,4779	1561,3	0,2826	28,26	38,478
170,4	78,105	8,4981	8,4981	1562,1	0,28327	28,327	38,498
170,8	78,66	8,5219	8,5219	1573,2	0,28406	28,406	38,522
171,2	77,724	8,5344	8,5344	1554,5	0,28448	28,448	38,534
171,6	78,503	8,563	8,563	1570,1	0,28543	28,543	38,563
172	77,932	8,5756	8,5756	1558,6	0,28585	28,585	38,576
172,4	78,24	8,5965	8,5965	1564,8	0,28655	28,655	38,597
172,8	78,006	8,6181	8,6181	1560,1	0,28727	28,727	38,618
173,2	77,386	8,6328	8,6328	1547,7	0,28776	28,776	38,633
173,6	78,515	8,6655	8,6655	1570,3	0,28885	28,885	38,666
174	76,878	8,6723	8,6723	1537,6	0,28908	28,908	38,672
174,4	77,48	8,696	8,696	1549,6	0,28987	28,987	38,696
174,7	77,435	8,7161	8,7161	1548,7	0,29054	29,054	38,716
175,1	77,556	8,7354	8,7354	1551,1	0,29118	29,118	38,735
175,5	78,287	8,7602	8,7602	1565,7	0,29201	29,201	38,76
175,9	77,397	8,7719	8,7719	1547,9	0,2924	29,24	38,772
176,3	79,175	8,8029	8,8029	1583,5	0,29343	29,343	38,803
176,7	77,567	8,8153	8,8153	1551,3	0,29384	29,384	38,815
177,1	78,261	8,8362	8,8362	1565,2	0,29454	29,454	38,836
177,5	78,276	8,8571	8,8571	1565,5	0,29524	29,524	38,857
177,9	77,79	8,8717	8,8717	1555,8	0,29572	29,572	38,872
178,3	78,812	8,901	8,901	1576,2	0,2967	29,67	38,901
178,7	77,662	8,9117	8,9117	1553,2	0,29706	29,706	38,912
179,1	78,394	8,936	8,936	1567,9	0,29787	29,787	38,936
179,5	77,695	8,9516	8,9516	1553,9	0,29839	29,839	38,952
179,9	77,795	8,9721	8,9721	1555,9	0,29907	29,907	38,972
180,3	78,3	8,9963	8,9963	1566	0,29988	29,988	38,996
180,7	77,612	9,0104	9,0104	1552,2	0,30035	30,035	39,01
181,1	78,507	9,0372	9,0372	1570,1	0,30124	30,124	39,037
181,5	77,662	9,0521	9,0521	1553,2	0,30174	30,174	39,052
181,9	78,175	9,0739	9,0739	1563,5	0,30246	30,246	39,074
182,3	78,361	9,0964	9,0964	1567,2	0,30321	30,321	39,096
182,7	77,803	9,1098	9,1098	1556,1	0,30366	30,366	39,11
183,1	78,106	9,1383	9,1383	1562,1	0,30461	30,461	39,138
183,5	77,658	9,1487	9,1487	1553,2	0,30496	30,496	39,149
183,9	78,002	9,1734	9,1734	1560	0,30578	30,578	39,173
184,3	77,789	9,1923	9,1923	1555,8	0,30641	30,641	39,192
184,7	77,877	9,2106	9,2106	1557,5	0,30702	30,702	39,211
185,1	78,58	9,2364	9,2364	1571,6	0,30788	30,788	39,236
185,4	77,576	9,247	9,247	1551,5	0,30823	30,823	39,247
185,8	78,424	9,2756	9,2756	1568,5	0,30919	30,919	39,276
186,2	77,747	9,2894	9,2894	1554,9	0,30965	30,965	39,289
186,6	77,876	9,3105	9,3105	1557,5	0,31035	31,035	39,311
187	78,149	9,3331	9,3331	1563	0,3111	31,11	39,333
187,4	77,292	9,3454	9,3454	1545,8	0,31151	31,151	39,345
187,8	78,917	9,3784	9,3784	1578,3	0,31261	31,261	39,378
188,2	77,403	9,3877	9,3877	1548,1	0,31292	31,292	39,388
188,6	77,969	9,4105	9,4105	1559,4	0,31368	31,368	39,41
189	77,845	9,4301	9,4301	1556,9	0,31434	31,434	39,43
189,4	77,934	9,4495	9,4495	1558,7	0,31498	31,498	39,449
189,8	78,43	9,4744	9,4744	1568,6	0,31581	31,581	39,474
190,2	77,574	9,486	9,486	1551,5	0,3162	31,62	39,486
190,6	78,629	9,5133	9,5133	1572,6	0,31711	31,711	39,513
191	77,944	9,5271	9,5271	1558,9	0,31757	31,757	39,527
191,4	78,017	9,5492	9,5492	1560,3	0,31831	31,831	39,549
191,8	77,94	9,5687	9,5687	1558,8	0,31896	31,896	39,569
192,2	77,666	9,586	9,586	1553,3	0,31953	31,953	39,586
192,6	78,599	9,6129	9,6129	1572	0,32043	32,043	39,613
193	77,683	9,6263	9,6263	1553,7	0,32088	32,088	39,626
193,4	78,2	9,6473	9,6473	1564	0,32158	32,158	39,647
193,8	77,73	9,6668	9,6668	1554,6	0,32223	32,223	39,667
194,2	77,778	9,6861	9,6861	1555,6	0,32287	32,287	39,686
194,6	78,374	9,7118	9,7118	1567,5	0,32373	32,373	39,712
195	77,482	9,723	9,723	1549,6	0,3241	32,41	39,723
195,4	78,42	9,7506	9,7506	1568,4	0,32502	32,502	39,751
195,8	77,903	9,7665	9,7665	1558,1	0,32555	32,555	39,767
196,1	77,805	9,7865	9,7865	1556,1	0,32622	32,622	39,786
196,5	78,184	9,8094	9,8094	1563,7	0,32698	32,698	39,809
196,9	77,273	9,8212	9,8212	1545,5	0,32737	32,737	39,821
197,3	79,019	9,8542	9,8542	1580,4	0,32847	32,847	39,854
197,7	77,665	9,8636	9,8636	1553,3	0,32879	32,879	39,864
198,1	77,94	9,8849	9,8849	1558,8	0,3295	32,95	39,885
198,5	78,046	9,9047	9,9047	1560,9	0,33016	33,016	39,905
198,9	77,693	9,9224	9,9224	1553,9	0,33075	33,075	39,922
199,3	78,497	9,9505	9,9505	1569,9	0,33168	33,168	39,95
199,7	77,441	9,9606	9,9606	1548,8	0,33202	33,202	39,961
200,1	78,122	9,9874	9,9874	1562,4	0,33291	33,291	39,987
200,5	77,682	10,003	10,003	1553,6	0,33342	33,342	40,003
200,9	77,85	10,022	10,022	1557	0,33407	33,407	40,022
201,3	78,211	10,047	10,047	1564,2	0,33491	33,491	40,047
201,7	77,447	10,06	10,06	1548,9	0,33532	33,532	40,06
202,1	79,003	10,092	10,092	1580,1	0,33641	33,641	40,092
202,5	77,384	10,099	10,099	1547,7	0,33665	33,665	40,099
202,9	77,974	10,125	10,125	1559,5	0,33751	33,751	40,125
203,3	77,753	10,143	10,143	1555,1	0,33811	33,811	40,143
203,7	77,602	10,162	10,162	1552	0,33873	33,873	40,162
204,1	78,312	10,187	10,187	1566,2	0,33957	33,957	40,187
204,5	77,232	10,199	10,199	1544,6	0,33997	33,997	40,199
204,9	78,228	10,226	10,226	1564,6	0,34087	34,087	40,226
205,3	77,844	10,243	10,243	1556,9	0,34144	34,144	40,243
205,7	77,771	10,262	10,262	1555,4	0,34205	34,205	40,262
206,1	78,116	10,285	10,285	1562,3	0,34282	34,282	40,285
206,5	77,486	10,298	10,298	1549,7	0,34326	34,326	40,298
206,8	78,412	10,326	10,326	1568,2	0,34419	34,419	40,326
207,2	77,781	10,341	10,341	1555,6	0,34469	34,469	40,341
207,6	78,174	10,36	10,36	1563,5	0,34534	34,534	40,36
208	77,942	10,38	10,38	1558,8	0,34601	34,601	40,38
208,4	77,665	10,397	10,397	1553,3	0,34658	34,658	40,397
208,8	78,699	10,427	10,427	1574	0,34757	34,757	40,427
209,2	77,742	10,438	10,438	1554,8	0,34795	34,795	40,438
209,6	78,063	10,463	10,463	1561,3	0,34878	34,878	40,463
210	77,801	10,479	10,479	1556	0,3493	34,93	40,479
210,4	78,166	10,498	10,498	1563,3	0,34995	34,995	40,498
210,8	78,506	10,524	10,524	1570,1	0,35079	35,079	40,524
211,2	77,525	10,534	10,534	1550,5	0,35114	35,114	40,534
211,6	78,622	10,562	10,562	1572,4	0,35208	35,208	40,562
212	77,651	10,575	10,575	1553	0,3525	35,25	40,575
212,4	78,285	10,598	10,598	1565,7	0,35326	35,326	40,598
212,8	78,116	10,618	10,618	1562,3	0,35393	35,393	40,618
213,2	77,771	10,635	10,635	1555,4	0,35451	35,451	40,635
213,6	78,64	10,663	10,663	1572,8	0,35543	35,543	40,663
214	77,407	10,674	10,674	1548,1	0,3558	35,58	40,674
214,4	78,539	10,701	10,701	1570,8	0,35671	35,671	40,701
214,8	78,024	10,718	10,718	1560,5	0,35727	35,727	40,718
215,2	78,079	10,737	10,737	1561,6	0,35789	35,789	40,737
215,6	78,173	10,758	10,758	1563,5	0,35859	35,859	40,758
216	77,667	10,773	10,773	1553,3	0,35911	35,911	40,773
216,4	78,602	10,805	10,805	1572	0,36016	36,016	40,805
216,8	77,748	10,815	10,815	1555	0,3605	36,05	40,815
217,1	78,26	10,838	10,838	1565,2	0,36127	36,127	40,838
217,5	78,116	10,858	10,858	1562,3	0,36193	36,193	40,858
217,9	77,71	10,873	10,873	1554,2	0,36244	36,244	40,873
218,3	78,646	10,902	10,902	1572,9	0,3634	36,34	40,902
218,7	77,658	10,913	10,913	1553,2	0,36378	36,378	40,913
219,1	77,983	10,935	10,935	1559,7	0,36452	36,452	40,935
219,5	77,616	10,954	10,954	1552,3	0,36513	36,513	40,954
219,9	77,878	10,974	10,974	1557,6	0,36581	36,581	40,974
220,3	78,401	10,999	10,999	1568	0,36665	36,665	40,999
220,7	77,534	11,011	11,011	1550,7	0,36702	36,702	41,011
221,1	78,532	11,039	11,039	1570,6	0,36797	36,797	41,039
221,5	77,882	11,053	11,053	1557,6	0,36844	36,844	41,053
221,9	78,18	11,073	11,073	1563,6	0,36911	36,911	41,073
222,3	77,821	11,094	11,094	1556,4	0,36979	36,979	41,094
222,7	77,618	11,111	11,111	1552,4	0,37037	37,037	41,111
223,1	78,58	11,14	11,14	1571,6	0,37135	37,135	41,14
223,5	77,609	11,15	11,15	1552,2	0,37167	37,167	41,15
223,9	78,245	11,175	11,175	1564,9	0,3725	37,25	41,175
224,3	77,542	11,191	11,191	1550,8	0,37302	37,302	41,191
224,7	77,698	11,212	11,212	1554	0,37372	37,372	41,212
225,1	78,213	11,235	11,235	1564,3	0,37451	37,451	41,235
225,5	77,471	11,247	11,247	1549,4	0,37491	37,491	41,247
225,9	78,859	11,278	11,278	1577,2	0,37593	37,593	41,278
226,3	77,885	11,291	11,291	1557,7	0,37636	37,636	41,291
226,7	77,924	11,312	11,312	1558,5	0,37708	37,708	41,312
227,1	78,049	11,334	11,334	1561	0,3778	37,78	41,334
227,5	77,609	11,348	11,348	1552,2	0,37828	37,828	41,348
227,8	78,415	11,377	11,377	1568,3	0,37924	37,924	41,377
228,2	77,427	11,388	11,388	1548,5	0,37959	37,959	41,388
228,6	77,965	11,411	11,411	1559,3	0,38037	38,037	41,411
229	77,581	11,43	11,43	1551,6	0,38101	38,101	41,43
229,4	77,708	11,45	11,45	1554,2	0,38166	38,166	41,45
229,8	78,027	11,474	11,474	1560,5	0,38246	38,246	41,474
230,2	77,351	11,485	11,485	1547	0,38283	38,283	41,485
230,6	78,189	11,515	11,515	1563,8	0,38383	38,383	41,515
231	77,604	11,529	11,529	1552,1	0,38431	38,431	41,529
231,4	78,044	11,549	11,549	1560,9	0,38495	38,495	41,549
231,8	78,055	11,571	11,571	1561,1	0,38569	38,569	41,571
232,2	77,595	11,587	11,587	1551,9	0,38623	38,623	41,587
232,6	78,491	11,613	11,613	1569,8	0,3871	38,71	41,613
233	77,618	11,626	11,626	1552,4	0,38752	38,752	41,626
233,4	78,277	11,651	11,651	1565,5	0,38838	38,838	41,651
233,8	77,741	11,667	11,667	1554,8	0,38891	38,891	41,667
234,2	77,66	11,687	11,687	1553,2	0,38957	38,957	41,687
234,6	78,182	11,712	11,712	1563,6	0,3904	39,04	41,712
235	77,326	11,723	11,723	1546,5	0,39078	39,078	41,723
235,4	78,677	11,754	11,754	1573,5	0,39179	39,179	41,754
235,8	77,613	11,765	11,765	1552,3	0,39217	39,217	41,765
236,2	78,078	11,788	11,788	1561,6	0,39295	39,295	41,788
236,6	77,781	11,808	11,808	1555,6	0,3936	39,36	41,808
237	77,37	11,823	11,823	1547,4	0,3941	39,41	41,823
237,4	78,379	11,853	11,853	1567,6	0,39511	39,511	41,853
237,8	77,477	11,864	11,864	1549,5	0,39547	39,547	41,864
238,2	77,699	11,889	11,889	1554	0,39632	39,632	41,889
238,5	77,453	11,906	11,906	1549,1	0,39688	39,688	41,906
238,9	77,291	11,923	11,923	1545,8	0,39744	39,744	41,923
239,3	77,832	11,949	11,949	1556,6	0,39829	39,829	41,949
239,7	77,003	11,961	11,961	1540,1	0,39871	39,871	41,961
240,1	77,874	11,989	11,989	1557,5	0,39963	39,963	41,989
240,5	77,416	12,003	12,003	1548,3	0,40012	40,012	42,003
240,9	77,475	12,025	12,025	1549,5	0,40084	40,084	42,025
241,3	77,803	12,048	12,048	1556,1	0,40159	40,159	42,048
241,7	77,136	12,06	12,06	1542,7	0,40201	40,201	42,06
242,1	78,289	12,09	12,09	1565,8	0,403	40,3	42,09
242,5	77,412	12,103	12,103	1548,2	0,40344	40,344	42,103
242,9	77,722	12,124	12,124	1554,4	0,40414	40,414	42,124
243,3	77,483	12,144	12,144	1549,7	0,4048	40,48	42,144
243,7	77,48	12,161	12,161	1549,6	0,40538	40,538	42,161
244,1	77,853	12,187	12,187	1557,1	0,40624	40,624	42,187
244,5	76,977	12,198	12,198	1539,5	0,40661	40,661	42,198
244,9	78,125	12,228	12,228	1562,5	0,4076	40,76	42,228
245,3	77,316	12,242	12,242	1546,3	0,40807	40,807	42,242
245,7	77,487	12,262	12,262	1549,7	0,40875	40,875	42,262
246,1	77,773	12,286	12,286	1555,5	0,40952	40,952	42,286
246,5	77,453	12,301	12,301	1549,1	0,41004	41,004	42,301
246,9	78,404	12,33	12,33	1568,1	0,41101	41,101	42,33
247,3	77,204	12,339	12,339	1544,1	0,4113	41,13	42,339
247,7	77,743	12,363	12,363	1554,9	0,4121	41,21	42,363
248,1	77,228	12,379	12,379	1544,6	0,41264	41,264	42,379
248,5	77,212	12,398	12,398	1544,2	0,41328	41,328	42,398
248,8	78,03	12,427	12,427	1560,6	0,41423	41,423	42,427
249,2	77,041	12,437	12,437	1540,8	0,41458	41,458	42,437
249,6	78,051	12,466	12,466	1561	0,41555	41,555	42,466
250	77,279	12,48	12,48	1545,6	0,416	41,6	42,48
250,4	77,734	12,502	12,502	1554,7	0,41673	41,673	42,502
250,8	77,741	12,523	12,523	1554,8	0,41744	41,744	42,523
251,2	77,223	12,537	12,537	1544,5	0,41791	41,791	42,537
251,6	77,996	12,566	12,566	1559,9	0,41886	41,886	42,566
252	76,956	12,576	12,576	1539,1	0,41921	41,921	42,576
252,4	77,313	12,599	12,599	1546,3	0,41996	41,996	42,599
252,8	77,386	12,621	12,621	1547,7	0,4207	42,07	42,621
253,2	77,113	12,637	12,637	1542,3	0,42124	42,124	42,637
253,6	77,8	12,664	12,664	1556	0,42212	42,212	42,664
254	77,057	12,674	12,674	1541,1	0,42245	42,245	42,674
254,4	77,687	12,7	12,7	1553,7	0,42333	42,333	42,7
254,8	77,172	12,719	12,719	1543,4	0,42396	42,396	42,719
255,2	77,385	12,737	12,737	1547,7	0,42455	42,455	42,737
255,6	77,843	12,762	12,762	1556,9	0,42542	42,542	42,762
256	77,054	12,774	12,774	1541,1	0,42579	42,579	42,774
256,4	78,305	12,806	12,806	1566,1	0,42686	42,686	42,806
256,8	77,166	12,814	12,814	1543,3	0,42715	42,715	42,814
257,2	77,525	12,84	12,84	1550,5	0,42799	42,799	42,84
257,6	77,393	12,858	12,858	1547,9	0,42861	42,861	42,858
258	77,345	12,876	12,876	1546,9	0,42919	42,919	42,876
258,4	78,063	12,904	12,904	1561,3	0,43012	43,012	42,904
258,8	77,011	12,913	12,913	1540,2	0,43043	43,043	42,913
259,2	77,792	12,94	12,94	1555,8	0,43133	43,133	42,94
259,5	77,203	12,955	12,955	1544,1	0,43182	43,182	42,955
259,9	77,415	12,974	12,974	1548,3	0,43247	43,247	42,974
260,3	77,579	12,997	12,997	1551,6	0,43323	43,323	42,997
260,7	77,295	13,013	13,013	1545,9	0,43377	43,377	43,013
261,1	78,183	13,043	13,043	1563,7	0,43476	43,476	43,043
261,5	77,297	13,052	13,052	1545,9	0,43508	43,508	43,052
261,9	77,442	13,077	13,077	1548,8	0,43589	43,589	43,077
262,3	77,447	13,096	13,096	1548,9	0,43652	43,652	43,096
262,7	77,185	13,113	13,113	1543,7	0,43711	43,711	43,113
263,1	77,767	13,138	13,138	1555,3	0,43794	43,794	43,138
263,5	76,862	13,151	13,151	1537,2	0,43836	43,836	43,151
263,9	77,604	13,175	13,175	1552,1	0,43918	43,918	43,175
264,3	77,231	13,194	13,194	1544,6	0,43979	43,979	43,194
264,7	77,252	13,216	13,216	1545	0,44052	44,052	43,216
265,1	77,79	13,237	13,237	1555,8	0,44125	44,125	43,237
265,5	76,996	13,249	13,249	1539,9	0,44164	44,164	43,249
265,9	78,331	13,282	13,282	1566,6	0,44272	44,272	43,282
266,3	77,229	13,291	13,291	1544,6	0,44302	44,302	43,291
266,7	77,599	13,313	13,313	1552	0,44377	44,377	43,313
267,1	77,723	13,335	13,335	1554,5	0,44451	44,451	43,335
267,5	77,269	13,35	13,35	1545,4	0,44499	44,499	43,35
267,9	78,148	13,379	13,379	1563	0,44595	44,595	43,379
268,3	77,159	13,389	13,389	1543,2	0,44629	44,629	43,389
268,7	77,871	13,415	13,415	1557,4	0,44715	44,715	43,415
269,1	77,336	13,431	13,431	1546,7	0,44769	44,769	43,431
269,5	77,567	13,451	13,451	1551,3	0,44838	44,838	43,451
269,9	77,961	13,476	13,476	1559,2	0,4492	44,92	43,476
270,2	77,25	13,487	13,487	1545	0,44958	44,958	43,487
270,6	78,71	13,522	13,522	1574,2	0,45075	45,075	43,522
271	77,048	13,527	13,527	1541	0,4509	45,09	43,527
271,4	77,53	13,551	13,551	1550,6	0,45169	45,169	43,551
271,8	77,386	13,569	13,569	1547,7	0,45228	45,228	43,569
272,2	77,486	13,59	13,59	1549,7	0,45301	45,301	43,59
272,6	78,044	13,615	13,615	1560,9	0,45383	45,383	43,615
273	77,18	13,626	13,626	1543,6	0,4542	45,42	43,626
273,4	77,976	13,653	13,653	1559,5	0,45509	45,509	43,653
273,8	77,443	13,669	13,669	1548,9	0,45562	45,562	43,669
274,2	77,575	13,69	13,69	1551,5	0,45632	45,632	43,69
274,6	77,815	13,712	13,712	1556,3	0,45708	45,708	43,712
275	77,298	13,726	13,726	1546	0,45752	45,752	43,726
275,4	78,165	13,754	13,754	1563,3	0,45848	45,848	43,754
275,8	77,401	13,766	13,766	1548	0,45888	45,888	43,766
276,2	77,897	13,789	13,789	1557,9	0,45964	45,964	43,789
276,6	77,882	13,809	13,809	1557,6	0,46031	46,031	43,809
277	77,428	13,826	13,826	1548,6	0,46085	46,085	43,826
277,4	78,334	13,854	13,854	1566,7	0,4618	46,18	43,854
277,8	77,644	13,867	13,867	1552,9	0,46225	46,225	43,867
278,2	77,907	13,89	13,89	1558,1	0,46301	46,301	43,89
278,6	77,586	13,906	13,906	1551,7	0,46355	46,355	43,906
279	77,777	13,927	13,927	1555,5	0,46422	46,422	43,927
279,4	78,054	13,95	13,95	1561,1	0,465	46,5	43,95
279,8	77,564	13,962	13,962	1551,3	0,46542	46,542	43,962
280,2	78,157	13,991	13,991	1563,1	0,46636	46,636	43,991
280,6	77,749	14,005	14,005	1555	0,46683	46,683	44,005
280,9	77,789	14,026	14,026	1555,8	0,46753	46,753	44,026
281,3	77,898	14,048	14,048	1558	0,46827	46,827	44,048
281,7	77,551	14,064	14,064	1551	0,4688	46,88	44,064
282,1	78,466	14,093	14,093	1569,3	0,46976	46,976	44,093
282,5	77,358	14,102	14,102	1547,2	0,47008	47,008	44,102
282,9	77,986	14,127	14,127	1559,7	0,47089	47,089	44,127
283,3	77,545	14,144	14,144	1550,9	0,47148	47,148	44,144
283,7	77,722	14,164	14,164	1554,4	0,47214	47,214	44,164
284,1	77,845	14,187	14,187	1556,9	0,47291	47,291	44,187
284,5	77,191	14,201	14,201	1543,8	0,47338	47,338	44,201
284,9	78,101	14,229	14,229	1562	0,4743	47,43	44,229
285,3	77,491	14,242	14,242	1549,8	0,47472	47,472	44,242
285,7	77,754	14,263	14,263	1555,1	0,47542	47,542	44,263
286,1	77,663	14,285	14,285	1553,3	0,47615	47,615	44,285
286,5	77,684	14,302	14,302	1553,7	0,47673	47,673	44,302
286,9	78,269	14,33	14,33	1565,4	0,47765	47,765	44,33
287,3	77,475	14,342	14,342	1549,5	0,47805	47,805	44,342
287,7	77,728	14,364	14,364	1554,6	0,47879	47,879	44,364
288,1	77,468	14,381	14,381	1549,4	0,47937	47,937	44,381
288,5	77,578	14,4	14,4	1551,6	0,47999	47,999	44,4
288,9	78,268	14,427	14,427	1565,4	0,48092	48,092	44,427
289,3	77,592	14,439	14,439	1551,8	0,48129	48,129	44,439
289,7	78,097	14,466	14,466	1561,9	0,4822	48,22	44,466
290,1	77,503	14,479	14,479	1550,1	0,48264	48,264	44,479
290,5	77,852	14,502	14,502	1557	0,4834	48,34	44,502
290,9	77,916	14,523	14,523	1558,3	0,4841	48,41	44,523
291,2	77,441	14,538	14,538	1548,8	0,4846	48,46	44,538
291,6	78,048	14,565	14,565	1561	0,48549	48,549	44,565
292	77,534	14,577	14,577	1550,7	0,4859	48,59	44,577
292,4	78,213	14,603	14,603	1564,3	0,48677	48,677	44,603
292,8	77,773	14,62	14,62	1555,5	0,48732	48,732	44,62
293,2	77,896	14,64	14,64	1557,9	0,48801	48,801	44,64
293,6	78,121	14,663	14,663	1562,4	0,48876	48,876	44,663
294	77,441	14,677	14,677	1548,8	0,48922	48,922	44,677
294,4	78,653	14,707	14,707	1573,1	0,49025	49,025	44,707
294,8	77,709	14,719	14,719	1554,2	0,49062	49,062	44,719
295,2	77,819	14,739	14,739	1556,4	0,4913	49,13	44,739
295,6	77,735	14,76	14,76	1554,7	0,492	49,2	44,76
296	77,526	14,776	14,776	1550,5	0,49254	49,254	44,776
296,4	78,306	14,803	14,803	1566,1	0,49343	49,343	44,803
296,8	77,585	14,818	14,818	1551,7	0,49393	49,393	44,818
297,2	78,106	14,839	14,839	1562,1	0,49464	49,464	44,839
297,6	78,036	14,859	14,859	1560,7	0,4953	49,53	44,859
298	77,727	14,876	14,876	1554,5	0,49588	49,588	44,876
298,4	78,141	14,901	14,901	1562,8	0,49671	49,671	44,901
298,8	77,568	14,915	14,915	1551,4	0,49717	49,717	44,915
299,2	78,28	14,94	14,94	1565,6	0,49801	49,801	44,94
299,6	77,974	14,957	14,957	1559,5	0,49855	49,855	44,957
300	77,804	14,977	14,977	1556,1	0,49922	49,922	44,977
300,4	78,04	14,999	14,999	1560,8	0,49998	49,998	44,999
300,8	77,615	15,014	15,014	1552,3	0,50045	50,045	45,014
301,2	78,349	15,041	15,041	1567	0,50136	50,136	45,041
301,6	77,899	15,053	15,053	1558	0,50176	50,176	45,053
301,9	78,234	15,076	15,076	1564,7	0,50254	50,254	45,076
302,3	78,138	15,097	15,097	1562,8	0,50325	50,325	45,097
302,7	77,869	15,114	15,114	1557,4	0,50379	50,379	45,114
303,1	78,382	15,139	15,139	1567,6	0,50465	50,465	45,139
303,5	77,709	15,152	15,152	1554,2	0,50505	50,505	45,152
303,9	78,694	15,181	15,181	1573,9	0,50604	50,604	45,181
304,3	77,913	15,193	15,193	1558,3	0,50642	50,642	45,193
304,7	78,145	15,215	15,215	1562,9	0,50715	50,715	45,215
305,1	78,28	15,236	15,236	1565,6	0,50787	50,787	45,236
305,5	77,946	15,251	15,251	1558,9	0,50838	50,838	45,251
305,9	78,98	15,282	15,282	1579,6	0,50939	50,939	45,282
306,3	78,143	15,292	15,292	1562,9	0,50974	50,974	45,292
306,7	78,514	15,316	15,316	1570,3	0,51054	51,054	45,316
307,1	78,229	15,331	15,331	1564,6	0,51105	51,105	45,331
307,5	78,222	15,352	15,352	1564,4	0,51174	51,174	45,352
307,9	78,334	15,374	15,374	1566,7	0,51248	51,248	45,374
308,3	77,894	15,391	15,391	1557,9	0,51305	51,305	45,391
308,7	78,727	15,417	15,417	1574,5	0,51389	51,389	45,417
309,1	78,002	15,431	15,431	1560	0,51436	51,436	45,431
309,5	78,157	15,451	15,451	1563,1	0,51503	51,503	45,451
309,9	78,434	15,475	15,475	1568,7	0,51582	51,582	45,475
310,3	77,829	15,487	15,487	1556,6	0,51623	51,623	45,487
310,7	79,075	15,52	15,52	1581,5	0,51734	51,734	45,52
311,1	78,209	15,531	15,531	1564,2	0,51769	51,769	45,531
311,5	78,554	15,553	15,553	1571,1	0,51842	51,842	45,553
311,9	78,412	15,572	15,572	1568,2	0,51907	51,907	45,572
312,3	78,382	15,589	15,589	1567,6	0,51963	51,963	45,589
312,6	78,842	15,615	15,615	1576,8	0,52049	52,049	45,615
313	78,131	15,628	15,628	1562,6	0,52092	52,092	45,628
313,4	79,062	15,656	15,656	1581,2	0,52186	52,186	45,656
313,8	78,647	15,671	15,671	1572,9	0,52238	52,238	45,671
314,2	78,592	15,689	15,689	1571,8	0,52298	52,298	45,689
314,6	78,906	15,712	15,712	1578,1	0,52374	52,374	45,712
315	78,47	15,726	15,726	1569,4	0,52422	52,422	45,726
315,4	79,254	15,756	15,756	1585,1	0,52521	52,521	45,756
315,8	78,548	15,768	15,768	1571	0,5256	52,56	45,768
316,2	78,847	15,79	15,79	1576,9	0,52634	52,634	45,79
316,6	78,541	15,809	15,809	1570,8	0,52695	52,695	45,809
317	78,429	15,826	15,826	1568,6	0,52753	52,753	45,826
317,4	79,09	15,853	15,853	1581,8	0,52843	52,843	45,853
317,8	78,512	15,867	15,867	1570,2	0,5289	52,89	45,867
318,2	79,062	15,89	15,89	1581,2	0,52966	52,966	45,89
318,6	78,579	15,909	15,909	1571,6	0,53029	53,029	45,909
319	78,611	15,927	15,927	1572,2	0,53091	53,091	45,927
319,4	78,773	15,95	15,95	1575,5	0,53167	53,167	45,95
319,8	78,543	15,964	15,964	1570,9	0,53215	53,215	45,964
320,2	79,349	15,995	15,995	1587	0,53318	53,318	45,995
320,6	78,454	16,005	16,005	1569,1	0,5335	53,35	46,005
321	78,923	16,029	16,029	1578,5	0,53429	53,429	46,029
321,4	78,696	16,047	16,047	1573,9	0,53489	53,489	46,047
321,8	78,706	16,065	16,065	1574,1	0,5355	53,55	46,065
322,2	79,558	16,095	16,095	1591,2	0,5365	53,65	46,095
322,6	78,541	16,103	16,103	1570,8	0,53677	53,677	46,103
322,9	79,065	16,128	16,128	1581,3	0,53759	53,759	46,128
323,3	78,75	16,145	16,145	1575	0,53817	53,817	46,145
323,7	78,922	16,166	16,166	1578,4	0,53887	53,887	46,166
324,1	79,113	16,189	16,189	1582,3	0,53962	53,962	46,189
324,5	78,423	16,2	16,2	1568,5	0,54	54	46,2
324,9	79,688	16,234	16,234	1593,8	0,54114	54,114	46,234
325,3	78,812	16,244	16,244	1576,2	0,54146	54,146	46,244
325,7	79,126	16,267	16,267	1582,5	0,54222	54,222	46,267
326,1	79,137	16,286	16,286	1582,7	0,54288	54,288	46,286
326,5	78,993	16,304	16,304	1579,9	0,54345	54,345	46,304
326,9	79,71	16,332	16,332	1594,2	0,54438	54,438	46,332
327,3	78,726	16,342	16,342	1574,5	0,54472	54,472	46,342
327,7	79,383	16,367	16,367	1587,7	0,54558	54,558	46,367
328,1	79,031	16,383	16,383	1580,6	0,54611	54,611	46,383
328,5	79,09	16,402	16,402	1581,8	0,54675	54,675	46,402
328,9	79,207	16,425	16,425	1584,1	0,5475	54,75	46,425
329,3	78,886	16,44	16,44	1577,7	0,54802	54,802	46,44
329,7	79,744	16,471	16,471	1594,9	0,54902	54,902	46,471
330,1	79,053	16,483	16,483	1581,1	0,54943	54,943	46,483
330,5	79,094	16,505	16,505	1581,9	0,55016	55,016	46,505
330,9	78,976	16,522	16,522	1579,5	0,55072	55,072	46,522
331,3	78,914	16,541	16,541	1578,3	0,55137	55,137	46,541
331,7	79,482	16,567	16,567	1589,6	0,55225	55,225	46,567
332,1	78,61	16,577	16,577	1572,2	0,55256	55,256	46,577
332,5	79,169	16,602	16,602	1583,4	0,55341	55,341	46,602
332,9	79,244	16,624	16,624	1584,9	0,55414	55,414	46,624
333,3	78,974	16,642	16,642	1579,5	0,55472	55,472	46,642
333,6	79,31	16,665	16,665	1586,2	0,55548	55,548	46,665
334	78,916	16,679	16,679	1578,3	0,55598	55,598	46,679
334,4	79,617	16,708	16,708	1592,3	0,55692	55,692	46,708
334,8	78,977	16,719	16,719	1579,5	0,5573	55,73	46,719
335,2	79,084	16,741	16,741	1581,7	0,55805	55,805	46,741
335,6	79,152	16,763	16,763	1583	0,55876	55,876	46,763
336	78,77	16,777	16,777	1575,4	0,55924	55,924	46,777
336,4	79,857	16,808	16,808	1597,1	0,56028	56,028	46,808
336,8	78,737	16,815	16,815	1574,7	0,56051	56,051	46,815
337,2	79,37	16,841	16,841	1587,4	0,56137	56,137	46,841
337,6	79,023	16,859	16,859	1580,5	0,56196	56,196	46,859
338	79,075	16,878	16,878	1581,5	0,56261	56,261	46,878
338,4	79,41	16,903	16,903	1588,2	0,56344	56,344	46,903
338,8	78,672	16,915	16,915	1573,4	0,56382	56,382	46,915
339,2	79,868	16,95	16,95	1597,4	0,56499	56,499	46,95
339,6	78,657	16,955	16,955	1573,1	0,56517	56,517	46,955
340	79,032	16,978	16,978	1580,6	0,56592	56,592	46,978
340,4	78,873	16,997	16,997	1577,5	0,56658	56,658	46,997
340,8	78,786	17,015	17,015	1575,7	0,56716	56,716	47,015
341,2	79,521	17,045	17,045	1590,4	0,56817	56,817	47,045
341,6	-1,4346	17,056	17,056	-28,693	0,56853	56,853	47,056
341,6		17,057	17,057		0,56856	56,856	47,057