File: Tests de traction/Fichiers source/04_12_2016/9 (ou 8).txt
Time (s)	Load (N)	Machine Extension (mm)	Extension (mm)	Stress (MPa)	Strain	Percentage Strain	Gauge Length (mm)
0
0,06678	0,0050628			0,10126
0,1336	0,0053661	0,000014826	0,000014826	0,10732	4,9421E-07	0,000049421	30
0,2004	0,0056694	0,00003441	0,00003441	0,11339	0,000001147	0,0001147	30
0,2671	0,0059726	0,000053993	0,000053993	0,11945	1,7998E-06	0,00017998	30
0,3339	0,0062759	0,000073576	0,000073576	0,12552	2,4525E-06	0,00024525	30
0,4007	0,0065792	0,00009316	0,00009316	0,13158	3,1053E-06	0,00031053	30
0,4675	0,0068825	0,00011274	0,00011274	0,13765	3,7581E-06	0,00037581	30
0,5343	0,0071858	0,00013233	0,00013233	0,14372	4,4109E-06	0,00044109	30
0,6011	0,0074891	0,0005489	0,0005489	0,14978	0,000018297	0,0018297	30,001
0,6678	0,028967	0,0024051	0,0024051	0,57934	0,000080169	0,0080169	30,002
0,7346	0,37436	0,011725	0,011725	7,4873	0,00039084	0,039084	30,012
0,8014	0,61798	0,016406	0,016406	12,36	0,00054686	0,054686	30,016
0,8682	0,96191	0,021938	0,021938	19,238	0,00073127	0,073127	30,022
0,935	2,9052	0,03537	0,03537	58,104	0,001179	0,1179	30,035
1,002	3,1284	0,036718	0,036718	62,567	0,0012239	0,12239	30,037
1,069	3,1268	0,03681	0,03681	62,536	0,001227	0,1227	30,037
1,135	3,1253	0,036902	0,036902	62,506	0,0012301	0,12301	30,037
1,202	3,1238	0,037726	0,037726	62,475	0,0012575	0,12575	30,038
1,269	4,2933	0,042138	0,042138	85,866	0,0014046	0,14046	30,042
1,336	4,7981	0,043741	0,043741	95,961	0,001458	0,1458	30,044
1,402	5,3028	0,046323	0,046323	106,06	0,0015441	0,15441	30,046
1,469	5,9373	0,048932	0,048932	118,75	0,0016311	0,16311	30,049
1,536	6,8543	0,052464	0,052464	137,09	0,0017488	0,17488	30,052
1,603	8,7412	0,057935	0,057935	174,82	0,0019312	0,19312	30,058
1,67	10,098	0,061315	0,061315	201,97	0,0020438	0,20438	30,061
1,736	11,386	0,064695	0,064695	227,73	0,0021565	0,21565	30,065
1,803	12,742	0,070501	0,070501	254,85	0,00235	0,235	30,071
1,87	15,927	0,079498	0,079498	318,54	0,0026499	0,26499	30,079
1,937	17,24	0,082162	0,082162	344,79	0,0027387	0,27387	30,082
2,004	17,463	0,083003	0,083003	349,26	0,0027668	0,27668	30,083
2,07	17,687	0,083844	0,083844	353,73	0,0027948	0,27948	30,084
2,137	17,91	0,084685	0,084685	358,2	0,0028228	0,28228	30,085
2,204	18,53	0,088441	0,088441	370,59	0,002948	0,2948	30,088
2,271	19,532	0,092844	0,092844	390,64	0,0030948	0,30948	30,093
2,337	20,534	0,0953	0,0953	410,68	0,0031767	0,31767	30,095
2,404	21,702	0,097755	0,097755	434,03	0,0032585	0,32585	30,098
2,471	22,892	0,10024	0,10024	457,85	0,0033415	0,33415	30,1
2,538	24,083	0,10446	0,10446	481,66	0,0034819	0,34819	30,104
2,605	25,274	0,10867	0,10867	505,48	0,0036223	0,36223	30,109
2,671	26,465	0,11288	0,11288	529,3	0,0037627	0,37627	30,113
2,738	27,656	0,11709	0,11709	553,11	0,0039031	0,39031	30,117
2,805	30,732	0,12525	0,12525	614,63	0,0041751	0,41751	30,125
2,872	32,762	0,13188	0,13188	655,23	0,0043958	0,43958	30,132
2,939	32,775	0,1322	0,1322	655,49	0,0044066	0,44066	30,132
3,005	32,788	0,13252	0,13252	655,76	0,0044175	0,44175	30,133
3,072	32,801	0,13285	0,13285	656,02	0,0044283	0,44283	30,133
3,139	33,021	0,13482	0,13482	660,42	0,004494	0,4494	30,135
3,206	34,835	0,13944	0,13944	696,69	0,004648	0,4648	30,139
3,272	35,505	0,1418	0,1418	710,1	0,0047266	0,47266	30,142
3,339	36,175	0,14416	0,14416	723,5	0,0048052	0,48052	30,144
3,406	36,846	0,14652	0,14652	736,91	0,0048839	0,48839	30,147
3,473	37,875	0,15095	0,15095	757,51	0,0050316	0,50316	30,151
3,54	38,992	0,15542	0,15542	779,84	0,0051806	0,51806	30,155
3,606	40,108	0,15991	0,15991	802,17	0,0053302	0,53302	30,16
3,673	41,225	0,1644	0,1644	824,5	0,0054799	0,54799	30,164
3,74	42,618	0,16969	0,16969	852,37	0,0056563	0,56563	30,17
3,807	44,806	0,17729	0,17729	896,13	0,0059097	0,59097	30,177
3,873	45,057	0,17862	0,17862	901,14	0,005954	0,5954	30,179
3,94	45,221	0,17957	0,17957	904,43	0,0059856	0,59856	30,18
4,007	45,386	0,18051	0,18051	907,71	0,0060171	0,60171	30,181
4,074	45,56	0,18146	0,18146	911,19	0,0060486	0,60486	30,181
4,141	46,811	0,1848	0,1848	936,22	0,00616	0,616	30,185
4,207	47,514	0,18819	0,18819	950,28	0,0062731	0,62731	30,188
4,274	48,183	0,19164	0,19164	963,66	0,0063878	0,63878	30,192
4,341	48,852	0,19509	0,19509	977,05	0,0065031	0,65031	30,195
4,408	49,521	0,19855	0,19855	990,43	0,0066184	0,66184	30,199
4,475	50,41	0,20201	0,20201	1008,2	0,0067337	0,67337	30,202
4,541	51,438	0,20547	0,20547	1028,8	0,006849	0,6849	30,205
4,608	52,466	0,20893	0,20893	1049,3	0,0069643	0,69643	30,209
4,675	53,493	0,21556	0,21556	1069,9	0,0071855	0,71855	30,216
4,742	56,125	0,2253	0,2253	1122,5	0,0075099	0,75099	30,225
4,808	56,552	0,22828	0,22828	1131	0,0076093	0,76093	30,228
4,875	56,475	0,22869	0,22869	1129,5	0,0076229	0,76229	30,229
4,942	56,398	0,2291	0,2291	1128	0,0076366	0,76366	30,229
5,009	56,321	0,22951	0,22951	1126,4	0,0076502	0,76502	30,23
5,076	57,009	0,23317	0,23317	1140,2	0,0077725	0,77725	30,233
5,142	58,001	0,23538	0,23538	1160	0,0078461	0,78461	30,235
5,209	58,522	0,23769	0,23769	1170,4	0,007923	0,7923	30,238
5,276	59,043	0,24034	0,24034	1180,9	0,0080113	0,80113	30,24
5,343	59,564	0,24299	0,24299	1191,3	0,0080997	0,80997	30,243
5,41	60,373	0,24676	0,24676	1207,5	0,0082253	0,82253	30,247
5,476	61,219	0,25053	0,25053	1224,4	0,008351	0,8351	30,251
5,543	62,066	0,2543	0,2543	1241,3	0,0084766	0,84766	30,254
5,61	62,913	0,25807	0,25807	1258,3	0,0086022	0,86022	30,258
5,677	64,462	0,26688	0,26688	1289,2	0,0088959	0,88959	30,267
5,743	65,917	0,27407	0,27407	1318,3	0,0091355	0,91355	30,274
5,81	65,821	0,27442	0,27442	1316,4	0,0091472	0,91472	30,274
5,877	65,725	0,27477	0,27477	1314,5	0,009159	0,9159	30,275
5,944	65,629	0,27515	0,27515	1312,6	0,0091717	0,91717	30,275
6,011	66,607	0,28022	0,28022	1332,1	0,0093405	0,93405	30,28
6,077	67,206	0,28237	0,28237	1344,1	0,0094123	0,94123	30,282
6,144	67,514	0,28396	0,28396	1350,3	0,0094652	0,94652	30,284
6,211	68,185	0,28718	0,28718	1363,7	0,0095727	0,95727	30,287
6,278	68,989	0,29057	0,29057	1379,8	0,0096857	0,96857	30,291
6,345	69,741	0,29449	0,29449	1394,8	0,0098163	0,98163	30,294
6,411	70,307	0,29841	0,29841	1406,1	0,0099471	0,99471	30,298
6,478	70,873	0,30235	0,30235	1417,5	0,010078	1,0078	30,302
6,545	71,772	0,3063	0,3063	1435,4	0,01021	1,021	30,306
6,612	73,075	0,31416	0,31416	1461,5	0,010472	1,0472	30,314
6,678	74,318	0,32119	0,32119	1486,4	0,010706	1,0706	30,321
6,745	74,282	0,32201	0,32201	1485,6	0,010734	1,0734	30,322
6,812	74,246	0,32284	0,32284	1484,9	0,010761	1,0761	30,323
6,879	74,242	0,32366	0,32366	1484,8	0,010789	1,0789	30,324
6,946	74,988	0,3269	0,3269	1499,8	0,010897	1,0897	30,327
7,012	75,672	0,3303	0,3303	1513,4	0,01101	1,101	30,33
7,079	76,201	0,33302	0,33302	1524	0,011101	1,1101	30,333
7,146	76,729	0,33573	0,33573	1534,6	0,011191	1,1191	30,336
7,213	77,258	0,33844	0,33844	1545,2	0,011281	1,1281	30,338
7,28	77,786	0,34149	0,34149	1555,7	0,011383	1,1383	30,341
7,346	78,494	0,3455	0,3455	1569,9	0,011517	1,1517	30,346
7,413	79,221	0,34952	0,34952	1584,4	0,011651	1,1651	30,35
7,48	79,948	0,35354	0,35354	1599	0,011785	1,1785	30,354
7,547	80,676	0,35755	0,35755	1613,5	0,011918	1,1918	30,358
7,613	81,993	0,36674	0,36674	1639,9	0,012225	1,2225	30,367
7,68	82,639	0,37129	0,37129	1652,8	0,012376	1,2376	30,371
7,747	82,482	0,37159	0,37159	1649,6	0,012386	1,2386	30,372
7,814	82,326	0,3719	0,3719	1646,5	0,012397	1,2397	30,372
7,881	82,17	0,3722	0,3722	1643,4	0,012407	1,2407	30,372
7,947	82,66	0,37612	0,37612	1653,2	0,012537	1,2537	30,376
8,014	83,826	0,38089	0,38089	1676,5	0,012696	1,2696	30,381
8,081	84,292	0,38306	0,38306	1685,8	0,012769	1,2769	30,383
8,148	84,758	0,38523	0,38523	1695,2	0,012841	1,2841	30,385
8,214	85,224	0,3874	0,3874	1704,5	0,012913	1,2913	30,387
8,281	85,691	0,39168	0,39168	1713,8	0,013056	1,3056	30,392
8,348	86,157	0,396	0,396	1723,1	0,0132	1,32	30,396
8,415	86,834	0,40033	0,40033	1736,7	0,013344	1,3344	30,4
8,482	87,726	0,40465	0,40465	1754,5	0,013488	1,3488	30,405
8,548	88,664	0,41206	0,41206	1773,3	0,013735	1,3735	30,412
8,615	89,482	0,41851	0,41851	1789,6	0,01395	1,395	30,419
8,682	89,378	0,41914	0,41914	1787,6	0,013971	1,3971	30,419
8,749	89,275	0,41977	0,41977	1785,5	0,013992	1,3992	30,42
8,816	89,171	0,42041	0,42041	1783,4	0,014014	1,4014	30,42
8,882	89,365	0,42247	0,42247	1787,3	0,014082	1,4082	30,422
8,949	89,789	0,4252	0,4252	1795,8	0,014173	1,4173	30,425
9,016	90,213	0,42793	0,42793	1804,3	0,014264	1,4264	30,428
9,083	90,637	0,43163	0,43163	1812,7	0,014388	1,4388	30,432
9,149	91,061	0,43564	0,43564	1821,2	0,014521	1,4521	30,436
9,216	91,484	0,43965	0,43965	1829,7	0,014655	1,4655	30,44
9,283	91,908	0,44367	0,44367	1838,2	0,014789	1,4789	30,444
9,35	92,332	0,44768	0,44768	1846,6	0,014923	1,4923	30,448
9,417	93,406	0,45169	0,45169	1868,1	0,015056	1,5056	30,452
9,483	94,517	0,45906	0,45906	1890,3	0,015302	1,5302	30,459
9,55	95,283	0,46376	0,46376	1905,7	0,015459	1,5459	30,464
9,617	95,288	0,46492	0,46492	1905,8	0,015497	1,5497	30,465
9,684	95,294	0,46608	0,46608	1905,9	0,015536	1,5536	30,466
9,751	95,3	0,46724	0,46724	1906	0,015575	1,5575	30,467
9,817	95,537	0,4692	0,4692	1910,7	0,01564	1,564	30,469
9,884	95,791	0,47155	0,47155	1915,8	0,015718	1,5718	30,472
9,951	96,045	0,4739	0,4739	1920,9	0,015797	1,5797	30,474
10,02	96,299	0,47625	0,47625	1926	0,015875	1,5875	30,476
10,08	96,552	0,4786	0,4786	1931	0,015953	1,5953	30,479
10,15	97,482	0,4841	0,4841	1949,6	0,016137	1,6137	30,484
10,22	98,265	0,48946	0,48946	1965,3	0,016315	1,6315	30,489
10,28	98,913	0,49414	0,49414	1978,3	0,016471	1,6471	30,494
10,35	99,56	0,49881	0,49881	1991,2	0,016627	1,6627	30,499
10,42	100,21	0,50349	0,50349	2004,1	0,016783	1,6783	30,503
10,49	101,07	0,51171	0,51171	2021,4	0,017057	1,7057	30,512
10,55	101,07	0,51335	0,51335	2021,3	0,017112	1,7112	30,513
10,62	100,91	0,51419	0,51419	2018,2	0,01714	1,714	30,514
10,69	100,75	0,51502	0,51502	2015	0,017167	1,7167	30,515
10,75	100,76	0,51627	0,51627	2015,2	0,017209	1,7209	30,516
10,82	101,06	0,51857	0,51857	2021,2	0,017286	1,7286	30,519
10,89	101,36	0,52088	0,52088	2027,3	0,017363	1,7363	30,521
10,95	101,66	0,52318	0,52318	2033,3	0,017439	1,7439	30,523
11,02	101,97	0,52548	0,52548	2039,3	0,017516	1,7516	30,525
11,09	102,76	0,53065	0,53065	2055,1	0,017688	1,7688	30,531
11,15	103,89	0,53695	0,53695	2077,8	0,017898	1,7898	30,537
11,22	104,39	0,54103	0,54103	2087,7	0,018034	1,8034	30,541
11,29	104,88	0,54512	0,54512	2097,6	0,018171	1,8171	30,545
11,35	105,39	0,54924	0,54924	2107,8	0,018308	1,8308	30,549
11,42	106,22	0,55669	0,55669	2124,4	0,018556	1,8556	30,557
11,49	106,29	0,56024	0,56024	2125,7	0,018675	1,8675	30,56
11,55	106,16	0,56184	0,56184	2123,1	0,018728	1,8728	30,562
11,62	106,03	0,56344	0,56344	2120,6	0,018781	1,8781	30,563
11,69	106,13	0,56503	0,56503	2122,6	0,018834	1,8834	30,565
11,75	106,4	0,56663	0,56663	2128,1	0,018888	1,8888	30,567
11,82	106,68	0,56862	0,56862	2133,5	0,018954	1,8954	30,569
11,89	106,95	0,57195	0,57195	2138,9	0,019065	1,9065	30,572
11,95	107,22	0,57528	0,57528	2144,4	0,019176	1,9176	30,575
12,02	107,78	0,57865	0,57865	2155,6	0,019288	1,9288	30,579
12,09	108,66	0,58223	0,58223	2173,2	0,019408	1,9408	30,582
12,15	109,01	0,58582	0,58582	2180,1	0,019527	1,9527	30,586
12,22	109,35	0,5894	0,5894	2187	0,019647	1,9647	30,589
12,29	110,21	0,5963	0,5963	2204,2	0,019877	1,9877	30,596
12,36	111,23	0,60512	0,60512	2224,7	0,020171	2,0171	30,605
12,42	111,3	0,60799	0,60799	2226,1	0,020266	2,0266	30,608
12,49	111,12	0,60913	0,60913	2222,3	0,020304	2,0304	30,609
12,56	110,93	0,61027	0,61027	2218,6	0,020342	2,0342	30,61
12,62	110,93	0,61141	0,61141	2218,6	0,02038	2,038	30,611
12,69	111,26	0,61371	0,61371	2225,2	0,020457	2,0457	30,614
12,76	111,6	0,61649	0,61649	2231,9	0,02055	2,055	30,616
12,82	111,93	0,61927	0,61927	2238,6	0,020642	2,0642	30,619
12,89	112,26	0,62206	0,62206	2245,3	0,020735	2,0735	30,622
12,96	112,6	0,62484	0,62484	2251,9	0,020828	2,0828	30,625
13,02	112,92	0,62848	0,62848	2258,4	0,020949	2,0949	30,628
13,09	113,24	0,63224	0,63224	2264,8	0,021075	2,1075	30,632
13,16	113,56	0,63601	0,63601	2271,2	0,0212	2,12	30,636
13,22	114,29	0,63977	0,63977	2285,7	0,021326	2,1326	30,64
13,29	115,23	0,64845	0,64845	2304,7	0,021615	2,1615	30,648
13,36	115,5	0,6531	0,6531	2310,1	0,02177	2,177	30,653
13,42	115,31	0,6545	0,6545	2306,2	0,021817	2,1817	30,654
13,49	115,11	0,65589	0,65589	2302,3	0,021863	2,1863	30,656
13,56	115,15	0,65746	0,65746	2302,9	0,021915	2,1915	30,657
13,62	115,37	0,65988	0,65988	2307,5	0,021996	2,1996	30,66
13,69	115,6	0,6623	0,6623	2312,1	0,022077	2,2077	30,662
13,76	115,83	0,66472	0,66472	2316,6	0,022157	2,2157	30,665
13,82	116,06	0,66713	0,66713	2321,2	0,022238	2,2238	30,667
13,89	116,29	0,66955	0,66955	2325,8	0,022318	2,2318	30,67
13,96	116,69	0,67349	0,67349	2333,8	0,02245	2,245	30,673
14,02	117,19	0,67813	0,67813	2343,7	0,022604	2,2604	30,678
14,09	117,68	0,683	0,683	2353,7	0,022767	2,2767	30,683
14,16	118,18	0,6894	0,6894	2363,6	0,02298	2,298	30,689
14,23	119,78	0,6963	0,6963	2395,6	0,02321	2,321	30,696
14,29	119,58	0,70268	0,70268	2391,6	0,023423	2,3423	30,703
14,36	119,24	0,70344	0,70344	2384,8	0,023448	2,3448	30,703
14,43	118,9	0,7042	0,7042	2378	0,023473	2,3473	30,704
14,49	118,56	0,70497	0,70497	2371,3	0,023499	2,3499	30,705
14,56	118,61	0,70602	0,70602	2372,2	0,023534	2,3534	30,706
14,63	119,75	0,71042	0,71042	2394,9	0,023681	2,3681	30,71
14,69	119,92	0,7136	0,7136	2398,3	0,023787	2,3787	30,714
14,76	120,09	0,71631	0,71631	2401,8	0,023877	2,3877	30,716
14,83	120,26	0,71902	0,71902	2405,2	0,023967	2,3967	30,719
14,89	120,62	0,7224	0,7224	2412,4	0,02408	2,408	30,722
14,96	121,02	0,72656	0,72656	2420,3	0,024219	2,4219	30,727
15,03	121,41	0,73073	0,73073	2428,2	0,024358	2,4358	30,731
15,09	121,81	0,73489	0,73489	2436,2	0,024496	2,4496	30,735
15,16	122,2	0,73905	0,73905	2444,1	0,024635	2,4635	30,739
15,23	122,84	0,74595	0,74595	2456,8	0,024865	2,4865	30,746
15,29	122,96	0,74995	0,74995	2459,2	0,024998	2,4998	30,75
15,36	122,75	0,75112	0,75112	2455	0,025037	2,5037	30,751
15,43	122,54	0,75229	0,75229	2450,8	0,025076	2,5076	30,752
15,49	122,42	0,75352	0,75352	2448,5	0,025117	2,5117	30,754
15,56	123,05	0,7559	0,7559	2461,1	0,025197	2,5197	30,756
15,63	123,43	0,75829	0,75829	2468,6	0,025276	2,5276	30,758
15,69	123,79	0,76068	0,76068	2475,9	0,025356	2,5356	30,761
15,76	124,16	0,76306	0,76306	2483,1	0,025435	2,5435	30,763
15,83	124,52	0,76545	0,76545	2490,4	0,025515	2,5515	30,765
15,89	124,89	0,76996	0,76996	2497,7	0,025665	2,5665	30,77
15,96	125,25	0,77508	0,77508	2505	0,025836	2,5836	30,775
16,03	125,61	0,78084	0,78084	2512,3	0,026028	2,6028	30,781
16,1	125,98	0,78683	0,78683	2519,6	0,026228	2,6228	30,787
16,16	126,06	0,79392	0,79392	2521,3	0,026464	2,6464	30,794
16,23	126	0,79793	0,79793	2520	0,026598	2,6598	30,798
16,3	125,88	0,79862	0,79862	2517,5	0,026621	2,6621	30,799
16,36	125,74	0,79932	0,79932	2514,9	0,026644	2,6644	30,799
16,43	125,61	0,80001	0,80001	2512,2	0,026667	2,6667	30,8
16,5	126,02	0,80397	0,80397	2520,4	0,026799	2,6799	30,804
16,56	126,58	0,80705	0,80705	2531,6	0,026902	2,6902	30,807
16,63	126,81	0,80889	0,80889	2536,1	0,026963	2,6963	30,809
16,7	127,03	0,81072	0,81072	2540,6	0,027024	2,7024	30,811
16,76	127,26	0,81361	0,81361	2545,1	0,02712	2,712	30,814
16,83	127,49	0,81792	0,81792	2549,9	0,027264	2,7264	30,818
16,9	127,82	0,82224	0,82224	2556,3	0,027408	2,7408	30,822
16,96	128,14	0,82665	0,82665	2562,8	0,027555	2,7555	30,827
17,03	128,49	0,83241	0,83241	2569,9	0,027747	2,7747	30,832
17,1	128,93	0,84059	0,84059	2578,6	0,02802	2,802	30,841
17,16	129,26	0,84494	0,84494	2585,3	0,028165	2,8165	30,845
17,23	129,07	0,84575	0,84575	2581,5	0,028192	2,8192	30,846
17,3	128,89	0,84656	0,84656	2577,7	0,028219	2,8219	30,847
17,36	128,7	0,84737	0,84737	2573,9	0,028246	2,8246	30,847
17,43	129,23	0,85043	0,85043	2584,7	0,028348	2,8348	30,85
17,5	129,65	0,85452	0,85452	2592,9	0,028484	2,8484	30,855
17,56	129,67	0,85729	0,85729	2593,3	0,028576	2,8576	30,857
17,63	129,69	0,86005	0,86005	2593,7	0,028668	2,8668	30,86
17,7	129,71	0,86281	0,86281	2594,1	0,02876	2,876	30,863
17,76	129,98	0,86656	0,86656	2599,7	0,028885	2,8885	30,867
17,83	130,28	0,87061	0,87061	2605,5	0,02902	2,902	30,871
17,9	130,57	0,87467	0,87467	2611,4	0,029156	2,9156	30,875
17,97	130,86	0,87873	0,87873	2617,2	0,029291	2,9291	30,879
18,03	131,15	0,88279	0,88279	2623	0,029426	2,9426	30,883
18,1	131,62	0,88895	0,88895	2632,4	0,029632	2,9632	30,889
18,17	131,94	0,89442	0,89442	2638,7	0,029814	2,9814	30,894
18,23	131,68	0,89595	0,89595	2633,5	0,029865	2,9865	30,896
18,3	131,42	0,89747	0,89747	2628,3	0,029916	2,9916	30,897
18,37	131,31	0,89899	0,89899	2626,2	0,029966	2,9966	30,899
18,43	131,4	0,90072	0,90072	2628	0,030024	3,0024	30,901
18,5	131,49	0,90294	0,90294	2629,9	0,030098	3,0098	30,903
18,57	131,59	0,90515	0,90515	2631,8	0,030172	3,0172	30,905
18,63	131,68	0,90737	0,90737	2633,6	0,030246	3,0246	30,907
18,7	131,96	0,91076	0,91076	2639,1	0,030359	3,0359	30,911
18,77	132,37	0,91489	0,91489	2647,4	0,030496	3,0496	30,915
18,83	132,81	0,91901	0,91901	2656,1	0,030634	3,0634	30,919
18,9	133,27	0,92429	0,92429	2665,4	0,03081	3,081	30,924
18,97	133,73	0,9298	0,9298	2674,7	0,030993	3,0993	30,93
19,03	134,11	0,93561	0,93561	2682,2	0,031187	3,1187	30,936
19,1	133,76	0,94164	0,94164	2675,1	0,031388	3,1388	30,942
19,17	133,4	0,94265	0,94265	2668,1	0,031422	3,1422	30,943
19,23	133,48	0,94366	0,94366	2669,6	0,031455	3,1455	30,944
19,3	133,79	0,94467	0,94467	2675,8	0,031489	3,1489	30,945
19,37	133,87	0,94704	0,94704	2677,4	0,031568	3,1568	30,947
19,43	133,81	0,9496	0,9496	2676,2	0,031653	3,1653	30,95
19,5	133,75	0,95289	0,95289	2675	0,031763	3,1763	30,953
19,57	133,69	0,95654	0,95654	2673,9	0,031885	3,1885	30,957
19,63	133,81	0,96019	0,96019	2676,2	0,032006	3,2006	30,96
19,7	134,09	0,96384	0,96384	2681,8	0,032128	3,2128	30,964
19,77	134,37	0,96749	0,96749	2687,4	0,03225	3,225	30,967
19,83	134,65	0,97114	0,97114	2693	0,032371	3,2371	30,971
19,9	134,93	0,97568	0,97568	2698,6	0,032523	3,2523	30,976
19,97	135,84	0,98389	0,98389	2716,7	0,032796	3,2796	30,984
20,04	136,09	0,98986	0,98986	2721,7	0,032995	3,2995	30,99
20,1	135,65	0,99047	0,99047	2713,1	0,033016	3,3016	30,99
20,17	135,22	0,99108	0,99108	2704,4	0,033036	3,3036	30,991
20,24	134,79	0,99168	0,99168	2695,8	0,033056	3,3056	30,992
20,3	135,33	0,99357	0,99357	2706,5	0,033119	3,3119	30,994
20,37	135,77	0,99743	0,99743	2715,4	0,033248	3,3248	30,997
20,44	135,86	1,0003	1,0003	2717,3	0,033343	3,3343	31
20,5	135,96	1,0032	1,0032	2719,2	0,033439	3,3439	31,003
20,57	136,05	1,006	1,006	2721	0,033534	3,3534	31,006
20,64	136,3	1,0094	1,0094	2725,9	0,033645	3,3645	31,009
20,7	136,56	1,0134	1,0134	2731,2	0,03378	3,378	31,013
20,77	136,83	1,0175	1,0175	2736,5	0,033915	3,3915	31,017
20,84	137,09	1,0215	1,0215	2741,8	0,034051	3,4051	31,022
20,9	137,36	1,0265	1,0265	2747,1	0,034217	3,4217	31,026
20,97	137,35	1,0337	1,0337	2746,9	0,034456	3,4456	31,034
21,04	137,16	1,0367	1,0367	2743,2	0,034555	3,4555	31,037
21,1	137,09	1,0379	1,0379	2741,8	0,034598	3,4598	31,038
21,17	137,03	1,0392	1,0392	2740,6	0,034641	3,4641	31,039
21,24	136,97	1,0405	1,0405	2739,4	0,034684	3,4684	31,041
21,3	137,02	1,0427	1,0427	2740,4	0,034758	3,4758	31,043
21,37	137,1	1,0452	1,0452	2741,9	0,034839	3,4839	31,045
21,44	137,17	1,0476	1,0476	2743,4	0,034921	3,4921	31,048
21,5	137,24	1,0501	1,0501	2744,9	0,035002	3,5002	31,05
21,57	137,37	1,0538	1,0538	2747,5	0,035127	3,5127	31,054
21,64	137,62	1,0593	1,0593	2752,4	0,035311	3,5311	31,059
21,7	137,87	1,0643	1,0643	2757,3	0,035476	3,5476	31,064
21,77	138,11	1,069	1,069	2762,3	0,035634	3,5634	31,069
21,84	138,36	1,0737	1,0737	2767,2	0,035791	3,5791	31,074
21,91	139,57	1,0813	1,0813	2791,4	0,036042	3,6042	31,081
21,97	139,17	1,0849	1,0849	2783,5	0,036164	3,6164	31,085
22,04	138,78	1,086	1,086	2775,6	0,036201	3,6201	31,086
22,11	138,38	1,0871	1,0871	2767,6	0,036238	3,6238	31,087
22,17	138,01	1,0883	1,0883	2760,1	0,036275	3,6275	31,088
22,24	138,23	1,0906	1,0906	2764,5	0,036354	3,6354	31,091
22,31	138,44	1,0931	1,0931	2768,9	0,036436	3,6436	31,093
22,37	138,71	1,0955	1,0955	2774,3	0,036518	3,6518	31,096
22,44	138,99	1,098	1,098	2779,8	0,0366	3,66	31,098
22,51	139,27	1,101	1,101	2785,3	0,036701	3,6701	31,101
22,57	139,54	1,1054	1,1054	2790,8	0,036846	3,6846	31,105
22,64	139,82	1,1098	1,1098	2796,4	0,036992	3,6992	31,11
22,71	139,73	1,114	1,114	2794,6	0,037132	3,7132	31,114
22,77	140,11	1,1206	1,1206	2802,3	0,037354	3,7354	31,121
22,84	140,74	1,1295	1,1295	2814,7	0,037649	3,7649	31,129
22,91	140,3	1,1306	1,1306	2806	0,037686	3,7686	31,131
22,97	139,86	1,1317	1,1317	2797,2	0,037722	3,7722	31,132
23,04	139,42	1,1328	1,1328	2788,5	0,037759	3,7759	31,133
23,11	139,33	1,134	1,134	2786,6	0,037799	3,7799	31,134
23,17	139,81	1,1365	1,1365	2796,1	0,037883	3,7883	31,136
23,24	139,96	1,139	1,139	2799,3	0,037966	3,7966	31,139
23,31	140,12	1,1415	1,1415	2802,4	0,03805	3,805	31,142
23,37	140,28	1,144	1,144	2805,6	0,038134	3,8134	31,144
23,44	140,44	1,1474	1,1474	2808,7	0,038247	3,8247	31,147
23,51	140,59	1,152	1,152	2811,9	0,038398	3,8398	31,152
23,57	140,75	1,1566	1,1566	2815	0,038552	3,8552	31,157
23,64	140,41	1,1615	1,1615	2808,3	0,038717	3,8717	31,162
23,71	140,99	1,1665	1,1665	2819,7	0,038882	3,8882	31,166
23,78	141,48	1,1729	1,1729	2829,6	0,039097	3,9097	31,173
23,84	141,59	1,1814	1,1814	2831,7	0,039379	3,9379	31,181
23,91	141,25	1,1822	1,1822	2825	0,039407	3,9407	31,182
23,98	140,9	1,183	1,183	2818	0,039434	3,9434	31,183
24,04	140,55	1,1838	1,1838	2810,9	0,039462	3,9462	31,184
24,11	140,19	1,1847	1,1847	2803,9	0,039489	3,9489	31,185
24,18	140,42	1,1867	1,1867	2808,5	0,039556	3,9556	31,187
24,24	140,69	1,1891	1,1891	2813,8	0,039637	3,9637	31,189
24,31	140,96	1,1915	1,1915	2819,1	0,039718	3,9718	31,192
24,38	141,22	1,1942	1,1942	2824,5	0,039808	3,9808	31,194
24,44	141,35	1,2	1,2	2827	0,04	4	31,2
24,51	141,4	1,2045	1,2045	2828	0,040151	4,0151	31,205
24,58	141,45	1,2078	1,2078	2829,1	0,040261	4,0261	31,208
24,64	141,5	1,2121	1,2121	2830,1	0,040404	4,0404	31,212
24,71	142,02	1,2204	1,2204	2840,4	0,04068	4,068	31,22
24,78	142,19	1,2252	1,2252	2843,8	0,040839	4,0839	31,225
24,84	141,84	1,2267	1,2267	2836,9	0,040891	4,0891	31,227
24,91	141,5	1,2282	1,2282	2830	0,040939	4,0939	31,228
24,98	141,15	1,2296	1,2296	2823	0,040987	4,0987	31,23
25,04	141,1	1,2316	1,2316	2822,1	0,041054	4,1054	31,232
25,11	141,16	1,2342	1,2342	2823,2	0,041139	4,1139	31,234
25,18	141,22	1,2367	1,2367	2824,4	0,041223	4,1223	31,237
25,24	141,28	1,2392	1,2392	2825,5	0,041308	4,1308	31,239
25,31	141,34	1,2418	1,2418	2826,7	0,041393	4,1393	31,242
25,38	141,44	1,2449	1,2449	2828,9	0,041498	4,1498	31,245
25,44	141,68	1,2491	1,2491	2833,6	0,041636	4,1636	31,249
25,51	142,04	1,2534	1,2534	2840,9	0,041781	4,1781	31,253
25,58	142,61	1,2599	1,2599	2852,3	0,041998	4,1998	31,26
25,65	142,93	1,2681	1,2681	2858,6	0,042272	4,2272	31,268
25,71	142,31	1,2755	1,2755	2846,2	0,042517	4,2517	31,276
25,78	141,69	1,2759	1,2759	2833,8	0,042529	4,2529	31,276
25,85	141,07	1,2762	1,2762	2821,5	0,042541	4,2541	31,276
25,91	140,45	1,2766	1,2766	2809,1	0,042553	4,2553	31,277
25,98	140,55	1,2769	1,2769	2811	0,042565	4,2565	31,277
26,05	140,88	1,2796	1,2796	2817,6	0,042652	4,2652	31,28
26,11	141,2	1,2832	1,2832	2824,1	0,042774	4,2774	31,283
26,18	141,38	1,2857	1,2857	2827,6	0,042857	4,2857	31,286
26,25	141,46	1,2882	1,2882	2829,1	0,04294	4,294	31,288
26,31	141,53	1,292	1,292	2830,6	0,043067	4,3067	31,292
26,38	141,61	1,2962	1,2962	2832,1	0,043206	4,3206	31,296
26,45	141,68	1,3004	1,3004	2833,6	0,043346	4,3346	31,3
26,51	141,76	1,3046	1,3046	2835,1	0,043486	4,3486	31,305
26,58	141,83	1,3093	1,3093	2836,5	0,043642	4,3642	31,309
26,65	141,84	1,3178	1,3178	2836,8	0,043925	4,3925	31,318
26,71	141,66	1,3188	1,3188	2833,3	0,04396	4,396	31,319
26,78	141,17	1,3199	1,3199	2823,4	0,043996	4,3996	31,32
26,85	140,67	1,3209	1,3209	2813,4	0,044031	4,4031	31,321
26,91	140,19	1,322	1,322	2803,9	0,044066	4,4066	31,322
26,98	140,13	1,3292	1,3292	2802,5	0,044307	4,4307	31,329
27,05	140,06	1,3319	1,3319	2801,2	0,044396	4,4396	31,332
27,11	139,99	1,3346	1,3346	2799,9	0,044485	4,4485	31,335
27,18	139,93	1,3372	1,3372	2798,5	0,044574	4,4574	31,337
27,25	139,86	1,3399	1,3399	2797,2	0,044663	4,4663	31,34
27,31	140,25	1,3432	1,3432	2805	0,044774	4,4774	31,343
27,38	141,05	1,3474	1,3474	2821,1	0,044914	4,4914	31,347
27,45	141,29	1,3516	1,3516	2825,7	0,045054	4,5054	31,352
27,52	141,52	1,3558	1,3558	2830,4	0,045194	4,5194	31,356
27,58	141,53	1,3645	1,3645	2830,6	0,045482	4,5482	31,364
27,65	141,27	1,3692	1,3692	2825,4	0,045639	4,5639	31,369
27,72	140,59	1,3699	1,3699	2811,7	0,045662	4,5662	31,37
27,78	139,9	1,3706	1,3706	2798	0,045685	4,5685	31,371
27,85	139,22	1,3713	1,3713	2784,4	0,045709	4,5709	31,371
27,92	139,32	1,3756	1,3756	2786,4	0,045852	4,5852	31,376
27,98	139,6	1,3783	1,3783	2792	0,045943	4,5943	31,378
28,05	139,61	1,3793	1,3793	2792,3	0,045978	4,5978	31,379
28,12	139,63	1,3815	1,3815	2792,5	0,04605	4,605	31,382
28,18	139,64	1,3857	1,3857	2792,8	0,046191	4,6191	31,386
28,25	139,66	1,3899	1,3899	2793,2	0,046331	4,6331	31,39
28,32	139,69	1,3942	1,3942	2793,7	0,046472	4,6472	31,394
28,38	139,72	1,3984	1,3984	2794,3	0,046613	4,6613	31,398
28,45	139,75	1,4025	1,4025	2794,9	0,046751	4,6751	31,403
28,52	140,04	1,409	1,409	2800,8	0,046966	4,6966	31,409
28,58	140,24	1,4174	1,4174	2804,7	0,047247	4,7247	31,417
28,65	139,15	1,4182	1,4182	2783	0,047273	4,7273	31,418
28,72	138,07	1,419	1,419	2761,4	0,047299	4,7299	31,419
28,78	136,98	1,4198	1,4198	2739,7	0,047325	4,7325	31,42
28,85	136,73	1,4211	1,4211	2734,6	0,047369	4,7369	31,421
28,92	137,32	1,424	1,424	2746,5	0,047468	4,7468	31,424
28,98	137,39	1,4272	1,4272	2747,7	0,047575	4,7575	31,427
29,05	137,45	1,4308	1,4308	2749	0,047694	4,7694	31,431
29,12	137,51	1,4344	1,4344	2750,2	0,047813	4,7813	31,434
29,18	137,57	1,4379	1,4379	2751,5	0,047932	4,7932	31,438
29,25	136,95	1,4416	1,4416	2739	0,048053	4,8053	31,442
29,32	135,9	1,4453	1,4453	2718,1	0,048175	4,8175	31,445
29,39	134,86	1,4489	1,4489	2697,2	0,048297	4,8297	31,449
29,45	133,36	1,4526	1,4526	2667,2	0,04842	4,842	31,453
29,52	126,92	1,4606	1,4606	2538,4	0,048688	4,8688	31,461
29,59	119,71	1,4641	1,4641	2394,1	0,048805	4,8805	31,464
29,65	116,96	1,4662	1,4662	2339,3	0,048873	4,8873	31,466
29,72	114,22	1,4682	1,4682	2284,5	0,048942	4,8942	31,468
29,79	113,26	1,4703	1,4703	2265,2	0,04901	4,901	31,47
29,85	112,78	1,4724	1,4724	2255,6	0,049079	4,9079	31,472
29,92	112,3	1,4744	1,4744	2246,1	0,049147	4,9147	31,474
29,99	111,83	1,4765	1,4765	2236,5	0,049216	4,9216	31,476
30,05	111,35	1,4785	1,4785	2226,9	0,049284	4,9284	31,479
30,12	111,34	1,4811	1,4811	2226,9	0,049369	4,9369	31,481
30,19	112,61	1,4856	1,4856	2252,2	0,049521	4,9521	31,486
30,25	113,48	1,4902	1,4902	2269,7	0,049673	4,9673	31,49
30,32	114,09	1,4948	1,4948	2281,7	0,049826	4,9826	31,495
30,39	114,69	1,4993	1,4993	2293,8	0,049978	4,9978	31,499
30,45	115,29	1,5039	1,5039	2305,8	0,05013	5,013	31,504
30,52	114,77	1,5128	1,5128	2295,5	0,050426	5,0426	31,513
30,59	113,63	1,5145	1,5145	2272,6	0,050482	5,0482	31,514
30,65	112,49	1,5158	1,5158	2249,8	0,050526	5,0526	31,516
30,72	111,35	1,5171	1,5171	2226,9	0,050571	5,0571	31,517
30,79	111,41	1,5188	1,5188	2228,3	0,050627	5,0627	31,519
30,85	111,13	1,5209	1,5209	2222,5	0,050697	5,0697	31,521
30,92	110,43	1,523	1,523	2208,6	0,050767	5,0767	31,523
30,99	109,73	1,5251	1,5251	2194,7	0,050836	5,0836	31,525
31,05	109,08	1,528	1,528	2181,6	0,050932	5,0932	31,528
31,12	109,32	1,5323	1,5323	2186,4	0,051078	5,1078	31,532
31,19	109,56	1,5367	1,5367	2191,2	0,051224	5,1224	31,537
31,26	109,8	1,5411	1,5411	2196,1	0,05137	5,137	31,541
31,32	110,04	1,5455	1,5455	2200,9	0,051516	5,1516	31,545
31,39	110,51	1,5516	1,5516	2210,3	0,051719	5,1719	31,552
31,46	111,71	1,5607	1,5607	2234,3	0,052024	5,2024	31,561
31,52	110,04	1,5618	1,5618	2200,8	0,052059	5,2059	31,562
31,59	108,37	1,5628	1,5628	2167,4	0,052094	5,2094	31,563
31,66	106,7	1,5639	1,5639	2133,9	0,052129	5,2129	31,564
31,72	105,78	1,5654	1,5654	2115,6	0,052182	5,2182	31,565
31,79	105,73	1,568	1,568	2114,6	0,052265	5,2265	31,568
31,86	105,68	1,5705	1,5705	2113,7	0,052349	5,2349	31,57
31,92	105,63	1,573	1,573	2112,7	0,052432	5,2432	31,573
31,99	105,58	1,5757	1,5757	2111,7	0,052522	5,2522	31,576
32,06	106,01	1,5794	1,5794	2120,2	0,052647	5,2647	31,579
32,12	106,45	1,5832	1,5832	2129,1	0,052773	5,2773	31,583
32,19	106,9	1,587	1,587	2138	0,052899	5,2899	31,587
32,26	107,34	1,5907	1,5907	2146,9	0,053025	5,3025	31,591
32,32	108,05	1,5971	1,5971	2161	0,053236	5,3236	31,597
32,39	109,18	1,6043	1,6043	2183,6	0,053477	5,3477	31,604
32,46	109,42	1,6083	1,6083	2188,4	0,05361	5,361	31,608
32,52	108,6	1,6093	1,6093	2172,1	0,053643	5,3643	31,609
32,59	107,79	1,6103	1,6103	2155,7	0,053675	5,3675	31,61
32,66	106,97	1,6112	1,6112	2139,4	0,053708	5,3708	31,611
32,72	106,89	1,6133	1,6133	2137,7	0,053775	5,3775	31,613
32,79	106,87	1,6157	1,6157	2137,4	0,053856	5,3856	31,616
32,86	106,86	1,6181	1,6181	2137,1	0,053937	5,3937	31,618
32,92	106,84	1,6205	1,6205	2136,8	0,054018	5,4018	31,621
32,99	107,44	1,6252	1,6252	2148,8	0,054174	5,4174	31,625
33,06	108,17	1,6303	1,6303	2163,3	0,054342	5,4342	31,63
33,13	108,73	1,6349	1,6349	2174,5	0,054498	5,4498	31,635
33,19	109,27	1,6396	1,6396	2185,3	0,054653	5,4653	31,64
33,26	109,81	1,6443	1,6443	2196,2	0,054809	5,4809	31,644
33,33	111,18	1,6526	1,6526	2223,6	0,055087	5,5087	31,653
33,39	111,13	1,6564	1,6564	2222,5	0,055214	5,5214	31,656
33,46	109,9	1,6568	1,6568	2198	0,055226	5,5226	31,657
33,53	108,68	1,6571	1,6571	2173,5	0,055238	5,5238	31,657
33,59	107,45	1,6575	1,6575	2149,1	0,055249	5,5249	31,657
33,66	107,04	1,6611	1,6611	2140,7	0,055369	5,5369	31,661
33,73	107,15	1,664	1,664	2143	0,055468	5,5468	31,664
33,79	107,27	1,6666	1,6666	2145,3	0,055554	5,5554	31,667
33,86	107,38	1,6692	1,6692	2147,6	0,055641	5,5641	31,669
33,93	107,6	1,6725	1,6725	2152	0,05575	5,575	31,672
33,99	108,54	1,677	1,677	2170,8	0,055899	5,5899	31,677
34,06	109,23	1,6814	1,6814	2184,5	0,056048	5,6048	31,681
34,13	109,79	1,6859	1,6859	2195,7	0,056197	5,6197	31,686
34,19	110,35	1,6904	1,6904	2206,9	0,056345	5,6345	31,69
34,26	111,05	1,6972	1,6972	2221,1	0,056572	5,6572	31,697
34,33	111,35	1,7026	1,7026	2227,1	0,056754	5,6754	31,703
34,39	110,43	1,7042	1,7042	2208,5	0,056806	5,6806	31,704
34,46	109,5	1,7058	1,7058	2190	0,056858	5,6858	31,706
34,53	108,75	1,7073	1,7073	2174,9	0,056911	5,6911	31,707
34,59	108,6	1,7089	1,7089	2172	0,056963	5,6963	31,709
34,66	108,45	1,7105	1,7105	2169,1	0,057015	5,7015	31,71
34,73	108,31	1,713	1,713	2166,1	0,0571	5,71	31,713
34,79	108,16	1,7159	1,7159	2163,2	0,057198	5,7198	31,716
34,86	108,54	1,7193	1,7193	2170,8	0,057311	5,7311	31,719
34,93	109,44	1,7237	1,7237	2188,7	0,057457	5,7457	31,724
35	109,83	1,7282	1,7282	2196,6	0,057606	5,7606	31,728
35,06	110,22	1,7333	1,7333	2204,4	0,057775	5,7775	31,733
35,13	110,61	1,7383	1,7383	2212,3	0,057945	5,7945	31,738
35,2	111,01	1,7434	1,7434	2220,2	0,058114	5,8114	31,743
35,26	111,88	1,7503	1,7503	2237,5	0,058343	5,8343	31,75
35,33	111,1	1,7528	1,7528	2222	0,058428	5,8428	31,753
35,4	110,02	1,7538	1,7538	2200,3	0,058461	5,8461	31,754
35,46	108,93	1,7548	1,7548	2178,7	0,058495	5,8495	31,755
35,53	107,85	1,7558	1,7558	2157	0,058528	5,8528	31,756
35,6	107,82	1,758	1,758	2156,4	0,058601	5,8601	31,758
35,66	108,03	1,7613	1,7613	2160,6	0,058708	5,8708	31,761
35,73	108,25	1,7645	1,7645	2164,9	0,058816	5,8816	31,764
35,8	108,46	1,7677	1,7677	2169,2	0,058924	5,8924	31,768
35,86	108,78	1,7717	1,7717	2175,6	0,059058	5,9058	31,772
35,93	109,15	1,7761	1,7761	2182,9	0,059203	5,9203	31,776
36	109,51	1,7804	1,7804	2190,3	0,059347	5,9347	31,78
36,06	109,88	1,7847	1,7847	2197,6	0,059491	5,9491	31,785
36,13	110,25	1,7891	1,7891	2205	0,059636	5,9636	31,789
36,2	110,47	1,7957	1,7957	2209,4	0,059855	5,9855	31,796
36,26	109,96	1,799	1,799	2199,2	0,059968	5,9968	31,799
36,33	108,92	1,8004	1,8004	2178,4	0,060014	6,0014	31,8
36,4	107,88	1,8018	1,8018	2157,6	0,06006	6,006	31,802
36,46	107,14	1,8032	1,8032	2142,9	0,060107	6,0107	31,803
36,53	107,04	1,8055	1,8055	2140,8	0,060184	6,0184	31,806
36,6	106,93	1,808	1,808	2138,7	0,060267	6,0267	31,808
36,66	106,83	1,8105	1,8105	2136,6	0,060351	6,0351	31,811
36,73	106,72	1,813	1,813	2134,5	0,060434	6,0434	31,813
36,8	106,82	1,8164	1,8164	2136,4	0,060546	6,0546	31,816
36,86	107,06	1,8204	1,8204	2141,2	0,060681	6,0681	31,82
36,93	107,3	1,8245	1,8245	2146	0,060815	6,0815	31,824
37	107,54	1,8285	1,8285	2150,8	0,06095	6,095	31,828
37,07	108,8	1,8361	1,8361	2176	0,061202	6,1202	31,836
37,13	109,98	1,844	1,844	2199,7	0,061467	6,1467	31,844
37,2	108,81	1,845	1,845	2176,2	0,061501	6,1501	31,845
37,27	107,64	1,846	1,846	2152,8	0,061533	6,1533	31,846
37,33	106,47	1,847	1,847	2129,4	0,061565	6,1565	31,847
37,4	105,86	1,8485	1,8485	2117,2	0,061617	6,1617	31,849
37,47	105,7	1,8507	1,8507	2114	0,06169	6,169	31,851
37,53	105,54	1,8529	1,8529	2110,9	0,061763	6,1763	31,853
37,6	105,39	1,8551	1,8551	2107,7	0,061836	6,1836	31,855
37,67	105,23	1,8573	1,8573	2104,6	0,061909	6,1909	31,857
37,73	106,23	1,864	1,864	2124,6	0,062132	6,2132	31,864
37,8	106,83	1,8676	1,8676	2136,6	0,062255	6,2255	31,868
37,87	106,75	1,8713	1,8713	2135	0,062377	6,2377	31,871
37,93	106,67	1,8765	1,8765	2133,4	0,062549	6,2549	31,876
38	107,25	1,8817	1,8817	2145,1	0,062723	6,2723	31,882
38,07	108,62	1,8878	1,8878	2172,4	0,062926	6,2926	31,888
38,13	108,65	1,8925	1,8925	2173	0,063082	6,3082	31,892
38,2	107,62	1,8937	1,8937	2152,4	0,063125	6,3125	31,894
38,27	106,59	1,895	1,895	2131,8	0,063167	6,3167	31,895
38,33	105,7	1,8964	1,8964	2114,1	0,063213	6,3213	31,896
38,4	105,48	1,8988	1,8988	2109,7	0,063294	6,3294	31,899
38,47	105,26	1,9012	1,9012	2105,3	0,063375	6,3375	31,901
38,53	105,05	1,9037	1,9037	2100,9	0,063455	6,3455	31,904
38,6	104,83	1,9061	1,9061	2096,5	0,063536	6,3536	31,906
38,67	104,63	1,9085	1,9085	2092,6	0,063617	6,3617	31,909
38,73	104,91	1,9126	1,9126	2098,2	0,063754	6,3754	31,913
38,8	105,19	1,9168	1,9168	2103,7	0,063892	6,3892	31,917
38,87	105,47	1,9209	1,9209	2109,3	0,06403	6,403	31,921
38,94	105,74	1,925	1,925	2114,9	0,064168	6,4168	31,925
39	108,18	1,9363	1,9363	2163,6	0,064542	6,4542	31,936
39,07	108,15	1,941	1,941	2163	0,064699	6,4699	31,941
39,14	106,89	1,9416	1,9416	2137,8	0,064719	6,4719	31,942
39,2	105,63	1,9422	1,9422	2112,6	0,06474	6,474	31,942
39,27	104,37	1,9428	1,9428	2087,4	0,06476	6,476	31,943
39,34	104,05	1,9455	1,9455	2080,9	0,06485	6,485	31,945
39,4	103,97	1,9489	1,9489	2079,5	0,064964	6,4964	31,949
39,47	103,9	1,9514	1,9514	2078	0,065048	6,5048	31,951
39,54	103,83	1,9539	1,9539	2076,5	0,065132	6,5132	31,954
39,6	103,75	1,9565	1,9565	2075,1	0,065215	6,5215	31,956
39,67	103,95	1,9601	1,9601	2079,1	0,065335	6,5335	31,96
39,74	104,32	1,964	1,964	2086,4	0,065465	6,5465	31,964
39,8	104,68	1,9679	1,9679	2093,6	0,065596	6,5596	31,968
39,87	105,04	1,9718	1,9718	2100,9	0,065726	6,5726	31,972
39,94	105,99	1,9785	1,9785	2119,9	0,065949	6,5949	31,978
40	107,2	1,9868	1,9868	2144	0,066225	6,6225	31,987
40,07	106,11	1,9878	1,9878	2122,1	0,066259	6,6259	31,988
40,14	105,02	1,9888	1,9888	2100,3	0,066294	6,6294	31,989
40,2	104,1	1,99	1,99	2081,9	0,066333	6,6333	31,99
40,27	104,06	1,993	1,993	2081,1	0,066433	6,6433	31,993
40,34	104,02	1,9958	1,9958	2080,3	0,066528	6,6528	31,996
40,4	103,98	1,9984	1,9984	2079,6	0,066614	6,6614	31,998
40,47	103,94	2,001	2,001	2078,8	0,066701	6,6701	32,001
40,54	103,94	2,0038	2,0038	2078,8	0,066794	6,6794	32,004
40,6	104,08	2,0073	2,0073	2081,5	0,066911	6,6911	32,007
40,67	104,21	2,0108	2,0108	2084,2	0,067028	6,7028	32,011
40,74	104,34	2,0143	2,0143	2086,8	0,067144	6,7144	32,014
40,81	104,47	2,0178	2,0178	2089,5	0,067261	6,7261	32,018
40,87	105,01	2,0232	2,0232	2100,1	0,067439	6,7439	32,023
40,94	106,58	2,0321	2,0321	2131,5	0,067736	6,7736	32,032
41,01	106,3	2,0359	2,0359	2126	0,067865	6,7865	32,036
41,07	105,38	2,0375	2,0375	2107,6	0,067915	6,7915	32,037
41,14	104,46	2,039	2,039	2089,3	0,067966	6,7966	32,039
41,21	103,82	2,0407	2,0407	2076,5	0,068023	6,8023	32,041
41,27	103,59	2,0431	2,0431	2071,7	0,068102	6,8102	32,043
41,34	103,35	2,0454	2,0454	2066,9	0,06818	6,818	32,045
41,41	103,11	2,0478	2,0478	2062,2	0,068259	6,8259	32,048
41,47	102,87	2,0501	2,0501	2057,4	0,068338	6,8338	32,05
41,54	102,8	2,0525	2,0525	2056	0,068417	6,8417	32,052
41,61	103,29	2,0565	2,0565	2065,9	0,068549	6,8549	32,056
41,67	103,79	2,0607	2,0607	2075,7	0,068689	6,8689	32,061
41,74	104,28	2,0649	2,0649	2085,6	0,068829	6,8829	32,065
41,81	104,56	2,0691	2,0691	2091,2	0,068969	6,8969	32,069
41,87	104,77	2,0733	2,0733	2095,4	0,06911	6,911	32,073
41,94	106,99	2,0851	2,0851	2139,8	0,069505	6,9505	32,085
42,01	105,79	2,0856	2,0856	2115,8	0,069521	6,9521	32,086
42,07	104,59	2,0862	2,0862	2091,8	0,069538	6,9538	32,086
42,14	103,39	2,0867	2,0867	2067,8	0,069555	6,9555	32,087
42,21	102,76	2,0888	2,0888	2055,2	0,069626	6,9626	32,089
42,27	102,58	2,0922	2,0922	2051,6	0,069739	6,9739	32,092
42,34	102,39	2,0952	2,0952	2047,9	0,069838	6,9838	32,095
42,41	102,21	2,0981	2,0981	2044,2	0,069936	6,9936	32,098
42,47	102,08	2,101	2,101	2041,7	0,070034	7,0034	32,101
42,54	102,68	2,1043	2,1043	2053,6	0,070144	7,0144	32,104
42,61	103,27	2,1082	2,1082	2065,3	0,070273	7,0273	32,108
42,68	103,71	2,1121	2,1121	2074,2	0,070403	7,0403	32,112
42,74	104,16	2,1159	2,1159	2083,1	0,070532	7,0532	32,116
42,81	104,6	2,1198	2,1198	2092	0,070661	7,0661	32,12
42,88	107,12	2,1333	2,1333	2142,3	0,07111	7,111	32,133
42,94	105,94	2,1343	2,1343	2118,8	0,071142	7,1142	32,134
43,01	104,76	2,1345	2,1345	2095,2	0,071151	7,1151	32,135
43,08	103,58	2,1348	2,1348	2071,7	0,071161	7,1161	32,135
43,14	102,41	2,1351	2,1351	2048,1	0,071171	7,1171	32,135
43,21	101,82	2,137	2,137	2036,4	0,071235	7,1235	32,137
43,28	101,92	2,1394	2,1394	2038,4	0,071314	7,1314	32,139
43,34	102,02	2,1424	2,1424	2040,4	0,071414	7,1414	32,142
43,41	102,12	2,1461	2,1461	2042,5	0,071538	7,1538	32,146
43,48	102,78	2,1516	2,1516	2055,7	0,07172	7,172	32,152
43,54	103,36	2,1557	2,1557	2067,1	0,071856	7,1856	32,156
43,61	103,41	2,1587	2,1587	2068,2	0,071955	7,1955	32,159
43,68	103,46	2,1617	2,1617	2069,2	0,072055	7,2055	32,162
43,74	104,51	2,169	2,169	2090,2	0,0723	7,23	32,169
43,81	106,07	2,1764	2,1764	2121,3	0,072546	7,2546	32,176
43,88	105,7	2,1796	2,1796	2114	0,072652	7,2652	32,18
43,94	104,55	2,1813	2,1813	2090,9	0,072709	7,2709	32,181
44,01	103,39	2,1822	2,1822	2067,8	0,072741	7,2741	32,182
44,08	102,24	2,1832	2,1832	2044,7	0,072773	7,2773	32,183
44,14	101,87	2,1851	2,1851	2037,3	0,072836	7,2836	32,185
44,21	101,85	2,1884	2,1884	2037,1	0,072948	7,2948	32,188
44,28	101,84	2,1903	2,1903	2036,8	0,07301	7,301	32,19
44,34	102,22	2,1924	2,1924	2044,4	0,073079	7,3079	32,192
44,41	102,89	2,197	2,197	2057,8	0,073232	7,3232	32,197
44,48	103,56	2,2008	2,2008	2071,3	0,073361	7,3361	32,201
44,55	103,8	2,2047	2,2047	2076,1	0,07349	7,349	32,205
44,61	103,57	2,2086	2,2086	2071,3	0,073619	7,3619	32,209
44,68	104	2,2128	2,2128	2079,9	0,073759	7,3759	32,213
44,75	105,45	2,224	2,224	2109,1	0,074134	7,4134	32,224
44,81	105,1	2,2263	2,2263	2101,9	0,074211	7,4211	32,226
44,88	104,16	2,2273	2,2273	2083,2	0,074244	7,4244	32,227
44,95	103,23	2,2283	2,2283	2064,6	0,074278	7,4278	32,228
45,01	102,29	2,2293	2,2293	2045,9	0,074311	7,4311	32,229
45,08	102,07	2,2318	2,2318	2041,3	0,074392	7,4392	32,232
45,15	101,88	2,2343	2,2343	2037,7	0,074477	7,4477	32,234
45,21	101,7	2,2372	2,2372	2034	0,074573	7,4573	32,237
45,28	101,52	2,2403	2,2403	2030,4	0,074675	7,4675	32,24
45,35	101,85	2,2435	2,2435	2037,1	0,074783	7,4783	32,243
45,41	103,07	2,2479	2,2479	2061,4	0,074931	7,4931	32,248
45,48	103,1	2,2523	2,2523	2062,1	0,075077	7,5077	32,252
45,55	103,14	2,2565	2,2565	2062,8	0,075218	7,5218	32,257
45,61	103,17	2,2608	2,2608	2063,4	0,07536	7,536	32,261
45,68	104,69	2,2673	2,2673	2093,8	0,075575	7,5575	32,267
45,75	105,25	2,2735	2,2735	2105	0,075785	7,5785	32,274
45,81	104,4	2,2751	2,2751	2088	0,075838	7,5838	32,275
45,88	103,55	2,2767	2,2767	2071	0,07589	7,589	32,277
45,95	102,83	2,2783	2,2783	2056,7	0,075943	7,5943	32,278
46,01	102,72	2,2801	2,2801	2054,4	0,076003	7,6003	32,28
46,08	102,61	2,2825	2,2825	2052,1	0,076082	7,6082	32,282
46,15	102,49	2,2848	2,2848	2049,9	0,07616	7,616	32,285
46,21	102,38	2,2872	2,2872	2047,6	0,076238	7,6238	32,287
46,28	102,35	2,2901	2,2901	2047,1	0,076335	7,6335	32,29
46,35	102,55	2,2939	2,2939	2051	0,076464	7,6464	32,294
46,42	102,74	2,2978	2,2978	2054,9	0,076592	7,6592	32,298
46,48	102,94	2,3016	2,3016	2058,7	0,07672	7,672	32,302
46,55	103,13	2,3084	2,3084	2062,6	0,076947	7,6947	32,308
46,62	104,38	2,3154	2,3154	2087,6	0,077179	7,7179	32,315
46,68	105,52	2,3199	2,3199	2110,3	0,077331	7,7331	32,32
46,75	104,54	2,3236	2,3236	2090,8	0,077452	7,7452	32,324
46,82	103,56	2,324	2,324	2071,2	0,077468	7,7468	32,324
46,88	102,59	2,3245	2,3245	2051,7	0,077484	7,7484	32,325
46,95	101,61	2,325	2,325	2032,2	0,077499	7,7499	32,325
47,02	101,52	2,3277	2,3277	2030,4	0,07759	7,759	32,328
47,08	101,61	2,3305	2,3305	2032,3	0,077682	7,7682	32,33
47,15	101,71	2,3334	2,3334	2034,2	0,07778	7,778	32,333
47,22	101,8	2,3367	2,3367	2036,1	0,077889	7,7889	32,337
47,28	102,01	2,3406	2,3406	2040,1	0,078019	7,8019	32,341
47,35	102,32	2,3449	2,3449	2046,3	0,078165	7,8165	32,345
47,42	102,63	2,3496	2,3496	2052,6	0,078321	7,8321	32,35
47,48	102,94	2,3543	2,3543	2058,8	0,078477	7,8477	32,354
47,55	103,93	2,3602	2,3602	2078,6	0,078672	7,8672	32,36
47,62	104,72	2,3679	2,3679	2094,5	0,078932	7,8932	32,368
47,68	103,77	2,3692	2,3692	2075,3	0,078974	7,8974	32,369
47,75	102,81	2,3703	2,3703	2056,1	0,07901	7,901	32,37
47,82	101,85	2,3714	2,3714	2037	0,079046	7,9046	32,371
47,88	101,54	2,3733	2,3733	2030,9	0,07911	7,911	32,373
47,95	101,39	2,3755	2,3755	2027,8	0,079184	7,9184	32,376
48,02	101,28	2,3777	2,3777	2025,6	0,079258	7,9258	32,378
48,08	101,36	2,38	2,38	2027,3	0,079332	7,9332	32,38
48,15	101,45	2,3822	2,3822	2028,9	0,079406	7,9406	32,382
48,22	101,65	2,3867	2,3867	2033,1	0,079558	7,9558	32,387
48,29	102,01	2,3925	2,3925	2040,2	0,079749	7,9749	32,392
48,35	102,37	2,3969	2,3969	2047,4	0,079895	7,9895	32,397
48,42	102,73	2,4013	2,4013	2054,5	0,080042	8,0042	32,401
48,49	103,24	2,4063	2,4063	2064,7	0,08021	8,021	32,406
48,55	105,61	2,4169	2,4169	2112,2	0,080563	8,0563	32,417
48,62	104,92	2,4196	2,4196	2098,4	0,080654	8,0654	32,42
48,69	103,86	2,4201	2,4201	2077,1	0,080669	8,0669	32,42
48,75	102,79	2,4205	2,4205	2055,8	0,080684	8,0684	32,421
48,82	101,73	2,421	2,421	2034,5	0,0807	8,07	32,421
48,89	100,66	2,4214	2,4214	2013,3	0,080715	8,0715	32,421
48,95	100,69	2,4247	2,4247	2013,7	0,080823	8,0823	32,425
49,02	100,84	2,4281	2,4281	2016,9	0,080937	8,0937	32,428
49,09	101	2,4297	2,4297	2020,1	0,080991	8,0991	32,43
49,15	101,21	2,4338	2,4338	2024,2	0,081125	8,1125	32,434
49,22	101,52	2,4378	2,4378	2030,5	0,081262	8,1262	32,438
49,29	101,84	2,4419	2,4419	2036,8	0,081398	8,1398	32,442
49,35	102,38	2,4468	2,4468	2047,5	0,081558	8,1558	32,447
49,42	103,15	2,452	2,452	2063	0,081733	8,1733	32,452
49,49	103,89	2,4578	2,4578	2077,8	0,081926	8,1926	32,458
49,55	103,32	2,4644	2,4644	2066,5	0,082147	8,2147	32,464
49,62	102,76	2,4659	2,4659	2055,2	0,082197	8,2197	32,466
49,69	102,43	2,4671	2,4671	2048,6	0,082235	8,2235	32,467
49,75	102,33	2,4682	2,4682	2046,6	0,082273	8,2273	32,468
49,82	102,23	2,4703	2,4703	2044,6	0,082342	8,2342	32,47
49,89	102,13	2,4728	2,4728	2042,6	0,082427	8,2427	32,473
49,95	102,03	2,4754	2,4754	2040,6	0,082512	8,2512	32,475
50,02	101,93	2,4779	2,4779	2038,6	0,082597	8,2597	32,478
50,09	101,83	2,4805	2,4805	2036,6	0,082682	8,2682	32,48
50,16	101,93	2,4838	2,4838	2038,7	0,082793	8,2793	32,484
50,22	102,23	2,4877	2,4877	2044,6	0,082923	8,2923	32,488
50,29	102,52	2,4916	2,4916	2050,5	0,083052	8,3052	32,492
50,36	102,82	2,4955	2,4955	2056,4	0,083182	8,3182	32,495
50,42	103,61	2,5048	2,5048	2072,3	0,083494	8,3494	32,505
50,49	104,18	2,5115	2,5115	2083,5	0,083716	8,3716	32,511
50,56	103,18	2,5121	2,5121	2063,7	0,083738	8,3738	32,512
50,62	102,19	2,5128	2,5128	2043,8	0,083759	8,3759	32,513
50,69	101,2	2,5134	2,5134	2023,9	0,08378	8,378	32,513
50,76	100,81	2,5162	2,5162	2016,2	0,083873	8,3873	32,516
50,82	100,72	2,5199	2,5199	2014,3	0,083996	8,3996	32,52
50,89	100,62	2,5228	2,5228	2012,4	0,084094	8,4094	32,523
50,96	100,84	2,5258	2,5258	2016,9	0,084192	8,4192	32,526
51,02	101,12	2,5287	2,5287	2022,4	0,08429	8,429	32,529
51,09	101,4	2,5319	2,5319	2027,9	0,084396	8,4396	32,532
51,16	101,67	2,5358	2,5358	2033,5	0,084526	8,4526	32,536
51,22	101,95	2,5397	2,5397	2039	0,084656	8,4656	32,54
51,29	102,23	2,5436	2,5436	2044,5	0,084787	8,4787	32,544
51,36	103,12	2,5505	2,5505	2062,5	0,085016	8,5016	32,55
51,42	104,47	2,5593	2,5593	2089,5	0,085312	8,5312	32,559
51,49	103,48	2,56	2,56	2069,5	0,085334	8,5334	32,56
51,56	102,48	2,5607	2,5607	2049,5	0,085357	8,5357	32,561
51,62	101,48	2,5614	2,5614	2029,6	0,08538	8,538	32,561
51,69	100,94	2,563	2,563	2018,7	0,085435	8,5435	32,563
51,76	101,23	2,5669	2,5669	2024,6	0,085563	8,5563	32,567
51,82	101,09	2,5695	2,5695	2021,7	0,085649	8,5649	32,569
51,89	100,94	2,572	2,572	2018,8	0,085735	8,5735	32,572
51,96	100,79	2,5746	2,5746	2015,8	0,085821	8,5821	32,575
52,03	100,95	2,5779	2,5779	2019	0,08593	8,593	32,578
52,09	101,15	2,5815	2,5815	2023	0,08605	8,605	32,582
52,16	101,35	2,5851	2,5851	2026,9	0,08617	8,617	32,585
52,23	101,89	2,5887	2,5887	2037,9	0,08629	8,629	32,589
52,29	102,52	2,5928	2,5928	2050,3	0,086426	8,6426	32,593
52,36	103,48	2,6041	2,6041	2069,6	0,086804	8,6804	32,604
52,43	103,4	2,6075	2,6075	2068,1	0,086915	8,6915	32,607
52,49	102,62	2,6087	2,6087	2052,4	0,086955	8,6955	32,609
52,56	101,83	2,6098	2,6098	2036,7	0,086995	8,6995	32,61
52,63	101,22	2,6114	2,6114	2024,4	0,087048	8,7048	32,611
52,69	101,06	2,6139	2,6139	2021,2	0,08713	8,713	32,614
52,76	100,9	2,6164	2,6164	2018	0,087212	8,7212	32,616
52,83	100,74	2,6188	2,6188	2014,7	0,087295	8,7295	32,619
52,89	100,57	2,6213	2,6213	2011,5	0,087377	8,7377	32,621
52,96	100,51	2,624	2,624	2010,1	0,087468	8,7468	32,624
53,03	100,83	2,6282	2,6282	2016,6	0,087606	8,7606	32,628
53,09	101,15	2,6323	2,6323	2023,1	0,087744	8,7744	32,632
53,16	101,48	2,6365	2,6365	2029,5	0,087882	8,7882	32,636
53,23	101,8	2,6406	2,6406	2036	0,08802	8,802	32,641
53,29	102,3	2,6466	2,6466	2046	0,088219	8,8219	32,647
53,36	103,59	2,655	2,655	2071,9	0,088499	8,8499	32,655
53,43	102,6	2,6559	2,6559	2052	0,088528	8,8528	32,656
53,49	101,61	2,6567	2,6567	2032,1	0,088558	8,8558	32,657
53,56	100,61	2,6576	2,6576	2012,2	0,088587	8,8587	32,658
53,63	100,12	2,6596	2,6596	2002,4	0,088655	8,8655	32,66
53,69	99,949	2,6626	2,6626	1999	0,088753	8,8753	32,663
53,76	99,777	2,6657	2,6657	1995,5	0,088858	8,8858	32,666
53,83	99,604	2,6691	2,6691	1992,1	0,088971	8,8971	32,669
53,9	99,668	2,6725	2,6725	1993,4	0,089085	8,9085	32,673
53,96	100,48	2,676	2,676	2009,6	0,089199	8,9199	32,676
54,03	100,62	2,6796	2,6796	2012,4	0,08932	8,932	32,68
54,1	100,76	2,6832	2,6832	2015,1	0,089441	8,9441	32,683
54,16	100,89	2,6869	2,6869	2017,9	0,089562	8,9562	32,687
54,23	101,48	2,6927	2,6927	2029,6	0,089756	8,9756	32,693
54,3	103,48	2,7023	2,7023	2069,5	0,090076	9,0076	32,702
54,36	102,81	2,7051	2,7051	2056,3	0,090168	9,0168	32,705
54,43	101,89	2,7059	2,7059	2037,8	0,090197	9,0197	32,706
54,5	100,96	2,7068	2,7068	2019,3	0,090225	9,0225	32,707
54,56	100,04	2,7076	2,7076	2000,8	0,090253	9,0253	32,708
54,63	99,71	2,7096	2,7096	1994,2	0,090321	9,0321	32,71
54,7	99,641	2,7122	2,7122	1992,8	0,090407	9,0407	32,712
54,76	99,571	2,7148	2,7148	1991,4	0,090493	9,0493	32,715
54,83	99,501	2,7174	2,7174	1990	0,09058	9,058	32,717
54,9	99,7	2,7208	2,7208	1994	0,090692	9,0692	32,721
54,96	100,18	2,7249	2,7249	2003,6	0,090829	9,0829	32,725
55,03	100,64	2,729	2,729	2012,8	0,090965	9,0965	32,729
55,1	100,79	2,7334	2,7334	2015,9	0,091112	9,1112	32,733
55,16	100,95	2,7383	2,7383	2018,9	0,091275	9,1275	32,738
55,23	102,74	2,7476	2,7476	2054,8	0,091585	9,1585	32,748
55,3	102,45	2,7509	2,7509	2049	0,091698	9,1698	32,751
55,36	101,72	2,7524	2,7524	2034,5	0,091748	9,1748	32,752
55,43	100,99	2,7539	2,7539	2019,9	0,091798	9,1798	32,754
55,5	100,27	2,7554	2,7554	2005,3	0,091848	9,1848	32,755
55,56	99,802	2,7569	2,7569	1996	0,091898	9,1898	32,757
55,63	99,762	2,7594	2,7594	1995,2	0,091979	9,1979	32,759
55,7	99,722	2,7619	2,7619	1994,4	0,092063	9,2063	32,762
55,76	99,681	2,7644	2,7644	1993,6	0,092147	9,2147	32,764
55,83	99,751	2,7675	2,7675	1995	0,09225	9,225	32,767
55,9	100	2,7715	2,7715	2000,1	0,092382	9,2382	32,771
55,97	100,25	2,7754	2,7754	2005,1	0,092515	9,2515	32,775
56,03	100,78	2,7805	2,7805	2015,6	0,092683	9,2683	32,78
56,1	101,36	2,7858	2,7858	2027,2	0,092859	9,2859	32,786
56,17	102,21	2,7923	2,7923	2044,2	0,093076	9,3076	32,792
56,23	102,86	2,7988	2,7988	2057,1	0,093292	9,3292	32,799
56,3	101,87	2,7996	2,7996	2037,3	0,09332	9,332	32,8
56,37	100,88	2,8004	2,8004	2017,5	0,093347	9,3347	32,8
56,43	99,933	2,8013	2,8013	1998,7	0,093376	9,3376	32,801
56,5	99,73	2,8034	2,8034	1994,6	0,093446	9,3446	32,803
56,57	99,527	2,8055	2,8055	1990,5	0,093516	9,3516	32,805
56,63	99,433	2,8076	2,8076	1988,7	0,093586	9,3586	32,808
56,7	99,477	2,8097	2,8097	1989,5	0,093655	9,3655	32,81
56,77	99,581	2,8139	2,8139	1991,6	0,093796	9,3796	32,814
56,83	99,894	2,8202	2,8202	1997,9	0,094006	9,4006	32,82
56,9	100,21	2,8237	2,8237	2004,2	0,094123	9,4123	32,824
56,97	100,54	2,8272	2,8272	2010,8	0,094239	9,4239	32,827
57,03	100,87	2,8307	2,8307	2017,4	0,094355	9,4355	32,831
57,1	101,31	2,8369	2,8369	2026,2	0,094563	9,4563	32,837
57,17	102,39	2,8455	2,8455	2047,8	0,09485	9,485	32,846
57,23	101,55	2,8467	2,8467	2031,1	0,09489	9,489	32,847
57,3	100,72	2,8479	2,8479	2014,4	0,094929	9,4929	32,848
57,37	99,884	2,8491	2,8491	1997,7	0,094969	9,4969	32,849
57,43	99,049	2,8502	2,8502	1981	0,095008	9,5008	32,85
57,5	13,216			264,32
57,57	-0,22844			-4,5689
57,58	-0,24059			-4,8117